Workbook

Sheet references
B2: Strid, Röös & Tidåker. (2014). Förluster av svenskt nötkött inom primärproduktion och slakt. SJV Rapport 2014:07

Sheet default
A1: f_breed | B1: f_prod_system | C1: f_sub_system | D1: f_animal | E1: f_feed | F1: f_from_ps | G1: f_to_ps | H1: parameter | I1: value | J1: unit | K1: description | L1: source
A2: Milk production
A3: Dairy
A4: dairy | B4: conventional | H4: milk_prod | I4: =AVERAGE(9829,9903,9953,10112,10330) -> 10025.4 | J4: kg/cow/year | K4: Total incl. for calves | L4: Växa Husdjursstatistik Tab. 17 (2016-2020)
A5: dairy | B5: conventional | H5: milk_fat | I5: =AVERAGE(4.3,4.2,4.2,4.3,4.3) -> 4.26 | J5: % | L5: Växa Husdjursstatistik Tab. 17 (2016-2020)
A6: dairy | B6: conventional | H6: milk_protein | I6: =AVERAGE(3.5,3.6,3.5,3.6,3.6) -> 3.56 | J6: % | L6: Växa Husdjursstatistik Tab. 17 (2016-2020)
A7: dairy | B7: organic | H7: milk_prod | I7: =AVERAGE(9135,9246,9280,9499,9676) -> 9367.2 | J7: kg/cow/year | L7: Växa Husdjursstatistik Tab. 17 (2016-2020)
A8: dairy | B8: organic | H8: milk_fat | I8: =AVERAGE(4.2,4.1,4.1,4.1,4.2) -> 4.14 | J8: % | L8: Växa Husdjursstatistik Tab. 17 (2016-2020)
A9: dairy | B9: organic | H9: milk_protein | I9: =AVERAGE(3.4,3.4,3.4,3.5,3.5) -> 3.44 | J9: % | L9: Växa Husdjursstatistik Tab. 17 (2016-2020)
A10: dairy | H10: milk_to_dairy | I10: 89 | J10: % | K10: share of milk delivered to dairy (sould incl. home cons.) | L10: Växa + Swedish Board of Agriculture
A11: Beef
A12: beef | H12: milk_prod | I12: =2013/(0.25+I13/100*12.2+I14/100*7.7) -> 1973.6068 | J12: kg/cow/year | K12: Converted from ECM. 2013 kg ECM/cow/year | L12: Hessle (2016) in Bertilsson (2016)
A13: beef | H13: milk_fat | I13: 4.14 | J13: % | K13: Assumes same as dairy cows
A14: beef | H14: milk_protein | I14: 3.44 | J14: % | K14: Assumes same as dairy cows | O14: milk kg x 0,25 + fat kg x 12,2 + protein kg x 7,7
A15: beef | H15: milk_to_dairy | I15: 0 | J15: %
A17: Fertility etc.
A18: Dairy
A19: dairy | B19: conventional | H19: calving_interval | I19: 13.2 | J19: months
A20: dairy | B20: organic | H20: calving_interval | I20: 12.9 | J20: months
A21: dairy | B21: conventional | H21: AFC | I21: 27 | J21: months | K21: age at first calving
A22: dairy | B22: organic | H22: AFC | I22: 27 | J22: months | K22: age at first calving
A23: dairy | B23: conventional | H23: recruitment_rate | I23: 37.1 | J23: % | K23: % of cows per year
A24: dairy | B24: organic | H24: recruitment_rate | I24: 36.1 | J24: % | K24: % of cows per year
A25: dairy | H25: ratio_male_calf | I25: 50.655978 | J25: % | K25: % of calves
A26: dairy | H26: twin_birth | I26: 3.2446264 | J26: % | K26: % of calvings
A27: dairy | B27: conventional | H27: stillborn_calf | I27: 5 | J27: % | K27: % of calvings
A28: dairy | B28: organic | H28: stillborn_calf | I28: 4.6 | J28: % | K28: % of calvings
A29: dairy | H29: weaning_age | I29: 100 | J29: days
A30: dairy | B30: conventional | H30: breeding_bulls_per_cow | I30: 0 | J30: nr
A31: dairy | B31: organic | H31: breeding_bulls_per_cow | I31: 0 | J31: nr
A33: Beef
A34: beef | H34: calving_interval | I34: 12.7 | J34: months
A35: beef | H35: AFC | I35: 28.68 | J35: months | K35: age at first calving
A36: beef | H36: recruitment_rate | I36: 25.100803 | J36: % | K36: % of cows per year
A37: beef | H37: ratio_male_calf | I37: 51.7 | J37: % | K37: % of calves
A38: beef | H38: twin_birth | I38: 4.5730449 | J38: % | K38: % of calvings
A39: beef | H39: stillborn_calf | I39: 2.2748383 | J39: % | K39: % of calvings
A40: beef | H40: weaning_age | I40: 212.8 | J40: days
A41: beef | B41: conventional | H41: breeding_bulls_per_cow | I41: 0 | J41: nr
A42: beef | B42: organic | H42: breeding_bulls_per_cow | I42: 0 | J42: nr
...

Sheet scn_baseline
A1: f_breed | B1: parameter | C1: val_is | D1: y_2020 | E1: y_2025 | F1: y_2030 | G1: y_2035 | H1: y_2040 | I1: y_2045 | J1: y_2050
A2: dairy | B2: milk_prod | C2: rel | D2: 1 | E2: =D2*1.01^5 -> 1.0510101 | F2: =E2*1.0081^5 -> 1.0942711 | G2: =F2*1.0061^5 -> 1.1280561 | H2: =G2*1.004^5 -> 1.1507984 | I2: =H2*1.002^5 -> 1.1623525 | J2: =I2*1.001^5 -> 1.1681759

Sheet Antal djur
B2: Mjölk besättningar | Y2: Diko besättningar
D3: Number | F3: Slaughtered | H3: Slaughtered (1000 tonnes) | J3: Dead/culled | AA3: Number | AC3: Slaughtered | AE3: Slaughtered (1000 tonnes) | AG3: Dead/culled
D4: Conv | E4: Org | F4: Conv | G4: Org | H4: Conv | I4: Org | J4: Conv | K4: Org | M4: Parameter | P4: Konv | Q4: Eko | R4: Enhet | T4: Källa | AA4: Conv | AB4: Org | AC4: Conv | AD4: Org | AE4: Conv | AF4: Org | AG4: Conv | AH4: Org | AJ4: Parameter | AM4: Konv | AN4: Eko | AO4: Enhet | AQ4: Källa
B5: Cows | D5: =D80*(1-E58/100) -> 261212.59 | E5: =D80*(E58/100) -> 55025.412 | F5: =D5*P7/100-J5 -> 79669.839 | G5: =E5*Q7/100-K5 -> 16232.497 | H5: =F5*P30/1000000 -> 24.39636 | I5: =G5*Q30/1000000 -> 4.9706869 | J5: =D5*P14/100 -> 17240.031 | K5: =E5*Q14/100 -> 3631.6772 | M5: Kalvningsintervall | P5: 13.2 | Q5: 12.9 | R5: mån | T5: (Växa tab 29) | Y5: Cows | AA5: =D81*(1-E59/100) -> 133821.07 | AB5: =D81*(E59/100) -> 72692.928 | AC5: =AA5*AM7/100-AG5 -> 30913.743 | AD5: =AB5*AN7/100-AH5 -> 16792.65 | AE5: =AC5*AM30/1000000 -> 10.529212 | AF5: =AD5*AN30/1000000 -> 5.7195719 | AG5: =AA5*AM14/100 -> 2676.4214 | AH5: =AB5*AN14/100 -> 1453.8586 | AJ5: Kalvningsintervall | AM5: =(12.7+12.7+12.7+12.7)/4 -> 12.7 | AN5: 12.7 | AO5: mån | AQ5: (Växa Husdjursstatistik 2020, tab 31)
B6: Heifers | D6: =D23*((P6-12)/12)+D27*((P25-12)/12) -> 145506.87 | E6: =E23*((Q6-12)/12)+E27*((Q25-12)/12) -> 27661.24 | F6: =D27 -> 14432.778 | G6: =E27 -> 1676.6639 | H6: =F6*P31/1000000 -> 4.3016645 | I6: =G6*Q31/1000000 -> 0.49972676 | M6: Inkalvningsålder | P6: 27 | Q6: 27 | R6: mån | T6: (Växa tab 29) | Y6: Heifers | AA6: =AA23*((AM6-12)/12)+AA27*((AM25-12)/12) -> 82615.684 | AB6: =AB23*((AN6-12)/12)+AB27*((AN25-12)/12) -> 39646.056 | AC6: =AA27 -> 28789.133 | AD6: =AB27 -> 11446.148 | AE6: =AC6*AM31/1000000 -> 8.9006236 | AF6: =AD6*AN31/1000000 -> 3.5387608 | AJ6: Inkalvningsålder | AM6: =(27.5+28.4+27.6+29.9+30)/5 -> 28.68 | AN6: =AM6 -> 28.68 | AO6: mån | AQ6: (Växa Husdjursstatistik 2020, tab 32)
B7: Steers | D7: =D28*((P27-12)/12) -> 26197.664 | E7: =E28*((Q27-12)/12) -> 2297.4411 | F7: =D28 -> 17767.611 | G7: =E28 -> 1558.1557 | H7: =F7*P33/1000000 -> 5.7888147 | I7: =G7*Q33/1000000 -> 0.50765827 | M7: Rekrytering | P7: 37.1 | Q7: 36.1 | R7: % | T7: (Växa tab 28) | Y7: Steers | AA7: =AA28*((AM27-12)/12) -> 8491.7251 | AB7: =AB28*((AN27-12)/12) -> 14285.7 | AC7: =AA28 -> 6195.4586 | AD7: =AB28 -> 10422.672 | AE7: =AC7*AM33/1000000 -> 2.0791692 | AF7: =AD7*AN33/1000000 -> 3.4978037 | AJ7: Rekrytering | AM7: =1/(AM24/12-AM6/12)*100 -> 25.100803 | AN7: =1/(AN24/12-AN6/12)*100 -> 25.100803 | AO7: % | AQ7: (ber.)
B8: Bulls | D8: =D29*((P28-12)/12) -> 90192.497 | E8: =E29*((Q28-12)/12) -> 722.47408 | F8: =D29 -> 102298.86 | G8: =E29 -> 819.45034 | H8: =F8*P34/1000000 -> 33.643696 | I8: =G8*Q34/1000000 -> 0.26949801 | M8: Könskvot, tjurkalvar | P8: =(48.7*77196+51.7*144627)/221823 -> 50.655978 | Q8: =P8 -> 50.655978 | R8: % | T8: (Växa Husdjursstatistik 2020, tab 20) | Y8: Bulls | AA8: =AA29*((AM28-12)/12) -> 40948.478 | AB8: =AB29*((AN28-12)/12) -> 12552.5 | AC8: =AA29 -> 60602.886 | AD8: =AB29 -> 18577.435 | AE8: =AC8*AM34/1000000 -> 21.722134 | AF8: =AD8*AN34/1000000 -> 6.6587841 | AJ8: Könskvot, tjurkalvar | AM8: 51.7 | AN8: =AM8 -> 51.7 | AO8: % | AQ8: (Växa KAP, tab 34)
B9: Calves | D9: =((D13-D17)*P16+(D14-D18)*P18+(D17-D19)*P20+(D18-D20)*P22+(D23+D27+D28+D29)*365.25+D24*P26*30.44)/365.25 -> 243483.84 | E9: =((E13-E17)*Q16+(E14-E18)*Q18+(E17-E19)*Q20+(E18-E20)*Q22+(E23+E27+E28+E29)*365.25+E24*Q26*30.44)/365.25 -> 25125.948 | F9: =D24 -> 11233.649 | G9: =E24 -> 338.62081 | H9: =F9*P32/1000000 -> 1.9042543 | I9: =G9*Q32/1000000 -> 0.057400775 | J9: =SUM(D21:D22) -> 23373.094 | K9: =SUM(E21:E22) -> 3061.7383 | M9: Tvilingfödslar | P9: =(79242*1.07+141785*4.46)/(79242+141785) -> 3.2446264 | Q9: =P9 -> 3.2446264 | R9: % | Y9: Calves | AA9: =((AA13-AA17)*AM16+(AA14-AA18)*AM18+(AA17-AA19)*AM20+(AA18-AA20)*AM22+(AA23+AA27+AA28+AA29)*365.25+AA24*AM26*30.44)/365.25 -> 132996.35 | AB9: =((AB13-AB17)*AN16+(AB14-AB18)*AN18+(AB17-AB19)*AN20+(AB18-AB20)*AN22+(AB23+AB27+AB28+AB29)*365.25+AB24*AN26*30.44)/365.25 -> 60532.101 | AC9: =AA24 -> 2408.7171 | AD9: =AB24 -> 1019.2087 | AE9: =AC9*AM32/1000000 -> 0.37893011 | AF9: =AD9*AN32/1000000 -> 0.16033799 | AG9: =SUM(AA21:AA22) -> 7304.4279 | AH9: =SUM(AB21:AB22) -> 3729.9363 | AJ9: Tvilingfödslar | AM9: 4.5730449 | AN9: =AM9 -> 4.5730449 | AO9: % | AQ9: (Växa Husdjursstatistik 2020, tab 34a)
M10: Dödfödda kalvar | P10: 5 | Q10: 4.6 | R10: % | T10: (Växa tab 28) | AJ10: Dödfödda kalvar | AM10: =(2.4*10433+1.6*1935)/(10433+1935) -> 2.2748383 | AN10: =AM10 -> 2.2748383 | AO10: % | AQ10: (Växa Husdjursstatistik 2020, tab 31)
B11: Intermediates | D11: Conv | E11: Org | G11: Andel | H11: =SUM(H5:H9)/SUM($H5:$I9,$AE5:$AF9) -> 0.50195123 | I11: =SUM(I5:I9)/SUM($H5:$I9,$AE5:$AF9) -> 0.045188796 | M11: Lev. kalvar per år | P11: =(12/P5*(1-P7/100)+(P7/100))*(1*(1-P9/100)+2*(P9/100))*(1-P10/100) -> 0.92473865 | Q11: =(12/Q5*(1-Q7/100)+(Q7/100))*(1*(1-Q9/100)+2*(Q9/100))*(1-Q10/100) -> 0.94104312 | R11: antal/ko/år | T11: (ber.) | Y11: Intermediates | AA11: Conv | AB11: Org | AD11: Andel | AE11: =SUM(AE5:AE9)/SUM($H5:$I9,$AE5:$AF9) -> 0.31256077 | AF11: =SUM(AF5:AF9)/SUM($H5:$I9,$AE5:$AF9) -> 0.1402992 | AJ11: Lev. kalvar per år | AM11: =(12/AM5*(1-AM7/100)+(AM7/100))*(1*(1-AM9/100)+2*(AM9/100))*(1-AM10/100) -> 0.97975293 | AN11: =(12/AN5*(1-AN7/100)+(AN7/100))*(1*(1-AN9/100)+2*(AN9/100))*(1-AN10/100) -> 0.97975293 | AO11: antal/ko/år | AQ11: (ber.)
B12: Calves born | D12: =D5*P11 -> 241553.38 | E12: =E5*Q11 -> 51781.286 | H12: =H11/SUM(H11:I11) -> 0.91740908 | I12: =I11/SUM(H11:I11) -> 0.082590916 | M12: Avvänjningsålder | P12: 100 | Q12: =P12 -> 100 | R12: dagar | T12: RISE | Y12: Calves born | AA12: =AA5*AM11 -> 131111.59 | AB12: =AB5*AN11 -> 71221.109 | AE12: =AE11/SUM(AE11:AF11) -> 0.69019297 | AF12: =AF11/SUM(AE11:AF11) -> 0.30980703 | AJ12: Avvänjningsålder | AM12: =7*30.4 -> 212.8 | AN12: =AM12 -> 212.8 | AO12: dagar
B13: Male calves born | D13: =D12*P8/100 -> 122361.23 | E13: =E12*Q8/100 -> 26230.317 | M13: Dödlighet | Y13: Male calves born | AA13: =AA12*AM8/100 -> 67784.691 | AB13: =AB12*AN8/100 -> 36821.313 | AJ13: Dödlighet
B14: Female calves born | D14: =D12-D13 -> 119192.15 | E14: =E12-E13 -> 25550.969 | M14: kor | P14: 6.6 | Q14: =P14 -> 6.6 | R14: % av djur | T14: RISE | Y14: Female calves born | AA14: =AA12-AA13 -> 63326.897 | AB14: =AB12-AB13 -> 34399.796 | AJ14: kor | AM14: 2 | AN14: =AM14 -> 2 | AO14: % av djur | AQ14: RISE
B15: Male calves 2 weaned before redist | D15: =D13*(1-P15/100) -> 117222.06 | E15: =E13*(1-Q15/100) -> 25128.644 | M15: tjurkalv (föds.-avv.) | P15: 4.2 | Q15: =P15 -> 4.2 | R15: % av levande födda | T15: RISE | AA15: =AA13*(1-AM15/100) -> 65073.303 | AB15: =AB13*(1-AN15/100) -> 35348.461 | AJ15: tjurkalv (föds.-avv.) | AM15: 4 | AN15: =AM15 -> 4 | AO15: % av levande födda | AQ15: RISE
B16: Female calves 2 weaned before redist | D16: =D14*(1-P17/100) -> 115139.62 | E16: =E14*(1-Q17/100) -> 24682.236 | M16: snittålder | P16: 10 | Q16: =P16 -> 10 | R16: dagar | T16: RISE | AA16: =AA14*(1-AM17/100) -> 61300.436 | AB16: =AB14*(1-AN17/100) -> 33299.002 | AJ16: snittålder | AM16: 3 | AN16: =AM16 -> 3 | AO16: dagar | AQ16: RISE
B17: Male calves 2 weaned | D17: =D15+E15*P39/100 -> 139586.55 | E17: =E15-E15*P39/100 -> 2764.1508 | M17: kvigkalv (föds.-avv.) | P17: 3.4 | Q17: =P17 -> 3.4 | R17: % av levande födda | T17: RISE | Y17: Male calves 2 weaned | AA17: =AA15+AB15*AM39/100 -> 70022.087 | AB17: =AB15-AB15*AM39/100 -> 30399.676 | AJ17: kvigkalv (föds.-avv.) | AM17: 3.2 | AN17: =AM17 -> 3.2 | AO17: % av levande födda | AQ17: RISE
B18: Female calves 2 weaned | D18: =D16+E16*P40/100 -> 117237.61 | E18: =E16-E16*P40/100 -> 22584.246 | M18: snittålder | P18: 10 | Q18: =P18 -> 10 | R18: dagar | T18: RISE | Y18: Female calves 2 weaned | AA18: =AA16+AB16*AM40/100 -> 64130.851 | AB18: =AB16-AB16*AM40/100 -> 30468.587 | AJ18: snittålder | AM18: 10 | AN18: =AM18 -> 10 | AO18: dagar | AQ18: RISE
B19: Male calves 2 end | D19: =D17*(1-P19/100) -> 130094.66 | E19: =E17*(1-Q19/100) -> 2576.1885 | M19: tjurar/stutar (avv.-slakt) | P19: 6.8 | Q19: =P19 -> 6.8 | R19: % av avvanda | T19: RISE | Y19: Male calves 2 end | AA19: =AA17*(1-AM19/100) -> 68481.602 | AB19: =AB17*(1-AN19/100) -> 29730.883 | AJ19: tjurar/stutar (avv.-slakt) | AM19: 2.2 | AN19: =AM19 -> 2.2 | AO19: % av avvanda | AQ19: RISE
B20: Female calves 2 end | D20: =D18*(1-P21/100) -> 112548.1 | E20: =E18*(1-Q21/100) -> 21680.876 | M20: snittålder | P20: 59 | Q20: =P20 -> 59 | R20: dagar | T20: RISE | Y20: Female calves 2 end | AA20: =AA18*(1-AM21/100) -> 63104.757 | AB20: =AB18*(1-AN21/100) -> 29981.09 | AJ20: snittålder | AM20: 234 | AN20: =AM20 -> 234 | AO20: dagar | AQ20: RISE
B21: Male calves 2 dead | D21: =D13-D15+D17-D19 -> 14631.057 | E21: =E13-E15+E17-E19 -> 1289.6356 | M21: kvigor (avv.-slakt) | P21: 4 | Q21: =P21 -> 4 | R21: % av avvanda | T21: RISE | Y21: Male calves 2 dead | AA21: =AA13-AA15+AA17-AA19 -> 4251.8735 | AB21: =AB13-AB15+AB17-AB19 -> 2141.6454 | AJ21: kvigor (avv.-slakt) | AM21: 1.6 | AN21: =AM21 -> 1.6 | AO21: % av avvanda | AQ21: RISE
B22: Female calves 2 dead | D22: =D14-D16+D18-D20 -> 8742.0374 | E22: =E14-E16+E18-E20 -> 1772.1028 | M22: snittålder | P22: 59 | Q22: =P22 -> 59 | R22: dagar | T22: RISE | Y22: Female calves 2 dead | AA22: =AA14-AA16+AA18-AA20 -> 3052.5543 | AB22: =AB14-AB16+AB18-AB20 -> 1588.2909 | AJ22: snittålder | AM22: 241 | AN22: =AM22 -> 241 | AO22: dagar | AQ22: RISE
B23: Calves 2 recruitment | D23: =D5*P7/100 -> 96909.87 | E23: =E5*Q7/100 -> 19864.174 | M23: Slaktålder | Y23: Calves 2 recruitment | AA23: =AA5*AM7/100 -> 33590.164 | AB23: =AB5*AN7/100 -> 18246.509 | AJ23: Slaktålder
B24: Calves 2 slaughter | D24: =(SUM(D19:D20)-D23)*P36/100 -> 11233.649 | E24: =(SUM(E19:E20)-E23)*Q36/100 -> 338.62081 | M24: kor | P24: 60.9 | Q24: 61.5 | R24: mån | T24: (Växa tab 28) | Y24: Calves 2 slaughter | AA24: =(SUM(AA19:AA20)-AA23)*AM36/100 -> 2408.7171 | AB24: =(SUM(AB19:AB20)-AB23)*AN36/100 -> 1019.2087 | AJ24: kor | AM24: ='G&D sammanställning'!K5 -> 76.487235 | AN24: =AM24 -> 76.487235 | AO24: mån
B25: Male calves 2 slaughter | D25: =D24*(D19)/(D19+D20-D23) -> 10028.194 | E25: =E24*(E19)/(E19+E20-E23) -> 198.58246 | M25: kvigor | P25: ='G&D sammanställning'!H8 -> 32.261824 | Q25: =P25 -> 32.261824 | R25: mån | Y25: Male calves 2 slaughter | AA25: =AA24*(AA19)/(AA19+AA20-AA23) -> 1683.2573 | AB25: =AB24*(AB19)/(AB19+AB20-AB23) -> 730.77621 | AJ25: kvigor | AM25: ='G&D sammanställning'!K8 -> 26.974548 | AN25: =AM25 -> 26.974548 | AO25: mån
B26: Female calves 2 slaughter | D26: =D24-D25 -> 1205.4548 | E26: =E24-E25 -> 140.03835 | M26: mellankalv | P26: ='G&D sammanställning'!H13 -> 10.897126 | Q26: =P26 -> 10.897126 | R26: mån | Y26: Female calves 2 slaughter | AA26: =AA24-AA25 -> 725.45986 | AB26: =AB24-AB25 -> 288.43248 | AJ26: mellankalv | AM26: ='G&D sammanställning'!K13 -> 10.935039 | AN26: =AM26 -> 10.935039 | AO26: mån
B27: Calves 2 heifers | D27: =D20-D23-D26 -> 14432.778 | E27: =E20-E23-E26 -> 1676.6639 | M27: stutar | P27: ='G&D sammanställning'!H9 -> 29.693542 | Q27: =P27 -> 29.693542 | R27: mån | Y27: Calves 2 heifers | AA27: =AA20-AA23-AA26 -> 28789.133 | AB27: =AB20-AB23-AB26 -> 11446.148 | AJ27: stutar | AM27: ='G&D sammanställning'!K9 -> 28.447645 | AN27: =AM27 -> 28.447645 | AO27: mån
B28: Calves 2 steers | D28: =(D19-D25)*(P37/100) -> 17767.611 | E28: =(E19-E25)*(Q37/100) -> 1558.1557 | M28: tjurar | P28: ='G&D sammanställning'!H10 -> 22.579883 | Q28: =P28 -> 22.579883 | R28: mån | Y28: Calves 2 steers | AA28: =(AA19-AA25)*(AM37/100) -> 6195.4586 | AB28: =(AB19-AB25)*(AN37/100) -> 10422.672 | AD28: 6180.1797 | AE28: 10387.902 | AJ28: tjurar | AM28: ='G&D sammanställning'!K10 -> 20.108223 | AN28: =AM28 -> 20.108223 | AO28: mån
B29: Calves 2 bulls | D29: =D19-D25-D28 -> 102298.86 | E29: =E19-E25-E28 -> 819.45034 | M29: Slaktvikt | Y29: Calves 2 bulls | AA29: =AA19-AA25-AA28 -> 60602.886 | AB29: =AB19-AB25-AB28 -> 18577.435 | AD29: 60706.757 | AE29: 18612.205 | AJ29: Slaktvikt
M30: kor | P30: ='G&D sammanställning'!B5 -> 306.21826 | Q30: =P30 -> 306.21826 | R30: kg | AJ30: kor | AM30: ='G&D sammanställning'!E5 -> 340.59971 | AN30: =AM30 -> 340.59971 | AO30: kg
M31: kvigor | P31: ='G&D sammanställning'!B8 -> 298.04827 | Q31: =P31 -> 298.04827 | R31: kg | AJ31: kvigor | AM31: ='G&D sammanställning'!E8 -> 309.16608 | AN31: =AM31 -> 309.16608 | AO31: kg
M32: mellankalv | P32: ='G&D sammanställning'!B13 -> 169.51343 | Q32: =P32 -> 169.51343 | R32: kg | AJ32: mellankalv | AM32: ='G&D sammanställning'!E13 -> 157.31615 | AN32: =AM32 -> 157.31615 | AO32: kg
M33: stutar | P33: ='G&D sammanställning'!B9 -> 325.80714 | Q33: =P33 -> 325.80714 | R33: kg | AJ33: stutar | AM33: ='G&D sammanställning'!E9 -> 335.59568 | AN33: =AM33 -> 335.59568 | AO33: kg
M34: tjurar | P34: ='G&D sammanställning'!B10 -> 328.87656 | Q34: =P34 -> 328.87656 | R34: kg | AJ34: tjurar | AM34: ='G&D sammanställning'!E10 -> 358.43398 | AN34: =AM34 -> 358.43398 | AO34: kg
M35: Andel av slaktade ungdjur | S35: adj | AJ35: Andel av slaktade ungdjur | AP35: adj
M36: som kalv | P36: ='G&D sammanställning'!$T$13*S36 -> 7.7083823 | Q36: ='G&D sammanställning'!$T$13*T36 -> 7.7083823 | R36: % | S36: 0.95 | T36: 0.95 | AJ36: mellankalv | AM36: ='G&D sammanställning'!$W$13*AP36 -> 2.4579701 | AN36: ='G&D sammanställning'!$W$13*AQ36 -> 2.4579701 | AO36: % | AP36: 0.95 | AQ36: 0.95
M37: som stut (av handjur) | P37: ='G&D sammanställning'!$T$9/SUM('G&D sammanställning'!T9:T10)*100*S37 -> 14.798146 | Q37: ='G&D sammanställning'!$T$9/SUM('G&D sammanställning'!T9:T10)*100*T37 -> 65.534646 | R37: % | S37: 0.7 | T37: 3.1 | AJ37: stutar | AM37: ='G&D sammanställning'!$W$9/SUM('G&D sammanställning'!W9:W10)*100*AP37 -> 9.2748685 | AN37: ='G&D sammanställning'!$W$9/SUM('G&D sammanställning'!W9:W10)*100*AQ37 -> 35.940115 | AO37: % | AP37: 0.8 | AQ37: 3.1
M38: Överföring djur eko -> konv | AJ38: Överföring djur eko -> konv
M39: tjurkalvar | P39: 89 | R39: % | T39: (uppskattat baserat på stat.) | AJ39: tjurkalvar | AM39: 14 | AO39: %
M40: kvigkalvar | P40: 8.5 | R40: % | T40: (uppskattat baserat på stat.) | AJ40: kvigkalvar | AM40: 8.5 | AO40: %
D42: Från modell | F42: Kontroll
...

Sheet Foderstater
B2: FEED RATIONS | C2: Ahlgren et al 2022 | X2: Mikaela Lindberg
C3: Tabell 10 | L3: Tabell 11 | R3: Tabell 12 | X3: pers. com. 2023-04
C4: Diko | F4: Köttrastjur | I4: Avelstjur | L4: Mjölkrastjur | O4: Mjölkrasstut | R4: Köttrasstut | U4: Köttraskviga | X4: Mjölkko | Y4: Mjölkko
C5: Gsk | D5: Gns | E5: Nn | F5: Gsk | G5: Gns | H5: Nn | I5: Gsk | J5: Gns | K5: Nn | L5: Gsk | M5: Gns | N5: Nn | O5: Gsk | P5: Gns | Q5: Nn | R5: Gsk | S5: Gns | T5: Nn | U5: Gsk | V5: Gns | W5: Nn | X5: vall | Y5: majs | AF5: DM
B6: Vallensilage, tidigt, kg tsb | F6: 1229 | H6: 1329 | L6: 2119 | N6: 2130 | X6: 2973.75 | Y6: 1619.55 | AF6: 1
B7: Vallensilage, medelsen, kg ts | O7: 2663 | P7: 2561 | Q7: 2690 | R7: 2568 | S7: 2502 | T7: 2401 | U7: 2506 | V7: 2459 | W7: 2431 | X7: 711.5 | Y7: 751.15 | AF7: 1
B8: Vallensilage, sent, kg tsb | C8: 659 | D8: 1254 | E8: 770 | J8: 1235 | AF8: 1
B9: Vallensilage, klöverrikt, kg ts | G9: 1165 | M9: 1868 | AF9: 1
B10: Majsensilage, kg ts | G10: 272 | M10: 436 | Y10: 1250.5 | AF10: 1
B11: Helsädesensilage, kg tsb | C11: 977 | E11: 970 | I11: 1536 | K11: 1614 | AF11: 1
B12: Halm, kgb | D12: 299 | J12: 139 | X12: 207.4 | Y12: 207.4 | AF12: 0.85
B13: Permanent bete, kg tsc | C13: 1953 | D13: 2053 | E13: 1806 | I13: 1313 | J13: 1390 | K13: 1235 | O13: 1548 | P13: 1662 | Q13: 1548 | R13: 932 | S13: 995 | T13: 951 | U13: 926 | V13: 978 | W13: 924 | AF13: 1
B14: Vallåterväxt, kg tsc | C14: 345 | D14: 362 | E14: 319 | I14: 232 | J14: 245 | K14: 218 | O14: 273 | P14: 293 | Q14: 273 | R14: 165 | S14: 176 | T14: 168 | U14: 163 | V14: 173 | W14: 163 | X14: 783 | Y14: 783 | AF14: 1
B15: Spannmål, kgc | F15: 861 | G15: 654 | L15: 1084 | M15: 1014 | O15: 188 | P15: 184 | X15: 1897.2525 | Y15: 1318.7895 | AF15: 0.87
B16: Åkerböna/ärt, kg | F16: 68 | G16: 78 | L16: 124 | M16: 32 | O16: 4 | P16: 3 | AF16: 0.87
B17: Färdigfoder, kg | H17: 991 | L17: 80 | M17: 79 | N17: 1279 | O17: 119 | P17: 119 | Q17: 294 | X17: 1120 | Y17: 1762 | AF17: 0.9
B18: Mineraler, kg | C18: 34 | D18: 34 | E18: 34 | F18: 12 | G18: 12 | H18: 14 | I18: 33 | J18: 33 | K18: 33 | L18: 22 | M18: 22 | N18: 21 | O18: 35 | P18: 35 | Q18: 35 | R18: 26 | S18: 26 | T18: 24 | U18: 26 | V18: 26 | W18: 26 | AF18: 1
B19: Total | C19: =SUM(C6:C18) -> 3968 | D19: =SUM(D6:D18) -> 4002 | E19: =SUM(E6:E18) -> 3899 | F19: =SUM(F6:F18) -> 2170 | G19: =SUM(G6:G18) -> 2181 | H19: =SUM(H6:H18) -> 2334 | I19: =SUM(I6:I18) -> 3114 | J19: =SUM(J6:J18) -> 3042 | ... Y19: =SUM(Y6:Y18) -> 7692.3895
B21: # Mjölkkor (2018) | C21: 103131 | D21: 40386 | E21: 21929
B22: # Dikor (2018) | C22: 87632 | D22: 21961 | E22: 15238
B24: Einarsson et al 2022 | C24: Feeds via feed industry | M24: Einarsson et al 2022 | P24: Cereals (on-farm)
B25: Supplementary Material | D25: DM | F25: DM | H25: share | I25: Share | M25: Supplementary Material | P25: Dairy | Q25: share | R25: Beef | S25: share | T25: Total | U25: to dairy
B26: Feed name | C26: Dairy | D26: share | E26: Beef | F26: share | G26: Total | H26: to dairy | I26: import | K26: DM | M26: Wheat | P26: =T26*U26 -> 77812.622 | Q26: =P26/SUM(P$26:P$29) -> 0.23414264 | R26: =T26-P26 -> 47594.139 | S26: =R26/SUM(R$26:R$29) -> 0.23414264 | T26: 125406.76 | U26: 0.62048187
B27: Grain maize | C27: =G27*H27 -> 8000.2143 | D27: =C27*$K27/SUMPRODUCT(C$27:C$47,$K$27:$K$47) -> 0.010616665 | E27: =G27-C27 -> 631.31904 | F27: =E27*$K27/SUMPRODUCT(E$27:E$47,$K$27:$K$47) -> 0.0046660442 | G27: 8631.5333 | H27: 0.92685899 | I27: 0.27270318 | K27: 0.87 | M27: Triticale | P27: =T27*U27 -> 61792.55 | Q27: =P27/SUM(P$26:P$29) -> 0.18593732 | R27: =T27-P27 -> 37795.452 | S27: =R27/SUM(R$26:R$29) -> 0.18593732 | T27: 99588.001 | U27: 0.62048187
B28: Wheat | C28: =G28*H28 -> 38739.786 | D28: =C28*K28/SUMPRODUCT(C$27:C$47,$K$27:$K$47) -> 0.051409537 | E28: =G28-C28 -> 23695.214 | F28: =E28*$K28/SUMPRODUCT(E$27:E$47,$K$27:$K$47) -> 0.17513002 | G28: 62435 | H28: 0.62048187 | I28: 0 | K28: 0.87 | M28: Barley | P28: =T28*U28 -> 159717.73 | Q28: =P28/SUM(P$26:P$29) -> 0.48059978 | R28: =T28-P28 -> 97691.447 | S28: =R28/SUM(R$26:R$29) -> 0.48059978 | T28: 257409.17 | U28: 0.62048187
B29: Triticale | C29: =G29*H29 -> 21059.031 | D29: =C29*K29/SUMPRODUCT(C$27:C$47,$K$27:$K$47) -> 0.027946335 | E29: =G29-C29 -> 12880.769 | F29: =E29*$K29/SUMPRODUCT(E$27:E$47,$K$27:$K$47) -> 0.095201056 | G29: 33939.8 | H29: 0.62048187 | I29: 0 | K29: 0.87 | M29: Oats | P29: =T29*U29 -> 33007.101 | Q29: =P29/SUM(P$26:P$29) -> 0.099320257 | R29: =T29-P29 -> 20188.814 | S29: =R29/SUM(R$26:R$29) -> 0.099320257 | T29: 53195.915 | U29: 0.62048187
B30: Barley | C30: =G30*H30 -> 68413.876 | D30: =C30*K30/SUMPRODUCT(C$27:C$47,$K$27:$K$47) -> 0.090788466 | E30: =G30-C30 -> 41845.39 | F30: =E30*$K30/SUMPRODUCT(E$27:E$47,$K$27:$K$47) -> 0.30927697 | G30: 110259.27 | H30: 0.62048187 | I30: 0 | K30: 0.87
B31: Oats | C31: =G31*H31 -> 14138.341 | D31: =C31*K31/SUMPRODUCT(C$27:C$47,$K$27:$K$47) -> 0.018762251 | E31: =G31-C31 -> 8647.7253 | F31: =E31*$K31/SUMPRODUCT(E$27:E$47,$K$27:$K$47) -> 0.063914861 | G31: 22786.067 | H31: 0.62048187 | I31: 0 | K31: 0.87
B32: Peas | C32: =G32*H32 -> 4095.4809 | D32: =C32*K32/SUMPRODUCT(C$27:C$47,$K$27:$K$47) -> 0.0054348979 | E32: =G32-C32 -> 323.18573 | F32: =E32*$K32/SUMPRODUCT(E$27:E$47,$K$27:$K$47) -> 0.0023886479 | G32: 4418.6667 | H32: 0.92685899 | I32: 0 | K32: 0.87 | M32: Einarsson et al 2022 | P32: Grain legumes (on-farm)
B33: Faba beans | C33: =G33*H33 -> 11613.018 | D33: =C33*K33/SUMPRODUCT(C$27:C$47,$K$27:$K$47) -> 0.015411027 | E33: =G33-C33 -> 916.41538 | F33: =E33*$K33/SUMPRODUCT(E$27:E$47,$K$27:$K$47) -> 0.0067731755 | G33: 12529.433 | H33: 0.92685899 | I33: 0 | K33: 0.87 | M33: Supplementary Material | P33: Dairy | Q33: share | R33: Beef | S33: share | T33: Total | U33: to dairy
B34: Rapeseed, whole | C34: =G34*H34 -> 125972.19 | D34: =C34*K34/SUMPRODUCT(C$27:C$47,$K$27:$K$47) -> 0.17870012 | E34: =G34-C34 -> 9940.8137 | F34: =E34*$K34/SUMPRODUCT(E$27:E$47,$K$27:$K$47) -> 0.078539041 | G34: 135913 | H34: 0.92685899 | I34: 0.19883912 | K34: 0.93 | M34: Peas | P34: =T34*U34 -> 18331.528 | Q34: =P34/SUM(P$34:P$35) -> 0.51302572 | R34: =T34-P34 -> 11212.49 | S34: =R34/SUM(R$34:R$35) -> 0.51302572 | T34: 29544.018 | U34: 0.62048187
B35: Distiller’s dried grain | C35: =G35*H35 -> 36603.206 | D35: =C35*K35/SUMPRODUCT(C$27:C$47,$K$27:$K$47) -> 0.050249167 | E35: =G35-C35 -> 2888.4603 | F35: =E35*$K35/SUMPRODUCT(E$27:E$47,$K$27:$K$47) -> 0.022084604 | G35: 39491.667 | H35: 0.92685899 | I35: 0 | K35: 0.9 | M35: Faba beans | P35: =T35*U35 -> 17400.653 | Q35: =P35/SUM(P$34:P$35) -> 0.48697428 | R35: =T35-P35 -> 10643.12 | S35: =R35/SUM(R$34:R$35) -> 0.48697428 | T35: 28043.773 | U35: 0.62048187
B36: Bran, middlings, etc. | C36: =G36*H36 -> 90204.111 | D36: =C36*K36/SUMPRODUCT(C$27:C$47,$K$27:$K$47) -> 0.11970514 | E36: =G36-C36 -> 7118.2559 | F36: =E36*$K36/SUMPRODUCT(E$27:E$47,$K$27:$K$47) -> 0.052610637 | G36: 97322.367 | H36: 0.92685899 | I36: 0 | K36: 0.87
B37: Palm kernel expeller | C37: =G37*H37 -> 29382.975 | D37: =C37*K37/SUMPRODUCT(C$27:C$47,$K$27:$K$47) -> 0.040785368 | E37: =G37-C37 -> 2318.6918 | F37: =E37*$K37/SUMPRODUCT(E$27:E$47,$K$27:$K$47) -> 0.017925246 | G37: 31701.667 | H37: 0.92685899 | I37: 1 | K37: 0.91
B38: Soybeans, whole | C38: =G38*H38 -> 15543.487 | D38: =C38*K38/SUMPRODUCT(C$27:C$47,$K$27:$K$47) -> 0.020626946 | E38: =G38-C38 -> 1226.5796 | F38: =E38*$K38/SUMPRODUCT(E$27:E$47,$K$27:$K$47) -> 0.009065582 | G38: 16770.067 | H38: 0.92685899 | I38: 1 | K38: 0.87
B39: Soybean meal via feed industry | C39: =G39*H39 -> 39489.569 | D39: =C39*K39/SUMPRODUCT(C$27:C$47,$K$27:$K$47) -> 0.052404535 | E39: =G39-C39 -> 3116.2311 | F39: =E39*$K39/SUMPRODUCT(E$27:E$47,$K$27:$K$47) -> 0.023031892 | G39: 42605.8 | H39: 0.92685899 | I39: 1 | K39: 0.87
B40: Rapeseed meal | C40: =G40*H40 -> 103581.4 | D40: =C40*K40/SUMPRODUCT(C$27:C$47,$K$27:$K$47) -> 0.14219736 | E40: =G40-C40 -> 8173.8952 | F40: =E40*$K40/SUMPRODUCT(E$27:E$47,$K$27:$K$47) -> 0.062496009 | G40: 111755.3 | H40: 0.92685899 | I40: 0.60570717 | K40: 0.9
B41: Sunflower meal | C41: =G41*H41 -> 3649.7236 | D41: =C41*K41/SUMPRODUCT(C$27:C$47,$K$27:$K$47) -> 0.0051217105 | E41: =G41-C41 -> 288.00978 | F41: =E41*$K41/SUMPRODUCT(E$27:E$47,$K$27:$K$47) -> 0.0022510015 | G41: 3937.7333 | H41: 0.92685899 | I41: 1 | K41: 0.92
B42: Luzern meal | C42: =G42*H42 -> 2313.4679 | D42: =C42*K42/SUMPRODUCT(C$27:C$47,$K$27:$K$47) -> 0.0031759467 | E42: =G42-C42 -> 182.56215 | F42: =E42*$K42/SUMPRODUCT(E$27:E$47,$K$27:$K$47) -> 0.0013958346 | G42: =2773.36666666667*0.9 -> 2496.03 | H42: 0.92685899 | I42: 0.40587013 | K42: 0.9
B43: Potatoe protein | C43: =G43*H43 -> 257.05198 | D43: =C43*K43/SUMPRODUCT(C$27:C$47,$K$27:$K$47) -> 0.00035288297 | E43: =G43-C43 -> 20.284683 | F43: =E43*$K43/SUMPRODUCT(E$27:E$47,$K$27:$K$47) -> 0.00015509273 | G43: =2773.36666666667*0.1 -> 277.33667 | H43: 0.92685899 | I43: 0.40587013 | K43: 0.9
...

Sheet G&D slakt
A1: Djur | B1: Ras | C1: År | D1: Antal djur | E1: Slaktvikt (kg) | F1: Fettgrupp | G1: Formklass | H1: Ålder (månader) | I1: Slaktvikt*Antal | J1: Ålder*Antal | L1: År | M1: (Multiple Items)
A2: ko | B2: 01 SRB | C2: 2016 | D2: 30638 | E2: 302.7 | F2: 7.7 | G2: 4 | H2: 68.6 | I2: =D2*E2 -> 9274122.6 | J2: =D2*H2 -> 2101766.8
A3: ko | B3: 01 SRB | C3: 2017 | D3: 26251 | E3: 308.5 | F3: 7.8 | G3: 4.1 | H3: 68.9 | I3: =D3*E3 -> 8098433.5 | J3: =D3*H3 -> 1808693.9 | L3: Row Labels | M3: Sum of Antal djur | N3: Sum of Slaktvikt*Antal | O3: Sum of Ålder*Antal
A4: ko | B4: 01 SRB | C4: 2018 | D4: 26489 | E4: 306.2 | F4: 7.5 | G4: 4 | H4: 69.3 | I4: =D4*E4 -> 8110931.8 | J4: =D4*H4 -> 1835687.7 | L4: Mjölkras
A5: ko | B5: 01 SRB | C5: 2019 | D5: 25859 | E5: 310.4 | F5: 7.6 | G5: 4.1 | H5: 70.1 | I5: =D5*E5 -> 8026633.6 | J5: =D5*H5 -> 1812715.9 | L5: ko, tot | M5: 458500 | N5: 1.4040107e+08 | O5: 28527102
A6: ko | B6: 01 SRB | C6: 2020 | D6: 23718 | E6: 311.7 | F6: 7.4 | G6: 4 | H6: 71.6 | I6: =D6*E6 -> 7392900.6 | J6: =D6*H6 -> 1698208.8 | L6: ko | M6: 334565 | N6: 1.0495434e+08 | O6: 23342514
A7: ko | B7: 01 SRB | C7: 2021 | D7: 21589 | E7: 313.4 | F7: 7.3 | G7: 4 | H7: 72.9 | I7: =D7*E7 -> 6765992.6 | J7: =D7*H7 -> 1573838.1 | L7: ungko | M7: 123935 | N7: 35446730 | O7: 5184588.5
A8: ko | B8: 02 SLB | C8: 2016 | D8: 41922 | E8: 310.8 | F8: 7 | G8: 3.4 | H8: 69.2 | I8: =D8*E8 -> 13029358 | J8: =D8*H8 -> 2901002.4 | L8: kviga | M8: 74870 | N8: 22314874 | O8: 2415442.8
A9: ko | B9: 02 SLB | C9: 2017 | D9: 38032 | E9: 316.9 | F9: 7.2 | G9: 3.5 | H9: 68.9 | I9: =D9*E9 -> 12052341 | J9: =D9*H9 -> 2620404.8 | L9: kviga | M9: 74870 | N9: 22314874 | O9: 2415442.8
A10: ko | B10: 02 SLB | C10: 2018 | D10: 40654 | E10: 317 | F10: 7 | G10: 3.4 | H10: 69.4 | I10: =D10*E10 -> 12887318 | J10: =D10*H10 -> 2821387.6 | L10: stut | M10: 108867 | N10: 35469646 | O10: 3232646.8
A11: ko | B11: 02 SLB | C11: 2019 | D11: 40784 | E11: 321.4 | F11: 7.1 | G11: 3.5 | H11: 70.2 | I11: =D11*E11 -> 13107978 | J11: =D11*H11 -> 2863036.8 | L11: stut | M11: 108867 | N11: 35469646 | O11: 3232646.8
A12: ko | B12: 02 SLB | C12: 2020 | D12: 40218 | E12: 322.6 | F12: 7 | G12: 3.4 | H12: 71.6 | I12: =D12*E12 -> 12974327 | J12: =D12*H12 -> 2879608.8 | L12: tjur, tot | M12: 406109 | N12: 1.3355973e+08 | O12: 9169893.8
A13: ko | B13: 02 SLB | C13: 2021 | D13: 38776 | E13: 324.9 | F13: 6.9 | G13: 3.4 | H13: 73.2 | I13: =D13*E13 -> 12598322 | J13: =D13*H13 -> 2838403.2 | L13: ungtjur | M13: 351490 | N13: 1.1433162e+08 | O13: 7579081.5
A14: ko | B14: 08 Hereford | C14: 2016 | D14: 2843 | E14: 368.4 | F14: 11.3 | G14: 6.2 | H14: 92.6 | I14: =D14*E14 -> 1047361.2 | J14: =D14*H14 -> 263261.8 | L14: yngre tjur | M14: 54619 | N14: 19228107 | O14: 1590812.3
A15: ko | B15: 08 Hereford | C15: 2017 | D15: 3147 | E15: 365 | F15: 11.1 | G15: 6.1 | H15: 94 | I15: =D15*E15 -> 1148655 | J15: =D15*H15 -> 295818 | L15: mellankalv | M15: 52087 | N15: 8829445.9 | O15: 567598.6
A16: ko | B16: 08 Hereford | C16: 2018 | D16: 4193 | E16: 352.3 | F16: 10.2 | G16: 5.9 | H16: 91.3 | I16: =D16*E16 -> 1477193.9 | J16: =D16*H16 -> 382820.9 | L16: mellankalv | M16: 52087 | N16: 8829445.9 | O16: 567598.6
A17: ko | B17: 08 Hereford | C17: 2019 | D17: 4427 | E17: 348.6 | F17: 9.9 | G17: 5.8 | H17: 91.1 | I17: =D17*E17 -> 1543252.2 | J17: =D17*H17 -> 403299.7 | L17: Köttras
A18: ko | B18: 08 Hereford | C18: 2020 | D18: 4642 | E18: 355.5 | F18: 10.1 | G18: 5.9 | H18: 89.2 | I18: =D18*E18 -> 1650231 | J18: =D18*H18 -> 414066.4 | L18: ko, tot | M18: 73015 | N18: 25944410 | O18: 5910236.4
A19: ko | B19: 08 Hereford | C19: 2021 | D19: 4235 | E19: 364.2 | F19: 10.1 | G19: 6.2 | H19: 89.6 | I19: =D19*E19 -> 1542387 | J19: =D19*H19 -> 379456 | L19: ko | M19: 57301 | N19: 20949588 | O19: 5314264.8
A20: ko | B20: 09 Charolais | C20: 2016 | D20: 2485 | E20: 408.3 | F20: 9.3 | G20: 7.4 | H20: 98.5 | I20: =D20*E20 -> 1014625.5 | J20: =D20*H20 -> 244772.5 | L20: ungko | M20: 15714 | N20: 4994822.6 | O20: 595971.6
A21: ko | B21: 09 Charolais | C21: 2017 | D21: 2981 | E21: 405.9 | F21: 9.1 | G21: 7.4 | H21: 99.1 | I21: =D21*E21 -> 1209987.9 | J21: =D21*H21 -> 295417.1 | L21: kviga | M21: 69883 | N21: 21504076 | O21: 1879535.8
A22: ko | B22: 09 Charolais | C22: 2018 | D22: 3573 | E22: 393 | F22: 8.3 | G22: 7.1 | H22: 94.2 | I22: =D22*E22 -> 1404189 | J22: =D22*H22 -> 336576.6 | L22: kviga | M22: 69883 | N22: 21504076 | O22: 1879535.8
A23: ko | B23: 09 Charolais | C23: 2019 | D23: 3426 | E23: 387.3 | F23: 8.1 | G23: 6.9 | H23: 94.6 | I23: =D23*E23 -> 1326889.8 | J23: =D23*H23 -> 324099.6 | L23: stut | M23: 15451 | N23: 5150008.2 | O23: 437018.7
A24: ko | B24: 09 Charolais | C24: 2020 | D24: 3258 | E24: 396.6 | F24: 8.2 | G24: 7.1 | H24: 96.2 | I24: =D24*E24 -> 1292122.8 | J24: =D24*H24 -> 313419.6 | L24: stut | M24: 15451 | N24: 5150008.2 | O24: 437018.7
A25: ko | B25: 09 Charolais | C25: 2021 | D25: 2898 | E25: 409.9 | F25: 8.3 | G25: 7.5 | H25: 96.2 | I25: =D25*E25 -> 1187890.2 | J25: =D25*H25 -> 278787.6 | L25: tjur, tot | M25: 146789 | N25: 52855908 | O25: 2981903.4
A26: ko | B26: 11 Aberdeen Angus | C26: 2016 | D26: 820 | E26: 363.4 | F26: 11.1 | G26: 6.4 | H26: 88.1 | I26: =D26*E26 -> 297988 | J26: =D26*H26 -> 72242 | L26: ungtjur | M26: 130247 | N26: 46602706 | O26: 2474850.4
A27: ko | B27: 11 Aberdeen Angus | C27: 2017 | D27: 800 | E27: 359.4 | F27: 10.8 | G27: 6.3 | H27: 89 | I27: =D27*E27 -> 287520 | J27: =D27*H27 -> 71200 | L27: yngre tjur | M27: 16542 | N27: 6253201.7 | O27: 507053
A28: ko | B28: 11 Aberdeen Angus | C28: 2018 | D28: 1144 | E28: 353.4 | F28: 10.2 | G28: 6.3 | H28: 85 | I28: =D28*E28 -> 404289.6 | J28: =D28*H28 -> 97240 | L28: mellankalv | M28: 5086 | N28: 788569.7 | O28: 54710.6
A29: ko | B29: 11 Aberdeen Angus | C29: 2019 | D29: 1352 | E29: 348.2 | F29: 10.1 | G29: 6.1 | H29: 87.3 | I29: =D29*E29 -> 470766.4 | J29: =D29*H29 -> 118029.6 | L29: mellankalv | M29: 5086 | N29: 788569.7 | O29: 54710.6
A30: ko | B30: 11 Aberdeen Angus | C30: 2020 | D30: 1390 | E30: 351.6 | F30: 9.9 | G30: 6.1 | H30: 84.5 | I30: =D30*E30 -> 488724 | J30: =D30*H30 -> 117455 | L30: Korsning/övriga raser
A31: ko | B31: 11 Aberdeen Angus | C31: 2021 | D31: 1184 | E31: 357.6 | F31: 9.9 | G31: 6.3 | H31: 82.1 | I31: =D31*E31 -> 423398.4 | J31: =D31*H31 -> 97206.4 | L31: ko, tot | M31: 129627 | N31: 43075396 | O31: 9589289.8
A32: ko | B32: 12 Limousin | C32: 2016 | D32: 376 | E32: 387.2 | F32: 9.3 | G32: 8.3 | H32: 96.2 | I32: =D32*E32 -> 145587.2 | J32: =D32*H32 -> 36171.2 | L32: ko | M32: 95834 | N32: 32796065 | O32: 8301026.9
A33: ko | B33: 12 Limousin | C33: 2017 | D33: 438 | E33: 381.2 | F33: 9 | G33: 8.3 | H33: 93 | I33: =D33*E33 -> 166965.6 | J33: =D33*H33 -> 40734 | L33: ungko | M33: 33793 | N33: 10279331 | O33: 1288262.9
A34: ko | B34: 12 Limousin | C34: 2018 | D34: 621 | E34: 372.9 | F34: 8.3 | G34: 8.1 | H34: 89.5 | I34: =D34*E34 -> 231570.9 | J34: =D34*H34 -> 55579.5 | L34: kviga | M34: 135714 | N34: 42059544 | O34: 3666350.4
A35: ko | B35: 12 Limousin | C35: 2019 | D35: 507 | E35: 365.3 | F35: 7.9 | G35: 7.7 | H35: 92.1 | I35: =D35*E35 -> 185207.1 | J35: =D35*H35 -> 46694.7 | L35: kviga | M35: 135714 | N35: 42059544 | O35: 3666350.4
A36: ko | B36: 12 Limousin | C36: 2020 | D36: 692 | E36: 372 | F36: 7.7 | G36: 7.8 | H36: 100.2 | I36: =D36*E36 -> 257424 | J36: =D36*H36 -> 69338.4 | L36: stut | M36: 39806 | N36: 13394002 | O36: 1134912.8
A37: ko | B37: 12 Limousin | C37: 2021 | D37: 549 | E37: 381.3 | F37: 8.3 | G37: 8 | H37: 89 | I37: =D37*E37 -> 209333.7 | J37: =D37*H37 -> 48861 | L37: stut | M37: 39806 | N37: 13394002 | O37: 1134912.8
A38: ko | B38: 14 Simmental | C38: 2016 | D38: 1709 | E38: 374.6 | F38: 8.8 | G38: 6.6 | H38: 91.2 | I38: =D38*E38 -> 640191.4 | J38: =D38*H38 -> 155860.8 | L38: tjur, tot | M38: 274571 | N38: 98173836 | O38: 5490897.6
A39: ko | B39: 14 Simmental | C39: 2017 | D39: 1951 | E39: 379.3 | F39: 8.7 | G39: 6.7 | H39: 92.5 | I39: =D39*E39 -> 740014.3 | J39: =D39*H39 -> 180467.5 | L39: ungtjur | M39: 245666 | N39: 87640451 | O39: 4640779.1
A40: ko | B40: 14 Simmental | C40: 2018 | D40: 2598 | E40: 358.3 | F40: 7.6 | G40: 6.2 | H40: 89.8 | I40: =D40*E40 -> 930863.4 | J40: =D40*H40 -> 233300.4 | L40: yngre tjur | M40: 28905 | N40: 10533385 | O40: 850118.5
...

Sheet G&D sammanställning
A2: Medel 2016-2020
B3: Slaktvikt (kg) | H3: Ålder (mån) | N3: Antal | T3: Andel av slaktade ungdjur (%)
B4: Mjölkras | C4: Köttras | D4: Korsning/övriga raser | E4: Kött+korsn./övr. | F4: Totalt | H4: Mjölkras | I4: Köttras | J4: Korsning/övriga raser | K4: Kött+korsn./övr. | L4: Totalt | N4: Mjölkras | O4: Köttras | P4: Korsning/övriga raser | Q4: Kött+korsn./övr. | R4: Totalt | T4: Mjölkras | U4: Köttras | V4: Korsning/övriga raser | W4: Kött+korsn./övr. | X4: Totalt
A5: Ko, tot | B5: =GETPIVOTDATA("Sum of Slaktvikt*Antal",'G&D slakt'!$L$3,"Djur2",$A5,"Ras2",B$4)/GETPIVOTDATA("Sum of Antal djur",'G&D slakt'!$L$3,"Djur2",$A5,"Ras2",B$4) -> 306.21826 | C5: =GETPIVOTDATA("Sum of Slaktvikt*Antal",'G&D slakt'!$L$3,"Djur2",$A5,"Ras2",C$4)/GETPIVOTDATA("Sum of Antal djur",'G&D slakt'!$L$3,"Djur2",$A5,"Ras2",C$4) -> 355.32987 | D5: =GETPIVOTDATA("Sum of Slaktvikt*Antal",'G&D slakt'!$L$3,"Djur2",$A5,"Ras2",D$4)/GETPIVOTDATA("Sum of Antal djur",'G&D slakt'!$L$3,"Djur2",$A5,"Ras2",D$4) -> 332.30265 | E5: =(C5*$O5+D5*$P5)/SUM($O5,$P5) -> 340.59971 | F5: =(B5*$N5+C5*$O5+D5*$P5)/SUM($N5:$P5) -> 316.75628 | H5: =GETPIVOTDATA("Sum of Ålder*Antal",'G&D slakt'!$L$3,"Djur2",$A5,"Ras2",H$4)/GETPIVOTDATA("Sum of Antal djur",'G&D slakt'!$L$3,"Djur2",$A5,"Ras2",H$4) -> 62.218325 | I5: =GETPIVOTDATA("Sum of Ålder*Antal",'G&D slakt'!$L$3,"Djur2",$A5,"Ras2",I$4)/GETPIVOTDATA("Sum of Antal djur",'G&D slakt'!$L$3,"Djur2",$A5,"Ras2",I$4) -> 80.94551 | J5: =GETPIVOTDATA("Sum of Ålder*Antal",'G&D slakt'!$L$3,"Djur2",$A5,"Ras2",J$4)/GETPIVOTDATA("Sum of Antal djur",'G&D slakt'!$L$3,"Djur2",$A5,"Ras2",J$4) -> 73.976022 | K5: =(I5*$O5+J5*$P5)/SUM($O5,$P5) -> 76.487235 | L5: =(H5*$N5+I5*$O5+J5*$P5)/SUM($N5:$P5) -> 66.591788 | N5: =GETPIVOTDATA("Sum of Antal djur",'G&D slakt'!$L$3,"Djur2",$A5,"Ras2",N$4)/5 -> 91700 | O5: =GETPIVOTDATA("Sum of Antal djur",'G&D slakt'!$L$3,"Djur2",$A5,"Ras2",O$4)/5 -> 14603 | P5: =GETPIVOTDATA("Sum of Antal djur",'G&D slakt'!$L$3,"Djur2",$A5,"Ras2",P$4)/5 -> 25925.4 | Q5: =SUM(O5,P5) -> 40528.4 | R5: =SUM(N5,O5,P5) -> 132228.4
A6: ko | B6: =GETPIVOTDATA("Sum of Slaktvikt*Antal",'G&D slakt'!$L$3,"Djur",$A6,"Ras2",B$4)/GETPIVOTDATA("Sum of Antal djur",'G&D slakt'!$L$3,"Djur",$A6,"Ras2",B$4) -> 313.70389 | C6: =GETPIVOTDATA("Sum of Slaktvikt*Antal",'G&D slakt'!$L$3,"Djur",$A6,"Ras2",C$4)/GETPIVOTDATA("Sum of Antal djur",'G&D slakt'!$L$3,"Djur",$A6,"Ras2",C$4) -> 365.60597 | D6: =GETPIVOTDATA("Sum of Slaktvikt*Antal",'G&D slakt'!$L$3,"Djur",$A6,"Ras2",D$4)/GETPIVOTDATA("Sum of Antal djur",'G&D slakt'!$L$3,"Djur",$A6,"Ras2",D$4) -> 342.21743 | E6: =(C6*$O6+D6*$P6)/SUM($O6,$P6) -> 350.96909 | F6: =(B6*$N6+C6*$O6+D6*$P6)/SUM($N6:$P6) -> 325.40495 | H6: =GETPIVOTDATA("Sum of Ålder*Antal",'G&D slakt'!$L$3,"Djur",$A6,"Ras2",H$4)/GETPIVOTDATA("Sum of Antal djur",'G&D slakt'!$L$3,"Djur",$A6,"Ras2",H$4) -> 69.769741 | I6: =GETPIVOTDATA("Sum of Ålder*Antal",'G&D slakt'!$L$3,"Djur",$A6,"Ras2",I$4)/GETPIVOTDATA("Sum of Antal djur",'G&D slakt'!$L$3,"Djur",$A6,"Ras2",I$4) -> 92.742968 | J6: =GETPIVOTDATA("Sum of Ålder*Antal",'G&D slakt'!$L$3,"Djur",$A6,"Ras2",J$4)/GETPIVOTDATA("Sum of Antal djur",'G&D slakt'!$L$3,"Djur",$A6,"Ras2",J$4) -> 86.618809 | K6: =(I6*$O6+J6*$P6)/SUM($O6,$P6) -> 88.910384 | L6: =(H6*$N6+I6*$O6+J6*$P6)/SUM($N6:$P6) -> 75.779793 | N6: =GETPIVOTDATA("Sum of Antal djur",'G&D slakt'!$L$3,"Djur",$A6,"Ras2",N$4)/5 -> 66913 | O6: =GETPIVOTDATA("Sum of Antal djur",'G&D slakt'!$L$3,"Djur",$A6,"Ras2",O$4)/5 -> 11460.2 | P6: =GETPIVOTDATA("Sum of Antal djur",'G&D slakt'!$L$3,"Djur",$A6,"Ras2",P$4)/5 -> 19166.8 | Q6: =SUM(O6,P6) -> 30627 | R6: =SUM(N6,O6,P6) -> 97540
A7: ungko | B7: =GETPIVOTDATA("Sum of Slaktvikt*Antal",'G&D slakt'!$L$3,"Djur",$A7,"Ras2",B$4)/GETPIVOTDATA("Sum of Antal djur",'G&D slakt'!$L$3,"Djur",$A7,"Ras2",B$4) -> 286.01065 | C7: =GETPIVOTDATA("Sum of Slaktvikt*Antal",'G&D slakt'!$L$3,"Djur",$A7,"Ras2",C$4)/GETPIVOTDATA("Sum of Antal djur",'G&D slakt'!$L$3,"Djur",$A7,"Ras2",C$4) -> 317.85813 | D7: =GETPIVOTDATA("Sum of Slaktvikt*Antal",'G&D slakt'!$L$3,"Djur",$A7,"Ras2",D$4)/GETPIVOTDATA("Sum of Antal djur",'G&D slakt'!$L$3,"Djur",$A7,"Ras2",D$4) -> 304.18523 | E7: =(C7*$O7+D7*$P7)/SUM($O7,$P7) -> 308.52514 | F7: =(B7*$N7+C7*$O7+D7*$P7)/SUM($N7:$P7) -> 292.43715 | H7: =GETPIVOTDATA("Sum of Ålder*Antal",'G&D slakt'!$L$3,"Djur",$A7,"Ras2",H$4)/GETPIVOTDATA("Sum of Antal djur",'G&D slakt'!$L$3,"Djur",$A7,"Ras2",H$4) -> 41.833126 | I7: =GETPIVOTDATA("Sum of Ålder*Antal",'G&D slakt'!$L$3,"Djur",$A7,"Ras2",I$4)/GETPIVOTDATA("Sum of Antal djur",'G&D slakt'!$L$3,"Djur",$A7,"Ras2",I$4) -> 37.926155 | J7: =GETPIVOTDATA("Sum of Ålder*Antal",'G&D slakt'!$L$3,"Djur",$A7,"Ras2",J$4)/GETPIVOTDATA("Sum of Antal djur",'G&D slakt'!$L$3,"Djur",$A7,"Ras2",J$4) -> 38.122182 | K7: =(I7*$O7+J7*$P7)/SUM($O7,$P7) -> 38.059961 | L7: =(H7*$N7+I7*$O7+J7*$P7)/SUM($N7:$P7) -> 40.75612 | N7: =GETPIVOTDATA("Sum of Antal djur",'G&D slakt'!$L$3,"Djur",$A7,"Ras2",N$4)/5 -> 24787 | O7: =GETPIVOTDATA("Sum of Antal djur",'G&D slakt'!$L$3,"Djur",$A7,"Ras2",O$4)/5 -> 3142.8 | P7: =GETPIVOTDATA("Sum of Antal djur",'G&D slakt'!$L$3,"Djur",$A7,"Ras2",P$4)/5 -> 6758.6 | Q7: =SUM(O7,P7) -> 9901.4 | R7: =SUM(N7,O7,P7) -> 34688.4
A8: kviga | B8: =GETPIVOTDATA("Sum of Slaktvikt*Antal",'G&D slakt'!$L$3,"Djur",$A8,"Ras2",B$4)/GETPIVOTDATA("Sum of Antal djur",'G&D slakt'!$L$3,"Djur",$A8,"Ras2",B$4) -> 298.04827 | C8: =GETPIVOTDATA("Sum of Slaktvikt*Antal",'G&D slakt'!$L$3,"Djur",$A8,"Ras2",C$4)/GETPIVOTDATA("Sum of Antal djur",'G&D slakt'!$L$3,"Djur",$A8,"Ras2",C$4) -> 307.71541 | D8: =GETPIVOTDATA("Sum of Slaktvikt*Antal",'G&D slakt'!$L$3,"Djur",$A8,"Ras2",D$4)/GETPIVOTDATA("Sum of Antal djur",'G&D slakt'!$L$3,"Djur",$A8,"Ras2",D$4) -> 309.91308 | E8: =(C8*$O8+D8*$P8)/SUM($O8,$P8) -> 309.16608 | F8: =(B8*$N8+C8*$O8+D8*$P8)/SUM($N8:$P8) -> 306.19821 | H8: =GETPIVOTDATA("Sum of Ålder*Antal",'G&D slakt'!$L$3,"Djur",$A8,"Ras2",H$4)/GETPIVOTDATA("Sum of Antal djur",'G&D slakt'!$L$3,"Djur",$A8,"Ras2",H$4) -> 32.261824 | I8: =GETPIVOTDATA("Sum of Ålder*Antal",'G&D slakt'!$L$3,"Djur",$A8,"Ras2",I$4)/GETPIVOTDATA("Sum of Antal djur",'G&D slakt'!$L$3,"Djur",$A8,"Ras2",I$4) -> 26.895465 | J8: =GETPIVOTDATA("Sum of Ålder*Antal",'G&D slakt'!$L$3,"Djur",$A8,"Ras2",J$4)/GETPIVOTDATA("Sum of Antal djur",'G&D slakt'!$L$3,"Djur",$A8,"Ras2",J$4) -> 27.01527 | K8: =(I8*$O8+J8*$P8)/SUM($O8,$P8) -> 26.974548 | L8: =(H8*$N8+I8*$O8+J8*$P8)/SUM($N8:$P8) -> 28.385974 | N8: =GETPIVOTDATA("Sum of Antal djur",'G&D slakt'!$L$3,"Djur",$A8,"Ras2",N$4)/5 -> 14974 | O8: =GETPIVOTDATA("Sum of Antal djur",'G&D slakt'!$L$3,"Djur",$A8,"Ras2",O$4)/5 -> 13976.6 | P8: =GETPIVOTDATA("Sum of Antal djur",'G&D slakt'!$L$3,"Djur",$A8,"Ras2",P$4)/5 -> 27142.8 | Q8: =SUM(O8,P8) -> 41119.4 | R8: =SUM(N8,O8,P8) -> 56093.4 | T8: =N8/SUM(N$8:N$10,N$13)*100 -> 11.663211 | U8: =O8/SUM(O$8:O$10,O$13)*100 -> 29.460518 | V8: =P8/SUM(P$8:P$10,P$13)*100 -> 29.303968 | W8: =Q8/SUM(Q$8:Q$10,Q$13)*100 -> 29.356993 | X8: =R8/SUM(R$8:R$10,R$13)*100 -> 20.895023
A9: stut | B9: =GETPIVOTDATA("Sum of Slaktvikt*Antal",'G&D slakt'!$L$3,"Djur",$A9,"Ras2",B$4)/GETPIVOTDATA("Sum of Antal djur",'G&D slakt'!$L$3,"Djur",$A9,"Ras2",B$4) -> 325.80714 | C9: =GETPIVOTDATA("Sum of Slaktvikt*Antal",'G&D slakt'!$L$3,"Djur",$A9,"Ras2",C$4)/GETPIVOTDATA("Sum of Antal djur",'G&D slakt'!$L$3,"Djur",$A9,"Ras2",C$4) -> 333.31229 | D9: =GETPIVOTDATA("Sum of Slaktvikt*Antal",'G&D slakt'!$L$3,"Djur",$A9,"Ras2",D$4)/GETPIVOTDATA("Sum of Antal djur",'G&D slakt'!$L$3,"Djur",$A9,"Ras2",D$4) -> 336.482 | E9: =(C9*$O9+D9*$P9)/SUM($O9,$P9) -> 335.59568 | F9: =(B9*$N9+C9*$O9+D9*$P9)/SUM($N9:$P9) -> 329.10273 | H9: =GETPIVOTDATA("Sum of Ålder*Antal",'G&D slakt'!$L$3,"Djur",$A9,"Ras2",H$4)/GETPIVOTDATA("Sum of Antal djur",'G&D slakt'!$L$3,"Djur",$A9,"Ras2",H$4) -> 29.693542 | I9: =GETPIVOTDATA("Sum of Ålder*Antal",'G&D slakt'!$L$3,"Djur",$A9,"Ras2",I$4)/GETPIVOTDATA("Sum of Antal djur",'G&D slakt'!$L$3,"Djur",$A9,"Ras2",I$4) -> 28.284169 | J9: =GETPIVOTDATA("Sum of Ålder*Antal",'G&D slakt'!$L$3,"Djur",$A9,"Ras2",J$4)/GETPIVOTDATA("Sum of Antal djur",'G&D slakt'!$L$3,"Djur",$A9,"Ras2",J$4) -> 28.511099 | K9: =(I9*$O9+J9*$P9)/SUM($O9,$P9) -> 28.447645 | L9: =(H9*$N9+I9*$O9+J9*$P9)/SUM($N9:$P9) -> 29.274075 | N9: =GETPIVOTDATA("Sum of Antal djur",'G&D slakt'!$L$3,"Djur",$A9,"Ras2",N$4)/5 -> 21773.4 | O9: =GETPIVOTDATA("Sum of Antal djur",'G&D slakt'!$L$3,"Djur",$A9,"Ras2",O$4)/5 -> 3090.2 | P9: =GETPIVOTDATA("Sum of Antal djur",'G&D slakt'!$L$3,"Djur",$A9,"Ras2",P$4)/5 -> 7961.2 | Q9: =SUM(O9,P9) -> 11051.4 | R9: =SUM(N9,O9,P9) -> 32824.8 | T9: =N9/SUM(N$8:N$10,N$13)*100 -> 16.959247 | U9: =O9/SUM(O$8:O$10,O$13)*100 -> 6.5136652 | V9: =P9/SUM(P$8:P$10,P$13)*100 -> 8.5950877 | W9: =Q9/SUM(Q$8:Q$10,Q$13)*100 -> 7.8900924 | X9: =R9/SUM(R$8:R$10,R$13)*100 -> 12.227374
A10: tjur, tot | B10: =GETPIVOTDATA("Sum of Slaktvikt*Antal",'G&D slakt'!$L$3,"Djur2",$A10,"Ras2",B$4)/GETPIVOTDATA("Sum of Antal djur",'G&D slakt'!$L$3,"Djur2",$A10,"Ras2",B$4) -> 328.87656 | C10: =GETPIVOTDATA("Sum of Slaktvikt*Antal",'G&D slakt'!$L$3,"Djur2",$A10,"Ras2",C$4)/GETPIVOTDATA("Sum of Antal djur",'G&D slakt'!$L$3,"Djur2",$A10,"Ras2",C$4) -> 360.08085 | D10: =GETPIVOTDATA("Sum of Slaktvikt*Antal",'G&D slakt'!$L$3,"Djur2",$A10,"Ras2",D$4)/GETPIVOTDATA("Sum of Antal djur",'G&D slakt'!$L$3,"Djur2",$A10,"Ras2",D$4) -> 357.55355 | E10: =(C10*$O10+D10*$P10)/SUM($O10,$P10) -> 358.43398 | F10: =(B10*$N10+C10*$O10+D10*$P10)/SUM($N10:$P10) -> 343.92766 | H10: =GETPIVOTDATA("Sum of Ålder*Antal",'G&D slakt'!$L$3,"Djur2",$A10,"Ras2",H$4)/GETPIVOTDATA("Sum of Antal djur",'G&D slakt'!$L$3,"Djur2",$A10,"Ras2",H$4) -> 22.579883 | I10: =GETPIVOTDATA("Sum of Ålder*Antal",'G&D slakt'!$L$3,"Djur2",$A10,"Ras2",I$4)/GETPIVOTDATA("Sum of Antal djur",'G&D slakt'!$L$3,"Djur2",$A10,"Ras2",I$4) -> 20.314216 | J10: =GETPIVOTDATA("Sum of Ålder*Antal",'G&D slakt'!$L$3,"Djur2",$A10,"Ras2",J$4)/GETPIVOTDATA("Sum of Antal djur",'G&D slakt'!$L$3,"Djur2",$A10,"Ras2",J$4) -> 19.998097 | K10: =(I10*$O10+J10*$P10)/SUM($O10,$P10) -> 20.108223 | L10: =(H10*$N10+I10*$O10+J10*$P10)/SUM($N10:$P10) -> 21.321276 | N10: =GETPIVOTDATA("Sum of Antal djur",'G&D slakt'!$L$3,"Djur2",$A10,"Ras2",N$4)/5 -> 81221.8 | O10: =GETPIVOTDATA("Sum of Antal djur",'G&D slakt'!$L$3,"Djur2",$A10,"Ras2",O$4)/5 -> 29357.8 | P10: =GETPIVOTDATA("Sum of Antal djur",'G&D slakt'!$L$3,"Djur2",$A10,"Ras2",P$4)/5 -> 54914.2 | Q10: =SUM(O10,P10) -> 84272 | R10: =SUM(N10,O10,P10) -> 165493.8 | T10: =N10/SUM(N$8:N$10,N$13)*100 -> 63.263456 | U10: =O10/SUM(O$8:O$10,O$13)*100 -> 61.881716 | V10: =P10/SUM(P$8:P$10,P$13)*100 -> 59.286586 | W10: =Q10/SUM(Q$8:Q$10,Q$13)*100 -> 60.165578 | X10: =R10/SUM(R$8:R$10,R$13)*100 -> 61.647124
A11: ungtjur | B11: =GETPIVOTDATA("Sum of Slaktvikt*Antal",'G&D slakt'!$L$3,"Djur",$A11,"Ras2",B$4)/GETPIVOTDATA("Sum of Antal djur",'G&D slakt'!$L$3,"Djur",$A11,"Ras2",B$4) -> 325.27703 | C11: =GETPIVOTDATA("Sum of Slaktvikt*Antal",'G&D slakt'!$L$3,"Djur",$A11,"Ras2",C$4)/GETPIVOTDATA("Sum of Antal djur",'G&D slakt'!$L$3,"Djur",$A11,"Ras2",C$4) -> 357.80253 | D11: =GETPIVOTDATA("Sum of Slaktvikt*Antal",'G&D slakt'!$L$3,"Djur",$A11,"Ras2",D$4)/GETPIVOTDATA("Sum of Antal djur",'G&D slakt'!$L$3,"Djur",$A11,"Ras2",D$4) -> 356.74636 | E11: =(C11*$O11+D11*$P11)/SUM($O11,$P11) -> 357.1123 | F11: =(B11*$N11+C11*$O11+D11*$P11)/SUM($N11:$P11) -> 341.72911 | H11: =GETPIVOTDATA("Sum of Ålder*Antal",'G&D slakt'!$L$3,"Djur",$A11,"Ras2",H$4)/GETPIVOTDATA("Sum of Antal djur",'G&D slakt'!$L$3,"Djur",$A11,"Ras2",H$4) -> 21.562723 | I11: =GETPIVOTDATA("Sum of Ålder*Antal",'G&D slakt'!$L$3,"Djur",$A11,"Ras2",I$4)/GETPIVOTDATA("Sum of Antal djur",'G&D slakt'!$L$3,"Djur",$A11,"Ras2",I$4) -> 19.001208 | J11: =GETPIVOTDATA("Sum of Ålder*Antal",'G&D slakt'!$L$3,"Djur",$A11,"Ras2",J$4)/GETPIVOTDATA("Sum of Antal djur",'G&D slakt'!$L$3,"Djur",$A11,"Ras2",J$4) -> 18.890604 | K11: =(I11*$O11+J11*$P11)/SUM($O11,$P11) -> 18.928926 | L11: =(H11*$N11+I11*$O11+J11*$P11)/SUM($N11:$P11) -> 20.201609 | N11: =GETPIVOTDATA("Sum of Antal djur",'G&D slakt'!$L$3,"Djur",$A11,"Ras2",N$4)/5 -> 70298 | O11: =GETPIVOTDATA("Sum of Antal djur",'G&D slakt'!$L$3,"Djur",$A11,"Ras2",O$4)/5 -> 26049.4 | P11: =GETPIVOTDATA("Sum of Antal djur",'G&D slakt'!$L$3,"Djur",$A11,"Ras2",P$4)/5 -> 49133.2 | Q11: =SUM(O11,P11) -> 75182.6 | R11: =SUM(N11,O11,P11) -> 145480.6 | T11: =N11/SUM(N$8:N$10,N$13)*100 -> 54.754935 | U11: =O11/SUM(O$8:O$10,O$13)*100 -> 54.908119 | V11: =P11/SUM(P$8:P$10,P$13)*100 -> 53.04529 | W11: =Q11/SUM(Q$8:Q$10,Q$13)*100 -> 53.676246 | X11: =R11/SUM(R$8:R$10,R$13)*100 -> 54.192124
A12: yngre tjur | B12: =GETPIVOTDATA("Sum of Slaktvikt*Antal",'G&D slakt'!$L$3,"Djur",$A12,"Ras2",B$4)/GETPIVOTDATA("Sum of Antal djur",'G&D slakt'!$L$3,"Djur",$A12,"Ras2",B$4) -> 352.04063 | C12: =GETPIVOTDATA("Sum of Slaktvikt*Antal",'G&D slakt'!$L$3,"Djur",$A12,"Ras2",C$4)/GETPIVOTDATA("Sum of Antal djur",'G&D slakt'!$L$3,"Djur",$A12,"Ras2",C$4) -> 378.01969 | D12: =GETPIVOTDATA("Sum of Slaktvikt*Antal",'G&D slakt'!$L$3,"Djur",$A12,"Ras2",D$4)/GETPIVOTDATA("Sum of Antal djur",'G&D slakt'!$L$3,"Djur",$A12,"Ras2",D$4) -> 364.41393 | E12: =(C12*$O12+D12*$P12)/SUM($O12,$P12) -> 369.36622 | F12: =(B12*$N12+C12*$O12+D12*$P12)/SUM($N12:$P12) -> 359.90939 | H12: =GETPIVOTDATA("Sum of Ålder*Antal",'G&D slakt'!$L$3,"Djur",$A12,"Ras2",H$4)/GETPIVOTDATA("Sum of Antal djur",'G&D slakt'!$L$3,"Djur",$A12,"Ras2",H$4) -> 29.125621 | I12: =GETPIVOTDATA("Sum of Ålder*Antal",'G&D slakt'!$L$3,"Djur",$A12,"Ras2",I$4)/GETPIVOTDATA("Sum of Antal djur",'G&D slakt'!$L$3,"Djur",$A12,"Ras2",I$4) -> 30.65246 | J12: =GETPIVOTDATA("Sum of Ålder*Antal",'G&D slakt'!$L$3,"Djur",$A12,"Ras2",J$4)/GETPIVOTDATA("Sum of Antal djur",'G&D slakt'!$L$3,"Djur",$A12,"Ras2",J$4) -> 29.410777 | K12: =(I12*$O12+J12*$P12)/SUM($O12,$P12) -> 29.86273 | L12: =(H12*$N12+I12*$O12+J12*$P12)/SUM($N12:$P12) -> 29.460394 | N12: =GETPIVOTDATA("Sum of Antal djur",'G&D slakt'!$L$3,"Djur",$A12,"Ras2",N$4)/5 -> 10923.8 | O12: =GETPIVOTDATA("Sum of Antal djur",'G&D slakt'!$L$3,"Djur",$A12,"Ras2",O$4)/5 -> 3308.4 | P12: =GETPIVOTDATA("Sum of Antal djur",'G&D slakt'!$L$3,"Djur",$A12,"Ras2",P$4)/5 -> 5781 | Q12: =SUM(O12,P12) -> 9089.4 | R12: =SUM(N12,O12,P12) -> 20013.2 | T12: =N12/SUM(N$8:N$10,N$13)*100 -> 8.5085204 | U12: =O12/SUM(O$8:O$10,O$13)*100 -> 6.9735971 | V12: =P12/SUM(P$8:P$10,P$13)*100 -> 6.2412955 | W12: =Q12/SUM(Q$8:Q$10,Q$13)*100 -> 6.4893322 | X12: =R12/SUM(R$8:R$10,R$13)*100 -> 7.4549996
A13: mellankalv | B13: =GETPIVOTDATA("Sum of Slaktvikt*Antal",'G&D slakt'!$L$3,"Djur",$A13,"Ras2",B$4)/GETPIVOTDATA("Sum of Antal djur",'G&D slakt'!$L$3,"Djur",$A13,"Ras2",B$4) -> 169.51343 | C13: =GETPIVOTDATA("Sum of Slaktvikt*Antal",'G&D slakt'!$L$3,"Djur",$A13,"Ras2",C$4)/GETPIVOTDATA("Sum of Antal djur",'G&D slakt'!$L$3,"Djur",$A13,"Ras2",C$4) -> 155.04713 | D13: =GETPIVOTDATA("Sum of Slaktvikt*Antal",'G&D slakt'!$L$3,"Djur",$A13,"Ras2",D$4)/GETPIVOTDATA("Sum of Antal djur",'G&D slakt'!$L$3,"Djur",$A13,"Ras2",D$4) -> 158.20155 | E13: =(C13*$O13+D13*$P13)/SUM($O13,$P13) -> 157.31615 | F13: =(B13*$N13+C13*$O13+D13*$P13)/SUM($N13:$P13) -> 166.36539 | H13: =GETPIVOTDATA("Sum of Ålder*Antal",'G&D slakt'!$L$3,"Djur",$A13,"Ras2",H$4)/GETPIVOTDATA("Sum of Antal djur",'G&D slakt'!$L$3,"Djur",$A13,"Ras2",H$4) -> 10.897126 | I13: =GETPIVOTDATA("Sum of Ålder*Antal",'G&D slakt'!$L$3,"Djur",$A13,"Ras2",I$4)/GETPIVOTDATA("Sum of Antal djur",'G&D slakt'!$L$3,"Djur",$A13,"Ras2",I$4) -> 10.757098 | J13: =GETPIVOTDATA("Sum of Ålder*Antal",'G&D slakt'!$L$3,"Djur",$A13,"Ras2",J$4)/GETPIVOTDATA("Sum of Antal djur",'G&D slakt'!$L$3,"Djur",$A13,"Ras2",J$4) -> 11.004473 | K13: =(I13*$O13+J13*$P13)/SUM($O13,$P13) -> 10.935039 | L13: =(H13*$N13+I13*$O13+J13*$P13)/SUM($N13:$P13) -> 10.906911 | N13: =GETPIVOTDATA("Sum of Antal djur",'G&D slakt'!$L$3,"Djur",$A13,"Ras2",N$4)/5 -> 10417.4 | O13: =GETPIVOTDATA("Sum of Antal djur",'G&D slakt'!$L$3,"Djur",$A13,"Ras2",O$4)/5 -> 1017.2 | P13: =GETPIVOTDATA("Sum of Antal djur",'G&D slakt'!$L$3,"Djur",$A13,"Ras2",P$4)/5 -> 2606.8 | Q13: =SUM(O13,P13) -> 3624 | R13: =SUM(N13,O13,P13) -> 14041.4 | T13: =N13/SUM(N$8:N$10,N$13)*100 -> 8.1140867 | U13: =O13/SUM(O$8:O$10,O$13)*100 -> 2.1441008 | V13: =P13/SUM(P$8:P$10,P$13)*100 -> 2.814359 | W13: =Q13/SUM(Q$8:Q$10,Q$13)*100 -> 2.5873369 | X13: =R13/SUM(R$8:R$10,R$13)*100 -> 5.2304795
H15: =H10/H11 -> 1.0471722 | I15: =I10/I11 -> 1.0691012 | J15: =J10/J11 -> 1.0586267 | K15: =K10/K11 -> 1.0623013 | L15: =L10/L11 -> 1.0554246

Sheet Växa slakt
A1: Medelvärde för 2015-2019
C4: Antal djur | D4: Födelsevikt (kg) | E4: Slaktvikt (kg) | F4: Klass | G4: Fett | H4: Ålder (mån) | I4: Slakttillväxt | N4: Antal djur | P4: Slaktvikt (kg) | R4: Ålder (mån)
A5: Mjölkraser | B5: Kor | C5: =C11+C17+C23+C29+C35 -> 254237 | E5: =($C11*E11+$C17*E17+$C23*E23+$C29*E29+$C35*E35)/$C5 -> 311.62468 | F5: =($C11*F11+$C17*F17+$C23*F23+$C29*F29+$C35*F35)/$C5 -> 4.0213435 | G5: =($C11*G11+$C17*G17+$C23*G23+$C29*G29+$C35*G35)/$C5 -> 7.3071406 | H5: =($C11*H11+$C17*H17+$C23*H23+$C29*H29+$C35*H35)/$C5 -> 69.224075 | K5: Ålder kor | L5: =SUMPRODUCT(C5:C6,H5:H6)/SUM(C5:C6)/12 -> 5.0579254 | M5: år | N5: =C11+C17+C23+C29 -> 212411 | O5: =N5/C5 -> 0.83548421 | P5: =($C11*E11+$C17*E17+$C23*E23+$C29*E29)/$N5 -> 312.02336 | Q5: =P5/E5 -> 1.0012794 | R5: =($C11*H11+$C17*H17+$C23*H23+$C29*H29)/$N5 -> 69.760475 | S5: =R5/H5 -> 1.0077487
B6: Ungko | C6: =C12+C18+C24+C30+C36 -> 101572 | E6: =($C12*E12+$C18*E18+$C24*E24+$C30*E30+$C36*E36)/$C6 -> 284.07222 | F6: =($C12*F12+$C18*F18+$C24*F24+$C30*F30+$C36*F36)/$C6 -> 3.8006232 | G6: =($C12*G12+$C18*G18+$C24*G24+$C30*G30+$C36*G36)/$C6 -> 6.922076 | H6: =($C12*H12+$C18*H18+$C24*H24+$C30*H30+$C36*H36)/$C6 -> 39.346901 | K6: Rekrytering | N6: =C12+C18+C24+C30 -> 83208 | O6: =N6/C6 -> 0.81920214 | P6: =($C12*E12+$C18*E18+$C24*E24+$C30*E30)/$N6 -> 284.70612 | Q6: =P6/E6 -> 1.0022315 | R6: =($C12*H12+$C18*H18+$C24*H24+$C30*H30)/$N6 -> 39.511742 | S6: =R6/H6 -> 1.0041894
B7: Kvigor | C7: =C13+C19+C25+C31+C37 -> 42815 | E7: =($C13*E13+$C19*E19+$C25*E25+$C31*E31+$C37*E37)/$C7 -> 294.00667 | F7: =($C13*F13+$C19*F19+$C25*F25+$C31*F31+$C37*F37)/$C7 -> 4.5251851 | G7: =($C13*G13+$C19*G19+$C25*G25+$C31*G31+$C37*G37)/$C7 -> 8.326131 | H7: =($C13*H13+$C19*H19+$C25*H25+$C31*H31+$C37*H37)/$C7 -> 28.461236 | I7: =($C13*I13+$C19*I19+$C25*I25+$C31*I31+$C37*I37)/$C7 -> 316.44786 | K7: Andel stut | L7: =(C9*(I9/12))/(C9*(I9/12)+C10*(I10/12)) -> 0.22305303 | N7: =C13+C19+C25+C31 -> 34206 | O7: =N7/C7 -> 0.79892561 | P7: =($C13*E13+$C19*E19+$C25*E25+$C31*E31)/$N7 -> 294.46138 | Q7: =P7/E7 -> 1.0015466 | R7: =($C13*H13+$C19*H19+$C25*H25+$C31*H31)/$N7 -> 28.526984 | S7: =R7/H7 -> 1.0023101
B8: Mellankalv | C8: =C14+C20+C26+C32+C38 -> 8283 | E8: =($C14*E14+$C20*E20+$C26*E26+$C32*E32+$C38*E38)/$C8 -> 167.41452 | F8: =($C14*F14+$C20*F20+$C26*F26+$C32*F32+$C38*F38)/$C8 -> 4.6737414 | G8: =($C14*G14+$C20*G20+$C26*G26+$C32*G32+$C38*G38)/$C8 -> 5.3224194 | H8: =($C14*H14+$C20*H20+$C26*H26+$C32*H32+$C38*H38)/$C8 -> 9.2787154 | I8: =($C14*I14+$C20*I20+$C26*I26+$C32*I32+$C38*I38)/$C8 -> 523.08379 | N8: =C14+C20+C26+C32 -> 6929 | O8: =N8/C8 -> 0.83653266 | P8: =($C14*E14+$C20*E20+$C26*E26+$C32*E32)/$N8 -> 168.04268 | Q8: =P8/E8 -> 1.0037521 | R8: =($C14*H14+$C20*H20+$C26*H26+$C32*H32)/$N8 -> 9.3136383 | S8: =R8/H8 -> 1.0037638
B9: Stut | C9: =C15+C21+C27+C33+C39 -> 39167 | E9: =($C15*E15+$C21*E21+$C27*E27+$C33*E33+$C39*E39)/$C9 -> 323.46097 | F9: =($C15*F15+$C21*F21+$C27*F27+$C33*F33+$C39*F39)/$C9 -> 4.3642786 | G9: =($C15*G15+$C21*G21+$C27*G27+$C33*G33+$C39*G39)/$C9 -> 7.5542293 | H9: =($C15*H15+$C21*H21+$C27*H27+$C33*H33+$C39*H39)/$C9 -> 27.685238 | I9: =($C15*I15+$C21*I21+$C27*I27+$C33*I33+$C39*I39)/$C9 -> 360.49805 | N9: =C15+C21+C27+C33 -> 30466 | O9: =N9/C9 -> 0.7778487 | P9: =($C15*E15+$C21*E21+$C27*E27+$C33*E33)/$N9 -> 323.73542 | Q9: =P9/E9 -> 1.0008485 | R9: =($C15*H15+$C21*H21+$C27*H27+$C33*H33)/$N9 -> 27.681021 | S9: =R9/H9 -> 0.99984771
B10: Ungtjur | C10: =C16+C22+C28+C34+C40 -> 97422 | E10: =($C16*E16+$C22*E22+$C28*E28+$C34*E34+$C40*E40)/$C10 -> 328.44804 | F10: =($C16*F16+$C22*F22+$C28*F28+$C34*F34+$C40*F40)/$C10 -> 4.7509351 | G10: =($C16*G16+$C22*G22+$C28*G28+$C34*G34+$C40*G40)/$C10 -> 6.6520776 | H10: =($C16*H16+$C22*H22+$C28*H28+$C34*H34+$C40*H40)/$C10 -> 20.048903 | I10: =($C16*I16+$C22*I22+$C28*I28+$C34*I34+$C40*I40)/$C10 -> 504.83497 | N10: =C16+C22+C28+C34 -> 77052 | O10: =N10/C10 -> 0.79090965 | P10: =($C16*E16+$C22*E22+$C28*E28+$C34*E34)/$N10 -> 328.59293 | Q10: =P10/E10 -> 1.0004411 | R10: =($C16*H16+$C22*H22+$C28*H28+$C34*H34)/$N10 -> 20.088268 | S10: =R10/H10 -> 1.0019634
A11: SJB | B11: Kor | C11: 1433 | D11: 40 | E11: 202.3 | F11: 3.5 | G11: 6.6 | H11: 69.6
B12: Ungko | C12: 438 | D12: 40 | E12: 184.8 | F12: 2.9 | G12: 6.4 | H12: 36.4
B13: Kvigor | C13: 205 | D13: 40 | E13: 205.2 | F13: 3.7 | G13: 8 | H13: 30.3 | I13: 201
B14: Mellankalv | C14: 85 | D14: 40 | E14: 129.7 | F14: 4 | G14: 5 | H14: 10.6 | I14: 341
B15: Stut | C15: 235 | D15: 39.9 | E15: 255.3 | F15: 3.7 | G15: 7.7 | H15: 32 | I15: 242
B16: Ungtjur | C16: 168 | D16: 40 | E16: 258.9 | F16: 4.3 | G16: 6.6 | H16: 21.6 | I16: 364
A17: SKB | B17: Kor | C17: 681 | E17: 247.2 | F17: 4 | G17: 9.9 | H17: 95.3
B18: Ungko | C18: 93 | E18: 207.6 | F18: 3.5 | G18: 8.4 | H18: 35.9
B19: Kvigor | C19: 106 | E19: 212.2 | F19: 4.2 | G19: 8.9 | H19: 28.9 | I19: 219
B20: Mellankalv | C20: 164 | E20: 123.8 | F20: 4.1 | G20: 5.3 | H20: 9.3 | I20: 366
B21: Stut | C21: 224 | E21: 242 | F21: 4 | G21: 7.8 | H21: 28.4 | I21: 257
B22: Ungtjur | C22: 301 | E22: 260.5 | F22: 4.6 | G22: 6 | H22: 23.1 | I22: 343
A23: SLB (Svensk Holstein) | B23: Kor | C23: 130623 | E23: 317.3 | F23: 3.8 | G23: 7 | H23: 69.3
B24: Ungko | C24: 55981 | E24: 289.1 | F24: 3.6 | G24: 6.7 | H24: 39.5
B25: Kvigor | C25: 21744 | E25: 296.8 | F25: 4.2 | G25: 8.2 | H25: 28.3 | I25: 321
B26: Mellankalv | C26: 5050 | E26: 170.3 | F26: 4.5 | G26: 5.1 | H26: 9.2 | I26: 537
B27: Stut | C27: 18610 | E27: 326.34 | F27: 4 | G27: 7.5 | H27: 27.3 | I27: 369
B28: Ungtjur | C28: 54487 | E28: 329.1 | F28: 4.4 | G28: 6.5 | H28: 19.9 | I28: 509
A29: SRB | B29: Kor | C29: 79674 | E29: 305.9 | F29: 4.3 | G29: 7.7 | H29: 70.3
B30: Ungko | C30: 26696 | E30: 277.4 | F30: 4.1 | G30: 7.2 | H30: 39.6
B31: Kvigor | C31: 12151 | E31: 292.5 | F31: 5 | G31: 8.5 | H31: 28.9 | I31: 310
B32: Mellankalv | C32: 1630 | E32: 167.5 | F32: 5.2 | G32: 5.8 | H32: 9.6 | I32: 507
B33: Stut | C33: 11397 | E33: 322.5 | F33: 4.8 | G33: 7.6 | H33: 28.2 | I33: 353
B34: Ungtjur | C34: 22096 | E34: 328.8 | F34: 5.3 | G34: 6.9 | H34: 20.5 | I34: 494
A35: Korsning | B35: Kor | C35: 41826 | E35: 309.6 | F35: 4.2 | G35: 7.5 | H35: 66.5 | J35: =C35/C5 -> 0.16451579
B36: Ungko | C36: 18364 | E36: 281.2 | F36: 4 | G36: 7.2 | H36: 38.6 | J36: =C36/C6 -> 0.18079786
B37: Kvigor | C37: 8609 | E37: 292.2 | F37: 4.7 | G37: 8.4 | H37: 28.2 | I37: 318 | J37: =C37/C7 -> 0.20107439
B38: Mellankalv | C38: 1354 | E38: 164.2 | F38: 4.8 | G38: 5.6 | H38: 9.1 | I38: 521 | J38: =C38/C8 -> 0.16346734
B39: Stut | C39: 8701 | E39: 322.5 | F39: 4.6 | G39: 7.6 | H39: 27.7 | I39: 358 | J39: =C39/C9 -> 0.2221513
B40: Ungtjur | C40: 20370 | E40: 327.9 | F40: 5.1 | G40: 6.8 | H40: 19.9 | I40: 509 | J40: =C40/C10 -> 0.20909035 | N40: Antal djur | P40: Slaktvikt (kg) | R40: Ålder (mån)
A41: Köttraser | B41: Kor | C41: =SUM(C47,C83) -> 16927 | D41: =($C47*D47+$C83*D83)/$C41 -> 41.574888 | E41: =($C47*E47+$C83*E83)/$C41 -> 379.16193 | F41: =($C47*F47+$C83*F83)/$C41 -> 6.7577598 | G41: =($C47*G47+$C83*G83)/$C41 -> 9.0394459 | H41: =($C47*H47+$C83*H83)/$C41 -> 91.658144 | K41: Ålder kor | L41: =SUMPRODUCT(C41:C42,H41:H42)/SUM(C41:C42)/12 -> 6.4128831 | M41: år | N41: =SUM(N47,N83) -> 10586 | O41: =N41/C41 -> 0.62539139 | P41: =($N47*P47+$N83*P83)/$N41 -> 389.6567 | Q41: =P41/E41 -> 1.0276789 | R41: =($N47*R47+$N83*R83)/$N41 -> 94.044559 | S41: =R41/H41 -> 1.026036
