Workbook

Sheet default
A1: f_species | B1: f_breed | C1: f_prod_system | D1: f_sub_system | E1: f_animal | F1: f_feed | G1: f_crop | H1: f_crop_prod | I1: f_by_prod | J1: parameter | K1: value | L1: unit | M1: description | N1: source
A2: Products to feeds | L2: kg DM feed/kg product | M2: need to align with DM in products and by-products
J3: feed_to_prod | K3: 0 | M3: fallback
F4: ley silage, 1st cut | H4: fodder | J4: feed_to_prod | K4: =1/INDEX('feed pars'!C$6:C$42/100,MATCH(F4,'feed pars'!B$6:B$42,0)) -> 1
F5: ley silage, regrowth | H5: fodder | J5: feed_to_prod | K5: =1/INDEX('feed pars'!C$6:C$42/100,MATCH(F5,'feed pars'!B$6:B$42,0)) -> 1
F6: other silage | H6: fodder | J6: feed_to_prod | K6: =1/INDEX('feed pars'!C$6:C$42/100,MATCH(F6,'feed pars'!B$6:B$42,0)) -> 1
F7: hay | H7: fodder | J7: feed_to_prod | K7: =1/INDEX('feed pars'!C$6:C$42/100,MATCH(F7,'feed pars'!B$6:B$42,0)) -> 1
F8: maize silage | H8: maize fodder | J8: feed_to_prod | K8: =1/INDEX('feed pars'!C$6:C$42/100,MATCH(F8,'feed pars'!B$6:B$42,0)) -> 1
F9: grazing | H9: grazing | J9: feed_to_prod | K9: =1/INDEX('feed pars'!C$6:C$42/100,MATCH(F9,'feed pars'!B$6:B$42,0)) -> 1
F10: wheat | H10: wheat | J10: feed_to_prod | K10: =1/INDEX('feed pars'!C$6:C$42/100,MATCH(F10,'feed pars'!B$6:B$42,0)) -> 1.1494253
F11: barley | H11: barley | J11: feed_to_prod | K11: =1/INDEX('feed pars'!C$6:C$42/100,MATCH(F11,'feed pars'!B$6:B$42,0)) -> 1.1494253
F12: oats | H12: oats | J12: feed_to_prod | K12: =1/INDEX('feed pars'!C$6:C$42/100,MATCH(F12,'feed pars'!B$6:B$42,0)) -> 1.1627907
F13: triticale | H13: triticale | J13: feed_to_prod | K13: =1/INDEX('feed pars'!C$6:C$42/100,MATCH(F13,'feed pars'!B$6:B$42,0)) -> 1.1494253
F14: rye | H14: rye | J14: feed_to_prod | K14: =1/INDEX('feed pars'!C$6:C$42/100,MATCH(F14,'feed pars'!B$6:B$42,0)) -> 1.1494253
F15: maize | H15: maize | J15: feed_to_prod | K15: =1/INDEX('feed pars'!C$6:C$42/100,MATCH(F15,'feed pars'!B$6:B$42,0)) -> 1.4814815
... F19: linseed | H19: linseed | J19: feed_to_prod | K19: =1/INDEX('feed pars'!C$6:C$42/100,MATCH(F19,'feed pars'!B$6:B$42,0)) -> 1.0869565
F20: vegetable oils | H20: rapeseed | J20: feed_to_prod | K20: =1/INDEX('feed pars'!C$6:C$42/100,MATCH(F20,'feed pars'!B$6:B$42,0))*1/0.38 -> 2.6315789
F21: vegetable oils | H21: rapeseed | I21: rapeseed meal | J21: feed_to_by_prod | M21: add by-prod generation calculation method!
F22: straw | I22: straw | J22: feed_to_prod | K22: =1/INDEX('feed pars'!C$6:C$42/100,MATCH(F22,'feed pars'!B$6:B$42,0)) -> 1.1764706
F23: soybeans | I23: soybeans | J23: feed_to_prod | K23: =1/INDEX('feed pars'!C$6:C$42/100,MATCH(F23,'feed pars'!B$6:B$42,0)) -> 1.1494253
F24: soybean meal | I24: soybean meal | J24: feed_to_prod | K24: =1/INDEX('feed pars'!C$6:C$42/100,MATCH(F24,'feed pars'!B$6:B$42,0)) -> 1.1428571
F25: soybean protein concentrate | I25: soybean protein concentrate | J25: feed_to_prod | K25: =1/INDEX('feed pars'!C$6:C$42/100,MATCH(F25,'feed pars'!B$6:B$42,0)) -> 1.1494253
F26: rapeseed meal | I26: rapeseed meal | J26: feed_to_prod | K26: =1/INDEX('feed pars'!C$6:C$42/100,MATCH(F26,'feed pars'!B$6:B$42,0)) -> 1.1173184
F27: sunflower seed meal | I27: sunflower seed meal | J27: feed_to_prod | K27: =1/INDEX('feed pars'!C$6:C$42/100,MATCH(F27,'feed pars'!B$6:B$42,0)) -> 1.0989011
F28: palm kernel expeller | I28: palm kernel expeller | J28: feed_to_prod | K28: =1/INDEX('feed pars'!C$6:C$42/100,MATCH(F28,'feed pars'!B$6:B$42,0)) -> 1.0989011
F29: luzern meal | I29: luzern meal | J29: feed_to_prod | K29: =1/INDEX('feed pars'!C$6:C$42/100,MATCH(F29,'feed pars'!B$6:B$42,0)) -> 1.1111111
F30: wheat bran | I30: wheat bran | J30: feed_to_prod | K30: =1/INDEX('feed pars'!C$6:C$42/100,MATCH(F30,'feed pars'!B$6:B$42,0)) -> 1.1494253
F31: wheat bran, fine | I31: wheat bran | J31: feed_to_prod | K31: =1/INDEX('feed pars'!C$6:C$42/100,MATCH(F31,'feed pars'!B$6:B$42,0)) -> 1.1363636
F32: wheat distillers grain, dry | I32: wheat distillers grain | J32: feed_to_prod | K32: =K33 -> 9.0909091
F33: wheat distillers grain, wet | I33: wheat distillers grain | J33: feed_to_prod | K33: =1/INDEX('feed pars'!C$6:C$42/100,MATCH(F33,'feed pars'!B$6:B$42,0)) -> 9.0909091
F34: barley brewers grain | I34: barley brewers grain | J34: feed_to_prod | K34: =1/0.25 -> 4
F35: sugar beet molasses | I35: sugar beet molasses | J35: feed_to_prod | K35: =1/INDEX('feed pars'!C$6:C$42/100,MATCH(F35,'feed pars'!B$6:B$42,0)) -> 1.3245033
F36: sugar beet pulp | I36: sugar beet pulp | J36: feed_to_prod | K36: =1/INDEX('feed pars'!C$6:C$42/100,MATCH(F36,'feed pars'!B$6:B$42,0)) -> 1.1173184
F37: whey | I37: whey | J37: feed_to_prod | K37: =1/INDEX('feed pars'!C$6:C$42/100,MATCH(F37,'feed pars'!B$6:B$42,0)) -> 16
F38: whey powder | I38: whey | J38: feed_to_prod | K38: =K37 -> 16
F39: potatoe protein | I39: potatoe protein | J39: feed_to_prod | K39: =1/INDEX('feed pars'!C$6:C$42/100,MATCH(F39,'feed pars'!B$6:B$42,0)) -> 1.0989011
F40: fish meal | I40: fish meal | J40: feed_to_prod | K40: =1/INDEX('feed pars'!C$6:C$42/100,MATCH(F40,'feed pars'!B$6:B$42,0)) -> 1.0869565
A41: Share of crop and by-products that must be produced regionally
J42: share_regional | K42: 0 | M42: fallback
H43: fodder | J43: share_regional | K43: 95 | L43: %
...

Sheet feed pars
B1: Source: | C1: http://www2.freefarm.se/fodertabell/
C3: general | E3: pigs | K3: cattle
E4: col | F4: 1 | G4: 2 | H4: 3 | K4: col | L4: 1 | M4: 2
B5: feed | C5: %DM | E5: row | F5: %DM | G5: MJ NEv | H5: MJ NEs | K5: row | L5: %DM | M5: MJ ME
B6: ley silage, 1st cut | C6: 100 | M6: 11.5
B7: ley silage, regrowth | C7: 100 | M7: 10.4
B8: other silage | C8: 100 | M8: 10
B9: hay | C9: 100 | M9: 9.1
B10: maize silage | C10: 100 | M10: 11.3
B11: grazing | C11: 100 | M11: 10
B13: wheat | C13: =AVERAGE(F13,L13) -> 87 | E13: =MATCH($B13,pigs!$A$3:$A$60,0) -> 53 | F13: =INDEX(pigs!$D$3:$AO$60,$E13,F$4) -> 87 | G13: =INDEX(pigs!$D$3:$AO$60,$E13,G$4) -> 12.1 | H13: =INDEX(pigs!$D$3:$AO$60,$E13,H$4) -> 12.3 | K13: =MATCH($B13,cattle!$A$3:$A$120,0) -> 112 | L13: =INDEX(cattle!$D$3:$AH$120,$K13,L$4) -> 87 | M13: =INDEX(cattle!$D$3:$AH$120,$K13,M$4) -> 14.1
B14: barley | C14: =AVERAGE(F14,L14) -> 87 | E14: =MATCH($B14,pigs!$A$3:$A$60,0) -> 13 | F14: =INDEX(pigs!$D$3:$AO$60,$E14,F$4) -> 87 | G14: =INDEX(pigs!$D$3:$AO$60,$E14,G$4) -> 11 | H14: =INDEX(pigs!$D$3:$AO$60,$E14,H$4) -> 11.2 | K14: =MATCH($B14,cattle!$A$3:$A$120,0) -> 42 | L14: =INDEX(cattle!$D$3:$AH$120,$K14,L$4) -> 87 | M14: =INDEX(cattle!$D$3:$AH$120,$K14,M$4) -> 13.2
B15: oats | C15: =AVERAGE(F15,L15) -> 86 | E15: =MATCH($B15,pigs!$A$3:$A$60,0) -> 11 | F15: =INDEX(pigs!$D$3:$AO$60,$E15,F$4) -> 87 | G15: =INDEX(pigs!$D$3:$AO$60,$E15,G$4) -> 9 | H15: =INDEX(pigs!$D$3:$AO$60,$E15,H$4) -> 9.4 | K15: =MATCH($B15,cattle!$A$3:$A$120,0) -> 28 | L15: =INDEX(cattle!$D$3:$AH$120,$K15,L$4) -> 85 | M15: =INDEX(cattle!$D$3:$AH$120,$K15,M$4) -> 11.7
B16: triticale | C16: =AVERAGE(F16,L16) -> 87 | E16: =MATCH($B16,pigs!$A$3:$A$60,0) -> 39 | F16: =INDEX(pigs!$D$3:$AO$60,$E16,F$4) -> 87 | G16: =INDEX(pigs!$D$3:$AO$60,$E16,G$4) -> 11.9 | H16: =INDEX(pigs!$D$3:$AO$60,$E16,H$4) -> 12 | K16: =MATCH($B16,cattle!$A$3:$A$120,0) -> 78 | L16: =INDEX(cattle!$D$3:$AH$120,$K16,L$4) -> 87 | M16: =INDEX(cattle!$D$3:$AH$120,$K16,M$4) -> 14
B17: rye | C17: =AVERAGE(F17,L17) -> 87 | E17: =MATCH($B17,pigs!$A$3:$A$60,0) -> 38 | K17: =MATCH($B17,cattle!$A$3:$A$120,0) -> 77 | L17: =INDEX(cattle!$D$3:$AH$120,$K17,L$4) -> 87 | M17: =INDEX(cattle!$D$3:$AH$120,$K17,M$4) -> 13.9
B18: maize | C18: =AVERAGE(F18,L18) -> 67.5 | E18: =MATCH($B18,pigs!$A$3:$A$60,0) -> 19 | F18: =INDEX(pigs!$D$3:$AO$60,$E18,F$4) -> 87 | G18: =INDEX(pigs!$D$3:$AO$60,$E18,G$4) -> 12.8 | H18: =INDEX(pigs!$D$3:$AO$60,$E18,H$4) -> 13.2 | K18: =MATCH($B18,cattle!$A$3:$A$120,0) -> 53 | L18: =INDEX(cattle!$D$3:$AH$120,$K18,L$4) -> 48 | M18: =INDEX(cattle!$D$3:$AH$120,$K18,M$4) -> 12.8
B19: peas | C19: =AVERAGE(F19,L19) -> 87 | E19: =MATCH($B19,pigs!$A$3:$A$60,0) -> 56 | F19: =INDEX(pigs!$D$3:$AO$60,$E19,F$4) -> 87 | G19: =INDEX(pigs!$D$3:$AO$60,$E19,G$4) -> 11.2 | H19: =INDEX(pigs!$D$3:$AO$60,$E19,H$4) -> 11.5 | K19: =MATCH($B19,cattle!$A$3:$A$120,0) -> 115 | L19: =INDEX(cattle!$D$3:$AH$120,$K19,L$4) -> 87 | M19: =INDEX(cattle!$D$3:$AH$120,$K19,M$4) -> 13.8
B20: broad beans | C20: =AVERAGE(F20,L20) -> 86.8 | E20: =MATCH($B20,pigs!$A$3:$A$60,0) -> 57 | F20: =INDEX(pigs!$D$3:$AO$60,$E20,F$4) -> 87 | G20: =INDEX(pigs!$D$3:$AO$60,$E20,G$4) -> 10.7 | H20: =INDEX(pigs!$D$3:$AO$60,$E20,H$4) -> 10.9 | L20: 86.6 | M20: 13.3 | N20: https://www.feedipedia.org/node/12799
B21: rapeseed | C21: =AVERAGE(F21,L21) -> 92.5 | E21: =MATCH($B21,pigs!$A$3:$A$60,0) -> 33 | F21: =INDEX(pigs!$D$3:$AO$60,$E21,F$4) -> 92 | G21: =INDEX(pigs!$D$3:$AO$60,$E21,G$4) -> 18 | H21: =INDEX(pigs!$D$3:$AO$60,$E21,H$4) -> 18.5 | K21: =MATCH($B21,cattle!$A$3:$A$120,0) -> 71 | L21: =INDEX(cattle!$D$3:$AH$120,$K21,L$4) -> 93 | M21: =INDEX(cattle!$D$3:$AH$120,$K21,M$4) -> 22.1
B22: linseed | C22: =AVERAGE(F22,L22) -> 92 | E22: =MATCH($B22,pigs!$A$3:$A$60,0) -> 14 | F22: =INDEX(pigs!$D$3:$AO$60,$E22,F$4) -> 91 | G22: =INDEX(pigs!$D$3:$AO$60,$E22,G$4) -> 17.3 | H22: =INDEX(pigs!$D$3:$AO$60,$E22,H$4) -> 17.5 | K22: =MATCH($B22,cattle!$A$3:$A$120,0) -> 45 | L22: =INDEX(cattle!$D$3:$AH$120,$K22,L$4) -> 93 | M22: =INDEX(cattle!$D$3:$AH$120,$K22,M$4) -> 20.1
B23: vegetable oils | C23: =AVERAGE(F23,L23) -> 100 | E23: =MATCH($B23,pigs!$A$3:$A$60,0) -> 28 | F23: =INDEX(pigs!$D$3:$AO$60,$E23,F$4) -> 100 | G23: =INDEX(pigs!$D$3:$AO$60,$E23,G$4) -> 29.8 | H23: =INDEX(pigs!$D$3:$AO$60,$E23,H$4) -> 29.8 | L23: 100 | M23: 36.6 | N23: https://www.feedtables.com/content/rapeseed-oil
B24: straw | C24: =AVERAGE(F24,L24) -> 85 | K24: =MATCH($B24,cattle!$A$3:$A$120,0) -> 22 | L24: =INDEX(cattle!$D$3:$AH$120,$K24,L$4) -> 85 | M24: =INDEX(cattle!$D$3:$AH$120,$K24,M$4) -> 6.6
B25: soybeans | C25: =AVERAGE(F25,L25) -> 87 | K25: =MATCH($B25,cattle!$A$3:$A$120,0) -> 92 | L25: =INDEX(cattle!$D$3:$AH$120,$K25,L$4) -> 87 | M25: =INDEX(cattle!$D$3:$AH$120,$K25,M$4) -> 16.4
B26: soybean meal | C26: =AVERAGE(F26,L26) -> 87.5 | E26: =MATCH($B26,pigs!$A$3:$A$60,0) -> 43 | F26: =INDEX(pigs!$D$3:$AO$60,$E26,F$4) -> 88 | G26: =INDEX(pigs!$D$3:$AO$60,$E26,G$4) -> 9.3 | H26: =INDEX(pigs!$D$3:$AO$60,$E26,H$4) -> 9.9 | K26: =MATCH($B26,cattle!$A$3:$A$120,0) -> 93 | L26: =INDEX(cattle!$D$3:$AH$120,$K26,L$4) -> 87 | M26: =INDEX(cattle!$D$3:$AH$120,$K26,M$4) -> 14.6
B27: soybean protein concentrate | C27: =AVERAGE(F27,L27) -> 87 | E27: =MATCH($B27,pigs!$A$3:$A$60,0) -> 45 | F27: =INDEX(pigs!$D$3:$AO$60,$E27,F$4) -> 87 | G27: =INDEX(pigs!$D$3:$AO$60,$E27,G$4) -> 9.7 | H27: =INDEX(pigs!$D$3:$AO$60,$E27,H$4) -> 10.3
B28: rapeseed meal | C28: =AVERAGE(F28,L28) -> 89.5 | E28: =MATCH($B28,pigs!$A$3:$A$60,0) -> 36 | F28: =INDEX(pigs!$D$3:$AO$60,$E28,F$4) -> 89 | G28: =INDEX(pigs!$D$3:$AO$60,$E28,G$4) -> 7.1 | H28: =INDEX(pigs!$D$3:$AO$60,$E28,H$4) -> 7.7 | K28: =MATCH($B28,cattle!$A$3:$A$120,0) -> 70 | L28: =INDEX(cattle!$D$3:$AH$120,$K28,L$4) -> 90 | M28: =INDEX(cattle!$D$3:$AH$120,$K28,M$4) -> 12.2
B29: sunflower seed meal | C29: =AVERAGE(F29,L29) -> 91 | E29: =MATCH($B29,pigs!$A$3:$A$60,0) -> 46 | F29: =INDEX(pigs!$D$3:$AO$60,$E29,F$4) -> 90 | G29: =INDEX(pigs!$D$3:$AO$60,$E29,G$4) -> 5.9 | H29: =INDEX(pigs!$D$3:$AO$60,$E29,H$4) -> 6.5 | K29: =MATCH($B29,cattle!$A$3:$A$120,0) -> 99 | L29: =INDEX(cattle!$D$3:$AH$120,$K29,L$4) -> 92 | M29: =INDEX(cattle!$D$3:$AH$120,$K29,M$4) -> 11.4
B30: palm kernel expeller | C30: =AVERAGE(F30,L30) -> 91 | E30: =MATCH($B30,pigs!$A$3:$A$60,0) -> 29 | F30: =INDEX(pigs!$D$3:$AO$60,$E30,F$4) -> 91 | G30: =INDEX(pigs!$D$3:$AO$60,$E30,G$4) -> 5.4 | H30: =INDEX(pigs!$D$3:$AO$60,$E30,H$4) -> 6.2 | K30: =MATCH($B30,cattle!$A$3:$A$120,0) -> 60 | L30: =INDEX(cattle!$D$3:$AH$120,$K30,L$4) -> 91 | M30: =INDEX(cattle!$D$3:$AH$120,$K30,M$4) -> 13.4
B31: luzern meal | C31: =AVERAGE(F31,L31) -> 90 | L31: 90 | M31: 8.5 | N31: https://www.feedipedia.org/node/11744
B32: wheat bran | C32: =AVERAGE(F32,L32) -> 87 | E32: =MATCH($B32,pigs!$A$3:$A$60,0) -> 55 | F32: =INDEX(pigs!$D$3:$AO$60,$E32,F$4) -> 87 | G32: =INDEX(pigs!$D$3:$AO$60,$E32,G$4) -> 7.2 | H32: =INDEX(pigs!$D$3:$AO$60,$E32,H$4) -> 7.8 | K32: =MATCH($B32,cattle!$A$3:$A$120,0) -> 111 | L32: =INDEX(cattle!$D$3:$AH$120,$K32,L$4) -> 87 | M32: =INDEX(cattle!$D$3:$AH$120,$K32,M$4) -> 11
B33: wheat bran, fine | C33: =AVERAGE(F33,L33) -> 88 | E33: =MATCH($B33,pigs!$A$3:$A$60,0) -> 54 | F33: =INDEX(pigs!$D$3:$AO$60,$E33,F$4) -> 88 | G33: =INDEX(pigs!$D$3:$AO$60,$E33,G$4) -> 8.7 | H33: =INDEX(pigs!$D$3:$AO$60,$E33,H$4) -> 9.2
B34: wheat distillers grain, dry | C34: =AVERAGE(F34,L34) -> 90 | E34: =MATCH($B34,pigs!$A$3:$A$60,0) -> 3 | F34: =INDEX(pigs!$D$3:$AO$60,$E34,F$4) -> 90 | G34: =INDEX(pigs!$D$3:$AO$60,$E34,G$4) -> 8.1 | H34: =INDEX(pigs!$D$3:$AO$60,$E34,H$4) -> 8.7 | K34: =MATCH($B34,cattle!$A$3:$A$120,0) -> 109 | L34: =INDEX(cattle!$D$3:$AH$120,$K34,L$4) -> 90 | M34: =INDEX(cattle!$D$3:$AH$120,$K34,M$4) -> 13.3
B35: wheat distillers grain, wet | C35: =AVERAGE(F35,L35) -> 11 | E35: =MATCH($B35,pigs!$A$3:$A$60,0) -> 1 | F35: =INDEX(pigs!$D$3:$AO$60,$E35,F$4) -> 11 | G35: =INDEX(pigs!$D$3:$AO$60,$E35,G$4) -> 8.2 | H35: =INDEX(pigs!$D$3:$AO$60,$E35,H$4) -> 8.9
B36: barley brewers grain | C36: =AVERAGE(F36,L36) -> 90 | F36: 90 | G36: 6.6 | H36: =H34/G34*G36 -> 7.0888889 | I36: https://www.feedipedia.org/node/74 | K36: =MATCH($B36,cattle!$A$3:$A$120,0) -> 38 | L36: =INDEX(cattle!$D$3:$AH$120,$K36,L$4) -> 90 | M36: =INDEX(cattle!$D$3:$AH$120,$K36,M$4) -> 11.6
B37: sugar beet molasses | C37: =AVERAGE(F37,L37) -> 75.5 | E37: =MATCH($B37,pigs!$A$3:$A$60,0) -> 23 | F37: =INDEX(pigs!$D$3:$AO$60,$E37,F$4) -> 76 | G37: =INDEX(pigs!$D$3:$AO$60,$E37,G$4) -> 8.7 | H37: =INDEX(pigs!$D$3:$AO$60,$E37,H$4) -> 9 | K37: =MATCH($B37,cattle!$A$3:$A$120,0) -> 88 | L37: =INDEX(cattle!$D$3:$AH$120,$K37,L$4) -> 75 | M37: =INDEX(cattle!$D$3:$AH$120,$K37,M$4) -> 12.4
B38: sugar beet pulp | C38: =AVERAGE(F38,L38) -> 89.5 | E38: =MATCH($B38,pigs!$A$3:$A$60,0) -> 4 | F38: =INDEX(pigs!$D$3:$AO$60,$E38,F$4) -> 89 | G38: =INDEX(pigs!$D$3:$AO$60,$E38,G$4) -> 6.9 | H38: =INDEX(pigs!$D$3:$AO$60,$E38,H$4) -> 8 | K38: =MATCH($B38,cattle!$A$3:$A$120,0) -> 91 | L38: =INDEX(cattle!$D$3:$AH$120,$K38,L$4) -> 90 | M38: =INDEX(cattle!$D$3:$AH$120,$K38,M$4) -> 12.3
B39: whey | C39: =AVERAGE(F39,L39) -> 6.25 | E39: =MATCH($B39,pigs!$A$3:$A$60,0) -> 50 | F39: =INDEX(pigs!$D$3:$AO$60,$E39,F$4) -> 5.5 | G39: =INDEX(pigs!$D$3:$AO$60,$E39,G$4) -> 12.4 | H39: =INDEX(pigs!$D$3:$AO$60,$E39,H$4) -> 12.2 | K39: =MATCH($B39,cattle!$A$3:$A$120,0) -> 57 | L39: =INDEX(cattle!$D$3:$AH$120,$K39,L$4) -> 7 | M39: =INDEX(cattle!$D$3:$AH$120,$K39,M$4) -> 13.6
B40: whey powder | C40: =AVERAGE(F40,L40) -> 97 | E40: =MATCH($B40,pigs!$A$3:$A$60,0) -> 52 | F40: =INDEX(pigs!$D$3:$AO$60,$E40,F$4) -> 97 | G40: =INDEX(pigs!$D$3:$AO$60,$E40,G$4) -> 12.4 | H40: =INDEX(pigs!$D$3:$AO$60,$E40,H$4) -> 12.2
B41: potatoe protein | C41: =AVERAGE(F41,L41) -> 91 | E41: =MATCH($B41,pigs!$A$3:$A$60,0) -> 31 | F41: =INDEX(pigs!$D$3:$AO$60,$E41,F$4) -> 92 | G41: =INDEX(pigs!$D$3:$AO$60,$E41,G$4) -> 11.1 | H41: =INDEX(pigs!$D$3:$AO$60,$E41,H$4) -> 11.3 | K41: =MATCH($B41,cattle!$A$3:$A$120,0) -> 65 | L41: =INDEX(cattle!$D$3:$AH$120,$K41,L$4) -> 90 | M41: =INDEX(cattle!$D$3:$AH$120,$K41,M$4) -> 15.5
B42: fish meal | C42: =AVERAGE(F42,L42) -> 92 | E42: =MATCH($B42,pigs!$A$3:$A$60,0) -> 7 | F42: =INDEX(pigs!$D$3:$AO$60,$E42,F$4) -> 92 | G42: =INDEX(pigs!$D$3:$AO$60,$E42,G$4) -> 10.8 | H42: =INDEX(pigs!$D$3:$AO$60,$E42,H$4) -> 10.8

Sheet pigs
D1: 1 | E1: 2 | F1: 3 | G1: 4 | H1: 5 | I1: 6 | J1: 7 | K1: 8 | L1: 9 | M1: 10 | N1: 11 | O1: 12 | P1: 13 | Q1: 14 | R1: 15 | S1: 16 | T1: 17 | U1: 18 | V1: 19 | W1: 20 | X1: 21 | Y1: 22 | Z1: 23 | AA1: 24 | AB1: 25 | AC1: 26 | AD1: 27 | AE1: 28 | AF1: 29 | AG1: 30 | AH1: 31 | AI1: 32 | AJ1: 33 | AK1: 34 | AL1: 35 | AM1: 36 | AN1: 37 | AO1: 38
A2: feed | B2: Nr | C2: Fodermedel | D2: Ts, % | E2: NEv, MJ | F2: NEs, MJ | G2: OEsv, MJ | H2: Råprotein, g | I2: Råfett, g | J2: Växttråd, g | K2: NDF, g | L2: ADF, g | M2: Stärkelse, g | N2: Socker, g | O2: Aska, g | P2: Lysin, g | Q2: Treonin, g | R2: Metionin, g | S2: Cystin, g | T2: Met+Cys, g | U2: Tryptofan, g | V2: Valin, g | W2: sisLys, g | X2: sisTreo, g | Y2: sisMet, g | Z2: sisCys, g | AA2: sisMetCys, g | AB2: sisTry, g | AC2: sisVal, g | AD2: sisRp, g | AE2: Ca, g | AF2: P, g | AG2: Mg, g | AH2: K, g | AI2: Na, g | AJ2: Mn, mg | AK2: Se, mg | AL2: Cu, mg | AM2: Zn, mg | AN2: Smb P, Pellets % | AO2: Smb P, Mjöl %
A3: wheat distillers grain, wet | B3: 1 | C3: Agrodrank10 | D3: 11 | E3: 8.2 | F3: 8.9 | G3: 10.8 | H3: 280 | I3: 45 | J3: 22 | O3: 68 | P3: 8.7 | Q3: 9.6 | R3: 5.2 | S3: 6.7 | T3: 11.9 | U3: 4.2 | V3: 10 | W3: 5.7 | X3: 7.7 | Y3: 4.5 | Z3: 5.5 | AA3: 10 | AB3: 3.4 | AC3: 8 | AD3: 196 | AE3: 0.9 | AF3: 10.9 | AI3: 1.8 | AN3: 20 | AO3: 20
B4: 2 | C4: Agrodrank27 | D4: 28 | E4: 8.2 | F4: 8.9 | G4: 10.9 | H4: 364 | I4: 43 | J4: 15 | K4: 71 | M4: 15 | O4: 80 | P4: 11.3 | Q4: 12.5 | R4: 6.8 | S4: 8.7 | T4: 15.5 | U4: 5.4 | V4: 13 | W4: 7.5 | X4: 10 | Y4: 5.8 | Z4: 7.1 | AA4: 13 | AB4: 4.4 | AC4: 10.4 | AD4: 255 | AE4: 1.1 | AF4: 13.9 | AI4: 4.3 | AN4: 20 | AO4: 20
A5: wheat distillers grain, dry | B5: 3 | C5: Agrodrank90 | D5: 90 | E5: 8.1 | F5: 8.7 | G5: 10.7 | H5: 340 | I5: 66 | K5: 354 | M5: 14 | O5: 44 | P5: 10.6 | Q5: 11.7 | R5: 6.3 | S5: 8.1 | T5: 14.5 | U5: 5.1 | V5: 12.1 | W5: 7 | X5: 9.3 | Y5: 5.4 | Z5: 6.7 | AA5: 12.1 | AB5: 4.1 | AC5: 9.7 | AD5: 231 | AE5: 1 | AF5: 7.3 | AG5: 2.6 | AH5: 9.6 | AK5: 0 | AN5: 20 | AO5: 20
A6: sugar beet pulp | B6: 4 | C6: Betfiber, omelasserad | D6: 89 | E6: 6.9 | F6: 8 | G6: 11.6 | H6: 91 | I6: 10 | J6: 194 | K6: 454 | L6: 231 | M6: 0 | N6: 75 | O6: 77 | P6: 7.2 | Q6: 4.5 | R6: 1.7 | S6: 1.2 | T6: 2.9 | U6: 0.9 | V6: 6.2 | W6: 3.6 | X6: 1.4 | Y6: 1 | Z6: 0.3 | AA6: 1.2 | AB6: 0.4 | AC6: 2.6 | AD6: 48 | AE6: 11.4 | AF6: 1 | AG6: 2.3 | AH6: 3.7 | AI6: 0.6 | AJ6: 54 | AK6: 0.1 | AL6: 6.9 | AM6: 16 | AN6: 20 | AO6: 20
B7: 5 | C7: Drank SBI | D7: 8.1 | E7: 8 | F7: 8.5 | G7: 11.7 | H7: 371 | I7: 65 | J7: 90 | K7: 338 | M7: 0 | O7: 53 | P7: 11.5 | Q7: 12.7 | R7: 6.9 | S7: 8.9 | T7: 15.8 | U7: 5.5 | V7: 13.2 | W7: 7.6 | X7: 10.2 | Y7: 5.9 | Z7: 7.3 | AA7: 13.3 | AB7: 4.5 | AC7: 10.6 | AD7: 252 | AE7: 2.1 | AF7: 8.8 | AG7: 3.1 | AH7: 11.7 | AI7: 2.21 | AN7: 20 | AO7: 20
B8: 6 | C8: Fetter, animala | D8: 100 | E8: 29.8 | F8: 29.8 | G8: 34 | H8: 0 | I8: 1000 | J8: 0 | K8: 0 | L8: 0 | M8: 0 | N8: 0 | O8: 0 | P8: 0 | Q8: 0 | R8: 0 | S8: 0 | T8: 0 | U8: 0 | V8: 0 | W8: 0 | X8: 0 | Y8: 0 | Z8: 0 | AA8: 0 | AB8: 0 | AC8: 0 | AD8: 0 | AE8: 0 | AF8: 0 | AG8: 0 | AH8: 0 | AI8: 0 | AJ8: 0 | AK8: 0 | AL8: 0 | AM8: 0 | AN8: 0 | AO8: 0
A9: fish meal | B9: 7 | C9: Fiskmjöl | D9: 92 | E9: 10.8 | F9: 10.8 | G9: 17.5 | H9: 760 | I9: 105 | J9: 0 | K9: 0 | L9: 0 | M9: 0 | N9: 0 | O9: 135 | P9: 57.2 | Q9: 31.6 | R9: 21.6 | S9: 6.3 | T9: 28 | U9: 7.8 | V9: 38.5 | W9: 53.2 | X9: 29.1 | Y9: 20.1 | Z9: 5.4 | AA9: 25.5 | AB9: 6.9 | AC9: 35.4 | AD9: 676 | AE9: 39.1 | AF9: 24.7 | AG9: 2.3 | AH9: 12 | AI9: 10 | AJ9: 6 | AK9: 2.4 | AL9: 4.6 | AM9: 84 | AN9: 77 | AO9: 77
B10: 8 | C10: Foderkalk | D10: 100 | E10: 0 | F10: 0 | G10: 0 | H10: 0 | I10: 0 | J10: 0 | K10: 0 | L10: 0 | M10: 0 | N10: 0 | O10: 1000 | P10: 0 | Q10: 0 | R10: 0 | S10: 0 | T10: 0 | U10: 0 | V10: 0 | W10: 0 | X10: 0 | Y10: 0 | Z10: 0 | AA10: 0 | AB10: 0 | AC10: 0 | AD10: 0 | AE10: 375 | AF10: 0 | AG10: 0 | AH10: 0 | AI10: 0 | AJ10: 0 | AK10: 0 | AL10: 0 | AM10: 0 | AN10: 0 | AO10: 0
B11: 9 | C11: Gräsmjöl | D11: 90 | E11: 3.9 | F11: 4.7 | G11: 7.7 | H11: 167 | I11: 34 | J11: 260 | K11: 542 | L11: 307 | M11: 0 | N11: 101 | O11: 87 | P11: 6.9 | Q11: 6.4 | R11: 2.4 | S11: 1.5 | T11: 3.8 | U11: 2.4 | V11: 8.5 | W11: 5.3 | X11: 4.9 | Y11: 2 | Z11: 1.1 | AA11: 3 | AB11: 1.9 | AC11: 6.6 | AD11: 87 | AE11: 6 | AF11: 3.1 | AG11: 1.9 | AH11: 23 | AI11: 4.3 | AJ11: 54 | AK11: 0.22 | AL11: 7.8 | AM11: 36 | AN11: 20 | AO11: 20
B12: 10 | C12: Halm, vete | D12: 91 | E12: 1.1 | F12: 1.6 | H12: 42 | I12: 14 | J12: 418 | K12: 789 | L12: 501 | M12: 8 | N12: 16 | O12: 64 | P12: 0 | Q12: 0 | R12: 0 | S12: 0 | T12: 0 | U12: 0 | V12: 0 | W12: 0 | X12: 0 | Y12: 0 | Z12: 0 | AA12: 0 | AB12: 0 | AC12: 0 | AD12: 9 | AE12: 4.9 | AF12: 0.8 | AG12: 0.7 | AH12: 10.3 | AI12: 0.33 | AJ12: 47 | AL12: 3.3 | AM12: 21 | AN12: 20 | AO12: 20
A13: oats | B13: 11 | C13: Havre | D13: 87 | E13: 9 | F13: 9.4 | G13: 12.1 | H13: 111 | I13: 54 | J13: 138 | K13: 372 | L13: 169 | M13: 411 | N13: 13 | O13: 30 | P13: 4.7 | Q13: 3.9 | R13: 2 | S13: 3.7 | T13: 5.7 | U13: 1.4 | V13: 5.9 | W13: 3.4 | X13: 2.7 | Y13: 1.7 | Z13: 2.8 | AA13: 4.4 | AB13: 1.1 | AC13: 4.5 | AD13: 84 | AE13: 0.8 | AF13: 3.6 | AG13: 1.2 | AH13: 5.5 | AI13: 0.3 | AJ13: 43 | AK13: 0.03 | AL13: 2.7 | AM13: 31 | AN13: 32 | AO13: 32
B14: 12 | C14: Havre, skalad | D14: 87 | E14: 11.6 | F14: 11.8 | H14: 124 | I14: 29 | J14: 47 | K14: 136 | L14: 54 | M14: 615 | N14: 14 | O14: 25 | P14: 5.2 | Q14: 4.4 | R14: 2.2 | S14: 3.9 | T14: 6.1 | U14: 1.6 | V14: 6.6 | W14: 4.1 | X14: 3.5 | Y14: 1.9 | Z14: 3.3 | AA14: 5.2 | AB14: 1.3 | AC14: 5.3 | AD14: 102 | AE14: 1 | AF14: 3.4 | AN14: 32 | AO14: 32
A15: barley | B15: 13 | C15: Korn | D15: 87 | E15: 11 | F15: 11.2 | G15: 14.2 | H15: 116 | I15: 21 | J15: 53 | K15: 216 | L15: 63 | M15: 602 | N15: 25 | O15: 26 | P15: 4.4 | Q15: 4 | R15: 2 | S15: 2.7 | T15: 4.7 | U15: 1.4 | V15: 6 | W15: 3.3 | X15: 3 | Y15: 1.7 | Z15: 2.3 | AA15: 3.9 | AB15: 1.1 | AC15: 4.8 | AD15: 93 | AE15: 0.5 | AF15: 3.5 | AG15: 1.2 | AH15: 5.7 | AI15: 0.4 | AJ15: 14 | AK15: 0.04 | AL15: 2.9 | AM15: 28 | AN15: 32 | AO15: 41
A16: linseed | B16: 14 | C16: Linfrö | D16: 91 | E16: 17.3 | F16: 17.5 | G16: 21.3 | H16: 227 | I16: 437 | J16: 80 | K16: 203 | L16: 83 | M16: 0 | N16: 29 | O16: 38 | P16: 9.8 | Q16: 11.6 | R16: 4.8 | S16: 4.9 | T16: 9.8 | U16: 4.3 | V16: 13.3 | W16: 7.5 | X16: 8.8 | Y16: 4.1 | Z16: 3.6 | AA16: 7.7 | AB16: 3.3 | AC16: 10.3 | AD16: 193 | AE16: 2.6 | AF16: 5.7 | AG16: 4.1 | AH16: 8.9 | AI16: 0.4 | AJ16: 30 | AK16: 0.4 | AL16: 14 | AM16: 50 | AN16: 20 | AO16: 20
B17: 15 | C17: Linfröexpeller | D17: 90 | E17: 9.2 | F17: 9.7 | G17: 14.2 | H17: 342 | I17: 90 | J17: 113 | K17: 259 | L17: 157 | M17: 0 | N17: 38 | O17: 65 | P17: 12.9 | Q17: 13 | R17: 5.9 | S17: 6.6 | T17: 12.5 | U17: 5.2 | V17: 16.4 | W17: 9.9 | X17: 9.9 | Y17: 5 | Z17: 4.8 | AA17: 9.8 | AB17: 4 | AC17: 12.7 | AD17: 301 | AE17: 4.7 | AF17: 9.1 | AG17: 5.5 | AH17: 13 | AI17: 0.9 | AJ17: 43 | AK17: 0.5 | AL17: 20 | AM17: 73 | AN17: 12 | AO17: 12
B18: 16 | C18: Lupin, vit | D18: 89 | E18: 10.3 | F18: 10.9 | G18: 15.4 | H18: 385 | I18: 95 | J18: 128 | K18: 214 | L18: 154 | M18: 0 | N18: 72 | O18: 39 | P18: 18.7 | Q18: 14.2 | R18: 3 | S18: 6.3 | T18: 9.3 | U18: 2.7 | V18: 16.5 | W18: 15.3 | X18: 11.1 | Y18: 2.3 | Z18: 4.8 | AA18: 7.1 | AB18: 2.1 | AC18: 12.2 | AD18: 316 | AE18: 3.8 | AF18: 4.3 | AG18: 1.9 | AH18: 13 | AI18: 0.5 | AJ18: 20 | AK18: 0.09 | AL18: 4.5 | AM18: 30 | AN18: 50 | AO18: 50
B19: 17 | C19: Lusernmjöl | D19: 91 | E19: 4.1 | F19: 4.8 | G19: 7.1 | H19: 185 | I19: 28 | J19: 283 | K19: 461 | L19: 326 | M19: 0 | N19: 46 | O19: 117 | P19: 8.5 | Q19: 7.5 | R19: 2.7 | S19: 2.5 | T19: 5.2 | U19: 2.6 | V19: 10.1 | W19: 5.3 | X19: 5 | Y19: 2.1 | Z19: 0.9 | AA19: 3 | AB19: 1.2 | AC19: 7 | AD19: 79 | AE19: 22.4 | AF19: 2.7 | AG19: 1.8 | AH19: 26.1 | AI19: 0.2 | AJ19: 62 | AK19: 0.28 | AL19: 5.6 | AM19: 21 | AN19: 20 | AO19: 20
B20: 18 | C20: Lysin, L-HCL | D20: 99.5 | E20: 14.2 | F20: 14.2 | G20: 17.8 | H20: 959 | I20: 0 | J20: 0 | K20: 0 | L20: 0 | M20: 0 | N20: 0 | O20: 0 | P20: 802 | Q20: 0 | R20: 0 | S20: 0 | T20: 0 | U20: 0 | V20: 0 | W20: 802 | X20: 0 | Y20: 0 | Z20: 0 | AA20: 0 | AB20: 0 | AC20: 0 | AD20: 959 | AE20: 0 | AF20: 0 | AG20: 0 | AH20: 0 | AI20: 0 | AJ20: 0 | AK20: 0 | AL20: 0 | AM20: 0 | AN20: 0 | AO20: 0
A21: maize | B21: 19 | C21: Majs | D21: 87 | E21: 12.8 | F21: 13.2 | G21: 15.6 | H21: 94 | I21: 43 | J21: 25 | K21: 120 | L21: 30 | M21: 742 | N21: 19 | O21: 14 | P21: 2.8 | Q21: 3.5 | R21: 2 | S21: 2.3 | T21: 4.3 | U21: 0.6 | V21: 4.7 | W21: 2.2 | X21: 2.9 | Y21: 1.8 | Z21: 2 | AA21: 3.9 | AB21: 0.5 | AC21: 4.1 | AD21: 81 | AE21: 0.1 | AF21: 3.2 | AG21: 1.2 | AH21: 4 | AI21: 0.3 | AJ21: 6 | AK21: 0.06 | AL21: 3.6 | AM21: 28 | AN21: 28 | AO21: 28
B22: 20 | C22: Majsdrank | D22: 88 | E22: 8 | F22: 9.2 | G22: 0 | H22: 279 | I22: 58 | J22: 83 | K22: 356 | L22: 102 | M22: 130 | N22: 6 | O22: 68 | P22: 7.1 | Q22: 9.7 | R22: 4.9 | S22: 5.4 | T22: 10.2 | U22: 1.9 | V22: 13.1 | W22: 4.1 | X22: 6 | Y22: 3.7 | Z22: 3.2 | AA22: 6.8 | AB22: 1.3 | AC22: 8.6 | AD22: 173 | AE22: 2.4 | AF22: 9.5 | AG22: 3.3 | AH22: 14.1 | AI22: 6.1 | AJ22: 21 | AK22: 0.39 | AL22: 11.4 | AM22: 74 | AN22: 31 | AO22: 31
B23: 21 | C23: Majsglutenfoder | D23: 88 | E23: 7.8 | F23: 9 | G23: 12.6 | H23: 219 | I23: 31 | J23: 85 | K23: 384 | L23: 100 | M23: 205 | N23: 19 | O23: 70 | P23: 6.6 | Q23: 7.4 | R23: 3.7 | S23: 4.3 | T23: 8 | U23: 1.4 | V23: 10.1 | W23: 4.4 | X23: 5.2 | Y23: 3.1 | Z23: 3 | AA23: 6.1 | AB23: 0.9 | AC23: 7.6 | AD23: 151 | AE23: 0.7 | AF23: 10.4 | AG23: 4.7 | AH23: 14 | AI23: 2.4 | AJ23: 23 | AK23: 0.15 | AL23: 5.4 | AM23: 82 | AN23: 22 | AO23: 22
B24: 22 | C24: Majsglutenmjöl | D24: 90 | E24: 12.9 | F24: 13.3 | G24: 17.8 | H24: 677 | I24: 71 | J24: 12 | K24: 26 | L24: 8 | M24: 192 | N24: 4 | O24: 21 | P24: 11.9 | Q24: 22.7 | R24: 16.3 | S24: 12.1 | T24: 28.4 | U24: 3.2 | V24: 31.2 | W24: 10.6 | X24: 20.9 | Y24: 15.5 | Z24: 11.1 | AA24: 26.7 | AB24: 2.8 | AC24: 28.4 | AD24: 623 | AE24: 0.3 | AF24: 6.4 | AG24: 1.6 | AH24: 5.5 | AI24: 0.8 | AJ24: 11 | AK24: 0.09 | AL24: 11 | AM24: 39 | AN24: 19 | AO24: 19
A25: sugar beet molasses | B25: 23 | C25: Melass, bet | D25: 76 | E25: 8.7 | F25: 9 | G25: 12.9 | H25: 145 | I25: 2 | J25: 0 | K25: 0 | L25: 0 | M25: 0 | N25: 616 | O25: 129 | P25: 2.1 | Q25: 0.9 | R25: 0.3 | S25: 0.9 | T25: 1.2 | U25: 1.1 | V25: 2.5 | W25: 1.6 | X25: 0.7 | Y25: 0.3 | Z25: 0.7 | AA25: 0.9 | AB25: 0.8 | AC25: 1.9 | AD25: 75 | AE25: 5.4 | AF25: 0.4 | AG25: 0.3 | AH25: 28 | AI25: 4.1 | AJ25: 17 | AK25: 0.1 | AL25: 4.1 | AM25: 16 | AN25: 20 | AO25: 20
B26: 24 | C26: Melass, rör | D26: 74 | E26: 8.7 | F26: 9 | G26: 12.9 | H26: 55 | I26: 15 | J26: 0 | K26: 0 | L26: 0 | M26: 0 | N26: 640 | O26: 140 | P26: 0.2 | Q26: 0.8 | R26: 0.2 | S26: 0.5 | T26: 0.7 | U26: 0.1 | V26: 1.7 | W26: 0.2 | X26: 0.6 | Y26: 0.2 | Z26: 0.4 | AA26: 0.6 | AB26: 0.1 | AC26: 1.3 | AD26: 25 | AE26: 5.4 | AF26: 0.7 | AG26: 4 | AH26: 49 | AI26: 2.3 | AJ26: 13 | AK26: 0.4 | AL26: 4.6 | AM26: 8 | AN26: 20 | AO26: 20
B27: 25 | C27: Metionin | D27: 99.5 | E27: 17.4 | F27: 17.4 | G27: 10.9 | H27: 587 | I27: 0 | J27: 0 | K27: 0 | L27: 0 | M27: 0 | N27: 0 | O27: 0 | P27: 0 | Q27: 0 | R27: 995 | S27: 0 | T27: 995 | U27: 0 | V27: 0 | W27: 0 | X27: 0 | Y27: 995 | Z27: 0 | AA27: 995 | AB27: 0 | AC27: 0 | AD27: 587 | AE27: 0 | AF27: 0 | AG27: 0 | AH27: 0 | AI27: 0 | AJ27: 0 | AK27: 0 | AL27: 0 | AM27: 0 | AN27: 0 | AO27: 0
B28: 26 | C28: Metioninhydroxyanalog | D28: 88 | E28: 17.4 | F28: 17.4 | G28: 10.9 | H28: 587 | I28: 0 | J28: 0 | K28: 0 | L28: 0 | M28: 0 | N28: 0 | O28: 0 | P28: 0 | Q28: 0 | R28: 870 | S28: 0 | T28: 870 | U28: 0 | V28: 0 | W28: 0 | X28: 0 | Y28: 653 | Z28: 0 | AA28: 653 | AB28: 0 | AC28: 0 | AD28: 587 | AE28: 0 | AF28: 0 | AG28: 0 | AH28: 0 | AI28: 0 | AJ28: 0 | AK28: 0 | AL28: 0 | AM28: 0 | AN28: 0 | AO28: 0
B29: 27 | C29: Monokalciumfosfat | D29: 100 | E29: 0 | F29: 0 | G29: 0 | H29: 0 | I29: 0 | J29: 0 | K29: 0 | L29: 0 | M29: 0 | N29: 0 | O29: 1000 | P29: 0 | Q29: 0 | R29: 0 | S29: 0 | T29: 0 | U29: 0 | V29: 0 | W29: 0 | X29: 0 | Y29: 0 | Z29: 0 | AA29: 0 | AB29: 0 | AC29: 0 | AD29: 0 | AE29: 195 | AF29: 230 | AG29: 0 | AH29: 0 | AI29: 0 | AJ29: 0 | AK29: 0 | AL29: 0 | AM29: 0 | AN29: 83 | AO29: 83
A30: vegetable oils | B30: 28 | C30: Oljor, vegetabila | D30: 100 | E30: 29.8 | F30: 29.8 | G30: 34 | H30: 0 | I30: 1000 | J30: 0 | K30: 0 | L30: 0 | M30: 0 | N30: 0 | O30: 0 | P30: 0 | Q30: 0 | R30: 0 | S30: 0 | T30: 0 | U30: 0 | V30: 0 | W30: 0 | X30: 0 | Y30: 0 | Z30: 0 | AA30: 0 | AB30: 0 | AC30: 0 | AD30: 0 | AE30: 0 | AF30: 0 | AG30: 0 | AH30: 0 | AI30: 0 | AJ30: 0 | AK30: 0 | AL30: 0 | AM30: 0 | AN30: 0 | AO30: 0
A31: palm kernel expeller | B31: 29 | C31: Palmkärnkaka | D31: 91 | E31: 5.4 | F31: 6.2 | H31: 163 | I31: 94 | J31: 62 | K31: 726 | L31: 445 | M31: 0 | N31: 22 | O31: 46 | P31: 4.5 | Q31: 4.9 | R31: 2.9 | S31: 1.8 | T31: 4.7 | U31: 1.1 | V31: 8.1 | W31: 1.7 | X31: 2.5 | Y31: 2 | Z31: 0.8 | AA31: 2.8 | AB31: 0.6 | AC31: 5.3 | AD31: 88 | AE31: 4.2 | AF31: 6.4 | AG31: 3.3 | AH31: 7.5 | AI31: 0.1 | AJ31: 260 | AL31: 25 | AM31: 47 | AN31: 31 | AO31: 31
B32: 30 | C32: Permeatvassle | D32: 16.5 | E32: 11.9 | F32: 11.7 | G32: 14.1 | H32: 29 | I32: 0 | J32: 0 | K32: 0 | L32: 0 | M32: 0 | N32: 880 | O32: 90 | P32: 2.1 | Q32: 1.7 | R32: 0.5 | S32: 0.5 | T32: 1 | U32: 0.4 | V32: 1.5 | W32: 1.9 | X32: 1.4 | Y32: 0.4 | Z32: 0.4 | AA32: 0.9 | AB32: 0.3 | AC32: 1.3 | AD32: 23 | AE32: 7 | AF32: 7 | AG32: 1 | AH32: 25 | AI32: 9 | AN32: 90 | AO32: 90
A33: potatoe protein | B33: 31 | C33: Potatisproteinkoncentrat | D33: 92 | E33: 11.1 | F33: 11.3 | G33: 17.1 | H33: 841 | I33: 10 | J33: 9 | K33: 65 | L33: 19 | M33: 7 | N33: 10 | O33: 28 | P33: 63.8 | Q33: 46.7 | R33: 18.8 | S33: 11.2 | T33: 30 | U33: 10.3 | V33: 55.5 | W33: 56.8 | X33: 42 | Y33: 17.1 | Z33: 8.7 | AA33: 25.8 | AB33: 7.7 | AC33: 49.4 | AD33: 732 | AE33: 0.5 | AF33: 4.3 | AG33: 0.5 | AH33: 7.4 | AI33: 0.3 | AJ33: 4 | AL33: 11 | AM33: 21 | AN33: 20 | AO33: 20
B34: 32 | C34: Potatispulpa | D34: 18 | E34: 10.5 | F34: 10.8 | G34: 14.4 | H34: 127 | I34: 13 | J34: 47 | K34: 116 | L34: 60 | M34: 470 | N34: 21 | O34: 71 | P34: 6.6 | Q34: 5.1 | R34: 2 | S34: 1.7 | T34: 3.7 | U34: 1.2 | V34: 6.6 | W34: 5.1 | X34: 3.9 | Y34: 1.7 | Z34: 1.2 | AA34: 2.9 | AB34: 0.9 | AC34: 5.1 | AD34: 96 | AE34: 1.9 | AF34: 2.3 | AN34: 20 | AO34: 20
A35: rapeseed | B35: 33 | C35: Rapsfrö | D35: 92 | E35: 18 | F35: 18.5 | G35: 22.1 | H35: 207 | I35: 455 | J35: 89 | K35: 190 | L35: 134 | M35: 0 | N35: 55 | O35: 43 | P35: 12.9 | Q35: 9.9 | R35: 4.5 | S35: 5.1 | T35: 9.6 | U35: 2.7 | V35: 10.8 | W35: 10.1 | X35: 7 | Y35: 3.6 | Z35: 4.1 | AA35: 7.7 | AB35: 2 | AC35: 7.6 | AD35: 149 | AE35: 5.8 | AF35: 7.6 | AG35: 3.5 | AH35: 10 | AI35: 0.2 | AJ35: 42 | AL35: 4.1 | AM35: 42 | AN35: 30 | AO35: 30
B36: 34 | C36: Rapskaka | D36: 89 | E36: 9.7 | F36: 10.2 | G36: 14.3 | H36: 331 | I36: 164 | J36: 122 | K36: 275 | L36: 192 | M36: 0 | N36: 77 | O36: 68 | P36: 17.7 | Q36: 14.2 | R36: 6.8 | S36: 8 | T36: 14.8 | U36: 4 | V36: 16.7 | W36: 13.3 | X36: 10.7 | Y36: 5.9 | Z36: 6.5 | AA36: 12.4 | AB36: 3.2 | AC36: 12.9 | AD36: 258 | AE36: 8.1 | AF36: 12 | AG36: 4.7 | AH36: 13.5 | AI36: 0.1 | AJ36: 61 | AL36: 7.3 | AM36: 59 | AN36: 32 | AO36: 32
B37: 35 | C37: Rapskaka, kallpressad | D37: 89 | E37: 10.5 | F37: 11 | G37: 15.1 | H37: 276 | I37: 200 | J37: 62 | K37: 254 | L37: 180 | M37: 0 | N37: 74 | O37: 58 | P37: 14.8 | Q37: 11.8 | R37: 5.7 | S37: 6.7 | T37: 12.4 | U37: 3.3 | V37: 14 | W37: 11.1 | X37: 8.9 | Y37: 4.9 | Z37: 5.4 | AA37: 10.4 | AB37: 2.7 | AC37: 10.7 | AD37: 215 | AE37: 7.8 | AF37: 11.5 | AG37: 4.5 | AH37: 13 | AI37: 0.1 | AJ37: 59 | AK37: 0.11 | AL37: 7 | AM37: 53 | AN37: 32 | AO37: 32
A38: rapeseed meal | B38: 36 | C38: Rapsmjöl | D38: 89 | E38: 7.1 | F38: 7.7 | G38: 11.5 | H38: 380 | I38: 26 | J38: 139 | K38: 319 | L38: 221 | M38: 0 | N38: 87 | O38: 79 | P38: 20.3 | Q38: 16.3 | R38: 7.8 | S38: 9.2 | T38: 17 | U38: 4.6 | V38: 19.2 | W38: 15.2 | X38: 12.2 | Y38: 6.8 | Z38: 7.5 | AA38: 14.3 | AB38: 3.7 | AC38: 14.8 | AD38: 300 | AE38: 9.6 | AF38: 12.9 | AG38: 5.3 | AH38: 15 | AI38: 0.4 | AJ38: 76 | AK38: 0.09 | AL38: 6.4 | AM38: 73 | AN38: 32 | AO38: 32
B39: 37 | C39: Ris, knäckt | D39: 87 | E39: 13.5 | F39: 13.5 | G39: 15.5 | H39: 88 | I39: 14 | J39: 12 | K39: 59 | L39: 15 | M39: 882 | N39: 5 | O39: 10 | P39: 3.2 | Q39: 3 | R39: 2.1 | S39: 2.1 | T39: 4.2 | U39: 1 | V39: 5.2 | W39: 2.5 | X39: 2.3 | Y39: 1.8 | Z39: 1.5 | AA39: 3.3 | AB39: 0.8 | AC39: 4 | AD39: 79 | AE39: 0.5 | AF39: 2.3 | AG39: 1.5 | AH39: 2.5 | AI39: 0.4 | AJ39: 13 | AK39: 0.3 | AL39: 24 | AM39: 19 | AN39: 20 | AO39: 20
A40: rye | B40: 38 | C40: Råg | D40: 87 | E40: 11.3 | F40: 11.5 | G40: 14.8 | H40: 103 | I40: 14 | J40: 22 | K40: 161 | L40: 36 | M40: 616 | N40: 36 | O40: 21 | P40: 4 | Q40: 3.5 | R40: 1.6 | S40: 2.3 | T40: 4 | U40: 1 | V40: 5 | W40: 2.9 | X40: 2.5 | Y40: 1.3 | Z40: 1.9 | AA40: 3.3 | AB40: 0.8 | AC40: 3.8 | AD40: 79 | AE40: 0.5 | AF40: 3.2 | AG40: 1.1 | AH40: 5.6 | AI40: 0.4 | AJ40: 28 | AK40: 0.03 | AL40: 3.5 | AM40: 34 | AN40: 30 | AO40: 50
...

Sheet cattle
D1: 1 | E1: 2 | F1: 3 | G1: 4 | H1: 5 | I1: 6 | J1: 7 | K1: 8 | L1: 9 | M1: 10 | N1: 11 | O1: 12 | P1: 13 | Q1: 14 | R1: 15 | S1: 16 | T1: 17 | U1: 18 | V1: 19 | W1: 20 | X1: 21 | Y1: 22 | Z1: 23 | AA1: 24 | AB1: 25 | AC1: 26 | AD1: 27 | AE1: 28 | AF1: 29 | AG1: 30 | AH1: 31
A2: feed | B2: Nr | C2: Fodermedel | D2: Ts, % | E2: Oms energi, MJ | F2: AAT, g | G2: PBV, g | H2: Smb råprot, g | I2: Smb energi, MJ | J2: Råprot, g | K2: Råfett, g | L2: Växttråd, g | M2: Aska, g | N2: NFE, g | O2: Råprotein smb.koeff | P2: Råfett smb.koeff | Q2: Växttråd smb.koeff | R2: NFE smb.koeff | S2: Org subst smb.koeff | T2: EFD smb.koeff | U2: EPD smb.koeff | V2: Protein i tarm smb.koeff | W2: Socker, g | X2: Pektin, g | Y2: Stärkelse, g | Z2: NDF, g | AA2: Lignin, g | AB2: Ca, g | AC2: P, g | AD2: Mg, g | AE2: K, g | AF2: Na, g | AG2: CAB, meq | AH2: Na, g
B3: 1 | C3: Asp, bark | D3: 50 | E3: 7.9 | H3: 18 | I3: 8.9 | J3: 60 | K3: 110 | L3: 330 | M3: 40 | N3: 460 | O3: 30 | P3: 75 | Q3: 15 | R3: 60 | S3: 44 | AB3: 12 | AC3: 0.6
B4: 2 | C4: Asp, löv | D4: 85 | E4: 7.9 | H4: 90 | I4: 9.6 | J4: 150 | K4: 70 | L4: 230 | M4: 70 | N4: 480 | O4: 60 | P4: 35 | Q4: 50 | R4: 55 | S4: 53 | AB4: 14.1 | AC4: 1.2
B5: 3 | C5: Babassu, kaka | D5: 90 | E5: 12.8 | H5: 213 | I5: 14.6 | J5: 250 | K5: 80 | L5: 170 | M5: 60 | N5: 440 | O5: 85 | P5: 90 | Q5: 30 | R5: 80 | S5: 73 | AB5: 1.8 | AC5: 7.7 | AD5: 4.4 | AE5: 10 | AF5: 0.3 | AH5: 0.3
B6: 4 | C6: Babassu, mjöl | D6: 90 | E6: 11.2 | H6: 221 | I6: 13.4 | J6: 260 | K6: 10 | L6: 180 | M6: 60 | N6: 490 | O6: 85 | P6: 90 | Q6: 30 | R6: 80 | S6: 72 | AB6: 2.2 | AC6: 12.2
B7: 5 | C7: Blandsäd, kärna havre/korn | D7: 84 | E7: 12.4 | F7: 78 | G7: -16 | H7: 90 | I7: 14.1 | J7: 116 | K7: 43 | L7: 100 | M7: 28 | N7: 713 | O7: 78 | P7: 82 | Q7: 30 | R7: 83 | S7: 81 | U7: 82 | V7: 71 | W7: 18 | Y7: 434 | Z7: 277 | AA7: 20 | AB7: 0.6 | AC7: 4 | AD7: 1.3 | AE7: 5.6 | AF7: 0.3 | AH7: 0.3
B8: 6 | C8: Blaster, diverse blaster, ensilerade | D8: 14 | E8: 10.2 | F8: 74 | G8: 46 | H8: 138 | I8: 12.3 | J8: 180 | K8: 30 | L8: 130 | M8: 180 | N8: 480 | P8: 50 | Q8: 80 | R8: 80 | S8: 78 | U8: 74 | V8: 73 | W8: 120 | Y8: 0 | AB8: 15 | AC8: 2.8 | AD8: 3 | AE8: 37 | AF8: 10 | AH8: 10
B9: 7 | C9: Bok, ollon | D9: 85 | E9: 15.6 | H9: 113 | I9: 16 | J9: 150 | K9: 300 | L9: 210 | M9: 50 | N9: 290 | O9: 75 | P9: 90 | Q9: 30 | R9: 60 | S9: 65 | AB9: 5.9 | AC9: 3.5
B10: 8 | C10: Bomull, expeller, ej välskalade | D10: 92 | E10: 10.9 | H10: 221 | I10: 12.5 | J10: 270 | K10: 70 | L10: 200 | M10: 70 | N10: 390 | O10: 82 | P10: 95 | Q10: 25 | R10: 60 | S10: 60 | U10: 58 | V10: 86 | W10: 54 | Y10: 15 | AB10: 2.2 | AC10: 11.9 | AD10: 6.4 | AE10: 18 | AF10: 0.2 | AH10: 0.2
B11: 9 | C11: Bomull, expeller, välskalade | D11: 92 | E11: 13.2 | F11: 162 | G11: 210 | H11: 374 | I11: 15.6 | J11: 440 | K11: 70 | L11: 100 | M11: 70 | N11: 320 | O11: 85 | P11: 90 | Q11: 30 | R11: 70 | S11: 74 | T11: 44 | U11: 58 | V11: 86 | W11: 54 | Y11: 15 | Z11: 257 | AA11: 60 | AB11: 2.2 | AC11: 11.9 | AD11: 6.4 | AE11: 18 | AF11: 0.2 | AG11: 71 | AH11: 0.2
B12: 10 | C12: Bomull, frö | D12: 92 | E12: 15.3 | H12: 168 | I12: 16.5 | J12: 240 | K12: 250 | L12: 250 | M12: 50 | N12: 210 | O12: 70 | P12: 90 | Q12: 60 | R12: 60 | S12: 70 | Z12: 400 | AA12: 150 | AB12: 1.6 | AC12: 9.8 | AD12: 4.1 | AE12: 11.8 | AF12: 0.1 | AH12: 0.1
B13: 11 | C13: Bomull, mjöl, oskalat frö | D13: 92 | E13: 8.8 | H13: 230 | I13: 10.8 | J13: 280 | K13: 10 | L13: 300 | M13: 60 | N13: 350 | O13: 82 | P13: 90 | Q13: 25 | R13: 60 | S13: 59 | W13: 15 | Y13: 54 | AB13: 2.1 | AC13: 12.6 | AD13: 6.9 | AE13: 19 | AF13: 0.2 | AH13: 0.2
B14: 12 | C14: Bomull, mjöl, skalat frö | D14: 90 | E14: 12 | F14: 167 | G14: 244 | H14: 417 | I14: 14.7 | J14: 490 | K14: 10 | L14: 110 | M14: 80 | N14: 310 | O14: 85 | P14: 90 | Q14: 30 | R14: 70 | S14: 73 | U14: 59 | V14: 82 | W14: 15 | Y14: 54 | Z14: 260 | AA14: 60 | AB14: 2.1 | AC14: 12.6 | AD14: 6.5 | AE14: 19 | AF14: 0.2 | AH14: 0.2
B15: 13 | C15: Citruspulpa | D15: 90 | E15: 12.6 | F15: 94 | G15: -89 | H15: 30 | I15: 14.5 | J15: 70 | K15: 26 | L15: 132 | M15: 65 | N15: 707 | O15: 43 | P15: 81 | Q15: 79 | R15: 92 | T15: 75 | U15: 66 | V15: 79 | W15: 243 | X15: 238 | Y15: 60 | Z15: 195 | AB15: 15.5 | AC15: 1.3 | AD15: 1.8 | AE15: 10.7
B16: 14 | C16: Fett, vegetabiliskt | D16: 99 | E16: 31.5 | F16: 0 | G16: 0 | H16: 0 | J16: 0 | K16: 1000 | L16: 0 | M16: 0 | N16: 0 | W16: 0 | Y16: 0 | Z16: 0 | AA16: 0 | AB16: 0 | AC16: 0 | AD16: 0 | AE16: 0 | AF16: 0 | AH16: 0
B17: 15 | C17: Foderbeta, rotfrukt | D17: 12 | E17: 12.5 | F17: 87 | G17: -71 | H17: 48 | I17: 14.3 | J17: 80 | K17: 10 | L17: 70 | M17: 90 | N17: 750 | O17: 60 | P17: 0 | Q17: 70 | R17: 95 | S17: 89 | U17: 82 | V17: 61 | W17: 610 | Y17: 0 | AB17: 2.3 | AC17: 1.6 | AD17: 1.3 | AE17: 15 | AF17: 1.5 | AG17: 346 | AH17: 1.5
B18: 16 | C18: Fodercellulosa | D18: 90 | E18: 10.6 | F18: 89 | G18: -150 | H18: 0 | I18: 14.5 | J18: 3 | K18: 5 | L18: 815 | M18: 7 | N18: 170 | O18: 0 | P18: 40 | Q18: 90 | R18: 60 | S18: 90 | U18: 0 | V18: 0
B19: 17 | C19: Fodermärgkål, hela plantan, ensilerad | D19: 15 | E19: 10.6 | F19: 71 | G19: 12 | H19: 100 | I19: 12.6 | J19: 140 | K19: 30 | L19: 200 | M19: 130 | N19: 500 | P19: 58 | Q19: 58 | R19: 88 | S19: 72 | U19: 80 | V19: 63 | W19: 10 | Y19: 0 | AB19: 19.4 | AC19: 4.3 | AD19: 2.8 | AE19: 30 | AF19: 2.5 | AH19: 2.5
B20: 18 | C20: Fodersockerbeta | D20: 16 | E20: 12.7 | F20: 90 | G20: -93 | H20: 36 | I20: 14.5 | J20: 60 | K20: 10 | L20: 68 | M20: 78 | N20: 784 | O20: 60 | P20: 0 | Q20: 65 | R20: 95 | S20: 90 | U20: 80 | V20: 82 | W20: 680 | Y20: 0 | AB20: 1.8 | AC20: 1.7 | AD20: 1.4 | AE20: 21 | AF20: 2 | AH20: 1.5
B21: 19 | C21: Halm, baljväxt | D21: 90 | E21: 7.3 | F21: 43 | G21: -9 | H21: 47 | I21: 8.4 | J21: 105 | K21: 20 | L21: 450 | M21: 71 | N21: 354 | O21: 45 | P21: 40 | Q21: 50 | R21: 50 | S21: 49 | U21: 60 | V21: 0 | W21: 0 | Y21: 0 | AB21: 13 | AC21: 2.4 | AD21: 3.9 | AE21: 14 | AF21: 0.1 | AH21: 0.1
B22: 20 | C22: Halm, gräs | D22: 89 | E22: 6.9 | F22: 47 | G22: -35 | H22: 29 | I22: 8.6 | J22: 73 | K22: 20 | L22: 400 | M22: 64 | N22: 443 | O22: 40 | P22: 40 | Q22: 55 | R22: 50 | S22: 51 | U22: 60 | V22: 0 | W22: 0 | Y22: 0 | AB22: 3.3 | AC22: 1.4 | AD22: 1.4 | AE22: 25 | AF22: 1 | AH22: 1
B23: 21 | C23: Halm, stråsäd, NH3-behandlad | D23: 80 | E23: 8.3 | F23: 54 | G23: 4 | H23: 50 | I23: 10.3 | J23: 119 | K23: 20 | L23: 400 | M23: 60 | N23: 401 | O23: 42 | P23: 40 | Q23: 65 | R23: 62 | S23: 61 | U23: 80 | V23: 0 | W23: 0 | Y23: 0 | AB23: 3.3 | AC23: 1.1 | AD23: 1.3 | AE23: 19 | AF23: 3 | AH23: 3
A24: straw | B24: 22 | C24: Halm, stråsäd, ej behandlad | D24: 85 | E24: 6.6 | F24: 45 | G24: -60 | H24: 0 | I24: 7.6 | J24: 69 | K24: 20 | L24: 436 | M24: 66 | N24: 409 | O24: 0 | P24: 40 | Q24: 55 | R24: 45 | S24: 47 | T24: 25 | U24: 23 | V24: 0 | W24: 0 | Y24: 0 | Z24: 748 | AA24: 120 | AB24: 7.5 | AC24: 2.6 | AD24: 2.8 | AE24: 16.8 | AF24: 3 | AG24: 162 | AH24: 3
B25: 23 | C25: Halm, stråsäd, torrlutad | D25: 59 | E25: 7.9 | F25: 63 | G25: -74 | H25: 0 | I25: 10.4 | J25: 40 | K25: 15 | L25: 408 | M25: 100 | N25: 437 | O25: 0 | P25: 35 | Q25: 75 | R25: 65 | S25: 65 | T25: 34 | U25: 80 | V25: 0 | W25: 0 | Y25: 0 | AB25: 3.3 | AC25: 1.1 | AD25: 1.3 | AE25: 19 | AF25: 28.1 | AH25: 28
B26: 24 | C26: Halm, stråsäd, våtlutad | D26: 74 | E26: 8.2 | F26: 59 | G26: -67 | H26: 0 | I26: 9.8 | J26: 40 | K26: 15 | L26: 421 | M26: 73 | N26: 451 | O26: 0 | P26: 35 | Q26: 65 | R26: 62 | S26: 73 | U26: 80 | V26: 0 | W26: 0 | Y26: 0 | AB26: 3.2 | AC26: 1.8
B27: 25 | C27: Hamp, frö | D27: 93 | E27: 17.7 | H27: 140 | I27: 18.2 | J27: 200 | K27: 350 | L27: 170 | M27: 50 | N27: 230 | O27: 70 | P27: 90 | Q27: 30 | R27: 80 | S27: 73 | AB27: 1.7 | AC27: 6
B28: 26 | C28: Havre, hela plantan, ensilerad | D28: 37 | E28: 9.1 | F28: 58 | G28: -8 | H28: 69 | I28: 11.2 | J28: 107 | K28: 25 | L28: 313 | M28: 72 | N28: 483 | P28: 54 | Q28: 62 | R28: 68 | S28: 63 | U28: 80 | V28: 19 | Z28: 536 | AA28: 90 | AB28: 4.5 | AC28: 2.9 | AD28: 1.4 | AE28: 20.1 | AF28: 1.5 | AH28: 0.5
B29: 27 | C29: Havre, kli | D29: 87 | E29: 7.2 | F29: 56 | G29: -28 | H29: 35 | I29: 8.4 | J29: 63 | K29: 32 | L29: 290 | M29: 55 | N29: 560 | O29: 56 | P29: 65 | Q29: 30 | R29: 55 | S29: 48 | U29: 67 | V29: 77 | AB29: 2 | AC29: 7.7
A30: oats | B30: 28 | C30: Havre, kärna | D30: 85 | E30: 11.7 | F30: 67 | G30: -2 | H30: 88 | I30: 13.3 | J30: 110 | K30: 61 | L30: 141 | M30: 34 | N30: 654 | O30: 80 | P30: 88 | Q30: 30 | R30: 76 | S30: 75 | T30: 37 | U30: 86 | V30: 73 | W30: 10 | X30: 21 | Y30: 338 | Z30: 358 | AA30: 30 | AB30: 0.7 | AC30: 3.7 | AD30: 1.2 | AE30: 5.3 | AF30: 0.1 | AG30: -32 | AH30: 0.1
B31: 29 | C31: Havre, skal | D31: 87 | E31: 5.2 | H31: 9 | I31: 6.2 | J31: 30 | K31: 20 | L31: 340 | M31: 50 | N31: 560 | O31: 30 | P31: 80 | Q31: 35 | R31: 35 | S31: 36 | W31: 11 | Y31: 130 | Z31: 780 | AA31: 80 | AB31: 1.2 | AC31: 4.4 | AD31: 1 | AE31: 6 | AF31: 0.3 | AH31: 0.3
B32: 30 | C32: Havre, skalad | D32: 87 | E32: 13.1 | F32: 75 | G32: 37 | H32: 118 | I32: 14.8 | J32: 160 | K32: 67 | L32: 33 | M32: 23 | N32: 717 | O32: 74 | P32: 80 | Q32: 25 | R32: 80 | S32: 77 | T32: 87 | U32: 88 | V32: 77 | W32: 13 | Y32: 637 | Z32: 94 | AB32: 0.8 | AC32: 4.6 | AD32: 1.3 | AE32: 4
B33: 31 | C33: Hästkastanj, kastanjer | D33: 50 | E33: 13.5 | H33: 48 | I33: 15.1 | J33: 80 | K33: 50 | L33: 50 | M33: 30 | N33: 790 | O33: 60 | P33: 80 | Q33: 30 | R33: 90 | S33: 84 | AB33: 1 | AC33: 4
B34: 32 | C34: Johannesbröd | D34: 82 | E34: 10.7 | F34: 91 | G34: -107 | H34: 0 | I34: 12 | J34: 43 | K34: 0 | L34: 79 | M34: 30 | N34: 848 | O34: 0 | P34: 0 | Q34: 47 | R34: 80 | S34: 74 | T34: 36 | U34: 49 | V34: 82 | W34: 457 | Y34: 0 | Z34: 288 | AB34: 4.5 | AC34: 1
B35: 33 | C35: Jäst, bryggerijäst | D35: 90 | E35: 14.6 | F35: 110 | G35: 332 | H35: 450 | I35: 17.7 | J35: 500 | K35: 10 | L35: 20 | M35: 70 | N35: 400 | O35: 90 | P35: 75 | Q35: 90 | R35: 90 | S35: 90 | U35: 80 | V35: 82 | AB35: 2.2 | AC35: 15.6 | AD35: 2.6 | AE35: 24 | AF35: 2.4 | AH35: 2.4
B36: 34 | C36: Kasein | D36: 88 | E36: 15.3 | F36: 3 | G36: 865 | H36: 783 | I36: 19.5 | J36: 870 | K36: 0 | L36: 0 | M36: 100 | N36: 30 | O36: 90 | P36: 0 | Q36: 0 | R36: 100 | S36: 91 | U36: 100 | V36: 82 | W36: 0 | Y36: 0 | AB36: 34 | AC36: 19 | AD36: 0.1 | AE36: 0 | AF36: 0.2 | AH36: 0.2
B37: 35 | C37: Kokos, expeller | D37: 94 | E37: 14.7 | F37: 125 | G37: 32 | H37: 178 | I37: 16.5 | J37: 223 | K37: 113 | L37: 115 | M37: 57 | N37: 492 | O37: 80 | P37: 95 | Q37: 65 | R37: 85 | S37: 82 | T37: 56 | U37: 54 | V37: 83 | W37: 110 | Y37: 6 | Z37: 388 | AB37: 1 | AC37: 5.4 | AD37: 3.3 | AE37: 21 | AF37: 1 | AG37: 202 | AH37: 1
B38: 36 | C38: Kokos, mjöl | D38: 92 | E38: 12 | F38: 153 | G38: 26 | H38: 208 | I38: 14.3 | J38: 260 | K38: 10 | L38: 160 | M38: 70 | N38: 500 | O38: 80 | P38: 80 | Q38: 60 | R38: 85 | S38: 79 | U38: 46 | V38: 82 | W38: 112 | Y38: 19 | Z38: 580 | AB38: 1.4 | AC38: 6.4 | AD38: 3.6 | AE38: 23 | AF38: 0.6 | AH38: 0.6
B39: 37 | C39: Korn, drank | D39: 7 | E39: 12.5 | F39: 72 | G39: 184 | H39: 210 | I39: 14.4 | J39: 300 | K39: 120 | L39: 90 | M39: 40 | N39: 450 | O39: 70 | P39: 80 | Q39: 60 | R39: 65 | S39: 68 | U39: 82 | V39: 77 | AB39: 2.5 | AC39: 7.5 | AD39: 2 | AE39: 1 | AF39: 0.3 | AH39: 0.3
A40: barley brewers grain | B40: 38 | C40: Korn, drav, 24 % rp | D40: 90 | E40: 11.6 | F40: 141 | G40: 20 | H40: 180 | I40: 13.6 | J40: 240 | K40: 80 | L40: 170 | M40: 40 | N40: 470 | O40: 75 | P40: 85 | Q40: 55 | R40: 65 | S40: 67 | U40: 38 | V40: 78 | W40: 20 | X40: 29 | Y40: 100 | Z40: 460 | AA40: 60 | AB40: 2 | AC40: 5.5 | AD40: 2 | AE40: 1 | AF40: 0.3 | AH40: 0.3
...
