Workbook

Sheet default
A1: f_prod_system | B1: f_animal | C1: f_feed | D1: parameter | E1: value | F1: unit | G1: description | H1: source
A2: Production system
D3: time_in_hen_house | E3: =(64+58+60)/3 -> 60.666667 | F3: weeks | G3: Avg och gård A, B in Sonesson and organic farm in Carlsson | H3: Sonesson et al 2008, Carlsson et al 2009
D4: chicks_per_breeding hen | E4: 100 | F4: nr | G4: ???
D5: roosters_per_breeding_hen | E5: 12.5 | F5: nr | G5: ???
B7: laying chicks | D7: weeks_in_stage | E7: =15-0+1 -> 16 | F7: weeks
B8: laying hens (16-28 weeks) | D8: weeks_in_stage | E8: =28-16+1 -> 13 | F8: weeks
B9: laying hens (29-59 weeks) | D9: weeks_in_stage | E9: =59-29+1 -> 31 | F9: weeks
B10: laying hens (>59 weeks) | D10: weeks_in_stage | E10: =(E3+E7)-60+1 -> 17.666667 | F10: weeks
A12: conventional | B12: laying chicks | D12: mortality | E12: 10 | F12: % | G12: assumed for now
A13: organic | B13: laying chicks | D13: mortality | E13: 10 | F13: % | G13: assumed for now
A14: conventional | D14: mortality | E14: =(3.85+6.24)/2 -> 5.045 | F14: % | G14: Avg gård A and B | H14: Sonesson et al 2008
A15: organic | D15: mortality | E15: 10 | F15: % | H15: Carlsson et al 2009
D16: rejections_at_slaughter | E16: 5 | F16: % | G16: assumed for now. 2.3% for broilers
A18: Productivity
D19: egg_production | E19: 0 | F19: kg/head/year | G19: Fallback
A20: conventional | B20: laying hens (16-28 weeks) | D20: egg_production | E20: =(22.5/64*52+20.2/58*52)/2 -> 18.195797 | F20: kg/head/year | G20: Avg gård A and B | H20: Sonesson et al 2008
A21: conventional | B21: laying hens (29-59 weeks) | D21: egg_production | E21: =E20 -> 18.195797 | F21: =F20 -> kg/head/year
A22: conventional | B22: laying hens (>59 weeks) | D22: egg_production | E22: =E20 -> 18.195797 | F22: =F21 -> kg/head/year
A23: organic | B23: laying hens (16-28 weeks) | D23: egg_production | E23: =20/60*52 -> 17.333333 | F23: kg/head/year | H23: Carlsson et al 2009
A24: organic | B24: laying hens (29-59 weeks) | D24: egg_production | E24: =E23 -> 17.333333 | F24: =F23 -> kg/head/year
A25: organic | B25: laying hens (>59 weeks) | D25: egg_production | E25: =E23 -> 17.333333 | F25: =F24 -> kg/head/year
D27: slaughter_weight | E27: 0 | F27: kg CW | G27: ???
A29: Feed requirements | F29: kg DM/live animal/year | H29: see Feed rations tab
A30: conventional | B30: laying chicks | D30: feed_per_head | E30: =INDEX('Feed rations'!$W$19:$AA$19,MATCH(B30,'Feed rations'!$W$4:$AA$4,0)) -> 14.427075
A31: conventional | B31: laying hens (16-28 weeks) | D31: feed_per_head | E31: =INDEX('Feed rations'!$W$19:$AA$19,MATCH(B31,'Feed rations'!$W$4:$AA$4,0)) -> 35.955136
A32: conventional | B32: laying hens (29-59 weeks) | D32: feed_per_head | E32: =INDEX('Feed rations'!$W$19:$AA$19,MATCH(B32,'Feed rations'!$W$4:$AA$4,0)) -> 31.729574
A33: conventional | B33: laying hens (>59 weeks) | D33: feed_per_head | E33: =INDEX('Feed rations'!$W$19:$AA$19,MATCH(B33,'Feed rations'!$W$4:$AA$4,0)) -> 36.304986
A34: conventional | B34: breeding hens and roosters | D34: feed_per_head | E34: =INDEX('Feed rations'!$W$19:$AA$19,MATCH(B34,'Feed rations'!$W$4:$AA$4,0)) -> 36.235119
A36: organic | B36: laying chicks | D36: feed_per_head | E36: =INDEX('Feed rations'!$AB$19:$AF$19,MATCH(B36,'Feed rations'!$AB$4:$AF$4,0)) -> 14.427075
A37: organic | B37: laying hens (16-28 weeks) | D37: feed_per_head | E37: =INDEX('Feed rations'!$AB$19:$AF$19,MATCH(B37,'Feed rations'!$AB$4:$AF$4,0)) -> 31.765467
A38: organic | B38: laying hens (29-59 weeks) | D38: feed_per_head | E38: =INDEX('Feed rations'!$AB$19:$AF$19,MATCH(B38,'Feed rations'!$AB$4:$AF$4,0)) -> 34.907874
A39: organic | B39: laying hens (>59 weeks) | D39: feed_per_head | E39: =INDEX('Feed rations'!$AB$19:$AF$19,MATCH(B39,'Feed rations'!$AB$4:$AF$4,0)) -> 38.050281
A40: organic | B40: breeding hens and roosters | D40: feed_per_head | E40: =INDEX('Feed rations'!$AB$19:$AF$19,MATCH(B40,'Feed rations'!$AB$4:$AF$4,0)) -> 36.235119
A42: Feed rations | F42: % of DM | H42: see Feed rations tab
A43: conventional | B43: laying chicks | C43: wheat | D43: share_in_ration | E43: =INDEX('Feed rations'!$W$5:$AA$17,MATCH(C43,'Feed rations'!$V$5:$V$17,0),MATCH(B43,'Feed rations'!$W$4:$AA$4,0)) -> 43.682113
A44: conventional | B44: laying chicks | C44: maize | D44: share_in_ration | E44: =INDEX('Feed rations'!$W$5:$AA$17,MATCH(C44,'Feed rations'!$V$5:$V$17,0),MATCH(B44,'Feed rations'!$W$4:$AA$4,0)) -> 2.68813
A45: conventional | B45: laying chicks | C45: oats | D45: share_in_ration | E45: =INDEX('Feed rations'!$W$5:$AA$17,MATCH(C45,'Feed rations'!$V$5:$V$17,0),MATCH(B45,'Feed rations'!$W$4:$AA$4,0)) -> 16.800813
A46: conventional | B46: laying chicks | C46: barley | D46: share_in_ration | E46: =INDEX('Feed rations'!$W$5:$AA$17,MATCH(C46,'Feed rations'!$V$5:$V$17,0),MATCH(B46,'Feed rations'!$W$4:$AA$4,0)) -> 3.9201896
A47: conventional | B47: laying chicks | C47: peas | D47: share_in_ration | E47: =INDEX('Feed rations'!$W$5:$AA$17,MATCH(C47,'Feed rations'!$V$5:$V$17,0),MATCH(B47,'Feed rations'!$W$4:$AA$4,0)) -> 0
...

Sheet Feed rations
F1: As fed [%] | N1: On dry matter basis [% of DM]
E2: Source: | F2: Sonesson 2008 | K2: Carlsson | N2: =F2 -> Sonesson 2008 | S2: =K2 -> Carlsson | W2: Final feed rations per animal[% of DM]
E3: Farm: | F3: A | I3: B | K3: N/A | N3: =F3 -> A | Q3: =I3 -> B | S3: =K3 -> N/A | V3: Production system: | W3: conventional | AB3: organic
B4: feed | C4: foder | D4: DM | E4: Feed: | F4: Värp fri start | G4: Värp fri max | H4: Värp fri slut | I4: Värp 95 | J4: Värp 110 | K4: Värp grön stark | L4: värp grön trygg | N4: =F4 -> Värp fri start | O4: =G4 -> Värp fri max | P4: =H4 -> Värp fri slut | Q4: =I4 -> Värp 95 | R4: =J4 -> Värp 110 | S4: =K4 -> Värp grön stark | T4: =L4 -> värp grön trygg | V4: Animal: | W4: laying chicks | X4: laying hens (16-28 weeks) | Y4: laying hens (29-59 weeks) | Z4: laying hens (>59 weeks) | AA4: breeding hens and roosters | AB4: laying chicks | AC4: laying hens (16-28 weeks) | AD4: laying hens (29-59 weeks) | AE4: laying hens (>59 weeks) | AF4: breeding hens and roosters
B5: wheat | C5: Höstvete och rågvete | D5: 0.86 | F5: 39 | G5: 35.2 | H5: 40.2 | I5: 54.3 | J5: 56.7 | K5: 49.9 | L5: 49 | N5: =F5*$D5/F$25 -> 43.682113 | O5: =G5*$D5/G$25 -> 39.526806 | P5: =H5*$D5/H$25 -> 45.302304 | Q5: =I5*$D5/I$25 -> 60.434839 | R5: =J5*$D5/J$25 -> 72.293551 | S5: =K5*$D5/K$25 -> 58.016196 | T5: =L5*$D5/L$25 -> 57.595845 | V5: =B5 -> wheat | W5: =N5 -> 43.682113 | X5: =(N5+Q5)/2 -> 52.058476 | Y5: =(O5+R5)/2 -> 55.910179 | Z5: =(P5+R5)/2 -> 58.797927 | AA5: =Z5 -> 58.797927 | AB5: =W5 -> 43.682113 | AC5: =S5 -> 58.016196 | AD5: =(S5+T5)/2 -> 57.80602 | AE5: =T5 -> 57.595845 | AF5: =AE5 -> 57.595845
B6: maize | C6: Majs | D6: 0.86 | F6: 2.4 | G6: 2.4 | H6: 2.4 | N6: =F6*$D6/F$25 -> 2.68813 | O6: =G6*$D6/G$25 -> 2.6950095 | P6: =H6*$D6/H$25 -> 2.7046151 | Q6: =I6*$D6/I$25 -> 0 | R6: =J6*$D6/J$25 -> 0 | S6: =K6*$D6/K$25 -> 0 | T6: =L6*$D6/L$25 -> 0 | V6: =B6 -> maize | W6: =N6 -> 2.68813 | X6: =(N6+Q6)/2 -> 1.344065 | Y6: =(O6+R6)/2 -> 1.3475048 | Z6: =(P6+R6)/2 -> 1.3523076 | AA6: =Z6 -> 1.3523076 | AB6: =W6 -> 2.68813 | AC6: =S6 -> 0 | AD6: =(S6+T6)/2 -> 0 | AE6: =T6 -> 0 | AF6: =AE6 -> 0
B7: oats | C7: Havre | D7: 0.86 | F7: 15 | G7: 17 | H7: 15 | I7: 8.2 | K7: 11.4 | L7: 14.1 | N7: =F7*$D7/F$25 -> 16.800813 | O7: =G7*$D7/G$25 -> 19.089651 | P7: =H7*$D7/H$25 -> 16.903845 | Q7: =I7*$D7/I$25 -> 9.1264398 | R7: =J7*$D7/J$25 -> 0 | S7: =K7*$D7/K$25 -> 13.254201 | T7: =L7*$D7/L$25 -> 16.573498 | V7: =B7 -> oats | W7: =N7 -> 16.800813 | X7: =(N7+Q7)/2 -> 12.963626 | Y7: =(O7+R7)/2 -> 9.5448254 | Z7: =(P7+R7)/2 -> 8.4519223 | AA7: =Z7 -> 8.4519223 | AB7: =W7 -> 16.800813 | AC7: =S7 -> 13.254201 | AD7: =(S7+T7)/2 -> 14.91385 | AE7: =T7 -> 16.573498 | AF7: =AE7 -> 16.573498
B8: barley | C8: Korn | D8: 0.86 | F8: 3.5 | G8: 5.7 | H8: 3.9 | K8: 4.4 | L8: 9.9 | N8: =F8*$D8/F$25 -> 3.9201896 | O8: =G8*$D8/G$25 -> 6.4006476 | P8: =H8*$D8/H$25 -> 4.3949996 | Q8: =I8*$D8/I$25 -> 0 | R8: =J8*$D8/J$25 -> 0 | S8: =K8*$D8/K$25 -> 5.1156566 | T8: =L8*$D8/L$25 -> 11.636712 | V8: =B8 -> barley | W8: =N8 -> 3.9201896 | X8: =(N8+Q8)/2 -> 1.9600948 | Y8: =(O8+R8)/2 -> 3.2003238 | Z8: =(P8+R8)/2 -> 2.1974998 | AA8: =Z8 -> 2.1974998 | AB8: =W8 -> 3.9201896 | AC8: =S8 -> 5.1156566 | AD8: =(S8+T8)/2 -> 8.3761841 | AE8: =T8 -> 11.636712 | AF8: =AE8 -> 11.636712
B9: peas | C9: ärter | D9: 0.85 | K9: 7.2 | L9: 0 | N9: =F9*$D9/F$25 -> 0 | O9: =G9*$D9/G$25 -> 0 | P9: =H9*$D9/H$25 -> 0 | Q9: =I9*$D9/I$25 -> 0 | R9: =J9*$D9/J$25 -> 0 | S9: =K9*$D9/K$25 -> 8.2737363 | T9: =L9*$D9/L$25 -> 0 | V9: =B9 -> peas | W9: =N9 -> 0 | X9: =(N9+Q9)/2 -> 0 | Y9: =(O9+R9)/2 -> 0 | Z9: =(P9+R9)/2 -> 0 | AA9: =Z9 -> 0 | AB9: =W9 -> 0 | AC9: =S9 -> 8.2737363 | AD9: =(S9+T9)/2 -> 4.1368681 | AE9: =T9 -> 0 | AF9: =AE9 -> 0
B10: rapeseed | C10: rapsfrö | D10: 0.91 | K10: 3 | L10: 3.5 | N10: =F10*$D10/F$25 -> 0 | O10: =G10*$D10/G$25 -> 0 | P10: =H10*$D10/H$25 -> 0 | Q10: =I10*$D10/I$25 -> 0 | R10: =J10*$D10/J$25 -> 0 | S10: =K10*$D10/K$25 -> 3.6907353 | T10: =L10*$D10/L$25 -> 4.3531743 | V10: =B10 -> rapeseed | W10: =N10 -> 0 | X10: =(N10+Q10)/2 -> 0 | Y10: =(O10+R10)/2 -> 0 | Z10: =(P10+R10)/2 -> 0 | AA10: =Z10 -> 0 | AB10: =W10 -> 0 | AC10: =S10 -> 3.6907353 | AD10: =(S10+T10)/2 -> 4.0219548 | AE10: =T10 -> 4.3531743 | AF10: =AE10 -> 4.3531743
B11: soybean meal | C11: Sojamjöl | D11: 0.88 | F11: 23.6 | G11: 20.7 | H11: 17.3 | I11: 19 | J11: 15.1 | N11: =F11*$D11/F$25 -> 27.048006 | O11: =G11*$D11/G$25 -> 23.785026 | P11: =H11*$D11/H$25 -> 19.949157 | Q11: =I11*$D11/I$25 -> 21.638411 | R11: =J11*$D11/J$25 -> 19.700519 | S11: =K11*$D11/K$25 -> 0 | T11: =L11*$D11/L$25 -> 0 | V11: =B11 -> soybean meal | W11: =N11 -> 27.048006 | X11: =(N11+Q11)/2 -> 24.343208 | Y11: =(O11+R11)/2 -> 21.742772 | Z11: =(P11+R11)/2 -> 19.824838 | AA11: =Z11 -> 19.824838 | AB11: =W11 -> 27.048006 | AC11: =S11 -> 0 | AD11: =(S11+T11)/2 -> 0 | AE11: =T11 -> 0 | AF11: =AE11 -> 0
B12: soybeans | C12: rostade sojabönor | D12: 0.87 | K12: 2 | L12: 2 | N12: =F12*$D12/F$25 -> 0 | O12: =G12*$D12/G$25 -> 0 | P12: =H12*$D12/H$25 -> 0 | Q12: =I12*$D12/I$25 -> 0 | R12: =J12*$D12/J$25 -> 0 | S12: =K12*$D12/K$25 -> 2.3523368 | T12: =L12*$D12/L$25 -> 2.3781863 | V12: =B12 -> soybeans | W12: =N12 -> 0 | X12: =(N12+Q12)/2 -> 0 | Y12: =(O12+R12)/2 -> 0 | Z12: =(P12+R12)/2 -> 0 | AA12: =Z12 -> 0 | AB12: =W12 -> 0 | AC12: =S12 -> 2.3523368 | AD12: =(S12+T12)/2 -> 2.3652615 | AE12: =T12 -> 2.3781863 | AF12: =AE12 -> 2.3781863
B13: rapeseed meal | C13: Rapsmjöl | D13: 0.9 | I13: 3 | J13: 2 | N13: =F13*$D13/F$25 -> 0 | O13: =G13*$D13/G$25 -> 0 | P13: =H13*$D13/H$25 -> 0 | Q13: =I13*$D13/I$25 -> 3.494241 | R13: =J13*$D13/J$25 -> 2.6686434 | S13: =K13*$D13/K$25 -> 0 | T13: =L13*$D13/L$25 -> 0 | V13: =B13 -> rapeseed meal | W13: =N13+N14 -> 0 | X13: =(N13+Q13+N14+Q14)/2 -> 1.7471205 | Y13: =(O13+R13+O14+R14)/2 -> 1.3343217 | Z13: =(P13+R13+P14+R14)/2 -> 1.3343217 | AA13: =Z13 -> 1.3343217 | AB13: =W13 -> 0 | AC13: =S13+S14 -> 1.5817437 | AD13: =(S13+S14+T13+T14)/2 -> 0.79087185 | AE13: =T13+T14 -> 0 | AF13: =AE13 -> 0
B14: rapeseed meal | C14: värmebehandlad rapsexpeller | D14: 0.9 | K14: 1.3 | L14: 0 | N14: =F14*$D14/F$25 -> 0 | O14: =G14*$D14/G$25 -> 0 | P14: =H14*$D14/H$25 -> 0 | Q14: =I14*$D14/I$25 -> 0 | R14: =J14*$D14/J$25 -> 0 | S14: =K14*$D14/K$25 -> 1.5817437 | T14: =L14*$D14/L$25 -> 0 | V14: =B15 -> wheat bran, fine | W14: =N15 -> 0 | X14: =(N15+Q15)/2 -> 0 | Y14: =(O15+R15)/2 -> 1.3788421 | Z14: =(P15+R15)/2 -> 2.8828262 | AA14: =Z14 -> 2.8828262 | AB14: =W14 -> 0 | AC14: =S15 -> 0 | AD14: =(S15+T15)/2 -> 0 | AE14: =T15 -> 0 | AF14: =AE14 -> 0
B15: wheat bran, fine | C15: Vetefodermjöl | D15: 0.88 | F15: 0 | G15: 2.4 | H15: 5 | N15: =F15*$D15/F$25 -> 0 | O15: =G15*$D15/G$25 -> 2.7576842 | P15: =H15*$D15/H$25 -> 5.7656524 | Q15: =I15*$D15/I$25 -> 0 | R15: =J15*$D15/J$25 -> 0 | S15: =K15*$D15/K$25 -> 0 | T15: =L15*$D15/L$25 -> 0 | V15: =B16 -> vegetable oils | W15: =N16 -> 5.8607486 | X15: =(N16+Q16)/2 -> 5.5834091 | Y15: =(O16+R16)/2 -> 5.5412311 | Z15: =(P16+R16)/2 -> 5.158357 | AA15: =Z15 -> 5.158357 | AB15: =W15 -> 5.8607486 | AC15: =S16 -> 0 | AD15: =(S16+T16)/2 -> 0 | AE15: =T16 -> 0 | AF15: =AE15 -> 0
B16: vegetable oils | C16: Vegetabiliska fettsyror | D16: 1 | F16: 4.5 | G16: 4.4 | H16: 3.8 | I16: 4.1 | J16: 3.6 | N16: =F16*$D16/F$25 -> 5.8607486 | O16: =G16*$D16/G$25 -> 5.7451754 | P16: =H16*$D16/H$25 -> 4.9794271 | Q16: =I16*$D16/I$25 -> 5.3060696 | R16: =J16*$D16/J$25 -> 5.3372869 | S16: =K16*$D16/K$25 -> 0 | T16: =L16*$D16/L$25 -> 0 | V16: =B17 -> potatoe protein | W16: =N17 -> 0 | X16: =(N17+Q17)/2 -> 0 | Y16: =(O17+R17)/2 -> 0 | Z16: =(P17+R17)/2 -> 0 | AA16: =Z16 -> 0 | AB16: =W16 -> 0 | AC16: =S17 -> 6.1512255 | AD16: =(S17+T17)/2 -> 6.806905 | AE16: =T17 -> 7.4625846 | AF16: =AE16 -> 7.4625846
B17: potatoe protein | C17: potatisprotein | D17: 0.91 | K17: 5 | L17: 6 | N17: =F17*$D17/F$25 -> 0 | O17: =G17*$D17/G$25 -> 0 | P17: =H17*$D17/H$25 -> 0 | Q17: =I17*$D17/I$25 -> 0 | R17: =J17*$D17/J$25 -> 0 | S17: =K17*$D17/K$25 -> 6.1512255 | T17: =L17*$D17/L$25 -> 7.4625846 | V17: =B18 -> maize gluten meal | W17: =N18 -> 0 | X17: =(N18+Q18)/2 -> 0 | Y17: =(O18+R18)/2 -> 0 | Z17: =(P18+R18)/2 -> 0 | AA17: =Z17 -> 0 | AB17: =W17 -> 0 | AC17: =S18 -> 1.5641688 | AD17: =(S18+T18)/2 -> 0.78208439 | AE17: =T18 -> 0 | AF17: =AE17 -> 0
B18: maize gluten meal | C18: majsgluten | D18: 0.89 | K18: 1.3 | L18: 0 | N18: =F18*$D18/F$25 -> 0 | O18: =G18*$D18/G$25 -> 0 | P18: =H18*$D18/H$25 -> 0 | Q18: =I18*$D18/I$25 -> 0 | R18: =J18*$D18/J$25 -> 0 | S18: =K18*$D18/K$25 -> 1.5641688 | T18: =L18*$D18/L$25 -> 0
B19: minerals | C19: Kalciumkarbonat | D19: 1 | F19: 9.9 | G19: 10.3 | H19: 10.6 | I19: 9.4 | J19: 10.8 | K19: 9.7 | L19: 10.7 | V19: Feed per head and year [kg DM]: | W19: =(550+1650+2800)/1000/(15-0+1)*52*F24 -> 14.427075 | X19: =(F31+I31)/2 -> 35.955136 | Y19: =(G31+J31)/2 -> 31.729574 | Z19: =H31 -> 36.304986 | AA19: =48/448*365.25/(1+1/12.5) -> 36.235119 | AB19: =W19 -> 14.427075 | AC19: =K31 -> 31.765467 | AD19: =(K31+L31)/2 -> 34.907874 | AE19: =L31 -> 38.050281 | AF19: =AA19 -> 36.235119
B20: minerals | C20: Monokalciumfosfat | D20: 1 | F20: 1 | G20: 0.7 | H20: 0.59 | I20: 1 | J20: 0.51 | K20: 1.44 | L20: 1.27
B21: minerals | C21: Salt | D21: 1 | F21: 0.3 | G21: 0.3 | H21: 0.3 | I21: 0.2 | J21: 0.2 | K21: 0.3 | L21: 0.3
B22: amino acids and vitamins | C22: Förblandning tillsatser | D22: 1 | F22: 0.8 | G22: 0.8 | H22: 0.8 | I22: 0.7 | J22: 0.9 | K22: 0.8 | L22: 0.3
E24: Ration DM: | F24: =SUMPRODUCT(F$5:F$22/100,$D$5:$D$22) -> 0.88782 | G24: =SUMPRODUCT(G$5:G$22/100,$D$5:$D$22) -> 0.88686 | H24: =SUMPRODUCT(H$5:H$22/100,$D$5:$D$22) -> 0.88604 | I24: =SUMPRODUCT(I$5:I$22/100,$D$5:$D$22) -> 0.8857 | J24: =SUMPRODUCT(J$5:J$22/100,$D$5:$D$22) -> 0.7986 | K24: =SUMPRODUCT(K$5:K$22/100,$D$5:$D$22) -> 0.86209 | L24: =SUMPRODUCT(L$5:L$22/100,$D$5:$D$22) -> 0.85735
E25: Ration DM (excl. minerals etc.): | F25: =SUMPRODUCT(F$5:F$18/100,$D$5:$D$18) -> 0.76782 | G25: =SUMPRODUCT(G$5:G$18/100,$D$5:$D$18) -> 0.76586 | H25: =SUMPRODUCT(H$5:H$18/100,$D$5:$D$18) -> 0.76314 | I25: =SUMPRODUCT(I$5:I$18/100,$D$5:$D$18) -> 0.7727 | J25: =SUMPRODUCT(J$5:J$18/100,$D$5:$D$18) -> 0.6745 | K25: =SUMPRODUCT(K$5:K$18/100,$D$5:$D$18) -> 0.73969 | L25: =SUMPRODUCT(L$5:L$18/100,$D$5:$D$18) -> 0.73165
E27: Nr animals farm | F27: 31500 | I27: 12560 | K27: 8300
E28: weeks with feed | F28: 15-28 | G28: 29-59 | H28: 60-79 | I28: 16-35 | J28: 36-74 | K28: 15-45 | L28: 46-75
E29: feed [kg/year] | F29: =(20828+279029) -> 299857 | G29: 799439 | H29: 496421 | I29: 221000 | J29: 303200 | K29: 182322 | L29: 212518
E30: feed per animal [kg/year/head] | F30: =F29/$F$27/(28-15+1)*52 -> 35.357288 | G30: =G29/$F$27/(59-29+1)*52 -> 42.571252 | H30: =H29/$F$27/(79-60+1)*52 -> 40.974432 | I30: =I29/$I$27/(35-16+1)*52 -> 45.748408 | J30: =J29/$I$27/(74-36+1)*52 -> 32.186837 | K30: =K29/$K$27/(45-15+1)*52 -> 36.847042 | L30: =L29/$K$27/(75-46+1)*52 -> 44.381269
E31: feed per animal [kg DM/year/head] | F31: =F30*F24 -> 31.390907 | G31: =G30*G24 -> 37.754741 | H31: =H30*H24 -> 36.304986 | I31: =I30*I24 -> 40.519365 | J31: =J30*J24 -> 25.704408 | K31: =K30*K24 -> 31.765467 | L31: =L30*L24 -> 38.050281
