Workbook

Sheet Inputs-Redskap
A1: Kan ändras
A2: Ändras ej
A3: Uträkning | B3: Traktor
B4: Variabler | C4: Symbol | D4: Värde | E4: Enhet
B5: Vikt | C5: m | D5: 10800 | E5: kg
B6: Fälthastighet | C6: S | D6: 5 | E6: km/h
B7: Acceleration, medel | C7: a | D7: 0.2 | E7: m/s^2
B8: Lutning, medel | C8: α | D8: 0.035 | E8: rad | F8: Verkningsgrader
B9: Märkeffekt | C9: P | D9: 250 | E9: kW | F9: Diesel/HVO | G9: 0.26
B10: Verkningsgrad, Total (pump-hjul) | C10: ηDriv | D10: 0.26 | F10: Bränslecell/H2 | G10: 0.45
B11: Medelavstånd fält-gård | C11: D | D11: 4 | E11: km | F11: Eldrift | G11: 0.76
B13: Konstanter | C13: Symbol | D13: Värde | E13: Enhet
B14: Frontarea | C14: A | D14: 4 | E14: m^2 | F14: Fdrag | G14: =D16*(D6/3.6)^2*D15*D14 -> 8.5069444 | H14: N
B15: Ytkoefficient fordon | C15: CD | D15: 0.9 | F15: Frr | G15: =D5*9.81*D17 -> 10594.8 | H15: N
B16: Densitet luft | C16: ρair | D16: 1.225 | E16: kg/m3 | F16: Facc | G16: =D5*D7 -> 2160 | H16: N
B17: Friktionskoefficient, fält | C17: Crr | D17: 0.1 | F17: Fgrad | G17: =D5*9.81*SIN(D8) -> 3707.423 | H17: N
B18: Friktionskoefficient, väg | C18: Crv | D18: 0.01 | F18: FMR | G18: =9.81*D5*(1/D21+0.04+0.05*(D19/SQRT(D21)))/1000 -> 6.3071075 | H18: N
B19: Slirning/Slippage | C19: s | D19: 0.2
B20: Fälteffektivitet | C20: ηFält | D20: 0.8
B21: Markmotstånd traktor | C21: Bn | D21: 55
B22: Arbetstakt per redskapsbredd | C22: CO/W | D22: =D20*D6/10 -> 0.4 | E22: ha/h m
B25: Traktorns energiförbrukning | D25: kWh/h | E25: =SUM(G14:G18)*(D6/3.6)/1000 -> 22.884774
B26: *antaget en medelarbetstakt på 2,0 ha/h | D26: kWh/ha | E26: =E25/2 -> 11.442387
B27: Redskap - jordartsberoende | D27: Redskapsparamtrar | G27: Arbetsdjup | H27: Jordartsparametrar, Fi | K27: Energibehov (kWh/ha)
B28: Arbete | C28: Redskap | D28: A | E28: B | F28: C | G28: T, cm | H28: Lera/fin | I28: Loam/mellan | J28: Sand/grov | K28: Lera/fin | L28: Loam/mellan | M28: Sand/grov
B29: Plöjning | C29: Moldboard plough | D29: 652 | E29: 0 | F29: 5.1 | G29: 20 | H29: 1 | I29: 0.7 | J29: 0.45 | K29: =H29*($D29+$E29*$D$6+$F29*$D$6^2)*$G29*($D$6/3.6)/1000/$D$22 -> 54.131944 | L29: =I29*($D29+$E29*$D$6+$F29*$D$6^2)*$G29*($D$6/3.6)/1000/$D$22 -> 37.892361 | M29: =J29*($D29+$E29*$D$6+$F29*$D$6^2)*$G29*($D$6/3.6)/1000/$D$22 -> 24.359375 | N29: Lägg till traktors energibehov | Q29: pinnar/m
B30: Harvning | C30: Field cultivator, primary tillage | D30: =46*Q30 -> 460 | E30: =2.8*Q30 -> 28 | F30: 0 | G30: 5 | H30: 1 | I30: 0.88 | J30: 0.78 | K30: =H30*($D30+$E30*$D$6+$F30*$D$6^2)*$G30*($D$6/3.6)/1000/$D$22 -> 10.416667 | L30: =I30*($D30+$E30*$D$6+$F30*$D$6^2)*$G30*($D$6/3.6)/1000/$D$22 -> 9.1666667 | M30: =J30*($D30+$E30*$D$6+$F30*$D$6^2)*$G30*($D$6/3.6)/1000/$D$22 -> 8.125 | N30: Lägg till traktors energibehov | Q30: 10
B31: Stubbearbetning /kultivering | C31: Chisel Plow, 7.5 cm shovel/35 cm sweep | D31: =107*Q31 -> 428 | E31: =6.3*Q31 -> 25.2 | F31: 0 | G31: 10 | H31: 1 | I31: 0.85 | J31: 0.65 | K31: =H31*($D31+$E31*$D$6+$F31*$D$6^2)*$G31*($D$6/3.6)/1000/$D$22 -> 19.236111 | L31: =I31*($D31+$E31*$D$6+$F31*$D$6^2)*$G31*($D$6/3.6)/1000/$D$22 -> 16.350694 | M31: =J31*($D31+$E31*$D$6+$F31*$D$6^2)*$G31*($D$6/3.6)/1000/$D$22 -> 12.503472 | N31: Lägg till traktors energibehov | Q31: 4
J33: Liter per hektar | N33: Baky, 2010
J34: Plöjning | K34: =(K29+$E$26)/$D$10/10.1165 -> 24.930457 | L34: =(L29+$E$26)/$D$10/10.1165 -> 18.756391 | M34: =(M29+$E$26)/$D$10/10.1165 -> 13.611336 | N34: 20.6
J35: Harvning | K35: =(K30+$E$26)/$D$10/10.1165 -> 8.3105108 | L35: =(L30+$E$26)/$D$10/10.1165 -> 7.835278 | M35: =(M30+$E$26)/$D$10/10.1165 -> 7.4392507 | N35: 5
J36: Stubbearbetning /kultivering | K36: =(K31+$E$26)/$D$10/10.1165 -> 11.663542 | L36: =(L31+$E$26)/$D$10/10.1165 -> 10.566546 | M36: =(M31+$E$26)/$D$10/10.1165 -> 9.1038855 | N36: 8
B37: Redskap - oberoende
B38: Arbete | C38: Redskap | D38: Effektbehov | E38: Enhet | F38: Energibehov | G38: Enhet | I38: Källa | K38: Notis
B39: Vältning | C39: Rullvält | F39: 3.7353333 | G39: kWh/ha | I39: Lindgren, 2002
B40: Sådd | C40: Direktsådd | F40: 11.828556 | G40: kWh/ha | I40: Lindgren, 2002
C41: Kombisåmaskin | F41: 26.302972 | G41: kWh/ha | I41: Baky, 2010
C42: Potatissättare | F42: 23.27813 | G42: kWh/ha | I42: Grisso, 2010
C43: Majs & betor | F43: 11.3 | G43: kWh/ha | I43: Grisso, 2010
B44: Gödsling | C44: Kletgödselspridning | F44: 4.6691667 | G44: kWh/ha | I44: Lindgren, 2002
...

Sheet Input-Grödor
A1: Kan ändras
A2: Ändras ej
A3: Uträkning / resultat | E3: Jordartsfördelning | H3: Jordbearbetning | O3: Gödsling & Bekämpning | S3: Sådd | W3: Skörd (per ton) | AB3: Skörd (per skörd) | AD3: Bärgning & ensilering | AG3: Transport skörd (per ton) | AI3: Transport (per tonkm) | AL3: Energiförbrukning, netto | AM3: Total bränsleförbrukning, brutto | AO3: Energiförbrukning, all areal
A4: Gröda | B4: Skörd (ton/ha) | C4: Halmskörd (ton/ha) | D4: Area (ha) | E4: Lera/ / fin jord | F4: Loam / medium jord | G4: Sand / grov jord | H4: Harvning | I4: Vältning | J4: Stubbearbetning | K4: Plöjning | L4: Putsning | M4: "Ridging" | N4: Toppning | O4: Konstgödsel | P4: Flytgödsel | Q4: Fast/kletgödsel | R4: Ogräsbekämpning, kemisk | S4: Kombisådd | T4: Såmaskin | U4: Potatissättare | V4: Majs & Betor | W4: Matpotatis | X4: Stärkelsepotatist | Y4: Betupptagare (självg.) | Z4: Majströska | AA4: Skördetröska (+hack) | AB4: Skördetröska + hack, fast förbrukning | AC4: Slåtter | AD4: Tornsilo | AE4: Plansilo | AF4: Rundbal | AG4: Transport kärna | AH4: Transport halm | AI4: Transport vagn allmän | AL4: kWh/ha | AM4: kWh/ha | AN4: L/ha eq. | AO4: kWh | AQ4: Total nationell energiföbrukning
A5: Slåttervall | B5: 5.24 | D5: 761400 | E5: 0.33 | F5: 0.33 | G5: 0.34 | O5: 2 | R5: 1 | T5: 0.3 | AC5: 2 | AF5: 2 | AL5: =E5*SUMPRODUCT(H5:AI5,$H$33:$AI$33)+F5*SUMPRODUCT(H5:AI5,$H$34:$AI$34)+G5*SUMPRODUCT(H5:AI5,$H$35:$AI$35) -> 113.8411 | AM5: =AL5/'Inputs-Redskap'!$D$10 -> 437.85037 | AN5: =AM5/10.1165 -> 43.280816 | AO5: =AM5*D5 -> 3.3337927e+08 | AQ5: =SUM(AO5:AO29) -> 1.3593718e+09 | AR5: kWh/år
A6: Betesvall | D6: =243900+51200 -> 295100 | E6: 0.33 | F6: 0.33 | G6: 0.34 | L6: 2 | O6: 2 | T6: 0.1 | AL6: =E6*SUMPRODUCT(H6:AI6,$H$33:$AI$33)+F6*SUMPRODUCT(H6:AI6,$H$34:$AI$34)+G6*SUMPRODUCT(H6:AI6,$H$35:$AI$35) -> 37.866942 | AM6: =AL6/'Inputs-Redskap'!$D$10 -> 145.64208 | AN6: =AM6/10.1165 -> 14.396489 | AO6: =AM6*D6 -> 42978979 | AQ6: =AQ5/10.1165 -> 1.3437175e+08 | AR6: L diesel eq.
A7: Höstvete | B7: 6.6 | C7: =B7*0.3*0.75 -> 1.485 | D7: 421150 | E7: 0.33 | F7: 0.33 | G7: 0.34 | H7: 2 | I7: 0.5 | J7: 0.5 | K7: 1 | O7: 1.5 | R7: 1.75 | T7: 1 | AA7: =B7 -> 6.6 | AB7: 1 | AG7: =B7 -> 6.6 | AH7: =C7 -> 1.485 | AL7: =E7*SUMPRODUCT(H7:AI7,$H$33:$AI$33)+F7*SUMPRODUCT(H7:AI7,$H$34:$AI$34)+G7*SUMPRODUCT(H7:AI7,$H$35:$AI$35) -> 189.26961 | AM7: =AL7/'Inputs-Redskap'!$D$10 -> 727.96005 | AN7: =AM7/10.1165 -> 71.957697 | AO7: =AM7*D7 -> 3.0658037e+08 | AQ7: =AQ6/1000 -> 134371.75 | AR7: m3 diesel eq.
A8: Vårkorn | B8: 3.77 | C8: =B8*0.65*0.3 -> 0.73515 | D8: 255612 | E8: 0.33 | F8: 0.33 | G8: 0.34 | H8: 2 | I8: 0.5 | J8: 0.5 | K8: 1 | O8: 1 | R8: 1.75 | S8: 1 | AA8: =B8 -> 3.77 | AB8: 1 | AG8: =B8 -> 3.77 | AH8: =C8 -> 0.73515 | AL8: =E8*SUMPRODUCT(H8:AI8,$H$33:$AI$33)+F8*SUMPRODUCT(H8:AI8,$H$34:$AI$34)+G8*SUMPRODUCT(H8:AI8,$H$35:$AI$35) -> 181.35015 | AM8: =AL8/'Inputs-Redskap'!$D$10 -> 697.50057 | AN8: =AM8/10.1165 -> 68.946826 | AO8: =AM8*D8 -> 1.7828952e+08
A9: Havre | B9: 3.31 | C9: =B9*0.7*0.3 -> 0.6951 | D9: 157570 | E9: 0.33 | F9: 0.33 | G9: 0.34 | H9: 2 | I9: 0.5 | J9: 0.5 | K9: 1 | O9: 1 | R9: 1.25 | S9: 1 | AA9: =B9 -> 3.31 | AB9: 1 | AG9: =B9 -> 3.31 | AH9: =C9 -> 0.6951 | AL9: =E9*SUMPRODUCT(H9:AI9,$H$33:$AI$33)+F9*SUMPRODUCT(H9:AI9,$H$34:$AI$34)+G9*SUMPRODUCT(H9:AI9,$H$35:$AI$35) -> 176.5068 | AM9: =AL9/'Inputs-Redskap'!$D$10 -> 678.87229 | AN9: =AM9/10.1165 -> 67.105451 | AO9: =AM9*D9 -> 1.0696991e+08
A10: Träda | D10: 154713 | E10: 0.33 | F10: 0.33 | G10: 0.34 | L10: 1 | AL10: =E10*SUMPRODUCT(H10:AI10,$H$33:$AI$33)+F10*SUMPRODUCT(H10:AI10,$H$34:$AI$34)+G10*SUMPRODUCT(H10:AI10,$H$35:$AI$35) -> 17.096932 | AM10: =AL10/'Inputs-Redskap'!$D$10 -> 65.757431 | AN10: =AM10/10.1165 -> 6.5000178 | AO10: =AM10*D10 -> 10173529
A11: Raps & rybs | B11: 3.38 | D11: 135149 | E11: 0.33 | F11: 0.33 | G11: 0.34 | H11: 2 | I11: 0.5 | J11: 0.5 | K11: 1 | O11: 1 | R11: 1.25 | S11: 1 | AA11: =B11 -> 3.38 | AB11: 1 | AI11: =B11*'Inputs-Redskap'!$D$11 -> 13.52 | AL11: =E11*SUMPRODUCT(H11:AI11,$H$33:$AI$33)+F11*SUMPRODUCT(H11:AI11,$H$34:$AI$34)+G11*SUMPRODUCT(H11:AI11,$H$35:$AI$35) -> 172.7615 | AM11: =AL11/'Inputs-Redskap'!$D$10 -> 664.4673 | AN11: =AM11/10.1165 -> 65.68154 | AO11: =AM11*D11 -> 89802091
A12: Ärter & åkerbönor | B12: 2.5 | D12: 47853 | E12: 0.33 | F12: 0.33 | G12: 0.34 | H12: 2 | I12: 0.5 | J12: 0.5 | K12: 1 | O12: 1 | R12: 1.25 | S12: 1 | AA12: =B12 -> 2.5 | AB12: 1 | AI12: =B12*'Inputs-Redskap'!$D$11 -> 10 | AL12: =E12*SUMPRODUCT(H12:AI12,$H$33:$AI$33)+F12*SUMPRODUCT(H12:AI12,$H$34:$AI$34)+G12*SUMPRODUCT(H12:AI12,$H$35:$AI$35) -> 167.2527 | AM12: =AL12/'Inputs-Redskap'!$D$10 -> 643.27961 | AN12: =AM12/10.1165 -> 63.58717 | AO12: =AM12*D12 -> 30782859
A13: Grönfoder | B13: 4.63 | D13: 46239 | E13: 0.33 | F13: 0.33 | G13: 0.34 | H13: 1 | I13: 0.5 | J13: 0.5 | K13: 1 | O13: 1 | R13: 1.25 | S13: 1 | AC13: 1 | AF13: 2 | AI13: =B13*'Inputs-Redskap'!$D$11 -> 18.52 | AL13: =E13*SUMPRODUCT(H13:AI13,$H$33:$AI$33)+F13*SUMPRODUCT(H13:AI13,$H$34:$AI$34)+G13*SUMPRODUCT(H13:AI13,$H$35:$AI$35) -> 212.50484 | AM13: =AL13/'Inputs-Redskap'!$D$10 -> 817.32631 | AN13: =AM13/10.1165 -> 80.791411 | AO13: =AM13*D13 -> 37792351
A14: Vårvete | B14: 3.51 | C14: =B14*0.75*0.3 -> 0.78975 | D14: 44527 | E14: 0.33 | F14: 0.33 | G14: 0.34 | H14: 2 | I14: 0.5 | J14: 0.5 | K14: 1 | O14: 1.5 | R14: 1.75 | S14: 1 | AA14: =B14 -> 3.51 | AB14: 1 | AG14: =B14 -> 3.51 | AH14: =C14 -> 0.78975 | AL14: =E14*SUMPRODUCT(H14:AI14,$H$33:$AI$33)+F14*SUMPRODUCT(H14:AI14,$H$34:$AI$34)+G14*SUMPRODUCT(H14:AI14,$H$35:$AI$35) -> 180.35255 | AM14: =AL14/'Inputs-Redskap'!$D$10 -> 693.66364 | AN14: =AM14/10.1165 -> 68.567552 | AO14: =AM14*D14 -> 30886761
A15: Sockerbetor | B15: 71.5 | D15: 29445 | E15: 0.33 | F15: 0.33 | G15: 0.34 | H15: 2 | I15: 0.5 | J15: 0.5 | K15: 1 | M15: 1 | N15: 1 | V15: 1 | Y15: =B15 -> 71.5 | AI15: =B15*'Inputs-Redskap'!$D$11 -> 286 | AL15: =E15*SUMPRODUCT(H15:AI15,$H$33:$AI$33)+F15*SUMPRODUCT(H15:AI15,$H$34:$AI$34)+G15*SUMPRODUCT(H15:AI15,$H$35:$AI$35) -> 345.76955 | AM15: =AL15/'Inputs-Redskap'!$D$10 -> 1329.8829 | AN15: =AM15/10.1165 -> 131.45682 | AO15: =AM15*D15 -> 39158402
A16: Rågvete | B16: 5.2 | C16: =B16*0.9*0.3 -> 1.404 | D16: 29440 | E16: 0.33 | F16: 0.33 | G16: 0.34 | H16: 2 | I16: 0.5 | J16: 0.5 | K16: 1 | O16: 1 | R16: 1.25 | S16: 1 | AA16: =B16 -> 5.2 | AB16: 1 | AG16: =B16 -> 5.2 | AH16: =C16 -> 1.404 | AL16: =E16*SUMPRODUCT(H16:AI16,$H$33:$AI$33)+F16*SUMPRODUCT(H16:AI16,$H$34:$AI$34)+G16*SUMPRODUCT(H16:AI16,$H$35:$AI$35) -> 191.68712 | AM16: =AL16/'Inputs-Redskap'!$D$10 -> 737.25817 | AN16: =AM16/10.1165 -> 72.876802 | AO16: =AM16*D16 -> 21704881
A17: Frövall | B17: 2.08 | D17: 22634 | E17: 0.33 | F17: 0.33 | G17: 0.34 | H17: 1 | O17: 1 | R17: 2 | T17: 1 | AA17: =B17 -> 2.08 | AB17: 1 | AI17: =B17*'Inputs-Redskap'!$D$11 -> 8.32 | AL17: =E17*SUMPRODUCT(H17:AI17,$H$33:$AI$33)+F17*SUMPRODUCT(H17:AI17,$H$34:$AI$34)+G17*SUMPRODUCT(H17:AI17,$H$35:$AI$35) -> 66.137409 | AM17: =AL17/'Inputs-Redskap'!$D$10 -> 254.37465 | AN17: =AM17/10.1165 -> 25.144531 | AO17: =AM17*D17 -> 5757515.8
A18: Majs | B18: 8.52 | D18: 22210 | E18: 0.33 | F18: 0.33 | G18: 0.34 | H18: 2 | I18: 0.5 | J18: 0.5 | K18: 1 | O18: 1 | R18: 2 | V18: 1 | Z18: =B18 -> 8.52 | AI18: =B18*'Inputs-Redskap'!$D$11 -> 34.08 | AL18: =E18*SUMPRODUCT(H18:AI18,$H$33:$AI$33)+F18*SUMPRODUCT(H18:AI18,$H$34:$AI$34)+G18*SUMPRODUCT(H18:AI18,$H$35:$AI$35) -> 171.44411 | AM18: =AL18/'Inputs-Redskap'!$D$10 -> 659.40041 | AN18: =AM18/10.1165 -> 65.180686 | AO18: =AM18*D18 -> 14645283
A19: Höstkorn | B19: 5.57 | C19: =B19*0.65*0.3 -> 1.08615 | D19: 21632 | E19: 0.33 | F19: 0.33 | G19: 0.34 | H19: 2 | I19: 0.5 | J19: 0.5 | K19: 1 | O19: 2 | R19: 1.75 | T19: 1 | AA19: =B19 -> 5.57 | AB19: 1 | AG19: =B19 -> 5.57 | AH19: =C19 -> 1.08615 | AL19: =E19*SUMPRODUCT(H19:AI19,$H$33:$AI$33)+F19*SUMPRODUCT(H19:AI19,$H$34:$AI$34)+G19*SUMPRODUCT(H19:AI19,$H$35:$AI$35) -> 181.58077 | AM19: =AL19/'Inputs-Redskap'!$D$10 -> 698.38756 | AN19: =AM19/10.1165 -> 69.034504 | AO19: =AM19*D19 -> 15107520
A20: Råg | B20: 5.71 | C20: =B20*0.95*0.3 -> 1.62735 | D20: 21151 | E20: 0.33 | F20: 0.33 | G20: 0.34 | H20: 2 | I20: 0.5 | J20: 0.5 | K20: 1 | O20: 1 | R20: 1.25 | S20: 1 | AA20: =B20 -> 5.71 | AB20: 1 | AG20: =B20 -> 5.71 | AH20: =C20 -> 1.62735 | AL20: =E20*SUMPRODUCT(H20:AI20,$H$33:$AI$33)+F20*SUMPRODUCT(H20:AI20,$H$34:$AI$34)+G20*SUMPRODUCT(H20:AI20,$H$35:$AI$35) -> 195.88207 | AM20: =AL20/'Inputs-Redskap'!$D$10 -> 753.39256 | AN20: =AM20/10.1165 -> 74.471661 | AO20: =AM20*D20 -> 15935006
A21: Matpotatis | B21: 33.4 | D21: 14979 | E21: 0.33 | F21: 0.33 | G21: 0.34 | H21: 1 | J21: 2 | K21: 1 | L21: 2 | M21: 1 | O21: 2 | R21: 2 | U21: 1 | W21: =B21 -> 33.4 | AI21: =B21*'Inputs-Redskap'!$D$11 -> 133.6 | AL21: =E21*SUMPRODUCT(H21:AI21,$H$33:$AI$33)+F21*SUMPRODUCT(H21:AI21,$H$34:$AI$34)+G21*SUMPRODUCT(H21:AI21,$H$35:$AI$35) -> 411.07943 | AM21: =AL21/'Inputs-Redskap'!$D$10 -> 1581.0747 | AN21: =AM21/10.1165 -> 156.28673 | AO21: =AM21*D21 -> 23682918
A22: Trädgårdsväxter | B22: 33.4 | D22: 14583 | E22: 0.33 | F22: 0.33 | G22: 0.34 | H22: 2 | J22: 2 | K22: 1 | L22: 2 | O22: 2 | R22: 2 | U22: 1 | W22: =B22 -> 33.4 | AI22: =B22*'Inputs-Redskap'!$D$11 -> 133.6 | AL22: =E22*SUMPRODUCT(H22:AI22,$H$33:$AI$33)+F22*SUMPRODUCT(H22:AI22,$H$34:$AI$34)+G22*SUMPRODUCT(H22:AI22,$H$35:$AI$35) -> 418.99681 | AM22: =AL22/'Inputs-Redskap'!$D$10 -> 1611.5262 | AN22: =AM22/10.1165 -> 159.29681 | AO22: =AM22*D22 -> 23500887
A23: Ospec. Åkermark | D23: 10919 | E23: 0.33 | F23: 0.33 | G23: 0.34 | H23: 1 | J23: 1 | O23: 1 | R23: 1 | T23: 1 | AI23: =B23*'Inputs-Redskap'!$D$11 -> 0 | AL23: =E23*SUMPRODUCT(H23:AI23,$H$33:$AI$33)+F23*SUMPRODUCT(H23:AI23,$H$34:$AI$34)+G23*SUMPRODUCT(H23:AI23,$H$35:$AI$35) -> 64.291044 | AM23: =AL23/'Inputs-Redskap'!$D$10 -> 247.27325 | AN23: =AM23/10.1165 -> 24.442569 | AO23: =AM23*D23 -> 2699976.6
A24: Blandsäd | B24: 2.76 | C24: =B24*0.7*0.3 -> 0.5796 | D24: 9467 | E24: 0.33 | F24: 0.33 | G24: 0.34 | H24: 1 | I24: 0.5 | J24: 0.5 | K24: 1 | M24: 1 | O24: 1 | R24: 1.25 | S24: 1 | AA24: =B24 -> 2.76 | AB24: 1 | AG24: =B24 -> 2.76 | AH24: =C24 -> 0.5796 | AL24: =E24*SUMPRODUCT(H24:AI24,$H$33:$AI$33)+F24*SUMPRODUCT(H24:AI24,$H$34:$AI$34)+G24*SUMPRODUCT(H24:AI24,$H$35:$AI$35) -> 164.45127 | AM24: =AL24/'Inputs-Redskap'!$D$10 -> 632.50487 | AN24: =AM24/10.1165 -> 62.522104 | AO24: =AM24*D24 -> 5987923.6
A25: Stärkelsepotatis | B25: 42.01 | D25: 8567 | E25: 0.33 | F25: 0.33 | G25: 0.34 | H25: 2 | J25: 2 | K25: 1 | L25: 2 | O25: 2 | R25: 2 | U25: 1 | X25: =B25 -> 42.01 | AI25: =B25*'Inputs-Redskap'!$D$11 -> 168.04 | AL25: =E25*SUMPRODUCT(H25:AI25,$H$33:$AI$33)+F25*SUMPRODUCT(H25:AI25,$H$34:$AI$34)+G25*SUMPRODUCT(H25:AI25,$H$35:$AI$35) -> 424.77057 | AM25: =AL25/'Inputs-Redskap'!$D$10 -> 1633.733 | AN25: =AM25/10.1165 -> 161.49192 | AO25: =AM25*D25 -> 13996190
A26: Andra växtslag | D26: 7983 | E26: 0.33 | F26: 0.33 | G26: 0.34 | H26: 1 | J26: 1 | O26: 1 | R26: 1 | T26: 1 | AI26: =B26*'Inputs-Redskap'!$D$11 -> 0 | AL26: =E26*SUMPRODUCT(H26:AI26,$H$33:$AI$33)+F26*SUMPRODUCT(H26:AI26,$H$34:$AI$34)+G26*SUMPRODUCT(H26:AI26,$H$35:$AI$35) -> 64.291044 | AM26: =AL26/'Inputs-Redskap'!$D$10 -> 247.27325 | AN26: =AM26/10.1165 -> 24.442569 | AO26: =AM26*D26 -> 1973982.3
A27: Konservärtor | B27: 2.54 | D27: 6412 | E27: 0.33 | F27: 0.33 | G27: 0.34 | H27: 1 | I27: 1 | J27: 1 | K27: 1 | O27: 1 | R27: 2 | S27: 1 | AA27: =B27 -> 2.54 | AB27: 1 | AI27: =B27*'Inputs-Redskap'!$D$11 -> 10.16 | AL27: =E27*SUMPRODUCT(H27:AI27,$H$33:$AI$33)+F27*SUMPRODUCT(H27:AI27,$H$34:$AI$34)+G27*SUMPRODUCT(H27:AI27,$H$35:$AI$35) -> 164.75657 | AM27: =AL27/'Inputs-Redskap'!$D$10 -> 633.67911 | AN27: =AM27/10.1165 -> 62.638176 | AO27: =AM27*D27 -> 4063150.4
A28: Oljelin | B28: 1.49 | C28: =B28*1.3 -> 1.937 | D28: 4970 | E28: 0.33 | F28: 0.33 | G28: 0.34 | H28: 2 | I28: 0.5 | J28: 0.5 | K28: 1 | O28: 1 | R28: 1.25 | S28: 1 | AA28: =B28 -> 1.49 | AB28: 1 | AG28: =B28 -> 1.49 | AH28: =C28 -> 1.937 | AL28: =E28*SUMPRODUCT(H28:AI28,$H$33:$AI$33)+F28*SUMPRODUCT(H28:AI28,$H$34:$AI$34)+G28*SUMPRODUCT(H28:AI28,$H$35:$AI$35) -> 167.81139 | AM28: =AL28/'Inputs-Redskap'!$D$10 -> 645.42841 | AN28: =AM28/10.1165 -> 63.799576 | AO28: =AM28*D28 -> 3207779.2
A29: Bruna Bönor | B29: 2.41 | D29: 491 | E29: 0.33 | F29: 0.33 | G29: 0.34 | H29: 2 | I29: 0.5 | J29: 0.5 | K29: 1 | O29: 1 | R29: 1.25 | S29: 1 | AA29: =B29 -> 2.41 | AB29: 1 | AI29: =B29*'Inputs-Redskap'!$D$11 -> 9.64 | AL29: =E29*SUMPRODUCT(H29:AI29,$H$33:$AI$33)+F29*SUMPRODUCT(H29:AI29,$H$34:$AI$34)+G29*SUMPRODUCT(H29:AI29,$H$35:$AI$35) -> 166.6893 | AM29: =AL29/'Inputs-Redskap'!$D$10 -> 641.11268 | AN29: =AM29/10.1165 -> 63.372973 | AO29: =AM29*D29 -> 314786.33
A30: Konservärtor (eko) | E30: 0.33 | F30: 0.33 | G30: 0.34 | H30: 2 | I30: 1 | J30: 2 | K30: 1 | L30: 2 | S30: 1 | AL30: =E30*SUMPRODUCT(H30:AI30,$H$33:$AI$33)+F30*SUMPRODUCT(H30:AI30,$H$34:$AI$34)+G30*SUMPRODUCT(H30:AI30,$H$35:$AI$35) -> 210.53396 | AM30: =AL30/'Inputs-Redskap'!$D$10 -> 809.74602 | AN30: =AM30/10.1165 -> 80.042111 | AO30: =AM30*D30 -> 0
G32: Bränsleåtgång (kWh/ha, vid hjul)
G33: Lera/ / fin jord | H33: ='Inputs-Redskap'!K30+'Inputs-Redskap'!E26 -> 21.859053 | I33: ='Inputs-Redskap'!F39 -> 3.7353333 | J33: ='Inputs-Redskap'!K31+'Inputs-Redskap'!E26 -> 30.678498 | K33: ='Inputs-Redskap'!K29+'Inputs-Redskap'!E26 -> 65.574331 | L33: 17.096932 | M33: ='Inputs-Redskap'!F50 -> 12.75 | N33: ='Inputs-Redskap'!F49 -> 17.75 | O33: ='Inputs-Redskap'!F46 -> 1.2451111 | P33: ='Inputs-Redskap'!F45 -> 3.1127778 | Q33: ='Inputs-Redskap'!F44 -> 4.6691667 | R33: ='Inputs-Redskap'!F47 -> 3.1127778 | S33: ='Inputs-Redskap'!F41 -> 26.302972 | T33: ='Inputs-Redskap'!F40 -> 11.828556 | U33: 23.27813 | V33: ='Inputs-Redskap'!F43 -> 11.3 | W33: ='Inputs-Redskap'!G64 -> 5.1828517 | X33: ='Inputs-Redskap'!G65 -> 4.0531065 | Y33: ='Inputs-Redskap'!G62 -> 1.7546281 | Z33: ='Inputs-Redskap'!G63 -> 4.3591311 | AA33: ='Inputs-Redskap'!G61 -> 5.26 | AB33: ='Inputs-Redskap'!D61 -> 13.15 | AC33: ='Inputs-Redskap'!F48 -> 14.6 | AD33: ='Inputs-Redskap'!F55 -> 36.955676 | AE33: ='Inputs-Redskap'!F56 -> 50.107162 | AF33: ='Inputs-Redskap'!F57 -> 37.744765 | AG33: ='Inputs-Redskap'!F52 -> 1.6176328 | AH33: ='Inputs-Redskap'!F53 -> 3.0774477 | AI33: ='Inputs-Redskap'!F54 -> 0.25
G34: Loam / medium jord | H34: ='Inputs-Redskap'!L30+'Inputs-Redskap'!E26 -> 20.609053 | I34: =I33 -> 3.7353333 | J34: ='Inputs-Redskap'!L31+'Inputs-Redskap'!E26 -> 27.793081 | K34: ='Inputs-Redskap'!L29+'Inputs-Redskap'!E26 -> 49.334748 | L34: =L33 -> 17.096932 | M34: =M33 -> 12.75 | N34: =N33 -> 17.75 | O34: =O33 -> 1.2451111 | P34: =P33 -> 3.1127778 | Q34: =Q33 -> 4.6691667 | R34: =R33 -> 3.1127778 | S34: =S33 -> 26.302972 | ... AI34: =AI33 -> 0.25
G35: Sand / grov jord | H35: ='Inputs-Redskap'!M30+'Inputs-Redskap'!E26 -> 19.567387 | I35: =I34 -> 3.7353333 | J35: ='Inputs-Redskap'!M31+'Inputs-Redskap'!E26 -> 23.945859 | K35: ='Inputs-Redskap'!M29+'Inputs-Redskap'!E26 -> 35.801762 | L35: =L34 -> 17.096932 | M35: =M34 -> 12.75 | N35: =N34 -> 17.75 | O35: =O34 -> 1.2451111 | P35: =P34 -> 3.1127778 | Q35: =Q34 -> 4.6691667 | R35: =R34 -> 3.1127778 | S35: =S34 -> 26.302972 | ... AI35: =AI34 -> 0.25

Sheet Källor
A3: Jordbruksverket (2022) Jordbruksstatistisk sammanställning 2022, JO1901, https://jordbruksverket.se/om-jordbruksverket/jordbruksverkets-officiella-statistik/jordbruksverkets-statistikrapporter/statistik/2022-07-05-jordbruksstatistisk---sammanstallning-2022
A4: Baky, A., Sundberg, M., & Brown, N. (2010). Kartläggning av jordbrukets energianvändning [Survey of energy use in Swedish agriculture]. Retrieved from JTI, Uppsala: https://www.diva-portal.org/smash/get/diva2:959931/FULLTEXT01.pdf
A5: Engström, J., & Lagnelöv, O. (2017). Battery Electric Autonomous Agricultural Machine - Simulation of all operations on a Swedish farm. http://www.diva-portal.org/smash/record.jsf?pid=diva2%3A1144170&dswid=-6740
A6: Grisso, R., Perumpral, J. V., Vaughan, D., Roberson, G. T., & Pitman, R. (2010). Predicting Tractor Diesel Fuel Consumption. In (Vol. Pub. 442-073). College of Agriculture and Life Sciences: Virginia Polytech Institute and State University.https://vtechworks.lib.vt.edu/bitstream/handle/10919/47472/442-073_pdf.pdf?sequence=1&isAllowed=y
A7: Kitani, A., Jungbluth, T., Peart, R. M., Ramdani, A., Badger, P. C., & Clark, N. R. (1999). CIGR Handbook of Agricultural Engineering (A. Kitani Ed. Vol. 5 - Energy and Biomass Engineering): American Society of Agricultural Engineers.
A8: Lindgren, M., Pettersson, O., Hansson, P.-A., & Norén, O. (2002). Jordbruks- och anläggningsmaskiners motorbelastning och avgasemissioner [Engine load pattern and engine exhaust gas emissions from off-road vehicles]. Retrieved from http://www.diva-portal.org/smash/record.jsf?pid=diva2%3A959556
A9: Maskinkalkylgruppen. (2020). Maskinkostnader 2020 [Machine costs 2020]. Retrieved from Maskinkalkylgruppen: http://maskinkostnader.se/
A10: Nilsson, B. (1976). Planering av jordbrukets maskinsystem. Problem, modeller och tillämpningar. [The planning of farm machinery systems - Problems, models and applications]. In (Vol. Report no. 38). Uppsala, Sweden: Swedish University of Agricultural Sciences
A11: Reif, K., & Dietsche, K.-H. (2014). Bosch Automotive Handbook (K. Reif Ed. 9th ed.). Robert Bosch GmbH, Germany: John Wiley & Sons Ltd.
A12: SAE. (2000). Agricultural Machinery Management Data. In. ASABE, St. Joseph, MI, USA: American Society of Agricultural Engineers
