Workbook

Sheet references
A1: Strid, Röös & Tidåker. (2014). Förluster av svenskt nötkött inom primärproduktion och slakt. SJV Rapport 2014:07
A2: Bertilsson (2016) Updating Swedish emission factors for cattle to be used for calculations of greenhouse gases. On commission of the Swedish Environmental Protection Agency 2016. https://publications.slu.se/?file=publ/show&id=76286
A3: Ahlgren, S., Behaderovic, D., Wirsenius, S., Carlsson, A., Hessle, A. Toräng, P., Seeman, A., den Braver, T. & et al. Kvarnbäck, O. (2022) Miljöpåverkan av svensk nöt- och lammköttsproduktion. RISE

Sheet default
A1: f_breed | B1: f_prod_system | C1: f_sub_system | D1: f_animal | E1: f_animal_rations:animal | F1: f_feed | G1: f_po8:region | H1: f_from_ps | I1: f_to_ps | J1: parameter | K1: value | L1: unit | M1: description | N1: source
A2: Milk production
A3: Dairy
A4: dairy | B4: conventional | J4: milk_prod | K4: =AVERAGE(9829,9903,9953,10112,10330) -> 10025.4 | L4: kg/cow/year | M4: Total incl. for calves | N4: Växa Husdjursstatistik Tab. 17 (2016-2020)
A5: dairy | B5: conventional | J5: milk_loss | K5: 8 | L5: % | M5: Mikaela?? 89% delivered to dairy?? | N5: Växa + Swedish Board of Agriculture
A6: dairy | B6: conventional | J6: milk_fat | K6: =AVERAGE(4.3,4.2,4.2,4.3,4.3) -> 4.26 | L6: % | N6: Växa Husdjursstatistik Tab. 17 (2016-2020)
A7: dairy | B7: conventional | J7: milk_protein | K7: =AVERAGE(3.5,3.6,3.5,3.6,3.6) -> 3.56 | L7: % | N7: Växa Husdjursstatistik Tab. 17 (2016-2020)
A8: dairy | B8: organic | J8: milk_prod | K8: =AVERAGE(9135,9246,9280,9499,9676) -> 9367.2 | L8: kg/cow/year | N8: Växa Husdjursstatistik Tab. 17 (2016-2020)
A9: dairy | B9: organic | J9: milk_loss | K9: 8 | L9: % | M9: Mikaela?? 89% delivered to dairy?? | N9: Växa + Swedish Board of Agriculture
A10: dairy | B10: organic | J10: milk_fat | K10: =AVERAGE(4.2,4.1,4.1,4.1,4.2) -> 4.14 | L10: % | N10: Växa Husdjursstatistik Tab. 17 (2016-2020)
A11: dairy | B11: organic | J11: milk_protein | K11: =AVERAGE(3.4,3.4,3.4,3.5,3.5) -> 3.44 | L11: % | N11: Växa Husdjursstatistik Tab. 17 (2016-2020)
A12: Beef
A13: beef | J13: milk_prod | K13: 0 | L13: kg/cow/year | M13: milk prod. calculated from share of calf energy req. from milk
A14: beef | J14: milk_loss | K14: 0 | L14: %
A15: beef | J15: milk_fat | K15: 4.14 | L15: % | M15: Assumes same as dairy cows
A16: beef | J16: milk_protein | K16: 3.44 | L16: % | M16: Assumes same as dairy cows | Q16: milk kg x 0,25 + fat kg x 12,2 + protein kg x 7,7
A17: beef | J17: milk_to_dairy | K17: 0 | L17: %
A19: Fertility etc.
A20: Dairy
A21: dairy | B21: conventional | J21: calving_interval | K21: 13.2 | L21: months | N21: Växa Husdjursstatistik 2020, tab 29
A22: dairy | B22: organic | J22: calving_interval | K22: 12.9 | L22: months | N22: Växa Husdjursstatistik 2020, tab 29
A23: dairy | B23: conventional | J23: AFC | K23: 27 | L23: months | M23: age at first calving | N23: Växa Husdjursstatistik 2020, tab 29
A24: dairy | B24: organic | J24: AFC | K24: 27 | L24: months | M24: age at first calving | N24: Växa Husdjursstatistik 2020, tab 29
A25: dairy | B25: conventional | J25: recruitment_rate | K25: 37.1 | L25: % | M25: % of cows per year | N25: Växa Husdjursstatistik 2020, tab 28
A26: dairy | B26: organic | J26: recruitment_rate | K26: 36.1 | L26: % | M26: % of cows per year | N26: Växa Husdjursstatistik 2020, tab 28
A27: dairy | J27: time_lag_recruitment | K27: 0 | L27: months
A28: dairy | J28: ratio_male_calf | K28: 50.655978 | L28: % | M28: % of calves | N28: Växa Husdjursstatistik 2020, tab 20
A29: dairy | J29: twin_birth | K29: =(79242*1.07+141785*4.46)/(79242+141785) -> 3.2446264 | L29: % | M29: % of calvings
A30: dairy | B30: conventional | J30: stillborn_calf | K30: 5 | L30: % | M30: % of calvings | N30: Växa Husdjursstatistik 2020, tab 28
A31: dairy | B31: organic | J31: stillborn_calf | K31: 4.6 | L31: % | M31: % of calvings | N31: Växa Husdjursstatistik 2020, tab 28
A32: dairy | B32: conventional | J32: weaning_age | K32: =9*7 -> 63 | L32: days | N32: Skottheim (2014) Hur stor betydelse har utfodrings- och avvänjningsstrategin för kalvens tillväxt och hälsa?. SLU, Uppsala
A33: dairy | B33: organic | J33: weaning_age | K33: =12*7 -> 84 | L33: days | N33: https://www.kalvportalen.se/mjoelk/mjoelkraskalvar/utfodringsperiod/
A34: dairy | B34: conventional | J34: breeding_bulls_per_cow | K34: =1/90*0.5 -> 0.0055555556 | L34: nr | M34: 0.5 breeding bulls ber farm / 90 cows per farm | N34: Artificial insemination, but often a bull for cases where it does not work (Anna Hessle, SLU)
A35: dairy | B35: organic | J35: breeding_bulls_per_cow | K35: =1/99*0.5 -> 0.0050505051 | L35: nr | M35: 0.5 breeding bulls ber farm / 99 cows per farm | N35: cows per farm from Swedish Board of Agriculture statistics database (avg. 2016-2020)
A37: Beef
A38: beef | J38: calving_interval | K38: 12.7 | L38: months
A39: beef | J39: AFC | K39: =(27.5+28.4+27.6+29.9+30)/5 -> 28.68 | L39: months | M39: age at first calving | N39: Växa Husdjursstatistik 2020 (KAP), tab 32
A40: beef | J40: recruitment_rate | K40: 25.100803 | L40: % | M40: % of cows per year
A41: beef | J41: time_lag_recruitment | K41: 5 | L41: months | M41: Time from slaughter of cow to first calving of replacement heifer | N41: Pers. com. Anna Hessle, SLU
A42: beef | J42: ratio_male_calf | K42: 51.7 | L42: % | M42: % of calves | N42: Växa Husdjursstatistik 2020 (KAP), tab 34
...

Sheet Antal djur
B2: Mjölk besättningar | P2: =(1-P7/100)+(P7/100) -> 1 | Y2: Diko besättningar
D3: Number | F3: Slaughtered | H3: Slaughtered (1000 tonnes) | J3: Dead/culled | AA3: Number | AC3: Slaughtered | AE3: Slaughtered (1000 tonnes) | AG3: Dead/culled
D4: Conv | E4: Org | F4: Conv | G4: Org | H4: Conv | I4: Org | J4: Conv | K4: Org | M4: Parameter | P4: Konv | Q4: Eko | R4: Enhet | T4: Källa | AA4: Conv | AB4: Org | AC4: Conv | AD4: Org | AE4: Conv | AF4: Org | AG4: Conv | AH4: Org | AJ4: Parameter | AM4: Konv | AN4: Eko | AO4: Enhet | AQ4: Källa
B5: Cows | D5: =D80*(1-E58/100) -> 261212.59 | E5: =D80*(E58/100) -> 55025.412 | F5: =D5*P7/100-J5 -> 79669.839 | G5: =E5*Q7/100-K5 -> 16232.497 | H5: =F5*P30/1000000 -> 24.81499 | I5: =G5*Q30/1000000 -> 5.0559815 | J5: =D5*P14/100 -> 17240.031 | K5: =E5*Q14/100 -> 3631.6772 | M5: Kalvningsintervall | P5: 13.2 | Q5: 12.9 | R5: mån | T5: (Växa tab 29) | Y5: Cows | AA5: =D81*(1-E59/100) -> 133821.07 | AB5: =D81*(E59/100) -> 72692.928 | AC5: =AA5*AM7/100-AG5 -> 31961.815 | AD5: =AB5*AN7/100-AH5 -> 17361.974 | AE5: =AC5*AM30/1000000 -> 10.8911 | AF5: =AD5*AN30/1000000 -> 5.916153 | AG5: =AA5*AM14/100 -> 2676.4214 | AH5: =AB5*AN14/100 -> 1453.8586 | AJ5: Kalvningsintervall | AM5: =(12.7+12.7+12.7+12.7)/4 -> 12.7 | AN5: 12.7 | AO5: mån | AQ5: (Växa Husdjursstatistik 2020, tab 31)
B6: Heifers | D6: =D23*((P6-12)/12)+D27*((P25-12)/12) -> 143116.4 | E6: =E23*((Q6-12)/12)+E27*((Q25-12)/12) -> 27383.537 | F6: =D27 -> 14501.166 | G6: =E27 -> 1684.6085 | H6: =F6*P31/1000000 -> 4.3516219 | I6: =G6*Q31/1000000 -> 0.50553033 | M6: Inkalvningsålder | P6: 27 | Q6: 27 | R6: mån | T6: (Växa tab 29) | Y6: Heifers | AA6: =AA23*((AM6-12)/12)+AA27*((AM25-12)/12) -> 80765.592 | AB6: =AB23*((AN6-12)/12)+AB27*((AN25-12)/12) -> 38950.444 | AC6: =AA27 -> 27905.346 | AD6: =AB27 -> 10947.457 | AE6: =AC6*AM31/1000000 -> 8.6629149 | AF6: =AD6*AN31/1000000 -> 3.3985205 | AJ6: Inkalvningsålder | AM6: =(27.5+28.4+27.6+29.9+30)/5 -> 28.68 | AN6: =AM6 -> 28.68 | AO6: mån | AQ6: (Växa Husdjursstatistik 2020, tab 32)
B7: Steers | D7: =D28*((P27-12)/12) -> 23725.405 | E7: =E28*((Q27-12)/12) -> 2080.6328 | F7: =D28 -> 16697.558 | G7: =E28 -> 1464.3159 | H7: =F7*P33/1000000 -> 5.4778103 | I7: =G7*Q33/1000000 -> 0.4803843 | M7: Rekrytering | P7: 37.1 | Q7: 36.1 | R7: % | T7: (Växa tab 28) | Y7: Steers | AA7: =AA28*((AM27-12)/12) -> 8165.0384 | AB7: =AB28*((AN27-12)/12) -> 13736.113 | AC7: =AA28 -> 6297.7419 | AD7: =AB28 -> 10594.744 | AE7: =AC7*AM33/1000000 -> 2.1158894 | AF7: =AD7*AN33/1000000 -> 3.5595785 | AJ7: Rekrytering | AM7: =1/(AM24/12-AM6/12)*100 -> 25.883993 | AN7: =1/(AN24/12-AN6/12)*100 -> 25.883993 | AO7: % | AQ7: (ber.)
B8: Bulls | D8: =D29*((P28-12)/12) -> 80328.021 | E8: =E29*((Q28-12)/12) -> 714.54026 | F8: =D29 -> 103937.83 | G8: =E29 -> 924.55612 | H8: =F8*P34/1000000 -> 34.109693 | I8: =G8*Q34/1000000 -> 0.30341528 | M8: Könskvot, tjurkalvar | P8: =(48.7*77196+51.7*144627)/221823 -> 50.655978 | Q8: =P8 -> 50.655978 | R8: % | T8: (Växa Husdjursstatistik 2020, tab 20) | Y8: Bulls | AA8: =AA29*((AM28-12)/12) -> 36700.477 | AB8: =AB29*((AN28-12)/12) -> 11188.195 | AC8: =AA29 -> 60797.103 | AD8: =AB29 -> 18534.087 | AE8: =AC8*AM34/1000000 -> 21.85512 | AF8: =AD8*AN34/1000000 -> 6.6625658 | AJ8: Könskvot, tjurkalvar | AM8: 51.7 | AN8: =AM8 -> 51.7 | AO8: % | AQ8: (Växa KAP, tab 34)
B9: Calves | D9: =((D13-D17)*P16+(D14-D18)*P18+(D17-D19)*P20+(D18-D20)*P22+(D23+D27+D28+D29)*365.25+D24*P26*30.44)/365.25 -> 243040.2 | E9: =((E13-E17)*Q16+(E14-E18)*Q18+(E17-E19)*Q20+(E18-E20)*Q22+(E23+E27+E28+E29)*365.25+E24*Q26*30.44)/365.25 -> 25112.575 | F9: =D24 -> 10596.344 | G9: =E24 -> 319.41025 | H9: =F9*P32/1000000 -> 1.7931145 | I9: =G9*Q32/1000000 -> 0.054050639 | J9: =SUM(D21:D22) -> 23373.094 | K9: =SUM(E21:E22) -> 3061.7383 | M9: Tvilingfödslar | P9: =(79242*1.07+141785*4.46)/(79242+141785) -> 3.2446264 | Q9: =P9 -> 3.2446264 | R9: % | Y9: Calves | AA9: =((AA13-AA17)*AM16+(AA14-AA18)*AM18+(AA17-AA19)*AM20+(AA18-AA20)*AM22+(AA23+AA27+AA28+AA29)*365.25+AA24*AM26*30.44)/365.25 -> 132918.96 | AB9: =((AB13-AB17)*AN16+(AB14-AB18)*AN18+(AB17-AB19)*AN20+(AB18-AB20)*AN22+(AB23+AB27+AB28+AB29)*365.25+AB24*AN26*30.44)/365.25 -> 60501.722 | AC9: =AA24 -> 2007.1808 | AD9: =AB24 -> 846.73891 | AE9: =AC9*AM32/1000000 -> 0.3169949 | AF9: =AD9*AN32/1000000 -> 0.13372583 | AG9: =SUM(AA21:AA22) -> 7307.7168 | AH9: =SUM(AB21:AB22) -> 3731.6157 | AJ9: Tvilingfödslar | AM9: 4.5730449 | AN9: =AM9 -> 4.5730449 | AO9: % | AQ9: (Växa Husdjursstatistik 2020, tab 34a)
M10: Dödfödda kalvar | P10: 5 | Q10: 4.6 | R10: % | T10: (Växa tab 28) | AJ10: Dödfödda kalvar | AM10: =(2.4*10433+1.6*1935)/(10433+1935) -> 2.2748383 | AN10: =AM10 -> 2.2748383 | AO10: % | AQ10: (Växa Husdjursstatistik 2020, tab 31)
B11: Intermediates | D11: Conv | E11: Org | G11: Andel | H11: =SUM(H5:H9)/SUM($H5:$I9,$AE5:$AF9) -> 0.50226153 | I11: =SUM(I5:I9)/SUM($H5:$I9,$AE5:$AF9) -> 0.045560306 | M11: Lev. kalvar per år | P11: =(12/P5*(1-P7/100)+(P7/100))*(1*(1-P9/100)+2*(P9/100))*(1-P10/100) -> 0.92473865 | Q11: =(12/Q5*(1-Q7/100)+(Q7/100))*(1*(1-Q9/100)+2*(Q9/100))*(1-Q10/100) -> 0.94104312 | R11: antal/ko/år | T11: (ber.) | Y11: Intermediates | AA11: Conv | AB11: Org | AD11: Andel | AE11: =SUM(AE5:AE9)/SUM($H5:$I9,$AE5:$AF9) -> 0.31213358 | AF11: =SUM(AF5:AF9)/SUM($H5:$I9,$AE5:$AF9) -> 0.14004458 | AJ11: Lev. kalvar per år | AM11: =(12/AM5*(1-AM7/100)+(AM7/100))*(1*(1-AM9/100)+2*(AM9/100))*(1-AM10/100) -> 0.98019408 | AN11: =(12/AN5*(1-AN7/100)+(AN7/100))*(1*(1-AN9/100)+2*(AN9/100))*(1-AN10/100) -> 0.98019408 | AO11: antal/ko/år | AQ11: (ber.)
B12: Calves born | D12: =D5*P11 -> 241553.38 | E12: =E5*Q11 -> 51781.286 | H12: =H11/SUM(H11:I11) -> 0.91683372 | I12: =I11/SUM(H11:I11) -> 0.083166284 | M12: Avvänjningsålder | P12: 100 | Q12: =P12 -> 100 | R12: dagar | T12: RISE | Y12: Calves born | AA12: =AA5*AM11 -> 131170.62 | AB12: =AB5*AN11 -> 71253.178 | AE12: =AE11/SUM(AE11:AF11) -> 0.69028893 | AF12: =AF11/SUM(AE11:AF11) -> 0.30971107 | AJ12: Avvänjningsålder | AM12: =7*30.4 -> 212.8 | AN12: =AM12 -> 212.8 | AO12: dagar
B13: Male calves born | D13: =D12*P8/100 -> 122361.23 | E13: =E12*Q8/100 -> 26230.317 | M13: Dödlighet | Y13: Male calves born | AA13: =AA12*AM8/100 -> 67815.212 | AB13: =AB12*AN8/100 -> 36837.893 | AJ13: Dödlighet
B14: Female calves born | D14: =D12-D13 -> 119192.15 | E14: =E12-E13 -> 25550.969 | M14: kor | P14: 6.6 | Q14: =P14 -> 6.6 | R14: % av djur | T14: RISE | Y14: Female calves born | AA14: =AA12-AA13 -> 63355.411 | AB14: =AB12-AB13 -> 34415.285 | AJ14: kor | AM14: 2 | AN14: =AM14 -> 2 | AO14: % av djur | AQ14: RISE
B15: Male calves 2 weaned before redist | D15: =D13*(1-P15/100) -> 117222.06 | E15: =E13*(1-Q15/100) -> 25128.644 | M15: tjurkalv (föds.-avv.) | P15: 4.2 | Q15: =P15 -> 4.2 | R15: % av levande födda | T15: RISE | AA15: =AA13*(1-AM15/100) -> 65102.603 | AB15: =AB13*(1-AN15/100) -> 35364.377 | AJ15: tjurkalv (föds.-avv.) | AM15: 4 | AN15: =AM15 -> 4 | AO15: % av levande födda | AQ15: RISE
B16: Female calves 2 weaned before redist | D16: =D14*(1-P17/100) -> 115139.62 | E16: =E14*(1-Q17/100) -> 24682.236 | M16: snittålder | P16: 10 | Q16: =P16 -> 10 | R16: dagar | T16: RISE | AA16: =AA14*(1-AM17/100) -> 61328.038 | AB16: =AB14*(1-AN17/100) -> 33313.996 | AJ16: snittålder | AM16: 3 | AN16: =AM16 -> 3 | AO16: dagar | AQ16: RISE
B17: Male calves 2 weaned | D17: =D15+E15*P39/100 -> 139586.55 | E17: =E15-E15*P39/100 -> 2764.1508 | M17: kvigkalv (föds.-avv.) | P17: 3.4 | Q17: =P17 -> 3.4 | R17: % av levande födda | T17: RISE | Y17: Male calves 2 weaned | AA17: =AA15+AB15*AM39/100 -> 70053.616 | AB17: =AB15-AB15*AM39/100 -> 30413.364 | AJ17: kvigkalv (föds.-avv.) | AM17: 3.2 | AN17: =AM17 -> 3.2 | AO17: % av levande födda | AQ17: RISE
B18: Female calves 2 weaned | D18: =D16+E16*P40/100 -> 117237.61 | E18: =E16-E16*P40/100 -> 22584.246 | M18: snittålder | P18: 10 | Q18: =P18 -> 10 | R18: dagar | T18: RISE | Y18: Female calves 2 weaned | AA18: =AA16+AB16*AM40/100 -> 64159.727 | AB18: =AB16-AB16*AM40/100 -> 30482.306 | AJ18: snittålder | AM18: 10 | AN18: =AM18 -> 10 | AO18: dagar | AQ18: RISE
B19: Male calves 2 end | D19: =D17*(1-P19/100) -> 130094.66 | E19: =E17*(1-Q19/100) -> 2576.1885 | M19: tjurar/stutar (avv.-slakt) | P19: 6.8 | Q19: =P19 -> 6.8 | R19: % av avvanda | T19: RISE | Y19: Male calves 2 end | AA19: =AA17*(1-AM19/100) -> 68512.437 | AB19: =AB17*(1-AN19/100) -> 29744.27 | AJ19: tjurar/stutar (avv.-slakt) | AM19: 2.2 | AN19: =AM19 -> 2.2 | AO19: % av avvanda | AQ19: RISE
B20: Female calves 2 end | D20: =D18*(1-P21/100) -> 112548.1 | E20: =E18*(1-Q21/100) -> 21680.876 | M20: snittålder | P20: 59 | Q20: =P20 -> 59 | R20: dagar | T20: RISE | Y20: Female calves 2 end | AA20: =AA18*(1-AM21/100) -> 63133.171 | AB20: =AB18*(1-AN21/100) -> 29994.589 | AJ20: snittålder | AM20: 234 | AN20: =AM20 -> 234 | AO20: dagar | AQ20: RISE
B21: Male calves 2 dead | D21: =D13-D15+D17-D19 -> 14631.057 | E21: =E13-E15+E17-E19 -> 1289.6356 | M21: kvigor (avv.-slakt) | P21: 4 | Q21: =P21 -> 4 | R21: % av avvanda | T21: RISE | Y21: Male calves 2 dead | AA21: =AA13-AA15+AA17-AA19 -> 4253.788 | AB21: =AB13-AB15+AB17-AB19 -> 2142.6097 | AJ21: kvigor (avv.-slakt) | AM21: 1.6 | AN21: =AM21 -> 1.6 | AO21: % av avvanda | AQ21: RISE
B22: Female calves 2 dead | D22: =D14-D16+D18-D20 -> 8742.0374 | E22: =E14-E16+E18-E20 -> 1772.1028 | M22: snittålder | P22: 59 | Q22: =P22 -> 59 | R22: dagar | T22: RISE | Y22: Female calves 2 dead | AA22: =AA14-AA16+AA18-AA20 -> 3053.9288 | AB22: =AB14-AB16+AB18-AB20 -> 1589.006 | AJ22: snittålder | AM22: 241 | AN22: =AM22 -> 241 | AO22: dagar | AQ22: RISE
B23: Calves 2 recruitment | D23: =D5*P7/100 -> 96909.87 | E23: =E5*Q7/100 -> 19864.174 | M23: Slaktålder | Y23: Calves 2 recruitment | AA23: =AA5*AM7/100 -> 34638.236 | AB23: =AB5*AN7/100 -> 18815.832 | AJ23: Slaktålder
B24: Calves 2 slaughter | D24: =(SUM(D19:D20)-D23)*P36/100 -> 10596.344 | E24: =(SUM(E19:E20)-E23)*Q36/100 -> 319.41025 | M24: kor | P24: 60.9 | Q24: 61.5 | R24: mån | T24: (Växa tab 28) | Y24: Calves 2 slaughter | AA24: =(SUM(AA19:AA20)-AA23)*AM36/100 -> 2007.1808 | AB24: =(SUM(AB19:AB20)-AB23)*AN36/100 -> 846.73891 | AJ24: kor | AM24: ='G&D sammanställning'!K5 -> 75.040699 | AN24: =AM24 -> 75.040699 | AO24: mån
B25: Male calves 2 slaughter | D25: =D24*(D19)/(D19+D20-D23) -> 9459.2765 | E25: =E24*(E19)/(E19+E20-E23) -> 187.31652 | M25: kvigor | P25: ='G&D sammanställning'!H8 -> 30.188105 | Q25: =P25 -> 30.188105 | R25: mån | Y25: Male calves 2 slaughter | AA25: =AA24*(AA19)/(AA19+AA20-AA23) -> 1417.5917 | AB25: =AB24*(AB19)/(AB19+AB20-AB23) -> 615.43909 | AJ25: kvigor | AM25: ='G&D sammanställning'!K8 -> 26.02675 | AN25: =AM25 -> 26.02675 | AO25: mån
B26: Female calves 2 slaughter | D26: =D24-D25 -> 1137.0672 | E26: =E24-E25 -> 132.09372 | M26: mellankalv | P26: ='G&D sammanställning'!H14 -> 10.328497 | Q26: =P26 -> 10.328497 | R26: mån | Y26: Female calves 2 slaughter | AA26: =AA24-AA25 -> 589.58908 | AB26: =AB24-AB25 -> 231.29981 | AJ26: mellankalv | AM26: ='G&D sammanställning'!K14 -> 9.9010036 | AN26: =AM26 -> 9.9010036 | AO26: mån
B27: Calves 2 heifers | D27: =D20-D23-D26 -> 14501.166 | E27: =E20-E23-E26 -> 1684.6085 | M27: stutar | P27: ='G&D sammanställning'!H9 -> 29.050688 | Q27: =P27 -> 29.050688 | R27: mån | Y27: Calves 2 heifers | AA27: =AA20-AA23-AA26 -> 27905.346 | AB27: =AB20-AB23-AB26 -> 10947.457 | AJ27: stutar | AM27: ='G&D sammanställning'!K9 -> 27.558031 | AN27: =AM27 -> 27.558031 | AO27: mån
B28: Calves 2 steers | D28: =(D19-D25)*(P37/100) -> 16697.558 | E28: =(E19-E25)*(Q37/100) -> 1464.3159 | M28: tjurar | P28: ='G&D sammanställning'!H10 -> 21.274162 | Q28: =P28 -> 21.274162 | R28: mån | Y28: Calves 2 steers | AA28: =(AA19-AA25)*(AM37/100) -> 6297.7419 | AB28: =(AB19-AB25)*(AN37/100) -> 10594.744 | AD28: 6180.1797 | AE28: 10387.902 | AJ28: tjurar | AM28: ='G&D sammanställning'!K10 -> 19.24386 | AN28: =AM28 -> 19.24386 | AO28: mån
B29: Calves 2 bulls | D29: =D19-D25-D28 -> 103937.83 | E29: =E19-E25-E28 -> 924.55612 | M29: Slaktvikt | Y29: Calves 2 bulls | AA29: =AA19-AA25-AA28 -> 60797.103 | AB29: =AB19-AB25-AB28 -> 18534.087 | AD29: 60706.757 | AE29: 18612.205 | AJ29: Slaktvikt
M30: kor | P30: ='G&D sammanställning'!B5 -> 311.47282 | Q30: =P30 -> 311.47282 | R30: kg | AJ30: kor | AM30: ='G&D sammanställning'!E5 -> 340.75348 | AN30: =AM30 -> 340.75348 | AO30: kg
M31: kvigor | P31: ='G&D sammanställning'!B8 -> 300.08773 | Q31: =P31 -> 300.08773 | R31: kg | AJ31: kvigor | AM31: ='G&D sammanställning'!E8 -> 310.43926 | AN31: =AM31 -> 310.43926 | AO31: kg
M32: mellankalv | P32: ='G&D sammanställning'!B14 -> 169.22012 | Q32: =P32 -> 169.22012 | R32: kg | AJ32: mellankalv | AM32: ='G&D sammanställning'!E14 -> 157.93042 | AN32: =AM32 -> 157.93042 | AO32: kg
M33: stutar | P33: ='G&D sammanställning'!B9 -> 328.06057 | Q33: =P33 -> 328.06057 | R33: kg | AJ33: stutar | AM33: ='G&D sammanställning'!E9 -> 335.97589 | AN33: =AM33 -> 335.97589 | AO33: kg
M34: tjurar | P34: ='G&D sammanställning'!B10 -> 328.174 | Q34: =P34 -> 328.174 | R34: kg | AJ34: tjurar | AM34: ='G&D sammanställning'!E10 -> 359.47634 | AN34: =AM34 -> 359.47634 | AO34: kg
M35: Andel av slaktade ungdjur | S35: adj | AJ35: Andel av slaktade ungdjur | AP35: adj
M36: som kalv | P36: ='G&D sammanställning'!$T$14*S36 -> 7.2710719 | Q36: ='G&D sammanställning'!$T$14*T36 -> 7.2710719 | R36: % | S36: 0.95 | T36: 0.95 | AJ36: mellankalv | AM36: ='G&D sammanställning'!$W$14*AP36 -> 2.0691013 | AN36: ='G&D sammanställning'!$W$14*AQ36 -> 2.0691013 | AO36: % | AP36: 0.95 | AQ36: 0.95
M37: som stut (av handjur) | P37: ='G&D sammanställning'!$T$9/SUM('G&D sammanställning'!T9:T10)*100*S37 -> 13.841343 | Q37: ='G&D sammanställning'!$T$9/SUM('G&D sammanställning'!T9:T10)*100*T37 -> 61.297378 | R37: % | S37: 0.7 | T37: 3.1 | AJ37: stutar | AM37: ='G&D sammanställning'!$W$9/SUM('G&D sammanställning'!W9:W10)*100*AP37 -> 9.3863275 | AN37: ='G&D sammanställning'!$W$9/SUM('G&D sammanställning'!W9:W10)*100*AQ37 -> 36.372019 | AO37: % | AP37: 0.8 | AQ37: 3.1
M38: Överföring djur eko -> konv | AJ38: Överföring djur eko -> konv
M39: tjurkalvar | P39: 89 | R39: % | T39: (uppskattat baserat på stat.) | AJ39: tjurkalvar | AM39: 14 | AO39: %
M40: kvigkalvar | P40: 8.5 | R40: % | T40: (uppskattat baserat på stat.) | AJ40: kvigkalvar | AM40: 8.5 | AO40: %
D42: Från modell | F42: Kontroll
...

Sheet Foderstater
B2: FEED RATIONS | D2: Ahlgren et al 2022 | Y2: Mikaela Lindberg | AA2: Hessle & Danielsson (2024)
B3: kg/head/year | D3: Tabell 10 | M3: Tabell 11 | S3: Tabell 12 | Y3: pers. com. 2023-04 | AA3: SM - Table S8 | AG3: SM - Table S7 | AP3: Einarsson et al 2022 SM2
D4: Diko (per år) | G4: Köttrastjur | J4: Avelstjur | M4: Mjölkrastjur | P4: Mjölkrasstut | S4: Köttrasstut | V4: Köttraskviga | Y4: Mjölkko | Z4: Mjölkko | AA4: Dairy heifer | AD4: Dairy steer | AG4: Beef heifer | AJ4: Beef steer | AP4: ('Feed rations') | AS4: Dairy cows | AT4: Calves, dairy, replacement | AU4: Heifers, dairy, replacement | AV4: Suckler cows | AW4: Calves, for slaughter | AX4: Calves, dairy, for fattening | AY4: Calves, suckler, replacement or fattening | AZ4: Heifers, suckler, replacement | BA4: Bulls, dairy breed | BB4: Bulls, beef breed | BC4: Steers, dairy/beef | BD4: Heifers, dairy breed, for slaughter | BE4: Heifers, beef breed, for slaughter | BF4: Calves, dariy | BG4: Calves, beef
D5: Gsk | E5: Gns | F5: Nn | G5: Gsk | H5: Gns | I5: Nn | J5: Gsk | K5: Gns | L5: Nn | M5: Gsk | N5: Gns | O5: Nn | P5: Gsk | Q5: Gns | R5: Nn | S5: Gsk | T5: Gns | U5: Nn | V5: Gsk | W5: Gns | X5: Nn | Y5: vall | Z5: majs | AA5: ALP | AB5: BOR | AC5: CON | AD5: ALP | AE5: BOR | AF5: CON | AG5: ALP | AH5: BOR | AI5: CON | AJ5: ALP | AK5: BOR | AL5: CON
B6: Feed ration | C6: DM | D6: 86 | E6: 86 | F6: 86 | G6: 15 | H6: 15 | I6: 16 | J6: 53 | K6: 53 | L6: 53 | M6: 18 | N6: 18 | O6: 18 | P6: 26 | Q6: 26 | R6: 26 | S6: 24 | T6: 24 | U6: 24 | V6: 24 | W6: 24 | X6: 24 | AA6: 27 | AB6: 27 | AC6: 27 | AD6: 26 | AE6: 26 | AF6: 26 | AG6: 24 | AH6: 24 | AI6: 24 | AJ6: 30 | AK6: 30 | AL6: 30
B7: Vallensilage, tidigt, kg ts | C7: 1 | G7: 1229 | I7: 1329 | M7: 2119 | O7: 2130 | Y7: 2973.75 | Z7: 1619.55 | AM7: Vallensilage, tidigt, kg ts | AP7: Population (heads) | AS7: 330888.67 | AT7: 134305.6 | AU7: 161884.48 | AV7: 195238.33 | AW7: 18420.386 | AX7: 143245.78 | AY7: 175831.9 | AZ7: 55410.68 | BA7: 93814.363 | BB7: 85881.771 | BC7: 36635.904 | BD7: 22798.726 | BE7: 35985.746
B8: Vallensilage, medelsen, kg ts | C8: 1 | P8: 2663 | Q8: 2561 | R8: 2690 | S8: 2568 | T8: 2502 | U8: 2401 | V8: 2506 | W8: 2459 | X8: 2431 | Y8: 711.5 | Z8: 751.15 | AA8: 2807 | AB8: 2343 | AC8: 2144 | AD8: 3190 | AE8: 2663 | AF8: 2436 | AG8: 2883 | AH8: 2506 | AI8: 2339 | AM8: Vallensilage, medelsen, kg ts | AP8: age | AS8: per yr | AT8: 0-12 | AU8: 12-28 | AV8: per yr | AW8: 0-8 | AX8: 0-12 | AY8: 0-12 | AZ8: 12-26 | BA8: 12-18.9 | BB8: 12-17 | BC8: 12-26 | BD8: 12-26 | BE8: 12-23
B9: Vallensilage, sent, kg ts | C9: 1 | D9: 659 | E9: 1254 | F9: 770 | K9: 1235 | AJ9: 3102 | AK9: 2615 | AL9: 2416 | AM9: Vallensilage, sent, kg ts
B10: Vallensilage, klöverrikt, kg ts | C10: 1 | H10: 1165 | N10: 1868 | AM10: Vallensilage, klöverrikt, kg ts | AP10: Feed ration | AR10: DM
B11: Majsensilage, kg ts | C11: 1 | H11: 272 | N11: 436 | Z11: 1250.5 | AM11: Majsensilage, kg ts | AP11: Grass/clover silage | AR11: 1 | AS11: 3312 | AT11: 1200 | AU11: 1574 | AV11: 786.48686 | AW11: 262.69098 | AX11: 806.85837 | AY11: 826.64376 | AZ11: 613.65525 | BA11: 1049.6483 | BB11: 579.64056 | BC11: 1672.5065 | BD11: 1390.5375 | BE11: 1039.6552 | BF11: =(AT11*AT$7+AX11*AX$7+AW11*AW$7)/SUM(AT$7,AW$7,AX$7) -> 951.39023 | BG11: =AY11 -> 826.64376
B12: Helsädesensilage, kg ts | C12: 1 | D12: 977 | F12: 970 | J12: 1536 | L12: 1614 | AM12: Helsädesensilage, kg ts | AP12: Whole crop silage | AR12: 1 | AU12: 426 | AV12: 707 | AZ12: 426
B13: Halm, kg | C13: 0.85 | E13: 299 | K13: 139 | Y13: 244 | Z13: 244 | AM13: Halm, kg | AP13: Maize silage | AR13: 1 | AS13: 543
B14: Permanent bete, kg ts | C14: 1 | D14: 1953 | E14: 2053 | F14: 1806 | J14: 1313 | K14: 1390 | L14: 1235 | P14: 1548 | Q14: 1662 | R14: 1548 | S14: 932 | T14: 995 | U14: 951 | V14: 926 | W14: 978 | X14: 924 | AA14: 939 | AB14: 1280 | AC14: 1530 | AD14: 1068 | AE14: 1457 | AF14: 1662 | AG14: 638 | AH14: 871 | AI14: 978 | AJ14: 1307 | AK14: 1782 | AL14: 2020 | AM14: Permanent bete, kg ts | AP14: Straw | AR14: 0.85 | AV14: 236.67856
B15: Bete vallåterväxt, kg ts | C15: 1 | D15: 345 | E15: 362 | F15: 319 | J15: 232 | K15: 245 | L15: 218 | P15: 273 | Q15: 293 | R15: 273 | S15: 165 | T15: 176 | U15: 168 | V15: 163 | W15: 173 | X15: 163 | Y15: 783 | Z15: 783 | AA15: 235 | AB15: 320 | AC15: 283 | AD15: 267 | AE15: 364 | AF15: 415 | AG15: 159 | AH15: 218 | AI15: 245 | AJ15: 327 | AK15: 446 | AL15: 505 | AM15: Bete vallåterväxt, kg ts | AP15: Pasture | AR15: 1 | AS15: 417.5 | AT15: 250 | AU15: 700 | AV15: 2089.9187 | AX15: 148.25672 | AY15: 315.82638 | AZ15: 1270.2489 | BB15: 0 | BC15: 2115.9077 | BD15: 1860.8263 | BE15: 1391.3037 | BF15: =(AT15*AT$7+AX15*AX$7+AW15*AW$7)/SUM(AT$7,AW$7,AX$7) -> 185.19858 | BG15: =AY15 -> 315.82638
B16: Spannmål, kg | C16: 0.86 | G16: 861 | H16: 654 | M16: 1084 | N16: 1014 | P16: 188 | Q16: 184 | Y16: =2180.75-(Y18*U59*C18/C16) -> 1824.2423 | Z16: =1516-(Y18*U59*C18/C16) -> 1159.4923 | AA16: 196 | AB16: 165 | AC16: 154 | AD16: 223 | AE16: 188 | AF16: 175 | AM16: Spannmål, kg | AP16: Grain | AR16: 0.86 | AS16: 1280.5 | AT16: 250 | AU16: 50 | AV16: 40 | AW16: 544.72413 | AX16: 470.02657 | AY16: 352.21215 | BA16: 761.89322 | BB16: 665.02407 | BC16: 54.611532 | BD16: 304.94243 | BE16: 0 | BF16: =(AT16*AT$7+AX16*AX$7+AW16*AW$7)/SUM(AT$7,AW$7,AX$7) -> 374.83221 | BG16: =AY16 -> 352.21215
B17: Åkerböna/ärt, kg | C17: 0.85 | G17: 68 | H17: 78 | M17: 124 | N17: 32 | P17: 4 | Q17: 3 | AM17: Åkerböna/ärt, kg | AP17: Conc | AR17: 0.9 | AS17: 1350.5 | AW17: 151.88274 | AX17: 76.165488 | AY17: 76.642835 | BB17: 70.25886 | BC17: 0 | BD17: 0 | BE17: 0 | BF17: =(AT17*AT$7+AX17*AX$7+AW17*AW$7)/SUM(AT$7,AW$7,AX$7) -> 46.315645 | BG17: =AY17 -> 76.642835
B18: Färdigfoder, kg | C18: 0.9 | I18: 991 | M18: 80 | N18: 79 | O18: 1279 | P18: 119 | Q18: 119 | R18: 294 | Y18: =1244*(1+U59) -> 1522.3714 | Z18: =1966*(1+U59) -> 2405.9342 | AA18: 128 | AB18: 108 | AC18: 102 | AD18: 146 | AE18: 123 | AF18: 116 | AM18: Färdigfoder, kg | AP18: Conc. for calves | AR18: 0.9 | AT18: 14 | AW18: 13.507589 | AX18: 13.575225 | BF18: =(AT18*AT$7+AX18*AX$7+AW18*AW$7)/SUM(AT$7,AW$7,AX$7) -> 13.763769
B19: Mineraler, kg | C19: 1 | D19: 34 | E19: 34 | F19: 34 | G19: 12 | H19: 12 | I19: 14 | J19: 33 | K19: 33 | L19: 33 | M19: 22 | N19: 22 | O19: 21 | P19: 35 | Q19: 35 | R19: 35 | S19: 26 | T19: 26 | U19: 24 | V19: 26 | W19: 26 | X19: 26 | Y19: =SUM(Y8:Y18)*0.01 -> 50.851137 | Z19: =SUM(Z8:Z18)*0.01 -> 65.940765 | AA19: 30 | AB19: 30 | AC19: 30 | AD19: 35 | AE19: 35 | AF19: 35 | AG19: 26 | AH19: 26 | AI19: 26 | AJ19: 28 | AK19: 28 | AL19: 28 | AM19: Mineraler, kg | AP19: Minerals | AR19: 1 | BF19: =SUM(BF11:BF18)*0.006 -> 9.4290026 | BG19: =SUM(BG11:BG18)*0.006 -> 9.4279507
AP20: Milk powder | AR20: 0.95 | AT20: 40 | AW20: 39.852222 | AX20: 39.877866 | BF20: =(AT20*AT$7+AX20*AX$7+AW20*AW$7)/SUM(AT$7,AW$7,AX$7) -> 39.931692
B21: Total | D21: =SUM(D7:D19) -> 3968 | E21: =SUM(E7:E19) -> 4002 | F21: =SUM(F7:F19) -> 3899 | G21: =SUM(G7:G19) -> 2170 | H21: =SUM(H7:H19) -> 2181 | I21: =SUM(I7:I19) -> 2334 | J21: =SUM(J7:J19) -> 3114 | K21: =SUM(K7:K19) -> 3042 | ... AL21: =SUM(AL7:AL19) -> 4969 | AP21: Whole milk | AR21: 0.13 | AY21: 1874.9852 | BG21: =AY21 -> 1874.9852
C22: Share grazing: | D22: =SUM(D14:D15)/D21 -> 0.57913306 | E22: =SUM(E14:E15)/E21 -> 0.60344828 | F22: =SUM(F14:F15)/F21 -> 0.54501154 | G22: =SUM(G14:G15)/G21 -> 0 | H22: =SUM(H14:H15)/H21 -> 0 | I22: =SUM(I14:I15)/I21 -> 0 | J22: =SUM(J14:J15)/J21 -> 0.49614644 | K22: =SUM(K14:K15)/K21 -> 0.53747535 | ... AL22: =SUM(AL14:AL15)/AL21 -> 0.50815053 | AP22: Total (excl. milk) | AS22: =SUM(AS11:AS18) -> 6903.5 | AT22: =SUM(AT11:AT18) -> 1714 | AU22: =SUM(AU11:AU18) -> 2750 | AV22: =SUM(AV11:AV18) -> 3860.0841 | AW22: =SUM(AW11:AW18) -> 972.80544 | AX22: =SUM(AX11:AX18) -> 1514.8824 | AY22: =SUM(AY11:AY18) -> 1571.3251 | AZ22: =SUM(AZ11:AZ18) -> 2309.9042 | ... BG22: =SUM(BG11:BG18) -> 1571.3251
B23: # Mjölkkor (2018) | D23: 103131 | E23: 40386 | F23: 21929 | L23: SCB Feed industry statistics 2022
B24: # Dikor (2018) | D24: 87632 | E24: 21961 | F24: 15238 | Q24: SWE | R24: IMP | S24: TOT | T24: Dairy | V24: Beef | X24: share | Z24: Einarsson et al 2022 SM2
P25: DM | T25: DM | U25: % of DM | V25: DM | W25: % of DM | X25: to dairy | Z25: ('Feed distribution') | AC25: Dairy | AD25: share | AE25: Beef | AF25: share | AG25: Total | AH25: to dairy
B26: Einarsson et al 2022 | D26: Feeds via feed industry | L26: wheat | P26: 0.86 | Q26: 84300.8 | R26: 2279 | S26: =SUM(Q26:R26) -> 86579.8 | T26: =S26*X26*P26 -> 46200.229 | U26: =T26/SUM(T$26:T$56) -> 0.077600984 | V26: =S26*(1-X26)*P26 -> 28258.399 | W26: =V26/SUM(V$26:V$56) -> 0.25895168 | X26: =$AH$27 -> 0.62048187 | Z26: Cereals (on-farm) | AC26: =SUM(AC27:AC30) -> 332330 | AD26: =AC26/(AC$26+AC$32) -> 0.86121145 | AE26: =SUM(AE27:AE30) -> 203269.85 | AF26: =AE26/(AE$26+AE$32) -> 0.98055414 | AG26: =SUM(AG27:AG30) -> 535599.85
B27: SM2 | E27: DM | G27: DM | I27: share | J27: Share | L27: barley | P27: 0.86 | Q27: 92367.8 | R27: 1785 | S27: =SUM(Q27:R27) -> 94152.8 | T27: =S27*X27*P27 -> 50241.291 | U27: =T27/SUM(T$26:T$56) -> 0.084388621 | V27: =S27*(1-X27)*P27 -> 30730.117 | W27: =V27/SUM(V$26:V$56) -> 0.28160178 | X27: =$AH$27 -> 0.62048187 | Z27: Wheat | AC27: =AG27*AH27 -> 77812.622 | AD27: =AC27/SUM(AC$27:AC$30) -> 0.23414264 | AE27: =AG27-AC27 -> 47594.139 | AF27: =AE27/SUM(AE$27:AE$30) -> 0.23414264 | AG27: 125406.76 | AH27: 0.62048187
B28: Feed name | C28: DM | D28: Dairy | E28: share | F28: Beef | G28: share | H28: Total | I28: to dairy | J28: import | L28: oats | P28: 0.86 | Q28: 31831.5 | R28: 0 | S28: =SUM(Q28:R28) -> 31831.5 | T28: =S28*X28*P28 -> 16985.747 | U28: =T28/SUM(T$26:T$56) -> 0.028530393 | V28: =S28*(1-X28)*P28 -> 10389.343 | W28: =V28/SUM(V$26:V$56) -> 0.09520489 | X28: =$AH$27 -> 0.62048187 | Z28: Triticale | AC28: =AG28*AH28 -> 61792.55 | AD28: =AC28/SUM(AC$27:AC$30) -> 0.18593732 | AE28: =AG28-AC28 -> 37795.452 | AF28: =AE28/SUM(AE$27:AE$30) -> 0.18593732 | AG28: 99588.001 | AH28: 0.62048187
B29: Grain maize | C29: 0.86 | D29: =H29*I29 -> 8000.2143 | E29: =D29*$C29/SUMPRODUCT(D$29:D$49,$C$29:$C$49) -> 0.010523812 | F29: =H29-D29 -> 631.31904 | G29: =F29*$C29/SUMPRODUCT(F$29:F$49,$C$29:$C$49) -> 0.0046480203 | H29: 8631.5333 | I29: 0.92685899 | J29: 0.27270318 | L29: triticale | P29: 0.86 | Q29: 11430.7 | R29: 0 | S29: =SUM(Q29:R29) -> 11430.7 | T29: =S29*X29*P29 -> 6099.5863 | U29: =T29/SUM(T$26:T$56) -> 0.010245272 | V29: =S29*(1-X29)*P29 -> 3730.8157 | W29: =V29/SUM(V$26:V$56) -> 0.034188101 | X29: =$AH$27 -> 0.62048187 | Z29: Barley | AC29: =AG29*AH29 -> 159717.73 | AD29: =AC29/SUM(AC$27:AC$30) -> 0.48059978 | AE29: =AG29-AC29 -> 97691.447 | AF29: =AE29/SUM(AE$27:AE$30) -> 0.48059978 | AG29: 257409.17 | AH29: 0.62048187
B30: Wheat | C30: 0.86 | D30: =H30*I30 -> 38739.786 | E30: =D30*C30/SUMPRODUCT(D$29:D$49,$C$29:$C$49) -> 0.050959914 | F30: =H30-D30 -> 23695.214 | G30: =F30*$C30/SUMPRODUCT(F$29:F$49,$C$29:$C$49) -> 0.17445353 | H30: 62435 | I30: 0.62048187 | J30: 0 | L30: rye | P30: 0.86 | Q30: 707 | R30: 0 | S30: =SUM(Q30:R30) -> 707 | T30: =S30*X30*P30 -> 377.26539 | U30: =T30/SUM(T$26:T$56) -> 0.00063368009 | V30: =S30*(1-X30)*P30 -> 230.75461 | W30: =V30/SUM(V$26:V$56) -> 0.0021145676 | X30: =$AH$27 -> 0.62048187 | Z30: Oats | AC30: =AG30*AH30 -> 33007.101 | AD30: =AC30/SUM(AC$27:AC$30) -> 0.099320257 | AE30: =AG30-AC30 -> 20188.814 | AF30: =AE30/SUM(AE$27:AE$30) -> 0.099320257 | AG30: 53195.915 | AH30: 0.62048187
B31: Triticale | C31: 0.86 | D31: =H31*I31 -> 21059.031 | E31: =D31*C31/SUMPRODUCT(D$29:D$49,$C$29:$C$49) -> 0.027701919 | F31: =H31-D31 -> 12880.769 | G31: =F31*$C31/SUMPRODUCT(F$29:F$49,$C$29:$C$49) -> 0.094833315 | H31: 33939.8 | I31: 0.62048187 | J31: 0 | L31: maize | P31: 0.86 | Q31: 16116.5 | R31: 537 | S31: =SUM(Q31:R31) -> 16653.5 | T31: =S31*X31*P31 -> 13319.469 | U31: =T31/SUM(T$26:T$56) -> 0.022372268 | V31: =S31*(1-X31)*P31 -> 1002.5407 | W31: =V31/SUM(V$26:V$56) -> 0.0091869889 | X31: =$AH$33 -> 0.93
B32: Barley | C32: 0.86 | D32: =H32*I32 -> 68413.876 | E32: =D32*C32/SUMPRODUCT(D$29:D$49,$C$29:$C$49) -> 0.089994438 | F32: =H32-D32 -> 41845.39 | G32: =F32*$C32/SUMPRODUCT(F$29:F$49,$C$29:$C$49) -> 0.3080823 | H32: 110259.27 | I32: 0.62048187 | J32: 0 | L32: peas | P32: 0.85 | Q32: 2047.3 | R32: 586 | S32: =SUM(Q32:R32) -> 2633.3 | T32: =S32*X32*P32 -> 2081.6237 | U32: =T32/SUM(T$26:T$56) -> 0.0034964338 | V32: =S32*(1-X32)*P32 -> 156.68135 | W32: =V32/SUM(V$26:V$56) -> 0.0014357819 | X32: =$AH$33 -> 0.93 | Z32: Grain legumes (on-farm) | AC32: =SUM(AC33:AC34) -> 53556.646 | AD32: =AC32/(AC$26+AC$32) -> 0.13878855 | AE32: =SUM(AE33:AE34) -> 4031.1454 | AF32: =AE32/(AE$26+AE$32) -> 0.019445856 | AG32: =SUM(AG33:AG34) -> 57587.792
B33: Oats | C33: 0.86 | D33: =H33*I33 -> 14138.341 | E33: =D33*C33/SUMPRODUCT(D$29:D$49,$C$29:$C$49) -> 0.018598158 | F33: =H33-D33 -> 8647.7253 | G33: =F33*$C33/SUMPRODUCT(F$29:F$49,$C$29:$C$49) -> 0.063667972 | H33: 22786.067 | I33: 0.62048187 | J33: 0 | L33: broad beans | P33: 0.85 | Q33: 9008.8 | R33: 40 | S33: =SUM(Q33:R33) -> 9048.8 | T33: =S33*X33*P33 -> 7153.0764 | U33: =T33/SUM(T$26:T$56) -> 0.012014784 | V33: =S33*(1-X33)*P33 -> 538.4036 | W33: =V33/SUM(V$26:V$56) -> 0.0049337726 | X33: =$AH$33 -> 0.93 | Z33: Peas | AC33: =AG33*AH33 -> 27475.937 | AD33: =AC33/SUM(AC$33:AC$34) -> 0.51302572 | AE33: =AG33-AC33 -> 2068.0813 | AF33: =AE33/SUM(AE$33:AE$34) -> 0.51302572 | AG33: 29544.018 | AH33: 0.93
B34: Peas | C34: 0.85 | D34: =H34*I34 -> 4095.4809 | E34: =D34*C34/SUMPRODUCT(D$29:D$49,$C$29:$C$49) -> 0.005324721 | F34: =H34-D34 -> 323.18573 | G34: =F34*$C34/SUMPRODUCT(F$29:F$49,$C$29:$C$49) -> 0.0023517534 | H34: 4418.6667 | I34: 0.92685899 | J34: 0 | L34: rapeseed | P34: 0.91 | Q34: 40016.7 | R34: 93785 | S34: =SUM(Q34:R34) -> 133801.7 | T34: =S34*X34*P34 -> 113236.38 | U34: =T34/SUM(T$26:T$56) -> 0.19019937 | V34: =S34*(1-X34)*P34 -> 8523.1683 | W34: =V34/SUM(V$26:V$56) -> 0.078103814 | X34: =$AH$33 -> 0.93 | Z34: Faba beans | AC34: =AG34*AH34 -> 26080.709 | AD34: =AC34/SUM(AC$33:AC$34) -> 0.48697428 | AE34: =AG34-AC34 -> 1963.0641 | AF34: =AE34/SUM(AE$33:AE$34) -> 0.48697428 | AG34: 28043.773 | AH34: 0.93
B35: Faba beans | C35: 0.85 | D35: =H35*I35 -> 11613.018 | E35: =D35*C35/SUMPRODUCT(D$29:D$49,$C$29:$C$49) -> 0.015098613 | F35: =H35-D35 -> 916.41538 | G35: =F35*$C35/SUMPRODUCT(F$29:F$49,$C$29:$C$49) -> 0.0066685586 | H35: 12529.433 | I35: 0.92685899 | J35: 0 | L35: linseed | P35: 0.91 | Q35: 98.7 | R35: 0 | S35: =SUM(Q35:R35) -> 98.7 | T35: =S35*X35*P35 -> 83.52981 | U35: =T35/SUM(T$26:T$56) -> 0.00014030224 | V35: =S35*(1-X35)*P35 -> 6.28719 | W35: =V35/SUM(V$26:V$56) -> 5.7613965e-05 | X35: =$AH$33 -> 0.93
B36: Rapeseed, whole | C36: 0.93 | D36: =H36*I36 -> 125972.19 | E36: =D36*C36/SUMPRODUCT(D$29:D$49,$C$29:$C$49) -> 0.17919696 | F36: =H36-D36 -> 9940.8137 | G36: =F36*$C36/SUMPRODUCT(F$29:F$49,$C$29:$C$49) -> 0.079145379 | H36: 135913 | I36: 0.92685899 | J36: 0.19883912 | L36: vegetable oils | P36: 1 | Q36: 2126.8 | R36: 192 | S36: =SUM(Q36:R36) -> 2318.8 | T36: =S36*X36*P36 -> 2156.484 | U36: =T36/SUM(T$26:T$56) -> 0.0036221742 | V36: =S36*(1-X36)*P36 -> 162.316 | W36: =V36/SUM(V$26:V$56) -> 0.0014874162 | X36: =$AH$33 -> 0.93
B37: Distiller’s dried grain | C37: 0.9 | D37: =H37*I37 -> 36603.206 | E37: =D37*C37/SUMPRODUCT(D$29:D$49,$C$29:$C$49) -> 0.050388875 | F37: =H37-D37 -> 2888.4603 | G37: =F37*$C37/SUMPRODUCT(F$29:F$49,$C$29:$C$49) -> 0.022255102 | H37: 39491.667 | I37: 0.92685899 | J37: 0 | L37: soybeans | P37: 0.87 | Q37: 0 | R37: 2604.6 | S37: =SUM(Q37:R37) -> 2604.6 | T37: =S37*X37*P37 -> 2107.3819 | U37: =T37/SUM(T$26:T$56) -> 0.003539699 | V37: =S37*(1-X37)*P37 -> 158.62014 | W37: =V37/SUM(V$26:V$56) -> 0.0014535484 | X37: =$AH$33 -> 0.93
B38: Bran, middlings, etc. | C38: 0.87 | D38: =H38*I38 -> 90204.111 | E38: =D38*C38/SUMPRODUCT(D$29:D$49,$C$29:$C$49) -> 0.12003796 | F38: =H38-D38 -> 7118.2559 | G38: =F38*$C38/SUMPRODUCT(F$29:F$49,$C$29:$C$49) -> 0.053016802 | H38: 97322.367 | I38: 0.92685899 | J38: 0 | L38: soybean meal | P38: 0.875 | Q38: 6226.3 | R38: 17429.8 | S38: =SUM(Q38:R38) -> 23656.1 | T38: =S38*X38*P38 -> 19250.151 | U38: =T38/SUM(T$26:T$56) -> 0.032333837 | V38: =S38*(1-X38)*P38 -> 1448.9361 | W38: =V38/SUM(V$26:V$56) -> 0.013277626 | X38: =$AH$33 -> 0.93
B39: Palm kernel expeller | C39: 0.91 | D39: =H39*I39 -> 29382.975 | E39: =D39*C39/SUMPRODUCT(D$29:D$49,$C$29:$C$49) -> 0.040898763 | F39: =H39-D39 -> 2318.6918 | G39: =F39*$C39/SUMPRODUCT(F$29:F$49,$C$29:$C$49) -> 0.018063633 | H39: 31701.667 | I39: 0.92685899 | J39: 1 | L39: soybean protein concentrate | P39: 0.87 | Q39: 0 | R39: 0 | S39: =SUM(Q39:R39) -> 0 | T39: =S39*X39*P39 -> 0 | U39: =T39/SUM(T$26:T$56) -> 0 | V39: =S39*(1-X39)*P39 -> 0 | W39: =V39/SUM(V$26:V$56) -> 0 | X39: =$AH$33 -> 0.93
B40: Soybeans, whole | C40: 0.87 | D40: =H40*I40 -> 15543.487 | E40: =D40*C40/SUMPRODUCT(D$29:D$49,$C$29:$C$49) -> 0.020684295 | F40: =H40-D40 -> 1226.5796 | G40: =F40*$C40/SUMPRODUCT(F$29:F$49,$C$29:$C$49) -> 0.0091355702 | H40: 16770.067 | I40: 0.92685899 | J40: 1 | L40: rapeseed meal | P40: 0.895 | Q40: 143785.1 | R40: 34843 | S40: =SUM(Q40:R40) -> 178628.1 | T40: =S40*X40*P40 -> 148681.1 | U40: =T40/SUM(T$26:T$56) -> 0.24973468 | V40: =S40*(1-X40)*P40 -> 11191.05 | W40: =V40/SUM(V$26:V$56) -> 0.1025515 | X40: =$AH$33 -> 0.93
B41: Soybean meal via feed industry | C41: 0.87 | D41: =H41*I41 -> 39489.569 | E41: =D41*C41/SUMPRODUCT(D$29:D$49,$C$29:$C$49) -> 0.052550235 | F41: =H41-D41 -> 3116.2311 | G41: =F41*$C41/SUMPRODUCT(F$29:F$49,$C$29:$C$49) -> 0.023209703 | H41: 42605.8 | I41: 0.92685899 | J41: 1 | L41: sunflower seed meal | P41: 0.91 | Q41: 1937.9 | R41: 489 | S41: =SUM(Q41:R41) -> 2426.9 | T41: =S41*X41*P41 -> 2053.8855 | U41: =T41/SUM(T$26:T$56) -> 0.0034498429 | V41: =S41*(1-X41)*P41 -> 154.59353 | W41: =V41/SUM(V$26:V$56) -> 0.0014166498 | X41: =$AH$33 -> 0.93
...

Sheet G&D slakt
A1: Djur | B1: Ras | C1: År | D1: Antal djur | E1: Slaktvikt (kg) | F1: Fettgrupp | G1: Formklass | H1: Ålder (månader) | I1: Slaktvikt*Antal | J1: Ålder*Antal
A2: ko | B2: 01 SRB | C2: 2016 | D2: 30638 | E2: 302.7 | F2: 7.7 | G2: 4 | H2: 68.6 | I2: =D2*E2 -> 9274122.6 | J2: =D2*H2 -> 2101766.8
A3: ko | B3: 01 SRB | C3: 2017 | D3: 26251 | E3: 308.5 | F3: 7.8 | G3: 4.1 | H3: 68.9 | I3: =D3*E3 -> 8098433.5 | J3: =D3*H3 -> 1808693.9
A4: ko | B4: 01 SRB | C4: 2018 | D4: 26489 | E4: 306.2 | F4: 7.5 | G4: 4 | H4: 69.3 | I4: =D4*E4 -> 8110931.8 | J4: =D4*H4 -> 1835687.7
A5: ko | B5: 01 SRB | C5: 2019 | D5: 25859 | E5: 310.4 | F5: 7.6 | G5: 4.1 | H5: 70.1 | I5: =D5*E5 -> 8026633.6 | J5: =D5*H5 -> 1812715.9
A6: ko | B6: 01 SRB | C6: 2020 | D6: 23718 | E6: 311.7 | F6: 7.4 | G6: 4 | H6: 71.6 | I6: =D6*E6 -> 7392900.6 | J6: =D6*H6 -> 1698208.8
A7: ko | B7: 01 SRB | C7: 2021 | D7: 21589 | E7: 313.4 | F7: 7.3 | G7: 4 | H7: 72.9 | I7: =D7*E7 -> 6765992.6 | J7: =D7*H7 -> 1573838.1
A8: ko | B8: 02 SLB | C8: 2016 | D8: 41922 | E8: 310.8 | F8: 7 | G8: 3.4 | H8: 69.2 | I8: =D8*E8 -> 13029358 | J8: =D8*H8 -> 2901002.4
A9: ko | B9: 02 SLB | C9: 2017 | D9: 38032 | E9: 316.9 | F9: 7.2 | G9: 3.5 | H9: 68.9 | I9: =D9*E9 -> 12052341 | J9: =D9*H9 -> 2620404.8
A10: ko | B10: 02 SLB | C10: 2018 | D10: 40654 | E10: 317 | F10: 7 | G10: 3.4 | H10: 69.4 | I10: =D10*E10 -> 12887318 | J10: =D10*H10 -> 2821387.6
A11: ko | B11: 02 SLB | C11: 2019 | D11: 40784 | E11: 321.4 | F11: 7.1 | G11: 3.5 | H11: 70.2 | I11: =D11*E11 -> 13107978 | J11: =D11*H11 -> 2863036.8
A12: ko | B12: 02 SLB | C12: 2020 | D12: 40218 | E12: 322.6 | F12: 7 | G12: 3.4 | H12: 71.6 | I12: =D12*E12 -> 12974327 | J12: =D12*H12 -> 2879608.8
A13: ko | B13: 02 SLB | C13: 2021 | D13: 38776 | E13: 324.9 | F13: 6.9 | G13: 3.4 | H13: 73.2 | I13: =D13*E13 -> 12598322 | J13: =D13*H13 -> 2838403.2
... A421: mellankalv | B421: 99 Korsning/övriga raser | C421: 2021 | D421: 1961 | E421: 164.3 | F421: 5.6 | G421: 5.5 | H421: 14.1 | I421: =D421*E421 -> 322192.3 | J421: =D421*H421 -> 27650.1

Sheet G&D slakt (ny)
A1: Djur | B1: Ras | C1: År | D1: Antal djur | E1: Slaktvikt (kg) | F1: Fettgrupp | G1: Formklass | H1: Ålder (månader) | I1: Slaktvikt*Antal | J1: Ålder*Antal
A2: ko | B2: 01 SRB | C2: 2019 | D2: 25859 | E2: 310.4 | F2: 7.6 | G2: 4.1 | H2: 70.1 | I2: =D2*E2 -> 8026633.6 | J2: =D2*H2 -> 1812715.9
A3: ko | B3: 02 SLB | C3: 2019 | D3: 40784 | E3: 321.4 | F3: 7.1 | G3: 3.5 | H3: 70.2 | I3: =D3*E3 -> 13107978 | J3: =D3*H3 -> 2863036.8
A4: ko | B4: 08 Hereford | C4: 2019 | D4: 4427 | E4: 348.6 | F4: 9.9 | G4: 5.8 | H4: 91.1 | I4: =D4*E4 -> 1543252.2 | J4: =D4*H4 -> 403299.7
A5: ko | B5: 09 Charolais | C5: 2019 | D5: 3426 | E5: 387.3 | F5: 8.1 | G5: 6.9 | H5: 94.6 | I5: =D5*E5 -> 1326889.8 | J5: =D5*H5 -> 324099.6
A6: ko | B6: 11 Aberdeen Angus | C6: 2019 | D6: 1352 | E6: 348.2 | F6: 10.1 | G6: 6.1 | H6: 87.3 | I6: =D6*E6 -> 470766.4 | J6: =D6*H6 -> 118029.6
A7: ko | B7: 12 Limousin | C7: 2019 | D7: 507 | E7: 365.3 | F7: 7.9 | G7: 7.7 | H7: 92.1 | I7: =D7*E7 -> 185207.1 | J7: =D7*H7 -> 46694.7
A8: ko | B8: 14 Simmental | C8: 2019 | D8: 2584 | E8: 359.2 | F8: 7.5 | G8: 6.3 | H8: 87.9 | I8: =D8*E8 -> 928172.8 | J8: =D8*H8 -> 227133.6
A9: ko | B9: 16 Highland Cattle | C9: 2019 | D9: 408 | E9: 224.2 | F9: 7.3 | G9: 4.3 | H9: 105.8 | I9: =D9*E9 -> 91473.6 | J9: =D9*H9 -> 43166.4
A10: ko | B10: 18 Blonde D´Aquitaine | C10: 2019 | D10: 162 | E10: 402.6 | F10: 7.1 | G10: 7.7 | H10: 105.8 | I10: =D10*E10 -> 65221.2 | J10: =D10*H10 -> 17139.6
A11: ko | B11: 99 Korsning/övriga raser | C11: 2019 | D11: 21397 | E11: 338.8 | F11: 8.2 | G11: 5.5 | H11: 86.2 | I11: =D11*E11 -> 7249303.6 | J11: =D11*H11 -> 1844421.4
A12: kviga | B12: 01 SRB | C12: 2019 | D12: 5421 | E12: 297.5 | F12: 8.3 | G12: 5.1 | H12: 33.8 | I12: =D12*E12 -> 1612747.5 | J12: =D12*H12 -> 183229.8
A13: kviga | B13: 02 SLB | C13: 2019 | D13: 8276 | E13: 299.8 | F13: 8.1 | G13: 4.4 | H13: 34.4 | I13: =D13*E13 -> 2481144.8 | J13: =D13*H13 -> 284694.4
... A61: yngre tjur | B61: 99 Korsning/övriga raser | C61: 2019 | D61: 6424 | E61: 361.6 | F61: 5.8 | G61: 6.7 | H61: 29.6 | I61: =D61*E61 -> 2322918.4 | J61: =D61*H61 -> 190150.4
A62: tjur | B62: 01 SRB | C62: 2019
A63: tjur | B63: 02 SLB | C63: 2019
A64: tjur | B64: 08 Hereford | C64: 2019
A65: tjur | B65: 09 Charolais | C65: 2019
A66: tjur | B66: 11 Aberdeen Angus | C66: 2019
A67: tjur | B67: 12 Limousin | C67: 2019
A68: tjur | B68: 14 Simmental | C68: 2019
A69: tjur | B69: 16 Highland Cattle | C69: 2019
A70: tjur | B70: 18 Blonde D´Aquitaine | C70: 2019
A71: tjur | B71: 99 Korsning/övriga raser | C71: 2019
A72: mellankalv | B72: 01 SRB | C72: 2019 | D72: 2526 | E72: 169.6 | F72: 5.5 | G72: 4.9 | H72: 11.2 | I72: =D72*E72 -> 428409.6 | J72: =D72*H72 -> 28291.2
A73: mellankalv | B73: 02 SLB | C73: 2019 | D73: 7329 | E73: 169.1 | F73: 5 | G73: 4.4 | H73: 12.5 | I73: =D73*E73 -> 1239333.9 | J73: =D73*H73 -> 91612.5
A74: mellankalv | B74: 08 Hereford | C74: 2019 | D74: 411 | E74: 158.8 | F74: 6.2 | G74: 5.4 | H74: 9.5 | I74: =D74*E74 -> 65266.8 | J74: =D74*H74 -> 3904.5
A75: mellankalv | B75: 09 Charolais | C75: 2019 | D75: 109 | E75: 169.1 | F75: 5.8 | G75: 6.3 | H75: 11 | I75: =D75*E75 -> 18431.9 | J75: =D75*H75 -> 1199
A76: mellankalv | B76: 11 Aberdeen Angus | C76: 2019 | D76: 281 | E76: 134.9 | F76: 5.5 | G76: 5.7 | H76: 12.7 | I76: =D76*E76 -> 37906.9 | J76: =D76*H76 -> 3568.7
A77: mellankalv | B77: 12 Limousin | C77: 2019 | D77: 69 | E77: 163 | F77: 4.9 | G77: 8 | H77: 11.1 | I77: =D77*E77 -> 11247 | J77: =D77*H77 -> 765.9
A78: mellankalv | B78: 14 Simmental | C78: 2019 | D78: 136 | E78: 160.6 | F78: 4.7 | G78: 5.4 | H78: 9.5 | I78: =D78*E78 -> 21841.6 | J78: =D78*H78 -> 1292
A79: mellankalv | B79: 16 Highland Cattle | C79: 2019 | D79: 76 | E79: 95.3 | F79: 4.4 | G79: 3.8 | H79: 11 | I79: =D79*E79 -> 7242.8 | J79: =D79*H79 -> 836
A80: mellankalv | B80: 18 Blonde D´Aquitaine | C80: 2019 | D80: 36 | E80: 210 | F80: 4.3 | G80: 9.9 | H80: 8 | I80: =D80*E80 -> 7560 | J80: =D80*H80 -> 288
A81: mellankalv | B81: 99 Korsning/övriga raser | C81: 2019 | D81: 2754 | E81: 157.3 | F81: 5.5 | G81: 5.4 | H81: 10.8 | I81: =D81*E81 -> 433204.2 | J81: =D81*H81 -> 29743.2
A82: ko | B82: 11 Aberdeen Angus | C82: 2020 | D82: 1392 | E82: 348.4 | F82: 9.8 | G82: 6 | H82: 84.7 | I82: =D82*E82 -> 484972.8 | J82: =D82*H82 -> 117902.4
A83: ko | B83: 18 Blonde D´Aquitaine | C83: 2020 | D83: 127 | E83: 405.9 | F83: 6.7 | G83: 7.8 | H83: 107.8 | I83: =D83*E83 -> 51549.3 | J83: =D83*H83 -> 13690.6
... A241: mellankalv | B241: 01 SRB | C241: 2021 | D241: 2294 | E241: 171.7 | F241: 5.5 | G241: 5.1 | H241: 9.7 | I241: =D241*E241 -> 393879.8 | J241: =D241*H241 -> 22251.8

Sheet G&D sammanställning
A2: Medel 2016-2020
B3: Slaktvikt (kg) | H3: Ålder (mån) | N3: Antal | T3: Andel av slaktade ungdjur (%)
B4: Mjölkras | C4: Köttras | D4: Korsning/övriga raser | E4: Kött+korsn./övr. | F4: Totalt | H4: Mjölkras | I4: Köttras | J4: Korsning/övriga raser | K4: Kött+korsn./övr. | L4: Totalt | N4: Mjölkras | O4: Köttras | P4: Korsning/övriga raser | Q4: Kött+korsn./övr. | R4: Totalt | T4: Mjölkras | U4: Köttras | V4: Korsning/övriga raser | W4: Kött+korsn./övr. | X4: Totalt
A5: Ko, tot | B5: =GETPIVOTDATA("Sum of Slaktvikt*Antal",'G&D sammanställning'!$B$21,"Djur2",$A5,"Ras2",B$4)/GETPIVOTDATA("Sum of Antal djur",'G&D sammanställning'!$B$21,"Djur2",$A5,"Ras2",B$4) -> 311.47282 | C5: =GETPIVOTDATA("Sum of Slaktvikt*Antal",'G&D sammanställning'!$B$21,"Djur2",$A5,"Ras2",C$4)/GETPIVOTDATA("Sum of Antal djur",'G&D sammanställning'!$B$21,"Djur2",$A5,"Ras2",C$4) -> 352.69439 | D5: =GETPIVOTDATA("Sum of Slaktvikt*Antal",'G&D sammanställning'!$B$21,"Djur2",$A5,"Ras2",D$4)/GETPIVOTDATA("Sum of Antal djur",'G&D sammanställning'!$B$21,"Djur2",$A5,"Ras2",D$4) -> 333.97561 | E5: =(C5*$O5+D5*$P5)/SUM($O5,$P5) -> 340.75348 | F5: =(B5*$N5+C5*$O5+D5*$P5)/SUM($N5:$P5) -> 321.58946 | H5: =GETPIVOTDATA("Sum of Ålder*Antal",'G&D sammanställning'!$B$21,"Djur2",$A5,"Ras2",H$4)/GETPIVOTDATA("Sum of Antal djur",'G&D sammanställning'!$B$21,"Djur2",$A5,"Ras2",H$4) -> 61.987433 | I5: =GETPIVOTDATA("Sum of Ålder*Antal",'G&D sammanställning'!$B$21,"Djur2",$A5,"Ras2",I$4)/GETPIVOTDATA("Sum of Antal djur",'G&D sammanställning'!$B$21,"Djur2",$A5,"Ras2",I$4) -> 78.744656 | J5: =GETPIVOTDATA("Sum of Ålder*Antal",'G&D sammanställning'!$B$21,"Djur2",$A5,"Ras2",J$4)/GETPIVOTDATA("Sum of Antal djur",'G&D sammanställning'!$B$21,"Djur2",$A5,"Ras2",J$4) -> 72.938268 | K5: =(I5*$O5+J5*$P5)/SUM($O5,$P5) -> 75.040699 | L5: =(H5*$N5+I5*$O5+J5*$P5)/SUM($N5:$P5) -> 66.497411 | N5: =GETPIVOTDATA("Sum of Antal djur",'G&D sammanställning'!$B$21,"Djur2",$A5,"Ras2",N$4)/5 -> 51163 | O5: =GETPIVOTDATA("Sum of Antal djur",'G&D sammanställning'!$B$21,"Djur2",$A5,"Ras2",O$4)/5 -> 9779.6 | P5: =GETPIVOTDATA("Sum of Antal djur",'G&D sammanställning'!$B$21,"Djur2",$A5,"Ras2",P$4)/5 -> 17229.2 | Q5: =SUM(O5,P5) -> 27008.8 | R5: =SUM(N5,O5,P5) -> 78171.8
A6: ko | B6: =GETPIVOTDATA("Sum of Slaktvikt*Antal",'G&D sammanställning'!$B$21,"Djur",$A6,"Ras2",B$4)/GETPIVOTDATA("Sum of Antal djur",'G&D sammanställning'!$B$21,"Djur",$A6,"Ras2",B$4) -> 318.90839 | C6: =GETPIVOTDATA("Sum of Slaktvikt*Antal",'G&D sammanställning'!$B$21,"Djur",$A6,"Ras2",C$4)/GETPIVOTDATA("Sum of Antal djur",'G&D sammanställning'!$B$21,"Djur",$A6,"Ras2",C$4) -> 363.27389 | D6: =GETPIVOTDATA("Sum of Slaktvikt*Antal",'G&D sammanställning'!$B$21,"Djur",$A6,"Ras2",D$4)/GETPIVOTDATA("Sum of Antal djur",'G&D sammanställning'!$B$21,"Djur",$A6,"Ras2",D$4) -> 343.5916 | E6: =(C6*$O6+D6*$P6)/SUM($O6,$P6) -> 350.91759 | F6: =(B6*$N6+C6*$O6+D6*$P6)/SUM($N6:$P6) -> 329.98153 | H6: =GETPIVOTDATA("Sum of Ålder*Antal",'G&D sammanställning'!$B$21,"Djur",$A6,"Ras2",H$4)/GETPIVOTDATA("Sum of Antal djur",'G&D sammanställning'!$B$21,"Djur",$A6,"Ras2",H$4) -> 69.480359 | I6: =GETPIVOTDATA("Sum of Ålder*Antal",'G&D sammanställning'!$B$21,"Djur",$A6,"Ras2",I$4)/GETPIVOTDATA("Sum of Antal djur",'G&D sammanställning'!$B$21,"Djur",$A6,"Ras2",I$4) -> 91.338348 | J6: =GETPIVOTDATA("Sum of Ålder*Antal",'G&D sammanställning'!$B$21,"Djur",$A6,"Ras2",J$4)/GETPIVOTDATA("Sum of Antal djur",'G&D sammanställning'!$B$21,"Djur",$A6,"Ras2",J$4) -> 85.930077 | K6: =(I6*$O6+J6*$P6)/SUM($O6,$P6) -> 87.943101 | L6: =(H6*$N6+I6*$O6+J6*$P6)/SUM($N6:$P6) -> 75.867285 | N6: =GETPIVOTDATA("Sum of Antal djur",'G&D sammanställning'!$B$21,"Djur",$A6,"Ras2",N$4)/5 -> 38149.2 | O6: =GETPIVOTDATA("Sum of Antal djur",'G&D sammanställning'!$B$21,"Djur",$A6,"Ras2",O$4)/5 -> 7510.2 | P6: =GETPIVOTDATA("Sum of Antal djur",'G&D sammanställning'!$B$21,"Djur",$A6,"Ras2",P$4)/5 -> 12667 | Q6: =SUM(O6,P6) -> 20177.2 | R6: =SUM(N6,O6,P6) -> 58326.4
A7: ungko | B7: =GETPIVOTDATA("Sum of Slaktvikt*Antal",'G&D sammanställning'!$B$21,"Djur",$A7,"Ras2",B$4)/GETPIVOTDATA("Sum of Antal djur",'G&D sammanställning'!$B$21,"Djur",$A7,"Ras2",B$4) -> 289.67587 | C7: =GETPIVOTDATA("Sum of Slaktvikt*Antal",'G&D sammanställning'!$B$21,"Djur",$A7,"Ras2",C$4)/GETPIVOTDATA("Sum of Antal djur",'G&D sammanställning'!$B$21,"Djur",$A7,"Ras2",C$4) -> 317.68332 | D7: =GETPIVOTDATA("Sum of Slaktvikt*Antal",'G&D sammanställning'!$B$21,"Djur",$A7,"Ras2",D$4)/GETPIVOTDATA("Sum of Antal djur",'G&D sammanställning'!$B$21,"Djur",$A7,"Ras2",D$4) -> 307.27671 | E7: =(C7*$O7+D7*$P7)/SUM($O7,$P7) -> 310.7337 | F7: =(B7*$N7+C7*$O7+D7*$P7)/SUM($N7:$P7) -> 296.92484 | H7: =GETPIVOTDATA("Sum of Ålder*Antal",'G&D sammanställning'!$B$21,"Djur",$A7,"Ras2",H$4)/GETPIVOTDATA("Sum of Antal djur",'G&D sammanställning'!$B$21,"Djur",$A7,"Ras2",H$4) -> 40.022358 | I7: =GETPIVOTDATA("Sum of Ålder*Antal",'G&D sammanställning'!$B$21,"Djur",$A7,"Ras2",I$4)/GETPIVOTDATA("Sum of Antal djur",'G&D sammanställning'!$B$21,"Djur",$A7,"Ras2",I$4) -> 37.067939 | J7: =GETPIVOTDATA("Sum of Ålder*Antal",'G&D sammanställning'!$B$21,"Djur",$A7,"Ras2",J$4)/GETPIVOTDATA("Sum of Antal djur",'G&D sammanställning'!$B$21,"Djur",$A7,"Ras2",J$4) -> 36.866363 | K7: =(I7*$O7+J7*$P7)/SUM($O7,$P7) -> 36.933325 | L7: =(H7*$N7+I7*$O7+J7*$P7)/SUM($N7:$P7) -> 38.958986 | N7: =GETPIVOTDATA("Sum of Antal djur",'G&D sammanställning'!$B$21,"Djur",$A7,"Ras2",N$4)/5 -> 13013.8 | O7: =GETPIVOTDATA("Sum of Antal djur",'G&D sammanställning'!$B$21,"Djur",$A7,"Ras2",O$4)/5 -> 2269.4 | P7: =GETPIVOTDATA("Sum of Antal djur",'G&D sammanställning'!$B$21,"Djur",$A7,"Ras2",P$4)/5 -> 4562.2 | Q7: =SUM(O7,P7) -> 6831.6 | R7: =SUM(N7,O7,P7) -> 19845.4
A8: kviga | B8: =GETPIVOTDATA("Sum of Slaktvikt*Antal",'G&D sammanställning'!$B$21,"Djur",$A8,"Ras2",B$4)/GETPIVOTDATA("Sum of Antal djur",'G&D sammanställning'!$B$21,"Djur",$A8,"Ras2",B$4) -> 300.08773 | C8: =GETPIVOTDATA("Sum of Slaktvikt*Antal",'G&D sammanställning'!$B$21,"Djur",$A8,"Ras2",C$4)/GETPIVOTDATA("Sum of Antal djur",'G&D sammanställning'!$B$21,"Djur",$A8,"Ras2",C$4) -> 309.18813 | D8: =GETPIVOTDATA("Sum of Slaktvikt*Antal",'G&D sammanställning'!$B$21,"Djur",$A8,"Ras2",D$4)/GETPIVOTDATA("Sum of Antal djur",'G&D sammanställning'!$B$21,"Djur",$A8,"Ras2",D$4) -> 311.10278 | E8: =(C8*$O8+D8*$P8)/SUM($O8,$P8) -> 310.43926 | F8: =(B8*$N8+C8*$O8+D8*$P8)/SUM($N8:$P8) -> 308.14341 | H8: =GETPIVOTDATA("Sum of Ålder*Antal",'G&D sammanställning'!$B$21,"Djur",$A8,"Ras2",H$4)/GETPIVOTDATA("Sum of Antal djur",'G&D sammanställning'!$B$21,"Djur",$A8,"Ras2",H$4) -> 30.188105 | I8: =GETPIVOTDATA("Sum of Ålder*Antal",'G&D sammanställning'!$B$21,"Djur",$A8,"Ras2",I$4)/GETPIVOTDATA("Sum of Antal djur",'G&D sammanställning'!$B$21,"Djur",$A8,"Ras2",I$4) -> 25.943964 | J8: =GETPIVOTDATA("Sum of Ålder*Antal",'G&D sammanställning'!$B$21,"Djur",$A8,"Ras2",J$4)/GETPIVOTDATA("Sum of Antal djur",'G&D sammanställning'!$B$21,"Djur",$A8,"Ras2",J$4) -> 26.070655 | K8: =(I8*$O8+J8*$P8)/SUM($O8,$P8) -> 26.02675 | L8: =(H8*$N8+I8*$O8+J8*$P8)/SUM($N8:$P8) -> 26.949692 | N8: =GETPIVOTDATA("Sum of Antal djur",'G&D sammanställning'!$B$21,"Djur",$A8,"Ras2",N$4)/5 -> 8196.6 | O8: =GETPIVOTDATA("Sum of Antal djur",'G&D sammanställning'!$B$21,"Djur",$A8,"Ras2",O$4)/5 -> 9966.8 | P8: =GETPIVOTDATA("Sum of Antal djur",'G&D sammanställning'!$B$21,"Djur",$A8,"Ras2",P$4)/5 -> 18793.4 | Q8: =SUM(O8,P8) -> 28760.2 | R8: =SUM(N8,O8,P8) -> 36956.8 | T8: =N8/SUM(N$8:N$10,N$14)*100 -> 11.454228 | U8: =O8/SUM(O$8:O$10,O$14)*100 -> 31.202414 | V8: =P8/SUM(P$8:P$10,P$14)*100 -> 31.077546 | W8: =Q8/SUM(Q$8:Q$10,Q$14)*100 -> 31.120706 | X8: =R8/SUM(R$8:R$10,R$14)*100 -> 22.538125
A9: stut | B9: =GETPIVOTDATA("Sum of Slaktvikt*Antal",'G&D sammanställning'!$B$21,"Djur",$A9,"Ras2",B$4)/GETPIVOTDATA("Sum of Antal djur",'G&D sammanställning'!$B$21,"Djur",$A9,"Ras2",B$4) -> 328.06057 | C9: =GETPIVOTDATA("Sum of Slaktvikt*Antal",'G&D sammanställning'!$B$21,"Djur",$A9,"Ras2",C$4)/GETPIVOTDATA("Sum of Antal djur",'G&D sammanställning'!$B$21,"Djur",$A9,"Ras2",C$4) -> 332.89401 | D9: =GETPIVOTDATA("Sum of Slaktvikt*Antal",'G&D sammanställning'!$B$21,"Djur",$A9,"Ras2",D$4)/GETPIVOTDATA("Sum of Antal djur",'G&D sammanställning'!$B$21,"Djur",$A9,"Ras2",D$4) -> 337.21851 | E9: =(C9*$O9+D9*$P9)/SUM($O9,$P9) -> 335.97589 | F9: =(B9*$N9+C9*$O9+D9*$P9)/SUM($N9:$P9) -> 331.12543 | H9: =GETPIVOTDATA("Sum of Ålder*Antal",'G&D sammanställning'!$B$21,"Djur",$A9,"Ras2",H$4)/GETPIVOTDATA("Sum of Antal djur",'G&D sammanställning'!$B$21,"Djur",$A9,"Ras2",H$4) -> 29.050688 | I9: =GETPIVOTDATA("Sum of Ålder*Antal",'G&D sammanställning'!$B$21,"Djur",$A9,"Ras2",I$4)/GETPIVOTDATA("Sum of Antal djur",'G&D sammanställning'!$B$21,"Djur",$A9,"Ras2",I$4) -> 27.273573 | J9: =GETPIVOTDATA("Sum of Ålder*Antal",'G&D sammanställning'!$B$21,"Djur",$A9,"Ras2",J$4)/GETPIVOTDATA("Sum of Antal djur",'G&D sammanställning'!$B$21,"Djur",$A9,"Ras2",J$4) -> 27.672725 | K9: =(I9*$O9+J9*$P9)/SUM($O9,$P9) -> 27.558031 | L9: =(H9*$N9+I9*$O9+J9*$P9)/SUM($N9:$P9) -> 28.472721 | N9: =GETPIVOTDATA("Sum of Antal djur",'G&D sammanställning'!$B$21,"Djur",$A9,"Ras2",N$4)/5 -> 11446 | O9: =GETPIVOTDATA("Sum of Antal djur",'G&D sammanställning'!$B$21,"Djur",$A9,"Ras2",O$4)/5 -> 2078.2 | P9: =GETPIVOTDATA("Sum of Antal djur",'G&D sammanställning'!$B$21,"Djur",$A9,"Ras2",P$4)/5 -> 5154.2 | Q9: =SUM(O9,P9) -> 7232.4 | R9: =SUM(N9,O9,P9) -> 18678.4 | T9: =N9/SUM(N$8:N$10,N$14)*100 -> 15.995059 | U9: =O9/SUM(O$8:O$10,O$14)*100 -> 6.506086 | V9: =P9/SUM(P$8:P$10,P$14)*100 -> 8.5231989 | W9: =Q9/SUM(Q$8:Q$10,Q$14)*100 -> 7.8260023 | X9: =R9/SUM(R$8:R$10,R$14)*100 -> 11.391033
A10: tjur, tot | B10: =GETPIVOTDATA("Sum of Slaktvikt*Antal",'G&D sammanställning'!$B$21,"Djur2",$A10,"Ras2",B$4)/GETPIVOTDATA("Sum of Antal djur",'G&D sammanställning'!$B$21,"Djur2",$A10,"Ras2",B$4) -> 328.174 | C10: =GETPIVOTDATA("Sum of Slaktvikt*Antal",'G&D sammanställning'!$B$21,"Djur2",$A10,"Ras2",C$4)/GETPIVOTDATA("Sum of Antal djur",'G&D sammanställning'!$B$21,"Djur2",$A10,"Ras2",C$4) -> 360.78224 | D10: =GETPIVOTDATA("Sum of Slaktvikt*Antal",'G&D sammanställning'!$B$21,"Djur2",$A10,"Ras2",D$4)/GETPIVOTDATA("Sum of Antal djur",'G&D sammanställning'!$B$21,"Djur2",$A10,"Ras2",D$4) -> 358.75871 | E10: =(C10*$O10+D10*$P10)/SUM($O10,$P10) -> 359.47634 | F10: =(B10*$N10+C10*$O10+D10*$P10)/SUM($N10:$P10) -> 345.062 | H10: =GETPIVOTDATA("Sum of Ålder*Antal",'G&D sammanställning'!$B$21,"Djur2",$A10,"Ras2",H$4)/GETPIVOTDATA("Sum of Antal djur",'G&D sammanställning'!$B$21,"Djur2",$A10,"Ras2",H$4) -> 21.274162 | I10: =GETPIVOTDATA("Sum of Ålder*Antal",'G&D sammanställning'!$B$21,"Djur2",$A10,"Ras2",I$4)/GETPIVOTDATA("Sum of Antal djur",'G&D sammanställning'!$B$21,"Djur2",$A10,"Ras2",I$4) -> 19.408368 | J10: =GETPIVOTDATA("Sum of Ålder*Antal",'G&D sammanställning'!$B$21,"Djur2",$A10,"Ras2",J$4)/GETPIVOTDATA("Sum of Antal djur",'G&D sammanställning'!$B$21,"Djur2",$A10,"Ras2",J$4) -> 19.153458 | K10: =(I10*$O10+J10*$P10)/SUM($O10,$P10) -> 19.24386 | L10: =(H10*$N10+I10*$O10+J10*$P10)/SUM($N10:$P10) -> 20.178789 | N10: =GETPIVOTDATA("Sum of Antal djur",'G&D sammanställning'!$B$21,"Djur2",$A10,"Ras2",N$4)/5 -> 46440 | O10: =GETPIVOTDATA("Sum of Antal djur",'G&D sammanställning'!$B$21,"Djur2",$A10,"Ras2",O$4)/5 -> 19296 | P10: =GETPIVOTDATA("Sum of Antal djur",'G&D sammanställning'!$B$21,"Djur2",$A10,"Ras2",P$4)/5 -> 35113.6 | Q10: =SUM(O10,P10) -> 54409.6 | R10: =SUM(N10,O10,P10) -> 100849.6 | T10: =N10/SUM(N$8:N$10,N$14)*100 -> 64.896953 | U10: =O10/SUM(O$8:O$10,O$14)*100 -> 60.408736 | V10: =P10/SUM(P$8:P$10,P$14)*100 -> 58.065306 | W10: =Q10/SUM(Q$8:Q$10,Q$14)*100 -> 58.875291 | X10: =R10/SUM(R$8:R$10,R$14)*100 -> 61.503184
A11: ungtjur | B11: =GETPIVOTDATA("Sum of Slaktvikt*Antal",'G&D sammanställning'!$B$21,"Djur",$A11,"Ras2",B$4)/GETPIVOTDATA("Sum of Antal djur",'G&D sammanställning'!$B$21,"Djur",$A11,"Ras2",B$4) -> 324.47747 | C11: =GETPIVOTDATA("Sum of Slaktvikt*Antal",'G&D sammanställning'!$B$21,"Djur",$A11,"Ras2",C$4)/GETPIVOTDATA("Sum of Antal djur",'G&D sammanställning'!$B$21,"Djur",$A11,"Ras2",C$4) -> 358.65829 | D11: =GETPIVOTDATA("Sum of Slaktvikt*Antal",'G&D sammanställning'!$B$21,"Djur",$A11,"Ras2",D$4)/GETPIVOTDATA("Sum of Antal djur",'G&D sammanställning'!$B$21,"Djur",$A11,"Ras2",D$4) -> 358.24003 | E11: =(C11*$O11+D11*$P11)/SUM($O11,$P11) -> 358.38838 | F11: =(B11*$N11+C11*$O11+D11*$P11)/SUM($N11:$P11) -> 342.95455 | H11: =GETPIVOTDATA("Sum of Ålder*Antal",'G&D sammanställning'!$B$21,"Djur",$A11,"Ras2",H$4)/GETPIVOTDATA("Sum of Antal djur",'G&D sammanställning'!$B$21,"Djur",$A11,"Ras2",H$4) -> 20.1989 | I11: =GETPIVOTDATA("Sum of Ålder*Antal",'G&D sammanställning'!$B$21,"Djur",$A11,"Ras2",I$4)/GETPIVOTDATA("Sum of Antal djur",'G&D sammanställning'!$B$21,"Djur",$A11,"Ras2",I$4) -> 18.079118 | J11: =GETPIVOTDATA("Sum of Ålder*Antal",'G&D sammanställning'!$B$21,"Djur",$A11,"Ras2",J$4)/GETPIVOTDATA("Sum of Antal djur",'G&D sammanställning'!$B$21,"Djur",$A11,"Ras2",J$4) -> 17.905968 | K11: =(I11*$O11+J11*$P11)/SUM($O11,$P11) -> 17.967381 | L11: =(H11*$N11+I11*$O11+J11*$P11)/SUM($N11:$P11) -> 18.98301 | N11: =GETPIVOTDATA("Sum of Antal djur",'G&D sammanställning'!$B$21,"Djur",$A11,"Ras2",N$4)/5 -> 40499 | O11: =GETPIVOTDATA("Sum of Antal djur",'G&D sammanställning'!$B$21,"Djur",$A11,"Ras2",O$4)/5 -> 17196.6 | P11: =GETPIVOTDATA("Sum of Antal djur",'G&D sammanställning'!$B$21,"Djur",$A11,"Ras2",P$4)/5 -> 31288 | Q11: =SUM(O11,P11) -> 48484.6 | R11: =SUM(N11,O11,P11) -> 88983.6 | T11: =N11/SUM(N$8:N$10,N$14)*100 -> 56.594783 | U11: =O11/SUM(O$8:O$10,O$14)*100 -> 53.83628 | V11: =P11/SUM(P$8:P$10,P$14)*100 -> 51.739135 | W11: =Q11/SUM(Q$8:Q$10,Q$14)*100 -> 52.463994 | X11: =R11/SUM(R$8:R$10,R$14)*100 -> 54.266697
