Workbook

Sheet default
A1: f_species | B1: f_breed | C1: f_prod_system | D1: f_sub_system | E1: f_animal | F1: f_feed | G1: f_feed_group:feed | H1: f_crop | I1: f_crop_prod | J1: f_by_prod | K1: f_region | L1: parameter | M1: value | N1: unit | O1: description | P1: source
A2: Products to feeds | N2: kg product/kg DM feed | O2: need to align with DM in products and by-products
L3: feed_to_prod | M3: 0 | O3: fallback
F4: ley silage, 1st cut | I4: fodder | L4: feed_to_prod | M4: =1/INDEX('feed pars'!C$6:C$46/100,MATCH(F4,'feed pars'!B$6:B$46,0)) -> 1
F5: ley silage, regrowth | I5: fodder | L5: feed_to_prod | M5: =1/INDEX('feed pars'!C$6:C$46/100,MATCH(F5,'feed pars'!B$6:B$46,0)) -> 1
F6: other silage | I6: fodder | L6: feed_to_prod | M6: =1/INDEX('feed pars'!C$6:C$46/100,MATCH(F6,'feed pars'!B$6:B$46,0)) -> 1
F7: hay | I7: fodder | L7: feed_to_prod | M7: =1/INDEX('feed pars'!C$6:C$46/100,MATCH(F7,'feed pars'!B$6:B$46,0)) -> 1
F8: maize silage | I8: maize fodder | L8: feed_to_prod | M8: =1/INDEX('feed pars'!C$6:C$46/100,MATCH(F8,'feed pars'!B$6:B$46,0)) -> 1
F9: grazing | I9: grazing | L9: feed_to_prod | M9: =1/INDEX('feed pars'!C$6:C$46/100,MATCH(F9,'feed pars'!B$6:B$46,0)) -> 1
F10: wheat | I10: wheat | L10: feed_to_prod | M10: =1/INDEX('feed pars'!C$6:C$46/100,MATCH(F10,'feed pars'!B$6:B$46,0)) -> 1.1627907
F11: barley | I11: barley | L11: feed_to_prod | M11: =1/INDEX('feed pars'!C$6:C$46/100,MATCH(F11,'feed pars'!B$6:B$46,0)) -> 1.1627907
F12: oats | I12: oats | L12: feed_to_prod | M12: =1/INDEX('feed pars'!C$6:C$46/100,MATCH(F12,'feed pars'!B$6:B$46,0)) -> 1.1627907
F13: triticale | I13: triticale | L13: feed_to_prod | M13: =1/INDEX('feed pars'!C$6:C$46/100,MATCH(F13,'feed pars'!B$6:B$46,0)) -> 1.1627907
F14: rye | I14: rye | L14: feed_to_prod | M14: =1/INDEX('feed pars'!C$6:C$46/100,MATCH(F14,'feed pars'!B$6:B$46,0)) -> 1.1627907
F15: maize | I15: maize | L15: feed_to_prod | M15: =1/INDEX('feed pars'!C$6:C$46/100,MATCH(F15,'feed pars'!B$6:B$46,0)) -> 1.1627907
... F19: linseed | I19: linseed | L19: feed_to_prod | M19: =1/INDEX('feed pars'!C$6:C$46/100,MATCH(F19,'feed pars'!B$6:B$46,0)) -> 1.0989011
F20: vegetable oils | I20: rapeseed | L20: feed_to_prod | M20: =1/INDEX('feed pars'!C$6:C$46/100,MATCH(F20,'feed pars'!B$6:B$46,0))*1/0.38 -> 2.6315789
F21: vegetable oils | I21: rapeseed | J21: rapeseed meal | L21: feed_to_by_prod | O21: add by-prod generation calculation method!
F22: straw | J22: straw | L22: feed_to_prod | M22: =1/INDEX('feed pars'!C$6:C$46/100,MATCH(F22,'feed pars'!B$6:B$46,0)) -> 1.1764706
F23: soybeans | I23: soybeans | L23: feed_to_prod | M23: =1/INDEX('feed pars'!C$6:C$46/100,MATCH(F23,'feed pars'!B$6:B$46,0)) -> 1.1494253
F24: soybean meal | J24: soybean meal | L24: feed_to_prod | M24: =1/INDEX('feed pars'!C$6:C$46/100,MATCH(F24,'feed pars'!B$6:B$46,0)) -> 1.1428571
F25: soybean protein concentrate | J25: soybean protein concentrate | L25: feed_to_prod | M25: =1/INDEX('feed pars'!C$6:C$46/100,MATCH(F25,'feed pars'!B$6:B$46,0)) -> 1.1428571 | O25: convert to soybean meal???
F26: rapeseed meal | J26: rapeseed meal | L26: feed_to_prod | M26: =1/INDEX('feed pars'!C$6:C$46/100,MATCH(F26,'feed pars'!B$6:B$46,0)) -> 1.1173184
F27: sunflower seed meal | J27: sunflower seed meal | L27: feed_to_prod | M27: =1/INDEX('feed pars'!C$6:C$46/100,MATCH(F27,'feed pars'!B$6:B$46,0)) -> 1.0989011
F28: palm kernel expeller | J28: palm kernel expeller | L28: feed_to_prod | M28: =1/INDEX('feed pars'!C$6:C$46/100,MATCH(F28,'feed pars'!B$6:B$46,0)) -> 1.0989011
F29: luzern meal | J29: luzern meal | L29: feed_to_prod | M29: =1/INDEX('feed pars'!C$6:C$46/100,MATCH(F29,'feed pars'!B$6:B$46,0)) -> 1.1111111
F30: wheat bran | J30: wheat bran | L30: feed_to_prod | M30: =1/INDEX('feed pars'!C$6:C$46/100,MATCH(F30,'feed pars'!B$6:B$46,0)) -> 1.1494253
F31: wheat bran, fine | J31: wheat bran | L31: feed_to_prod | M31: =1/INDEX('feed pars'!C$6:C$46/100,MATCH(F31,'feed pars'!B$6:B$46,0)) -> 1.1389522
F32: oat hulls | J32: oat hulls | L32: feed_to_prod | M32: =1/INDEX('feed pars'!C$6:C$46/100,MATCH(F32,'feed pars'!B$6:B$46,0)) -> 1.1415525
F33: oat bran | J33: oat bran | L33: feed_to_prod | M33: =1/INDEX('feed pars'!C$6:C$46/100,MATCH(F33,'feed pars'!B$6:B$46,0)) -> 1.1415525
F34: rye bran | J34: rye bran | L34: feed_to_prod | M34: =1/INDEX('feed pars'!C$6:C$46/100,MATCH(F34,'feed pars'!B$6:B$46,0)) -> 1.1415525
F35: wheat distillers grain, dry | J35: wheat distillers grain | L35: feed_to_prod | M35: =1/INDEX('feed pars'!C$6:C$46/100,MATCH(F35,'feed pars'!B$6:B$46,0)) -> 1.1111111
F36: wheat distillers grain, wet | J36: wheat distillers grain | L36: feed_to_prod | M36: =M35 -> 1.1111111
F37: barley brewers grain | J37: barley brewers grain | L37: feed_to_prod | M37: =1/0.25 -> 4
F38: sugar beet molasses | J38: sugar beet molasses | L38: feed_to_prod | M38: =1/INDEX('feed pars'!C$6:C$46/100,MATCH(F38,'feed pars'!B$6:B$46,0)) -> 1.3245033
F39: sugar beet pulp | J39: sugar beet pulp | L39: feed_to_prod | M39: =1/INDEX('feed pars'!C$6:C$46/100,MATCH(F39,'feed pars'!B$6:B$46,0)) -> 1.1173184
F40: whey | J40: whey | L40: feed_to_prod | M40: =1/INDEX('feed pars'!C$6:C$46/100,MATCH(F40,'feed pars'!B$6:B$46,0)) -> 16
F41: whey powder | J41: whey | L41: feed_to_prod | M41: =M40 -> 16
F42: potatoe protein | J42: potatoe protein | L42: feed_to_prod | M42: =1/INDEX('feed pars'!C$6:C$46/100,MATCH(F42,'feed pars'!B$6:B$46,0)) -> 1.0989011
F43: potatoe offals | J43: potatoe offals | L43: feed_to_prod | M43: =1/INDEX('feed pars'!C$6:C$46/100,MATCH(F43,'feed pars'!B$6:B$46,0)) -> 4.3478261
...

Sheet references
A1: Statistics Netherlands (2012) Standardised calculation methods for animal manure and nutrients. Standard data 1990–2008
A2: Cederberg, C. & Henriksson, M. (2020). Gräsmarkernas användning i jordbruket

Sheet feed pars
B1: Source (if no other stated): | C1: http://www2.freefarm.se/fodertabell/
C3: general | K3: ruminants | T3: CP --> N | U3: =1/6.25 -> 0.16 | Z3: pigs | AI3: CP --> N | AJ3: =1/6.25 -> 0.16 | AP3: poultry
K4: col | L4: 1 | M4: calculated | N4: 2 | O4: 6 | P4: 7 | Q4: 8 | R4: 9 | S4: 11 | T4: 10 | V4: 26 | W4: 28 | Z4: col | AA4: 1 | AB4: calculated | AC4: feedipedia | AD4: 2 | AE4: 3 | AF4: 5 | AG4: 6 | AI4: 12 | AK4: 29 | AL4: 31 | AP4: col | AQ4: 1 | AR4: 2
B5: feed | C5: %DM | D5: GE, MJ/kg DM | E5: ASH, % of DM | F5: N, % of DM | G5: P, % of DM | H5: K, % of DM | I5: Source | K5: row | L5: %DM | M5: GE, MJ | N5: ME, MJ | O5: DE, MJ | P5: Prot, g | Q5: Fat, g | R5: Fiber, g | S5: NFE, g | T5: Ash, g | U5: N, % of DM | V5: P, % of DM | W5: K, % of DM | X5: Source | Z5: row | AA5: %DM | AB5: GE, MJ | AC5: DE, MJ | AD5: NEv, MJ | AE5: NEs, MJ | AF5: Prot, g | AG5: Fat, g | AH5: fiber+NFE, g | AI5: Ash, g | AJ5: N, % of DM | AK5: P, % of DM | AL5: K, % of DM | AM5: Source | AN5: Source for DE | AP5: row | AQ5: %DM | AR5: AME?, MJ | AS5: Source
B6: ley silage, 1st cut | C6: =AVERAGE(AA6,L6) -> 100 | D6: =M6 -> 17.316948 | E6: =AVERAGE(T6,AI6)/1000*100 -> 7.55 | F6: =AVERAGE(U6,AJ6) -> 2.424 | G6: =AVERAGE(V6,AK6) -> 0.28 | H6: =AVERAGE(W6,AL6) -> 2.425 | L6: 100 | M6: =( 5.7*P6+9.4*Q6+4.1*(R6+S6) ) * 0.004184 -> 17.316948 | N6: =AVERAGE('ruminants, roughage'!D21:D22) -> 11.3 | O6: =AVERAGE('ruminants, roughage'!H21:H22) -> 13.35 | P6: =AVERAGE('ruminants, roughage'!I21:I22) -> 151.5 | Q6: 20 | S6: =1000-SUM(P6:R6,T6) -> 753 | T6: =AVERAGE('ruminants, roughage'!K21:K22) -> 75.5 | U6: =P6*U$3/1000*100 -> 2.424 | V6: =AVERAGE('ruminants, roughage'!X21:X22)/1000*100 -> 0.28 | W6: =AVERAGE('ruminants, roughage'!Z21:Z22)/1000*100 -> 2.425
B7: ley silage, regrowth | C7: =AVERAGE(AA7,L7) -> 100 | D7: =M7 -> 17.150216 | E7: =AVERAGE(T7,AI7)/1000*100 -> 7.8 | F7: =AVERAGE(U7,AJ7) -> 2.128 | G7: =AVERAGE(V7,AK7) -> 0.27 | H7: =AVERAGE(W7,AL7) -> 2.34 | L7: 100 | M7: =( 5.7*P7+9.4*Q7+4.1*(R7+S7) ) * 0.004184 -> 17.150216 | N7: =AVERAGE('ruminants, roughage'!D25:D25) -> 10.1 | O7: =AVERAGE('ruminants, roughage'!H22:H23) -> 11.9 | P7: =AVERAGE('ruminants, roughage'!I25:I25) -> 133 | Q7: 20 | S7: =1000-SUM(P7:R7,T7) -> 769 | T7: =AVERAGE('ruminants, roughage'!K25:K25) -> 78 | U7: =P7*U$3/1000*100 -> 2.128 | V7: =AVERAGE('ruminants, roughage'!X25:X25)/1000*100 -> 0.27 | W7: =AVERAGE('ruminants, roughage'!Z25:Z25)/1000*100 -> 2.34
B8: other silage | C8: =AVERAGE(AA8,L8) -> 100 | D8: =M8 -> 16.789764 | E8: =AVERAGE(T8,AI8)/1000*100 -> 8.8 | F8: =AVERAGE(U8,AJ8) -> 1.544 | G8: =AVERAGE(V8,AK8) -> 0.21 | H8: =AVERAGE(W8,AL8) -> 2.35 | L8: 100 | M8: =( 5.7*P8+9.4*Q8+4.1*(R8+S8) ) * 0.004184 -> 16.789764 | N8: =(8.3+8.7)/2 -> 8.5 | O8: =AVERAGE('ruminants, roughage'!H23:H24) -> 10.75 | P8: =(91+102)/2 -> 96.5 | Q8: =(22+23)/2 -> 22.5 | S8: =1000-SUM(P8:R8,T8) -> 793 | T8: =(83+93)/2 -> 88 | U8: =P8*U$3/1000*100 -> 1.544 | V8: =(2+2.2)/2/1000*100 -> 0.21 | W8: =(20.3+26.7)/2/1000*100 -> 2.35 | X8: https://www.feedipedia.org/node/500, https://www.feedipedia.org/node/432
B9: hay | C9: =AVERAGE(AA9,L9) -> 100 | D9: =M9 -> 17.160258 | E9: =AVERAGE(T9,AI9)/1000*100 -> 6.2 | F9: =AVERAGE(U9,AJ9) -> 1.496 | G9: =AVERAGE(V9,AK9) -> 0.21 | H9: =AVERAGE(W9,AL9) -> 1.81 | L9: 100 | M9: =( 5.7*P9+9.4*Q9+4.1*(R9+S9) ) * 0.004184 -> 17.160258 | N9: =AVERAGE('ruminants, roughage'!D33:D33) -> 9.1 | O9: =AVERAGE('ruminants, roughage'!H24:H25) -> 11.8 | P9: =AVERAGE('ruminants, roughage'!I33:I33) -> 93.5 | Q9: 20 | S9: =1000-SUM(P9:R9,T9) -> 824.5 | T9: =AVERAGE('ruminants, roughage'!K33:K33) -> 62 | U9: =P9*U$3/1000*100 -> 1.496 | V9: =AVERAGE('ruminants, roughage'!X33:X33)/1000*100 -> 0.21 | W9: =AVERAGE('ruminants, roughage'!Z33:Z33)/1000*100 -> 1.81
B10: maize silage | C10: =AVERAGE(AA10,L10) -> 100 | D10: =M10 -> 17.657317 | E10: =AVERAGE(T10,AI10)/1000*100 -> 3.6 | F10: =AVERAGE(U10,AJ10) -> 1.088 | G10: =AVERAGE(V10,AK10) -> 0.17 | H10: =AVERAGE(W10,AL10) -> 1.03 | L10: 100 | M10: =( 5.7*P10+9.4*Q10+4.1*(R10+S10) ) * 0.004184 -> 17.657317 | N10: 11 | O10: =AVERAGE('ruminants, roughage'!H25:H26) -> 12.3 | P10: 68 | Q10: 30 | R10: 198 | S10: =1000-SUM(P10:R10,T10) -> 668 | T10: 36 | U10: =P10*U$3/1000*100 -> 1.088 | V10: =1.7/1000*100 -> 0.17 | W10: =10.3/1000*100 -> 1.03 | X10: https://www.feedipedia.org/node/13883
B11: grazing | C11: =AVERAGE(AA11,L11) -> 100 | D11: =M11 -> 17.411437 | E11: =AVERAGE(T11,AI11)/1000*100 -> 6.5666667 | F11: =AVERAGE(U11,AJ11) -> 2.2466667 | G11: =AVERAGE(V11,AK11) -> 0.27 | H11: =AVERAGE(W11,AL11) -> 2.34 | L11: 100 | M11: =( 5.7*P11+9.4*Q11+4.1*(R11+S11) ) * 0.004184 -> 17.411437 | N11: =AVERAGE('ruminants, roughage'!D3:D14) -> 9.9416667 | O11: =AVERAGE('ruminants, roughage'!H26:H27) -> 12.4 | P11: =AVERAGE('ruminants, roughage'!I3:I14) -> 140.41667 | Q11: 20 | S11: =1000-SUM(P11:R11,T11) -> 773.91667 | T11: =AVERAGE('ruminants, roughage'!K3:K14) -> 65.666667 | U11: =P11*U$3/1000*100 -> 2.2466667 | V11: =V7 -> 0.27 | W11: =W7 -> 2.34
B12: wheat | C12: =100-14 -> 86 | D12: =M12 -> 18.210023 | E12: =AVERAGE(T12,AI12)/1000*100 -> 1.8 | F12: =AVERAGE(U12,AJ12) -> 1.936 | G12: =AVERAGE(V12,AK12) -> 0.345 | H12: =AVERAGE(W12,AL12) -> 0.525 | I12: %DM accrding to harvest stat | K12: =MATCH($B12,ruminants!$A$3:$A$120,0) -> 112 | L12: =INDEX(ruminants!$D$3:$AH$120,$K12,L$4) -> 87 | M12: =( 5.7*P12+9.4*Q12+4.1*(R12+S12) ) * 0.004184 -> 18.210023 | N12: =INDEX(ruminants!$D$3:$AH$120,$K12,N$4) -> 14.1 | O12: =INDEX(ruminants!$D$3:$AH$120,$K12,O$4) -> 16 | P12: =INDEX(ruminants!$D$3:$AH$120,$K12,P$4) -> 121 | Q12: =INDEX(ruminants!$D$3:$AH$120,$K12,Q$4) -> 25 | R12: =INDEX(ruminants!$D$3:$AH$120,$K12,R$4) -> 30 | S12: =INDEX(ruminants!$D$3:$AH$120,$K12,S$4) -> 806 | T12: =INDEX(ruminants!$D$3:$AH$120,$K12,T$4) -> 18 | U12: =P12*U$3/1000*100 -> 1.936 | V12: =INDEX(ruminants!$D$3:$AH$120,$K12,V$4)/1000*100 -> 0.37 | W12: =INDEX(ruminants!$D$3:$AH$120,$K12,W$4)/1000*100 -> 0.47 | Z12: =MATCH($B12,pigs!$A$3:$A$60,0) -> 53 | AA12: =INDEX(pigs!$D$3:$AO$60,$Z12,AA$4) -> 87 | AB12: =( 5.7*AF12+9.4*AG12+4.1*(AH12) ) * 0.004184 -> 18.032622 | AC12: 15.9 | AD12: =INDEX(pigs!$D$3:$AO$60,$Z12,AD$4) -> 12.1 | AE12: =INDEX(pigs!$D$3:$AO$60,$Z12,AE$4) -> 12.3 | AF12: =INDEX(pigs!$D$3:$AO$60,$Z12,AF$4) -> 121 | AG12: =INDEX(pigs!$D$3:$AO$60,$Z12,AG$4) -> 17 | AH12: =1000-SUM(AF12:AG12,AI12) -> 844 | AI12: =INDEX(pigs!$D$3:$AO$60,$Z12,AI$4) -> 18 | AJ12: =AF12*AJ$3/1000*100 -> 1.936 | AK12: =INDEX(pigs!$D$3:$AO$60,$Z12,AK$4)/1000*100 -> 0.32 | AL12: =INDEX(pigs!$D$3:$AO$60,$Z12,AL$4)/1000*100 -> 0.58 | AN12: https://www.feedipedia.org/node/223 | AP12: =MATCH($B12,poultry!$A$3:$A$41,0) -> 35 | AQ12: =INDEX(poultry!$D$3:$U$41,$AP12,AQ$4) -> 87 | AR12: =INDEX(poultry!$D$3:$U$41,$AP12,AR$4)/(AQ12/100) -> 14.712644
B13: barley | C13: =100-14 -> 86 | D13: =M13 -> 18.089524 | E13: =AVERAGE(T13,AI13)/1000*100 -> 2.7 | F13: =AVERAGE(U13,AJ13) -> 1.904 | G13: =AVERAGE(V13,AK13) -> 0.375 | H13: =AVERAGE(W13,AL13) -> 0.58 | I13: %DM accrding to harvest stat | K13: =MATCH($B13,ruminants!$A$3:$A$120,0) -> 42 | L13: =INDEX(ruminants!$D$3:$AH$120,$K13,L$4) -> 87 | M13: =( 5.7*P13+9.4*Q13+4.1*(R13+S13) ) * 0.004184 -> 18.089524 | N13: =INDEX(ruminants!$D$3:$AH$120,$K13,N$4) -> 13.2 | O13: =INDEX(ruminants!$D$3:$AH$120,$K13,O$4) -> 15 | P13: =INDEX(ruminants!$D$3:$AH$120,$K13,P$4) -> 122 | Q13: =INDEX(ruminants!$D$3:$AH$120,$K13,Q$4) -> 27 | R13: =INDEX(ruminants!$D$3:$AH$120,$K13,R$4) -> 62 | S13: =INDEX(ruminants!$D$3:$AH$120,$K13,S$4) -> 761 | T13: =INDEX(ruminants!$D$3:$AH$120,$K13,T$4) -> 28 | U13: =P13*U$3/1000*100 -> 1.952 | V13: =INDEX(ruminants!$D$3:$AH$120,$K13,V$4)/1000*100 -> 0.4 | W13: =INDEX(ruminants!$D$3:$AH$120,$K13,W$4)/1000*100 -> 0.59 | Z13: =MATCH($B13,pigs!$A$3:$A$60,0) -> 13 | AA13: =INDEX(pigs!$D$3:$AO$60,$Z13,AA$4) -> 87 | AB13: =( 5.7*AF13+9.4*AG13+4.1*(AH13) ) * 0.004184 -> 17.950615 | AC13: 14.8 | AD13: =INDEX(pigs!$D$3:$AO$60,$Z13,AD$4) -> 11 | AE13: =INDEX(pigs!$D$3:$AO$60,$Z13,AE$4) -> 11.2 | AF13: =INDEX(pigs!$D$3:$AO$60,$Z13,AF$4) -> 116 | AG13: =INDEX(pigs!$D$3:$AO$60,$Z13,AG$4) -> 21 | AH13: =1000-SUM(AF13:AG13,AI13) -> 837 | AI13: =INDEX(pigs!$D$3:$AO$60,$Z13,AI$4) -> 26 | AJ13: =AF13*AJ$3/1000*100 -> 1.856 | AK13: =INDEX(pigs!$D$3:$AO$60,$Z13,AK$4)/1000*100 -> 0.35 | AL13: =INDEX(pigs!$D$3:$AO$60,$Z13,AL$4)/1000*100 -> 0.57 | AN13: https://www.feedipedia.org/node/227 | AP13: =MATCH($B13,poultry!$A$3:$A$41,0) -> 16 | AQ13: =INDEX(poultry!$D$3:$U$41,$AP13,AQ$4) -> 87 | AR13: =INDEX(poultry!$D$3:$U$41,$AP13,AR$4)/(AQ13/100) -> 13.563218
B14: oats | C14: =100-14 -> 86 | D14: =M14 -> 18.660222 | E14: =AVERAGE(T14,AI14)/1000*100 -> 3.2 | F14: =AVERAGE(U14,AJ14) -> 1.768 | G14: =AVERAGE(V14,AK14) -> 0.365 | H14: =AVERAGE(W14,AL14) -> 0.54 | I14: %DM accrding to harvest stat | K14: =MATCH($B14,ruminants!$A$3:$A$120,0) -> 28 | L14: =INDEX(ruminants!$D$3:$AH$120,$K14,L$4) -> 85 | M14: =( 5.7*P14+9.4*Q14+4.1*(R14+S14) ) * 0.004184 -> 18.660222 | N14: =INDEX(ruminants!$D$3:$AH$120,$K14,N$4) -> 11.7 | O14: =INDEX(ruminants!$D$3:$AH$120,$K14,O$4) -> 13.3 | P14: =INDEX(ruminants!$D$3:$AH$120,$K14,P$4) -> 110 | Q14: =INDEX(ruminants!$D$3:$AH$120,$K14,Q$4) -> 61 | R14: =INDEX(ruminants!$D$3:$AH$120,$K14,R$4) -> 141 | S14: =INDEX(ruminants!$D$3:$AH$120,$K14,S$4) -> 654 | T14: =INDEX(ruminants!$D$3:$AH$120,$K14,T$4) -> 34 | U14: =P14*U$3/1000*100 -> 1.76 | V14: =INDEX(ruminants!$D$3:$AH$120,$K14,V$4)/1000*100 -> 0.37 | W14: =INDEX(ruminants!$D$3:$AH$120,$K14,W$4)/1000*100 -> 0.53 | Z14: =MATCH($B14,pigs!$A$3:$A$60,0) -> 11 | AA14: =INDEX(pigs!$D$3:$AO$60,$Z14,AA$4) -> 87 | AB14: =( 5.7*AF14+9.4*AG14+4.1*(AH14) ) * 0.004184 -> 18.580307 | AC14: 12.7 | AD14: =INDEX(pigs!$D$3:$AO$60,$Z14,AD$4) -> 9 | AE14: =INDEX(pigs!$D$3:$AO$60,$Z14,AE$4) -> 9.4 | AF14: =INDEX(pigs!$D$3:$AO$60,$Z14,AF$4) -> 111 | AG14: =INDEX(pigs!$D$3:$AO$60,$Z14,AG$4) -> 54 | AH14: =1000-SUM(AF14:AG14,AI14) -> 805 | AI14: =INDEX(pigs!$D$3:$AO$60,$Z14,AI$4) -> 30 | AJ14: =AF14*AJ$3/1000*100 -> 1.776 | AK14: =INDEX(pigs!$D$3:$AO$60,$Z14,AK$4)/1000*100 -> 0.36 | AL14: =INDEX(pigs!$D$3:$AO$60,$Z14,AL$4)/1000*100 -> 0.55 | AN14: https://www.feedipedia.org/node/231 | AP14: =MATCH($B14,poultry!$A$3:$A$41,0) -> 10 | AQ14: =INDEX(poultry!$D$3:$U$41,$AP14,AQ$4) -> 87 | AR14: =INDEX(poultry!$D$3:$U$41,$AP14,AR$4)/(AQ14/100) -> 12.298851
B15: triticale | C15: =100-14 -> 86 | D15: =M15 -> 18.228433 | E15: =AVERAGE(T15,AI15)/1000*100 -> 2.05 | F15: =AVERAGE(U15,AJ15) -> 1.864 | G15: =AVERAGE(V15,AK15) -> 0.38 | H15: =AVERAGE(W15,AL15) -> 0.58 | I15: %DM accrding to harvest stat | K15: =MATCH($B15,ruminants!$A$3:$A$120,0) -> 78 | L15: =INDEX(ruminants!$D$3:$AH$120,$K15,L$4) -> 87 | M15: =( 5.7*P15+9.4*Q15+4.1*(R15+S15) ) * 0.004184 -> 18.228433 | N15: =INDEX(ruminants!$D$3:$AH$120,$K15,N$4) -> 14 | O15: =INDEX(ruminants!$D$3:$AH$120,$K15,O$4) -> 15.8 | P15: =INDEX(ruminants!$D$3:$AH$120,$K15,P$4) -> 123 | Q15: =INDEX(ruminants!$D$3:$AH$120,$K15,Q$4) -> 26 | R15: =INDEX(ruminants!$D$3:$AH$120,$K15,R$4) -> 33 | S15: =INDEX(ruminants!$D$3:$AH$120,$K15,S$4) -> 799 | T15: =INDEX(ruminants!$D$3:$AH$120,$K15,T$4) -> 19 | U15: =P15*U$3/1000*100 -> 1.968 | V15: =INDEX(ruminants!$D$3:$AH$120,$K15,V$4)/1000*100 -> 0.4 | W15: =INDEX(ruminants!$D$3:$AH$120,$K15,W$4)/1000*100 -> 0.54 | Z15: =MATCH($B15,pigs!$A$3:$A$60,0) -> 39 | AA15: =INDEX(pigs!$D$3:$AO$60,$Z15,AA$4) -> 87 | AB15: =( 5.7*AF15+9.4*AG15+4.1*(AH15) ) * 0.004184 -> 17.846015 | AC15: 15.6 | AD15: =INDEX(pigs!$D$3:$AO$60,$Z15,AD$4) -> 11.9 | AE15: =INDEX(pigs!$D$3:$AO$60,$Z15,AE$4) -> 12 | AF15: =INDEX(pigs!$D$3:$AO$60,$Z15,AF$4) -> 110 | AG15: =INDEX(pigs!$D$3:$AO$60,$Z15,AG$4) -> 15 | AH15: =1000-SUM(AF15:AG15,AI15) -> 853 | AI15: =INDEX(pigs!$D$3:$AO$60,$Z15,AI$4) -> 22 | AJ15: =AF15*AJ$3/1000*100 -> 1.76 | AK15: =INDEX(pigs!$D$3:$AO$60,$Z15,AK$4)/1000*100 -> 0.36 | AL15: =INDEX(pigs!$D$3:$AO$60,$Z15,AL$4)/1000*100 -> 0.62 | AN15: https://www.feedipedia.org/node/6476 | AP15: =MATCH($B15,poultry!$A$3:$A$41,0) -> 31 | AQ15: =INDEX(poultry!$D$3:$U$41,$AP15,AQ$4) -> 89 | AR15: =INDEX(poultry!$D$3:$U$41,$AP15,AR$4)/(AQ15/100) -> 14.606742
B16: rye | C16: =100-14 -> 86 | D16: =M16 -> 17.924256 | E16: =AVERAGE(T16,AI16)/1000*100 -> 2.05 | F16: =AVERAGE(U16,AJ16) -> 1.624 | G16: =AVERAGE(V16,AK16) -> 0.33 | H16: =AVERAGE(W16,AL16) -> 0.555 | I16: %DM accrding to harvest stat | K16: =MATCH($B16,ruminants!$A$3:$A$120,0) -> 77 | L16: =INDEX(ruminants!$D$3:$AH$120,$K16,L$4) -> 87 | M16: =( 5.7*P16+9.4*Q16+4.1*(R16+S16) ) * 0.004184 -> 17.924256 | N16: =INDEX(ruminants!$D$3:$AH$120,$K16,N$4) -> 13.9 | O16: =INDEX(ruminants!$D$3:$AH$120,$K16,O$4) -> 15.8 | P16: =INDEX(ruminants!$D$3:$AH$120,$K16,P$4) -> 100 | Q16: =INDEX(ruminants!$D$3:$AH$120,$K16,Q$4) -> 20 | R16: =INDEX(ruminants!$D$3:$AH$120,$K16,R$4) -> 25 | S16: =INDEX(ruminants!$D$3:$AH$120,$K16,S$4) -> 835 | T16: =INDEX(ruminants!$D$3:$AH$120,$K16,T$4) -> 20 | U16: =P16*U$3/1000*100 -> 1.6 | V16: =INDEX(ruminants!$D$3:$AH$120,$K16,V$4)/1000*100 -> 0.34 | W16: =INDEX(ruminants!$D$3:$AH$120,$K16,W$4)/1000*100 -> 0.55 | Z16: =MATCH($B16,pigs!$A$3:$A$60,0) -> 38 | AA16: =INDEX(pigs!$D$3:$AO$60,$Z16,AA$4) -> 87 | AB16: =( 5.7*AF16+9.4*AG16+4.1*(AH16) ) * 0.004184 -> 17.794134 | AD16: =INDEX(pigs!$D$3:$AO$60,$Z16,AD$4) -> 11.3 | AE16: =INDEX(pigs!$D$3:$AO$60,$Z16,AE$4) -> 11.5 | AF16: =INDEX(pigs!$D$3:$AO$60,$Z16,AF$4) -> 103 | AG16: =INDEX(pigs!$D$3:$AO$60,$Z16,AG$4) -> 14 | AH16: =1000-SUM(AF16:AG16,AI16) -> 862 | AI16: =INDEX(pigs!$D$3:$AO$60,$Z16,AI$4) -> 21 | AJ16: =AF16*AJ$3/1000*100 -> 1.648 | AK16: =INDEX(pigs!$D$3:$AO$60,$Z16,AK$4)/1000*100 -> 0.32 | AL16: =INDEX(pigs!$D$3:$AO$60,$Z16,AL$4)/1000*100 -> 0.56 | AP16: =MATCH($B16,poultry!$A$3:$A$41,0) -> 30 | AQ16: =INDEX(poultry!$D$3:$U$41,$AP16,AQ$4) -> 87 | AR16: =INDEX(poultry!$D$3:$U$41,$AP16,AR$4)/(AQ16/100) -> 12.873563
B17: maize | C17: =100-14 -> 86 | D17: =M17 -> 18.389935 | E17: =AVERAGE(T17,AI17)/1000*100 -> 1.85 | F17: =AVERAGE(U17,AJ17) -> 1.64 | G17: =AVERAGE(V17,AK17) -> 0.34 | H17: =AVERAGE(W17,AL17) -> 0.465 | I17: %DM accrding to harvest stat | K17: =MATCH($B17,ruminants!$A$3:$A$120,0) -> 53 | L17: =INDEX(ruminants!$D$3:$AH$120,$K17,L$4) -> 48 | M17: =( 5.7*P17+9.4*Q17+4.1*(R17+S17) ) * 0.004184 -> 18.389935 | N17: =INDEX(ruminants!$D$3:$AH$120,$K17,N$4) -> 12.8 | O17: =INDEX(ruminants!$D$3:$AH$120,$K17,O$4) -> 14.5 | P17: =INDEX(ruminants!$D$3:$AH$120,$K17,P$4) -> 111 | Q17: =INDEX(ruminants!$D$3:$AH$120,$K17,Q$4) -> 40 | R17: =INDEX(ruminants!$D$3:$AH$120,$K17,R$4) -> 63 | S17: =INDEX(ruminants!$D$3:$AH$120,$K17,S$4) -> 763 | T17: =INDEX(ruminants!$D$3:$AH$120,$K17,T$4) -> 23 | U17: =P17*U$3/1000*100 -> 1.776 | V17: =INDEX(ruminants!$D$3:$AH$120,$K17,V$4)/1000*100 -> 0.36 | W17: =INDEX(ruminants!$D$3:$AH$120,$K17,W$4)/1000*100 -> 0.53 | Z17: =MATCH($B17,pigs!$A$3:$A$60,0) -> 19 | AA17: =INDEX(pigs!$D$3:$AO$60,$Z17,AA$4) -> 87 | AB17: =( 5.7*AF17+9.4*AG17+4.1*(AH17) ) * 0.004184 -> 18.497046 | AC17: 16.5 | AD17: =INDEX(pigs!$D$3:$AO$60,$Z17,AD$4) -> 12.8 | AE17: =INDEX(pigs!$D$3:$AO$60,$Z17,AE$4) -> 13.2 | AF17: =INDEX(pigs!$D$3:$AO$60,$Z17,AF$4) -> 94 | AG17: =INDEX(pigs!$D$3:$AO$60,$Z17,AG$4) -> 43 | AH17: =1000-SUM(AF17:AG17,AI17) -> 849 | AI17: =INDEX(pigs!$D$3:$AO$60,$Z17,AI$4) -> 14 | AJ17: =AF17*AJ$3/1000*100 -> 1.504 | AK17: =INDEX(pigs!$D$3:$AO$60,$Z17,AK$4)/1000*100 -> 0.32 | AL17: =INDEX(pigs!$D$3:$AO$60,$Z17,AL$4)/1000*100 -> 0.4 | AN17: https://www.feedipedia.org/node/556 | AP17: =MATCH($B17,poultry!$A$3:$A$41,0) -> 24 | AQ17: =INDEX(poultry!$D$3:$U$41,$AP17,AQ$4) -> 87 | AR17: =INDEX(poultry!$D$3:$U$41,$AP17,AR$4)/(AQ17/100) -> 15.862069
B18: peas | C18: =100-15 -> 85 | D18: =M18 -> 18.478218 | E18: =AVERAGE(T18,AI18)/1000*100 -> 3.4 | F18: =AVERAGE(U18,AJ18) -> 3.72 | G18: =AVERAGE(V18,AK18) -> 0.445 | H18: =AVERAGE(W18,AL18) -> 1.155 | I18: %DM accrding to harvest stat | K18: =MATCH($B18,ruminants!$A$3:$A$120,0) -> 115 | L18: =INDEX(ruminants!$D$3:$AH$120,$K18,L$4) -> 87 | M18: =( 5.7*P18+9.4*Q18+4.1*(R18+S18) ) * 0.004184 -> 18.478218 | N18: =INDEX(ruminants!$D$3:$AH$120,$K18,N$4) -> 13.8 | O18: =INDEX(ruminants!$D$3:$AH$120,$K18,O$4) -> 16 | P18: =INDEX(ruminants!$D$3:$AH$120,$K18,P$4) -> 226 | Q18: =INDEX(ruminants!$D$3:$AH$120,$K18,Q$4) -> 17 | R18: =INDEX(ruminants!$D$3:$AH$120,$K18,R$4) -> 78 | S18: =INDEX(ruminants!$D$3:$AH$120,$K18,S$4) -> 646 | T18: =INDEX(ruminants!$D$3:$AH$120,$K18,T$4) -> 33 | U18: =P18*U$3/1000*100 -> 3.616 | V18: =INDEX(ruminants!$D$3:$AH$120,$K18,V$4)/1000*100 -> 0.43 | W18: =INDEX(ruminants!$D$3:$AH$120,$K18,W$4)/1000*100 -> 1.11 | Z18: =MATCH($B18,pigs!$A$3:$A$60,0) -> 56 | AA18: =INDEX(pigs!$D$3:$AO$60,$Z18,AA$4) -> 87 | AB18: =( 5.7*AF18+9.4*AG18+4.1*(AH18) ) * 0.004184 -> 18.42006 | AC18: 16.1 | AD18: =INDEX(pigs!$D$3:$AO$60,$Z18,AD$4) -> 11.2 | AE18: =INDEX(pigs!$D$3:$AO$60,$Z18,AE$4) -> 11.5 | AF18: =INDEX(pigs!$D$3:$AO$60,$Z18,AF$4) -> 239 | AG18: =INDEX(pigs!$D$3:$AO$60,$Z18,AG$4) -> 12 | AH18: =1000-SUM(AF18:AG18,AI18) -> 714 | AI18: =INDEX(pigs!$D$3:$AO$60,$Z18,AI$4) -> 35 | AJ18: =AF18*AJ$3/1000*100 -> 3.824 | AK18: =INDEX(pigs!$D$3:$AO$60,$Z18,AK$4)/1000*100 -> 0.46 | AL18: =INDEX(pigs!$D$3:$AO$60,$Z18,AL$4)/1000*100 -> 1.2 | AN18: https://www.feedipedia.org/node/264 | AP18: =MATCH($B18,poultry!$A$3:$A$41,0) -> 39 | AQ18: =INDEX(poultry!$D$3:$U$41,$AP18,AQ$4) -> 87 | AR18: =INDEX(poultry!$D$3:$U$41,$AP18,AR$4)/(AQ18/100) -> 12.643678
B19: broad beans | C19: =100-15 -> 85 | D19: =M19 -> 18.737207 | E19: =AVERAGE(T19,AI19)/1000*100 -> 4 | F19: =AVERAGE(U19,AJ19) -> 4.808 | G19: =AVERAGE(V19,AK19) -> 0.615 | H19: =AVERAGE(W19,AL19) -> 1.375 | I19: %DM accrding to harvest stat | L19: 86.6 | M19: =( 5.7*P19+9.4*Q19+4.1*(R19+S19) ) * 0.004184 -> 18.737207 | N19: 13.3 | O19: =INDEX(ruminants!$D$3:$AH$120,$K19,O$4) -> 12.6 | P19: 290 | Q19: 14 | R19: 91 | S19: =1000-SUM(P19:R19,T19) -> 566 | T19: 39 | U19: =P19*U$3/1000*100 -> 4.64 | V19: =5.5/1000*100 -> 0.55 | W19: =11.5/1000*100 -> 1.15 | X19: https://www.feedipedia.org/node/12799 | Z19: =MATCH($B19,pigs!$A$3:$A$60,0) -> 57 | AA19: =INDEX(pigs!$D$3:$AO$60,$Z19,AA$4) -> 87 | AB19: =( 5.7*AF19+9.4*AG19+4.1*(AH19) ) * 0.004184 -> 18.821306 | AC19: 15.5 | AD19: =INDEX(pigs!$D$3:$AO$60,$Z19,AD$4) -> 10.7 | AE19: =INDEX(pigs!$D$3:$AO$60,$Z19,AE$4) -> 10.9 | AF19: =INDEX(pigs!$D$3:$AO$60,$Z19,AF$4) -> 311 | AG19: =INDEX(pigs!$D$3:$AO$60,$Z19,AG$4) -> 13 | AH19: =1000-SUM(AF19:AG19,AI19) -> 635 | AI19: =INDEX(pigs!$D$3:$AO$60,$Z19,AI$4) -> 41 | AJ19: =AF19*AJ$3/1000*100 -> 4.976 | AK19: =INDEX(pigs!$D$3:$AO$60,$Z19,AK$4)/1000*100 -> 0.68 | AL19: =INDEX(pigs!$D$3:$AO$60,$Z19,AL$4)/1000*100 -> 1.6 | AN19: https://www.feedipedia.org/node/12799
B20: rapeseed | C20: =100-9 -> 91 | D20: =M20 -> 27.903096 | E20: =AVERAGE(T20,AI20)/1000*100 -> 4.65 | F20: =AVERAGE(U20,AJ20) -> 3.336 | G20: =AVERAGE(V20,AK20) -> 0.81 | H20: =AVERAGE(W20,AL20) -> 0.91 | I20: %DM accrding to harvest stat | K20: =MATCH($B20,ruminants!$A$3:$A$120,0) -> 71 | L20: =INDEX(ruminants!$D$3:$AH$120,$K20,L$4) -> 93 | M20: =( 5.7*P20+9.4*Q20+4.1*(R20+S20) ) * 0.004184 -> 27.903096 | N20: =INDEX(ruminants!$D$3:$AH$120,$K20,N$4) -> 22.1 | O20: =INDEX(ruminants!$D$3:$AH$120,$K20,O$4) -> 22.1 | P20: =INDEX(ruminants!$D$3:$AH$120,$K20,P$4) -> 210 | Q20: =INDEX(ruminants!$D$3:$AH$120,$K20,Q$4) -> 460 | R20: =INDEX(ruminants!$D$3:$AH$120,$K20,R$4) -> 80 | S20: =INDEX(ruminants!$D$3:$AH$120,$K20,S$4) -> 200 | T20: =INDEX(ruminants!$D$3:$AH$120,$K20,T$4) -> 50 | U20: =P20*U$3/1000*100 -> 3.36 | V20: =INDEX(ruminants!$D$3:$AH$120,$K20,V$4)/1000*100 -> 0.86 | W20: =INDEX(ruminants!$D$3:$AH$120,$K20,W$4)/1000*100 -> 0.82 | Z20: =MATCH($B20,pigs!$A$3:$A$60,0) -> 33 | AA20: =INDEX(pigs!$D$3:$AO$60,$Z20,AA$4) -> 92 | AB20: =( 5.7*AF20+9.4*AG20+4.1*(AH20) ) * 0.004184 -> 27.892218 | AC20: 23.5 | AD20: =INDEX(pigs!$D$3:$AO$60,$Z20,AD$4) -> 18 | AE20: =INDEX(pigs!$D$3:$AO$60,$Z20,AE$4) -> 18.5 | AF20: =INDEX(pigs!$D$3:$AO$60,$Z20,AF$4) -> 207 | AG20: =INDEX(pigs!$D$3:$AO$60,$Z20,AG$4) -> 455 | AH20: =1000-SUM(AF20:AG20,AI20) -> 295 | AI20: =INDEX(pigs!$D$3:$AO$60,$Z20,AI$4) -> 43 | AJ20: =AF20*AJ$3/1000*100 -> 3.312 | AK20: =INDEX(pigs!$D$3:$AO$60,$Z20,AK$4)/1000*100 -> 0.76 | AL20: =INDEX(pigs!$D$3:$AO$60,$Z20,AL$4)/1000*100 -> 1 | AN20: https://www.feedipedia.org/node/15617 | AR20: 16.8 | AS20: https://www.feedipedia.org/node/15617
B21: linseed | C21: =100-9 -> 91 | D21: =M21 -> 26.501456 | E21: =AVERAGE(T21,AI21)/1000*100 -> 3.9 | F21: =AVERAGE(U21,AJ21) -> 3.736 | G21: =AVERAGE(V21,AK21) -> 0.57 | H21: =AVERAGE(W21,AL21) -> 0.895 | I21: %DM accrding to harvest stat | K21: =MATCH($B21,ruminants!$A$3:$A$120,0) -> 45 | L21: =INDEX(ruminants!$D$3:$AH$120,$K21,L$4) -> 93 | M21: =( 5.7*P21+9.4*Q21+4.1*(R21+S21) ) * 0.004184 -> 26.501456 | N21: =INDEX(ruminants!$D$3:$AH$120,$K21,N$4) -> 20.1 | O21: =INDEX(ruminants!$D$3:$AH$120,$K21,O$4) -> 20.8 | P21: =INDEX(ruminants!$D$3:$AH$120,$K21,P$4) -> 240 | Q21: =INDEX(ruminants!$D$3:$AH$120,$K21,Q$4) -> 380 | R21: =INDEX(ruminants!$D$3:$AH$120,$K21,R$4) -> 70 | S21: =INDEX(ruminants!$D$3:$AH$120,$K21,S$4) -> 270 | T21: =INDEX(ruminants!$D$3:$AH$120,$K21,T$4) -> 40 | U21: =P21*U$3/1000*100 -> 3.84 | V21: =INDEX(ruminants!$D$3:$AH$120,$K21,V$4)/1000*100 -> 0.57 | W21: =INDEX(ruminants!$D$3:$AH$120,$K21,W$4)/1000*100 -> 0.9 | Z21: =MATCH($B21,pigs!$A$3:$A$60,0) -> 14 | AA21: =INDEX(pigs!$D$3:$AO$60,$Z21,AA$4) -> 91 | AB21: =( 5.7*AF21+9.4*AG21+4.1*(AH21) ) * 0.004184 -> 27.712724 | AC21: 20.9 | AD21: =INDEX(pigs!$D$3:$AO$60,$Z21,AD$4) -> 17.3 | AE21: =INDEX(pigs!$D$3:$AO$60,$Z21,AE$4) -> 17.5 | AF21: =INDEX(pigs!$D$3:$AO$60,$Z21,AF$4) -> 227 | AG21: =INDEX(pigs!$D$3:$AO$60,$Z21,AG$4) -> 437 | AH21: =1000-SUM(AF21:AG21,AI21) -> 298 | AI21: =INDEX(pigs!$D$3:$AO$60,$Z21,AI$4) -> 38 | AJ21: =AF21*AJ$3/1000*100 -> 3.632 | AK21: =INDEX(pigs!$D$3:$AO$60,$Z21,AK$4)/1000*100 -> 0.57 | AL21: =INDEX(pigs!$D$3:$AO$60,$Z21,AL$4)/1000*100 -> 0.89 | AN21: https://www.feedipedia.org/node/36
B22: vegetable oils | C22: =AVERAGE(AA22,L22) -> 100 | D22: =M22 -> 39.3296 | E22: =AVERAGE(T22,AI22)/1000*100 -> 0 | F22: =AVERAGE(U22,AJ22) -> 0 | G22: =AVERAGE(V22,AK22) -> 0 | H22: =AVERAGE(W22,AL22) -> 0 | L22: 100 | M22: =( 5.7*P22+9.4*Q22+4.1*(R22+S22) ) * 0.004184 -> 39.3296 | N22: 36.6 | O22: =N22 -> 36.6 | P22: 0 | Q22: 1000 | R22: 0 | S22: 0 | T22: 0 | U22: =P22*U$3/1000*100 -> 0 | V22: 0 | W22: 0 | X22: https://www.feedtables.com/content/rapeseed-oil | Z22: =MATCH($B22,pigs!$A$3:$A$60,0) -> 28 | AA22: =INDEX(pigs!$D$3:$AO$60,$Z22,AA$4) -> 100 | AB22: =( 5.7*AF22+9.4*AG22+4.1*(AH22) ) * 0.004184 -> 39.3296 | AC22: 34.5 | AD22: =INDEX(pigs!$D$3:$AO$60,$Z22,AD$4) -> 29.8 | AE22: =INDEX(pigs!$D$3:$AO$60,$Z22,AE$4) -> 29.8 | AF22: =INDEX(pigs!$D$3:$AO$60,$Z22,AF$4) -> 0 | AG22: =INDEX(pigs!$D$3:$AO$60,$Z22,AG$4) -> 1000 | AH22: =1000-SUM(AF22:AG22,AI22) -> 0 | AI22: =INDEX(pigs!$D$3:$AO$60,$Z22,AI$4) -> 0 | AJ22: =AF22*AJ$3/1000*100 -> 0 | AK22: =INDEX(pigs!$D$3:$AO$60,$Z22,AK$4)/1000*100 -> 0 | AL22: =INDEX(pigs!$D$3:$AO$60,$Z22,AL$4)/1000*100 -> 0 | AN22: https://www.feedtables.com/content/rapeseed-oil | AP22: =MATCH($B22,poultry!$A$3:$A$41,0) -> 1 | AQ22: =INDEX(poultry!$D$3:$U$41,$AP22,AQ$4) -> 99 | AR22: =INDEX(poultry!$D$3:$U$41,$AP22,AR$4)/(AQ22/100) -> 38.080808
B23: straw | C23: =AVERAGE(AA23,L23) -> 85 | D23: =M23 -> 16.927627 | E23: =AVERAGE(T23,AI23)/1000*100 -> 6.6 | F23: =AVERAGE(U23,AJ23) -> 1.104 | G23: =AVERAGE(V23,AK23) -> 0.26 | H23: =AVERAGE(W23,AL23) -> 1.68 | K23: =MATCH($B23,ruminants!$A$3:$A$120,0) -> 22 | L23: =INDEX(ruminants!$D$3:$AH$120,$K23,L$4) -> 85 | M23: =( 5.7*P23+9.4*Q23+4.1*(R23+S23) ) * 0.004184 -> 16.927627 | N23: =INDEX(ruminants!$D$3:$AH$120,$K23,N$4) -> 6.6 | O23: =INDEX(ruminants!$D$3:$AH$120,$K23,O$4) -> 7.6 | P23: =INDEX(ruminants!$D$3:$AH$120,$K23,P$4) -> 69 | Q23: =INDEX(ruminants!$D$3:$AH$120,$K23,Q$4) -> 20 | R23: =INDEX(ruminants!$D$3:$AH$120,$K23,R$4) -> 436 | S23: =INDEX(ruminants!$D$3:$AH$120,$K23,S$4) -> 409 | T23: =INDEX(ruminants!$D$3:$AH$120,$K23,T$4) -> 66 | U23: =P23*U$3/1000*100 -> 1.104 | V23: =INDEX(ruminants!$D$3:$AH$120,$K23,V$4)/1000*100 -> 0.26 | W23: =INDEX(ruminants!$D$3:$AH$120,$K23,W$4)/1000*100 -> 1.68
B24: soybeans | C24: =AVERAGE(AA24,L24) -> 87 | D24: =M24 -> 22.965976 | E24: =AVERAGE(T24,AI24)/1000*100 -> 5 | F24: =AVERAGE(U24,AJ24) -> 6.4 | G24: =AVERAGE(V24,AK24) -> 0.63 | H24: =AVERAGE(W24,AL24) -> 1.9 | K24: =MATCH($B24,ruminants!$A$3:$A$120,0) -> 92 | L24: =INDEX(ruminants!$D$3:$AH$120,$K24,L$4) -> 87 | M24: =( 5.7*P24+9.4*Q24+4.1*(R24+S24) ) * 0.004184 -> 22.965976 | N24: =INDEX(ruminants!$D$3:$AH$120,$K24,N$4) -> 16.4 | O24: =INDEX(ruminants!$D$3:$AH$120,$K24,O$4) -> 18.4 | P24: =INDEX(ruminants!$D$3:$AH$120,$K24,P$4) -> 400 | Q24: =INDEX(ruminants!$D$3:$AH$120,$K24,Q$4) -> 180 | R24: =INDEX(ruminants!$D$3:$AH$120,$K24,R$4) -> 60 | S24: =INDEX(ruminants!$D$3:$AH$120,$K24,S$4) -> 310 | T24: =INDEX(ruminants!$D$3:$AH$120,$K24,T$4) -> 50 | U24: =P24*U$3/1000*100 -> 6.4 | V24: =INDEX(ruminants!$D$3:$AH$120,$K24,V$4)/1000*100 -> 0.63 | W24: =INDEX(ruminants!$D$3:$AH$120,$K24,W$4)/1000*100 -> 1.9 | AR24: 16 | AS24: https://www.feedipedia.org/node/12625
B25: soybean meal | C25: =AVERAGE(AA25,L25) -> 87.5 | D25: =M25 -> 19.589488 | E25: =AVERAGE(T25,AI25)/1000*100 -> 7.15 | F25: =AVERAGE(U25,AJ25) -> 8.208 | G25: =AVERAGE(V25,AK25) -> 0.715 | H25: =AVERAGE(W25,AL25) -> 2.35 | K25: =MATCH($B25,ruminants!$A$3:$A$120,0) -> 93 | L25: =INDEX(ruminants!$D$3:$AH$120,$K25,L$4) -> 87 | M25: =( 5.7*P25+9.4*Q25+4.1*(R25+S25) ) * 0.004184 -> 19.589488 | N25: =INDEX(ruminants!$D$3:$AH$120,$K25,N$4) -> 14.6 | O25: =INDEX(ruminants!$D$3:$AH$120,$K25,O$4) -> 17.8 | P25: =INDEX(ruminants!$D$3:$AH$120,$K25,P$4) -> 510 | Q25: =INDEX(ruminants!$D$3:$AH$120,$K25,Q$4) -> 10 | R25: =INDEX(ruminants!$D$3:$AH$120,$K25,R$4) -> 60 | S25: =INDEX(ruminants!$D$3:$AH$120,$K25,S$4) -> 350 | T25: =INDEX(ruminants!$D$3:$AH$120,$K25,T$4) -> 70 | U25: =P25*U$3/1000*100 -> 8.16 | V25: =INDEX(ruminants!$D$3:$AH$120,$K25,V$4)/1000*100 -> 0.72 | W25: =INDEX(ruminants!$D$3:$AH$120,$K25,W$4)/1000*100 -> 2.3 | Z25: =MATCH($B25,pigs!$A$3:$A$60,0) -> 43 | AA25: =INDEX(pigs!$D$3:$AO$60,$Z25,AA$4) -> 88 | AB25: =( 5.7*AF25+9.4*AG25+4.1*(AH25) ) * 0.004184 -> 19.822118 | AC25: 16.8 | AD25: =INDEX(pigs!$D$3:$AO$60,$Z25,AD$4) -> 9.3 | AE25: =INDEX(pigs!$D$3:$AO$60,$Z25,AE$4) -> 9.9 | AF25: =INDEX(pigs!$D$3:$AO$60,$Z25,AF$4) -> 516 | AG25: =INDEX(pigs!$D$3:$AO$60,$Z25,AG$4) -> 21 | AH25: =1000-SUM(AF25:AG25,AI25) -> 390 | AI25: =INDEX(pigs!$D$3:$AO$60,$Z25,AI$4) -> 73 | AJ25: =AF25*AJ$3/1000*100 -> 8.256 | AK25: =INDEX(pigs!$D$3:$AO$60,$Z25,AK$4)/1000*100 -> 0.71 | AL25: =INDEX(pigs!$D$3:$AO$60,$Z25,AL$4)/1000*100 -> 2.4 | AN25: https://www.feedipedia.org/node/26068 | AP25: =MATCH($B25,poultry!$A$3:$A$41,0) -> 33 | AQ25: =INDEX(poultry!$D$3:$U$41,$AP25,AQ$4) -> 87 | AR25: =INDEX(poultry!$D$3:$U$41,$AP25,AR$4)/(AQ25/100) -> 10.45977
B26: soybean protein concentrate | C26: =AVERAGE(AA26,L26) -> 87.5 | D26: =AB26 -> 20.560594 | E26: =AVERAGE(T26,AI26)/1000*100 -> 7.35 | F26: =AVERAGE(U26,AJ26) -> 9.288 | G26: =AVERAGE(V26,AK26) -> 0.79 | H26: =AVERAGE(W26,AL26) -> 2.465 | L26: 88 | M26: =( 5.7*P26+9.4*Q26+4.1*(R26+S26) ) * 0.004184 -> 19.974416 | N26: 13.4 | O26: =M26*0.911 -> 18.196693 | P26: 552 | Q26: 17 | R26: 44 | S26: =1000-SUM(P26:R26,T26) -> 314 | T26: 73 | U26: =P26*U$3/1000*100 -> 8.832 | V26: =7.1/1000*100 -> 0.71 | W26: =24.3/1000*100 -> 2.43 | X26: https://www.feedipedia.org/node/11683 | Z26: =MATCH($B26,pigs!$A$3:$A$60,0) -> 45 | AA26: =INDEX(pigs!$D$3:$AO$60,$Z26,AA$4) -> 87 | AB26: =( 5.7*AF26+9.4*AG26+4.1*(AH26) ) * 0.004184 -> 20.560594 | AC26: 17.3 | AD26: =INDEX(pigs!$D$3:$AO$60,$Z26,AD$4) -> 9.7 | AE26: =INDEX(pigs!$D$3:$AO$60,$Z26,AE$4) -> 10.3 | AF26: =INDEX(pigs!$D$3:$AO$60,$Z26,AF$4) -> 609 | AG26: =INDEX(pigs!$D$3:$AO$60,$Z26,AG$4) -> 27 | AH26: =1000-SUM(AF26:AG26,AI26) -> 290 | AI26: =INDEX(pigs!$D$3:$AO$60,$Z26,AI$4) -> 74 | AJ26: =AF26*AJ$3/1000*100 -> 9.744 | AK26: =INDEX(pigs!$D$3:$AO$60,$Z26,AK$4)/1000*100 -> 0.87 | AL26: =INDEX(pigs!$D$3:$AO$60,$Z26,AL$4)/1000*100 -> 2.5 | AN26: https://www.feedipedia.org/node/11683
B27: rapeseed meal | C27: =AVERAGE(AA27,L27) -> 89.5 | D27: =M27 -> 19.492001 | E27: =AVERAGE(T27,AI27)/1000*100 -> 7.7 | F27: =AVERAGE(U27,AJ27) -> 6.152 | G27: =AVERAGE(V27,AK27) -> 1.245 | H27: =AVERAGE(W27,AL27) -> 1.55 | K27: =MATCH($B27,ruminants!$A$3:$A$120,0) -> 70 | L27: =INDEX(ruminants!$D$3:$AH$120,$K27,L$4) -> 90 | M27: =( 5.7*P27+9.4*Q27+4.1*(R27+S27) ) * 0.004184 -> 19.492001 | N27: =INDEX(ruminants!$D$3:$AH$120,$K27,N$4) -> 12.2 | O27: =INDEX(ruminants!$D$3:$AH$120,$K27,O$4) -> 14.6 | P27: =INDEX(ruminants!$D$3:$AH$120,$K27,P$4) -> 389 | Q27: =INDEX(ruminants!$D$3:$AH$120,$K27,Q$4) -> 46 | R27: =INDEX(ruminants!$D$3:$AH$120,$K27,R$4) -> 140 | S27: =INDEX(ruminants!$D$3:$AH$120,$K27,S$4) -> 350 | T27: =INDEX(ruminants!$D$3:$AH$120,$K27,T$4) -> 75 | U27: =P27*U$3/1000*100 -> 6.224 | V27: =INDEX(ruminants!$D$3:$AH$120,$K27,V$4)/1000*100 -> 1.2 | W27: =INDEX(ruminants!$D$3:$AH$120,$K27,W$4)/1000*100 -> 1.6 | Z27: =MATCH($B27,pigs!$A$3:$A$60,0) -> 36 | AA27: =INDEX(pigs!$D$3:$AO$60,$Z27,AA$4) -> 89 | AB27: =( 5.7*AF27+9.4*AG27+4.1*(AH27) ) * 0.004184 -> 18.91963 | AC27: 13.3 | AD27: =INDEX(pigs!$D$3:$AO$60,$Z27,AD$4) -> 7.1 | AE27: =INDEX(pigs!$D$3:$AO$60,$Z27,AE$4) -> 7.7 | AF27: =INDEX(pigs!$D$3:$AO$60,$Z27,AF$4) -> 380 | AG27: =INDEX(pigs!$D$3:$AO$60,$Z27,AG$4) -> 26 | AH27: =1000-SUM(AF27:AG27,AI27) -> 515 | AI27: =INDEX(pigs!$D$3:$AO$60,$Z27,AI$4) -> 79 | AJ27: =AF27*AJ$3/1000*100 -> 6.08 | AK27: =INDEX(pigs!$D$3:$AO$60,$Z27,AK$4)/1000*100 -> 1.29 | AL27: =INDEX(pigs!$D$3:$AO$60,$Z27,AL$4)/1000*100 -> 1.5 | AN27: https://www.feedipedia.org/node/12503 | AP27: =MATCH($B27,poultry!$A$3:$A$41,0) -> 29 | AQ27: =INDEX(poultry!$D$3:$U$41,$AP27,AQ$4) -> 90 | AR27: =INDEX(poultry!$D$3:$U$41,$AP27,AR$4)/(AQ27/100) -> 8.4444444
B28: sunflower seed meal | C28: =AVERAGE(AA28,L28) -> 91 | D28: =M28 -> 19.083224 | E28: =AVERAGE(T28,AI28)/1000*100 -> 7.75 | F28: =AVERAGE(U28,AJ28) -> 6.664 | G28: =AVERAGE(V28,AK28) -> 1.305 | H28: =AVERAGE(W28,AL28) -> 1.75 | K28: =MATCH($B28,ruminants!$A$3:$A$120,0) -> 99 | L28: =INDEX(ruminants!$D$3:$AH$120,$K28,L$4) -> 92 | M28: =( 5.7*P28+9.4*Q28+4.1*(R28+S28) ) * 0.004184 -> 19.083224 | N28: =INDEX(ruminants!$D$3:$AH$120,$K28,N$4) -> 11.4 | O28: =INDEX(ruminants!$D$3:$AH$120,$K28,O$4) -> 14.1 | P28: =INDEX(ruminants!$D$3:$AH$120,$K28,P$4) -> 460 | Q28: =INDEX(ruminants!$D$3:$AH$120,$K28,Q$4) -> 10 | R28: =INDEX(ruminants!$D$3:$AH$120,$K28,R$4) -> 170 | S28: =INDEX(ruminants!$D$3:$AH$120,$K28,S$4) -> 280 | T28: =INDEX(ruminants!$D$3:$AH$120,$K28,T$4) -> 80 | U28: =P28*U$3/1000*100 -> 7.36 | V28: =INDEX(ruminants!$D$3:$AH$120,$K28,V$4)/1000*100 -> 1.35 | W28: =INDEX(ruminants!$D$3:$AH$120,$K28,W$4)/1000*100 -> 1.8 | Z28: =MATCH($B28,pigs!$A$3:$A$60,0) -> 46 | AA28: =INDEX(pigs!$D$3:$AO$60,$Z28,AA$4) -> 90 | AB28: =( 5.7*AF28+9.4*AG28+4.1*(AH28) ) * 0.004184 -> 18.78616 | AC28: 10.3 | AD28: =INDEX(pigs!$D$3:$AO$60,$Z28,AD$4) -> 5.9 | AE28: =INDEX(pigs!$D$3:$AO$60,$Z28,AE$4) -> 6.5 | AF28: =INDEX(pigs!$D$3:$AO$60,$Z28,AF$4) -> 373 | AG28: =INDEX(pigs!$D$3:$AO$60,$Z28,AG$4) -> 19 | AH28: =1000-SUM(AF28:AG28,AI28) -> 533 | AI28: =INDEX(pigs!$D$3:$AO$60,$Z28,AI$4) -> 75 | AJ28: =AF28*AJ$3/1000*100 -> 5.968 | AK28: =INDEX(pigs!$D$3:$AO$60,$Z28,AK$4)/1000*100 -> 1.26 | AL28: =INDEX(pigs!$D$3:$AO$60,$Z28,AL$4)/1000*100 -> 1.7 | AN28: https://www.feedipedia.org/node/12663 | AR28: 8.6 | AS28: https://www.feedipedia.org/node/12663
B29: palm kernel expeller | C29: =AVERAGE(AA29,L29) -> 91 | D29: =M29 -> 19.581538 | E29: =AVERAGE(T29,AI29)/1000*100 -> 4.5 | F29: =AVERAGE(U29,AJ29) -> 2.536 | G29: =AVERAGE(V29,AK29) -> 0.645 | H29: =AVERAGE(W29,AL29) -> 0.775 | K29: =MATCH($B29,ruminants!$A$3:$A$120,0) -> 60 | L29: =INDEX(ruminants!$D$3:$AH$120,$K29,L$4) -> 91 | M29: =( 5.7*P29+9.4*Q29+4.1*(R29+S29) ) * 0.004184 -> 19.581538 | N29: =INDEX(ruminants!$D$3:$AH$120,$K29,N$4) -> 13.4 | O29: =INDEX(ruminants!$D$3:$AH$120,$K29,O$4) -> 15 | P29: =INDEX(ruminants!$D$3:$AH$120,$K29,P$4) -> 154 | Q29: =INDEX(ruminants!$D$3:$AH$120,$K29,Q$4) -> 97 | R29: =INDEX(ruminants!$D$3:$AH$120,$K29,R$4) -> 228 | S29: =INDEX(ruminants!$D$3:$AH$120,$K29,S$4) -> 477 | T29: =INDEX(ruminants!$D$3:$AH$120,$K29,T$4) -> 44 | U29: =P29*U$3/1000*100 -> 2.464 | V29: =INDEX(ruminants!$D$3:$AH$120,$K29,V$4)/1000*100 -> 0.65 | W29: =INDEX(ruminants!$D$3:$AH$120,$K29,W$4)/1000*100 -> 0.8 | Z29: =MATCH($B29,pigs!$A$3:$A$60,0) -> 29 | AA29: =INDEX(pigs!$D$3:$AO$60,$Z29,AA$4) -> 91 | AB29: =( 5.7*AF29+9.4*AG29+4.1*(AH29) ) * 0.004184 -> 19.540954 | AC29: 8.4 | AD29: =INDEX(pigs!$D$3:$AO$60,$Z29,AD$4) -> 5.4 | AE29: =INDEX(pigs!$D$3:$AO$60,$Z29,AE$4) -> 6.2 | AF29: =INDEX(pigs!$D$3:$AO$60,$Z29,AF$4) -> 163 | AG29: =INDEX(pigs!$D$3:$AO$60,$Z29,AG$4) -> 94 | AH29: =1000-SUM(AF29:AG29,AI29) -> 697 | AI29: =INDEX(pigs!$D$3:$AO$60,$Z29,AI$4) -> 46 | AJ29: =AF29*AJ$3/1000*100 -> 2.608 | AK29: =INDEX(pigs!$D$3:$AO$60,$Z29,AK$4)/1000*100 -> 0.64 | AL29: =INDEX(pigs!$D$3:$AO$60,$Z29,AL$4)/1000*100 -> 0.75
B30: luzern meal | C30: =AVERAGE(AA30,L30) -> 90 | D30: =M30 -> 16.971141 | E30: =AVERAGE(T30,AI30)/1000*100 -> 11.7 | F30: =AVERAGE(U30,AJ30) -> 2.928 | G30: =AVERAGE(V30,AK30) -> 0.27 | H30: =AVERAGE(W30,AL30) -> 2.56 | L30: 90 | M30: =( 5.7*P30+9.4*Q30+4.1*(R30+S30) ) * 0.004184 -> 16.971141 | N30: 8.5 | O30: 10.7 | P30: 183 | Q30: 27 | R30: 286 | S30: =1000-SUM(P30:R30,T30) -> 387 | T30: 117 | U30: =P30*U$3/1000*100 -> 2.928 | V30: =2.7/1000*100 -> 0.27 | W30: =25.6/1000*100 -> 2.56 | X30: https://www.feedipedia.org/node/11744
B31: wheat bran | C31: =AVERAGE(AA31,L31) -> 87 | D31: =M31 -> 18.194124 | E31: =AVERAGE(T31,AI31)/1000*100 -> 5.9 | F31: =AVERAGE(U31,AJ31) -> 2.64 | G31: =AVERAGE(V31,AK31) -> 1.195 | H31: =AVERAGE(W31,AL31) -> 1.35 | K31: =MATCH($B31,ruminants!$A$3:$A$120,0) -> 111 | L31: =INDEX(ruminants!$D$3:$AH$120,$K31,L$4) -> 87 | M31: =( 5.7*P31+9.4*Q31+4.1*(R31+S31) ) * 0.004184 -> 18.194124 | N31: =INDEX(ruminants!$D$3:$AH$120,$K31,N$4) -> 11 | O31: =INDEX(ruminants!$D$3:$AH$120,$K31,O$4) -> 12.7 | P31: =INDEX(ruminants!$D$3:$AH$120,$K31,P$4) -> 160 | Q31: =INDEX(ruminants!$D$3:$AH$120,$K31,Q$4) -> 45 | R31: =INDEX(ruminants!$D$3:$AH$120,$K31,R$4) -> 115 | S31: =INDEX(ruminants!$D$3:$AH$120,$K31,S$4) -> 620 | T31: =INDEX(ruminants!$D$3:$AH$120,$K31,T$4) -> 60 | U31: =P31*U$3/1000*100 -> 2.56 | V31: =INDEX(ruminants!$D$3:$AH$120,$K31,V$4)/1000*100 -> 1.2 | W31: =INDEX(ruminants!$D$3:$AH$120,$K31,W$4)/1000*100 -> 1.2 | Z31: =MATCH($B31,pigs!$A$3:$A$60,0) -> 55 | AA31: =INDEX(pigs!$D$3:$AO$60,$Z31,AA$4) -> 87 | AB31: =( 5.7*AF31+9.4*AG31+4.1*(AH31) ) * 0.004184 -> 18.184501 | AC31: 10.8 | AD31: =INDEX(pigs!$D$3:$AO$60,$Z31,AD$4) -> 7.2 | AE31: =INDEX(pigs!$D$3:$AO$60,$Z31,AE$4) -> 7.8 | AF31: =INDEX(pigs!$D$3:$AO$60,$Z31,AF$4) -> 170 | AG31: =INDEX(pigs!$D$3:$AO$60,$Z31,AG$4) -> 40 | AH31: =1000-SUM(AF31:AG31,AI31) -> 732 | AI31: =INDEX(pigs!$D$3:$AO$60,$Z31,AI$4) -> 58 | AJ31: =AF31*AJ$3/1000*100 -> 2.72 | AK31: =INDEX(pigs!$D$3:$AO$60,$Z31,AK$4)/1000*100 -> 1.19 | AL31: =INDEX(pigs!$D$3:$AO$60,$Z31,AL$4)/1000*100 -> 1.5 | AN31: https://www.feedipedia.org/node/12751 | AP31: =MATCH($B31,poultry!$A$3:$A$41,0) -> 38 | AQ31: =INDEX(poultry!$D$3:$U$41,$AP31,AQ$4) -> 87 | AR31: =INDEX(poultry!$D$3:$U$41,$AP31,AR$4)/(AQ31/100) -> 7.816092
B32: wheat bran, fine | C32: =AVERAGE(AA32,L32) -> 87.8 | D32: =M32 -> 18.47236 | E32: =AVERAGE(T32,AI32)/1000*100 -> 3.3 | F32: =AVERAGE(U32,AJ32) -> 2.616 | G32: =AVERAGE(V32,AK32) -> 0.815 | H32: =AVERAGE(W32,AL32) -> 0.96 | L32: 87.6 | M32: =( 5.7*P32+9.4*Q32+4.1*(R32+S32) ) * 0.004184 -> 18.47236 | N32: 13.3 | O32: =M32*0.846 -> 15.627617 | P32: 151 | Q32: 27 | R32: 11 | S32: =1000-SUM(P32:R32,T32) -> 794 | T32: 17 | U32: =P32*U$3/1000*100 -> 2.416 | V32: =4.4/1000*100 -> 0.44 | W32: =6.2/1000*100 -> 0.62 | X32: https://www.feedtables.com/content/wheat-feed-flour | Z32: =MATCH($B32,pigs!$A$3:$A$60,0) -> 54 | AA32: =INDEX(pigs!$D$3:$AO$60,$Z32,AA$4) -> 88 | AB32: =( 5.7*AF32+9.4*AG32+4.1*(AH32) ) * 0.004184 -> 18.379057 | AC32: 17.5 | AD32: =INDEX(pigs!$D$3:$AO$60,$Z32,AD$4) -> 8.7 | AE32: =INDEX(pigs!$D$3:$AO$60,$Z32,AE$4) -> 9.2 | AF32: =INDEX(pigs!$D$3:$AO$60,$Z32,AF$4) -> 176 | AG32: =INDEX(pigs!$D$3:$AO$60,$Z32,AG$4) -> 40 | AH32: =1000-SUM(AF32:AG32,AI32) -> 735 | AI32: =INDEX(pigs!$D$3:$AO$60,$Z32,AI$4) -> 49 | AJ32: =AF32*AJ$3/1000*100 -> 2.816 | AK32: =INDEX(pigs!$D$3:$AO$60,$Z32,AK$4)/1000*100 -> 1.19 | AL32: =INDEX(pigs!$D$3:$AO$60,$Z32,AL$4)/1000*100 -> 1.3 | AN32: https://www.feedtables.com/content/wheat-feed-flour | AP32: =MATCH($B32,poultry!$A$3:$A$41,0) -> 36 | AQ32: =INDEX(poultry!$D$3:$U$41,$AP32,AQ$4) -> 87 | AR32: =INDEX(poultry!$D$3:$U$41,$AP32,AR$4)/(AQ32/100) -> 14.022989
B33: oat hulls | C33: =AVERAGE(AA33,L33) -> 87.6 | D33: =M33 -> 16.941016 | E33: =AVERAGE(T33,AI33)/1000*100 -> 5 | F33: =AVERAGE(U33,AJ33) -> 0.48 | G33: =AVERAGE(V33,AK33) -> 0.44 | H33: =AVERAGE(W33,AL33) -> 0.6 | K33: =MATCH($B33,ruminants!$A$3:$A$120,0) -> 29 | L33: 87.6 | M33: =( 5.7*P33+9.4*Q33+4.1*(R33+S33) ) * 0.004184 -> 16.941016 | N33: =INDEX(ruminants!$D$3:$AH$120,$K33,N$4) -> 5.2 | O33: =INDEX(ruminants!$D$3:$AH$120,$K33,O$4) -> 6.2 | P33: =INDEX(ruminants!$D$3:$AH$120,$K33,P$4) -> 30 | Q33: =INDEX(ruminants!$D$3:$AH$120,$K33,Q$4) -> 20 | R33: =INDEX(ruminants!$D$3:$AH$120,$K33,R$4) -> 340 | S33: =INDEX(ruminants!$D$3:$AH$120,$K33,S$4) -> 560 | T33: =INDEX(ruminants!$D$3:$AH$120,$K33,T$4) -> 50 | U33: =P33*U$3/1000*100 -> 0.48 | V33: =INDEX(ruminants!$D$3:$AH$120,$K33,V$4)/1000*100 -> 0.44 | W33: =INDEX(ruminants!$D$3:$AH$120,$K33,W$4)/1000*100 -> 0.6
B34: oat bran | C34: =AVERAGE(AA34,L34) -> 87.6 | D34: =M34 -> 17.342262 | E34: =AVERAGE(T34,AI34)/1000*100 -> 5.5 | F34: =AVERAGE(U34,AJ34) -> 1.008 | G34: =AVERAGE(V34,AK34) -> 0.77 | H34: =AVERAGE(W34,AL34) -> 0 | K34: =MATCH($B34,ruminants!$A$3:$A$120,0) -> 27 | L34: 87.6 | M34: =( 5.7*P34+9.4*Q34+4.1*(R34+S34) ) * 0.004184 -> 17.342262 | N34: =INDEX(ruminants!$D$3:$AH$120,$K34,N$4) -> 7.2 | O34: =INDEX(ruminants!$D$3:$AH$120,$K34,O$4) -> 8.4 | P34: =INDEX(ruminants!$D$3:$AH$120,$K34,P$4) -> 63 | Q34: =INDEX(ruminants!$D$3:$AH$120,$K34,Q$4) -> 32 | R34: =INDEX(ruminants!$D$3:$AH$120,$K34,R$4) -> 290 | S34: =INDEX(ruminants!$D$3:$AH$120,$K34,S$4) -> 560 | T34: =INDEX(ruminants!$D$3:$AH$120,$K34,T$4) -> 55 | U34: =P34*U$3/1000*100 -> 1.008 | V34: =INDEX(ruminants!$D$3:$AH$120,$K34,V$4)/1000*100 -> 0.77 | W34: =INDEX(ruminants!$D$3:$AH$120,$K34,W$4)/1000*100 -> 0
B35: rye bran | C35: =AVERAGE(AA35,L35) -> 87.6 | D35: =M35 -> 18.340564 | E35: =AVERAGE(T35,AI35)/1000*100 -> 4.5 | F35: =AVERAGE(U35,AJ35) -> 2.56 | G35: =AVERAGE(V35,AK35) -> 1.11 | H35: =AVERAGE(W35,AL35) -> 1.6 | K35: =MATCH($B35,ruminants!$A$3:$A$120,0) -> 76 | L35: 87.6 | M35: =( 5.7*P35+9.4*Q35+4.1*(R35+S35) ) * 0.004184 -> 18.340564 | N35: =INDEX(ruminants!$D$3:$AH$120,$K35,N$4) -> 11.6 | O35: =INDEX(ruminants!$D$3:$AH$120,$K35,O$4) -> 13.2 | P35: =INDEX(ruminants!$D$3:$AH$120,$K35,P$4) -> 160 | Q35: =INDEX(ruminants!$D$3:$AH$120,$K35,Q$4) -> 40 | R35: =INDEX(ruminants!$D$3:$AH$120,$K35,R$4) -> 55 | S35: =INDEX(ruminants!$D$3:$AH$120,$K35,S$4) -> 700 | T35: =INDEX(ruminants!$D$3:$AH$120,$K35,T$4) -> 45 | U35: =P35*U$3/1000*100 -> 2.56 | V35: =INDEX(ruminants!$D$3:$AH$120,$K35,V$4)/1000*100 -> 1.11 | W35: =INDEX(ruminants!$D$3:$AH$120,$K35,W$4)/1000*100 -> 1.6
B36: wheat distillers grain, dry | C36: =AVERAGE(AA36,L36) -> 90 | D36: =M36 -> 19.659779 | E36: =AVERAGE(T36,AI36)/1000*100 -> 4.05 | F36: =AVERAGE(U36,AJ36) -> 5.28 | G36: =AVERAGE(V36,AK36) -> 0.88 | H36: =AVERAGE(W36,AL36) -> 1.165 | K36: =MATCH($B36,ruminants!$A$3:$A$120,0) -> 109 | L36: =INDEX(ruminants!$D$3:$AH$120,$K36,L$4) -> 90 | M36: =( 5.7*P36+9.4*Q36+4.1*(R36+S36) ) * 0.004184 -> 19.659779 | N36: =INDEX(ruminants!$D$3:$AH$120,$K36,N$4) -> 13.3 | O36: =INDEX(ruminants!$D$3:$AH$120,$K36,O$4) -> 15.7 | P36: =INDEX(ruminants!$D$3:$AH$120,$K36,P$4) -> 320 | Q36: =INDEX(ruminants!$D$3:$AH$120,$K36,Q$4) -> 45 | R36: =INDEX(ruminants!$D$3:$AH$120,$K36,R$4) -> 106 | S36: =INDEX(ruminants!$D$3:$AH$120,$K36,S$4) -> 492 | T36: =INDEX(ruminants!$D$3:$AH$120,$K36,T$4) -> 37 | U36: =P36*U$3/1000*100 -> 5.12 | V36: =INDEX(ruminants!$D$3:$AH$120,$K36,V$4)/1000*100 -> 1.03 | W36: =INDEX(ruminants!$D$3:$AH$120,$K36,W$4)/1000*100 -> 1.37 | Z36: =MATCH($B36,pigs!$A$3:$A$60,0) -> 3 | AA36: =INDEX(pigs!$D$3:$AO$60,$Z36,AA$4) -> 90 | AB36: =( 5.7*AF36+9.4*AG36+4.1*(AH36) ) * 0.004184 -> 20.139266 | AC36: 13.9 | AD36: =INDEX(pigs!$D$3:$AO$60,$Z36,AD$4) -> 8.1 | AE36: =INDEX(pigs!$D$3:$AO$60,$Z36,AE$4) -> 8.7 | AF36: =INDEX(pigs!$D$3:$AO$60,$Z36,AF$4) -> 340 | AG36: =INDEX(pigs!$D$3:$AO$60,$Z36,AG$4) -> 66 | AH36: =1000-SUM(AF36:AG36,AI36) -> 550 | AI36: =INDEX(pigs!$D$3:$AO$60,$Z36,AI$4) -> 44 | AJ36: =AF36*AJ$3/1000*100 -> 5.44 | AK36: =INDEX(pigs!$D$3:$AO$60,$Z36,AK$4)/1000*100 -> 0.73 | AL36: =INDEX(pigs!$D$3:$AO$60,$Z36,AL$4)/1000*100 -> 0.96 | AN36: https://www.feedipedia.org/node/12801
B37: wheat distillers grain, wet | C37: =AVERAGE(AA37,L37) -> 11 | D37: =AB37 -> 18.860217 | E37: =AVERAGE(T37,AI37)/1000*100 -> 6.8 | F37: =AVERAGE(U37,AJ37) -> 4.48 | G37: =AVERAGE(V37,AK37) -> 1.09 | H37: =AVERAGE(W37,AL37) -> 0 | Z37: =MATCH($B37,pigs!$A$3:$A$60,0) -> 1 | AA37: =INDEX(pigs!$D$3:$AO$60,$Z37,AA$4) -> 11 | AB37: =( 5.7*AF37+9.4*AG37+4.1*(AH37) ) * 0.004184 -> 18.860217 | AC37: =(AC36/AB36)*AB37 -> 13.017208 | AD37: =INDEX(pigs!$D$3:$AO$60,$Z37,AD$4) -> 8.2 | AE37: =INDEX(pigs!$D$3:$AO$60,$Z37,AE$4) -> 8.9 | AF37: =INDEX(pigs!$D$3:$AO$60,$Z37,AF$4) -> 280 | AG37: =INDEX(pigs!$D$3:$AO$60,$Z37,AG$4) -> 45 | AH37: =1000-SUM(AF37:AG37,AI37) -> 607 | AI37: =INDEX(pigs!$D$3:$AO$60,$Z37,AI$4) -> 68 | AJ37: =AF37*AJ$3/1000*100 -> 4.48 | AK37: =INDEX(pigs!$D$3:$AO$60,$Z37,AK$4)/1000*100 -> 1.09 | AL37: =INDEX(pigs!$D$3:$AO$60,$Z37,AL$4)/1000*100 -> 0
B38: barley brewers grain | C38: =AVERAGE(AA38,L38) -> 90 | D38: =M38 -> 19.848896 | E38: =AVERAGE(T38,AI38)/1000*100 -> 4.3 | F38: =AVERAGE(U38,AJ38) -> 3.984 | G38: =AVERAGE(V38,AK38) -> 0.56 | H38: =AVERAGE(W38,AL38) -> 0.195 | K38: =MATCH($B38,ruminants!$A$3:$A$120,0) -> 38 | L38: =INDEX(ruminants!$D$3:$AH$120,$K38,L$4) -> 90 | M38: =( 5.7*P38+9.4*Q38+4.1*(R38+S38) ) * 0.004184 -> 19.848896 | N38: =INDEX(ruminants!$D$3:$AH$120,$K38,N$4) -> 11.6 | O38: =INDEX(ruminants!$D$3:$AH$120,$K38,O$4) -> 13.6 | P38: =INDEX(ruminants!$D$3:$AH$120,$K38,P$4) -> 240 | Q38: =INDEX(ruminants!$D$3:$AH$120,$K38,Q$4) -> 80 | R38: =INDEX(ruminants!$D$3:$AH$120,$K38,R$4) -> 170 | S38: =INDEX(ruminants!$D$3:$AH$120,$K38,S$4) -> 470 | T38: =INDEX(ruminants!$D$3:$AH$120,$K38,T$4) -> 40 | U38: =P38*U$3/1000*100 -> 3.84 | V38: =INDEX(ruminants!$D$3:$AH$120,$K38,V$4)/1000*100 -> 0.55 | W38: =INDEX(ruminants!$D$3:$AH$120,$K38,W$4)/1000*100 -> 0.1 | AA38: 90 | AB38: =( 5.7*AF38+9.4*AG38+4.1*(AH38) ) * 0.004184 -> 19.578191 | AC38: 10.6 | AD38: 6.6 | AE38: =AE36/AD36*AD38 -> 7.0888889 | AF38: 258 | AG38: 67 | AH38: =1000-SUM(AF38:AG38,AI38) -> 629 | AI38: 46 | AJ38: =AF38*AJ$3/1000*100 -> 4.128 | AK38: =5.7/1000*100 -> 0.57 | AL38: =2.9/1000*100 -> 0.29 | AM38: https://www.feedipedia.org/node/11893 | AN38: https://www.feedipedia.org/node/11893
B39: maize gluten meal | C39: =AVERAGE(AA39,L39,AQ39) -> 89.666667 | D39: =AB39 -> 22.900706 | E39: =AVERAGE(T39,AI39)/1000*100 -> 1.95 | F39: =AVERAGE(U39,AJ39) -> 10.792 | G39: =AVERAGE(V39,AK39) -> 0.485 | H39: =AVERAGE(W39,AL39) -> 0.325 | K39: =MATCH($B39,ruminants!$A$3:$A$120,0) -> 50 | L39: =INDEX(ruminants!$D$3:$AH$120,$K39,L$4) -> 92 | M39: =( 5.7*P39+9.4*Q39+4.1*(R39+S39) ) * 0.004184 -> 21.876462 | N39: =INDEX(ruminants!$D$3:$AH$120,$K39,N$4) -> 16 | O39: =INDEX(ruminants!$D$3:$AH$120,$K39,O$4) -> 19.6 | P39: =INDEX(ruminants!$D$3:$AH$120,$K39,P$4) -> 672 | Q39: =INDEX(ruminants!$D$3:$AH$120,$K39,Q$4) -> 24 | R39: =INDEX(ruminants!$D$3:$AH$120,$K39,R$4) -> 22 | S39: =INDEX(ruminants!$D$3:$AH$120,$K39,S$4) -> 264 | T39: =INDEX(ruminants!$D$3:$AH$120,$K39,T$4) -> 18 | U39: =P39*U$3/1000*100 -> 10.752 | V39: =INDEX(ruminants!$D$3:$AH$120,$K39,V$4)/1000*100 -> 0.33 | W39: =INDEX(ruminants!$D$3:$AH$120,$K39,W$4)/1000*100 -> 0.1 | Z39: =MATCH($B39,pigs!$A$3:$A$60,0) -> 22 | AA39: =INDEX(pigs!$D$3:$AO$60,$Z39,AA$4) -> 90 | AB39: =( 5.7*AF39+9.4*AG39+4.1*(AH39) ) * 0.004184 -> 22.900706 | AC39: 21.4 | AD39: =INDEX(pigs!$D$3:$AO$60,$Z39,AD$4) -> 12.9 | AE39: =INDEX(pigs!$D$3:$AO$60,$Z39,AE$4) -> 13.3 | AF39: =INDEX(pigs!$D$3:$AO$60,$Z39,AF$4) -> 677 | AG39: =INDEX(pigs!$D$3:$AO$60,$Z39,AG$4) -> 71 | AH39: =1000-SUM(AF39:AG39,AI39) -> 231 | AI39: =INDEX(pigs!$D$3:$AO$60,$Z39,AI$4) -> 21 | AJ39: =AF39*AJ$3/1000*100 -> 10.832 | AK39: =INDEX(pigs!$D$3:$AO$60,$Z39,AK$4)/1000*100 -> 0.64 | AL39: =INDEX(pigs!$D$3:$AO$60,$Z39,AL$4)/1000*100 -> 0.55 | AN39: https://www.feedipedia.org/node/12288 | AP39: =MATCH($B39,poultry!$A$3:$A$41,0) -> 25 | AQ39: =INDEX(poultry!$D$3:$U$41,$AP39,AQ$4) -> 87 | AR39: =INDEX(poultry!$D$3:$U$41,$AP39,AR$4)/(AQ39/100) -> 16.321839
B40: sugar beet molasses | C40: =AVERAGE(AA40,L40) -> 75.5 | D40: =M40 -> 16.161537 | E40: =AVERAGE(T40,AI40)/1000*100 -> 11.9 | F40: =AVERAGE(U40,AJ40) -> 2.208 | G40: =AVERAGE(V40,AK40) -> 0.03 | H40: =AVERAGE(W40,AL40) -> 3.65 | K40: =MATCH($B40,ruminants!$A$3:$A$120,0) -> 88 | L40: =INDEX(ruminants!$D$3:$AH$120,$K40,L$4) -> 75 | M40: =( 5.7*P40+9.4*Q40+4.1*(R40+S40) ) * 0.004184 -> 16.161537 | N40: =INDEX(ruminants!$D$3:$AH$120,$K40,N$4) -> 12.4 | O40: =INDEX(ruminants!$D$3:$AH$120,$K40,O$4) -> 14.1 | P40: =INDEX(ruminants!$D$3:$AH$120,$K40,P$4) -> 131 | Q40: =INDEX(ruminants!$D$3:$AH$120,$K40,Q$4) -> 0 | R40: =INDEX(ruminants!$D$3:$AH$120,$K40,R$4) -> 0 | S40: =INDEX(ruminants!$D$3:$AH$120,$K40,S$4) -> 760 | T40: =INDEX(ruminants!$D$3:$AH$120,$K40,T$4) -> 109 | U40: =P40*U$3/1000*100 -> 2.096 | V40: =INDEX(ruminants!$D$3:$AH$120,$K40,V$4)/1000*100 -> 0.02 | W40: =INDEX(ruminants!$D$3:$AH$120,$K40,W$4)/1000*100 -> 4.5 | Z40: =MATCH($B40,pigs!$A$3:$A$60,0) -> 23 | AA40: =INDEX(pigs!$D$3:$AO$60,$Z40,AA$4) -> 76 | AB40: =( 5.7*AF40+9.4*AG40+4.1*(AH40) ) * 0.004184 -> 15.956521 | AC40: 13.1 | AD40: =INDEX(pigs!$D$3:$AO$60,$Z40,AD$4) -> 8.7 | AE40: =INDEX(pigs!$D$3:$AO$60,$Z40,AE$4) -> 9 | AF40: =INDEX(pigs!$D$3:$AO$60,$Z40,AF$4) -> 145 | AG40: =INDEX(pigs!$D$3:$AO$60,$Z40,AG$4) -> 2 | AH40: =1000-SUM(AF40:AG40,AI40) -> 724 | AI40: =INDEX(pigs!$D$3:$AO$60,$Z40,AI$4) -> 129 | AJ40: =AF40*AJ$3/1000*100 -> 2.32 | AK40: =INDEX(pigs!$D$3:$AO$60,$Z40,AK$4)/1000*100 -> 0.04 | AL40: =INDEX(pigs!$D$3:$AO$60,$Z40,AL$4)/1000*100 -> 2.8 | AN40: https://www.feedipedia.org/node/12340
B41: sugar beet pulp | C41: =AVERAGE(AA41,L41) -> 89.5 | D41: =M41 -> 17.334312 | E41: =AVERAGE(T41,AI41)/1000*100 -> 7.15 | F41: =AVERAGE(U41,AJ41) -> 1.448 | G41: =AVERAGE(V41,AK41) -> 0.1 | H41: =AVERAGE(W41,AL41) -> 0.485 | K41: =MATCH($B41,ruminants!$A$3:$A$120,0) -> 91 | L41: =INDEX(ruminants!$D$3:$AH$120,$K41,L$4) -> 90 | M41: =( 5.7*P41+9.4*Q41+4.1*(R41+S41) ) * 0.004184 -> 17.334312 | N41: =INDEX(ruminants!$D$3:$AH$120,$K41,N$4) -> 12.3 | O41: =INDEX(ruminants!$D$3:$AH$120,$K41,O$4) -> 14.7 | P41: =INDEX(ruminants!$D$3:$AH$120,$K41,P$4) -> 90 | Q41: =INDEX(ruminants!$D$3:$AH$120,$K41,Q$4) -> 32 | R41: =INDEX(ruminants!$D$3:$AH$120,$K41,R$4) -> 187 | S41: =INDEX(ruminants!$D$3:$AH$120,$K41,S$4) -> 625 | T41: =INDEX(ruminants!$D$3:$AH$120,$K41,T$4) -> 66 | U41: =P41*U$3/1000*100 -> 1.44 | V41: =INDEX(ruminants!$D$3:$AH$120,$K41,V$4)/1000*100 -> 0.1 | W41: =INDEX(ruminants!$D$3:$AH$120,$K41,W$4)/1000*100 -> 0.6 | Z41: =MATCH($B41,pigs!$A$3:$A$60,0) -> 4 | AA41: =INDEX(pigs!$D$3:$AO$60,$Z41,AA$4) -> 89 | AB41: =( 5.7*AF41+9.4*AG41+4.1*(AH41) ) * 0.004184 -> 16.664454 | AC41: 12.2 | AD41: =INDEX(pigs!$D$3:$AO$60,$Z41,AD$4) -> 6.9 | AE41: =INDEX(pigs!$D$3:$AO$60,$Z41,AE$4) -> 8 | AF41: =INDEX(pigs!$D$3:$AO$60,$Z41,AF$4) -> 91 | AG41: =INDEX(pigs!$D$3:$AO$60,$Z41,AG$4) -> 10 | AH41: =1000-SUM(AF41:AG41,AI41) -> 822 | AI41: =INDEX(pigs!$D$3:$AO$60,$Z41,AI$4) -> 77 | AJ41: =AF41*AJ$3/1000*100 -> 1.456 | AK41: =INDEX(pigs!$D$3:$AO$60,$Z41,AK$4)/1000*100 -> 0.1 | AL41: =INDEX(pigs!$D$3:$AO$60,$Z41,AL$4)/1000*100 -> 0.37 | AN41: https://www.feedipedia.org/node/24378
...

Sheet feed pars csv
A1: GENERAL | I1: CATTLE | P1: SHEEP (same as cattle) | W1: HORSES | AD1: PIGS | AJ1: PIGS (sows) | AP1: POULTRY
A2: f_feed | B2: feed_par_DM | C2: feed_par_GE | D2: feed_par_ASH | E2: feed_par_N | F2: feed_par_P | G2: feed_par_K | I2: f_feed | J2: f_species | K2: f_animal | L2: feed_par_DE | M2: feed_par_E | N2: feed_par_fat | P2: f_feed | Q2: f_species | R2: f_animal | S2: feed_par_DE | T2: feed_par_E | U2: feed_par_fat | W2: f_feed | X2: f_species | Y2: f_animal | Z2: feed_par_DE | AA2: feed_par_E | AB2: feed_par_fat | AD2: f_feed | AE2: f_species | AF2: f_animal | AG2: feed_par_DE | AH2: feed_par_E | AJ2: f_feed | AK2: f_species | AL2: f_animal | AM2: feed_par_DE | AN2: feed_par_E | AP2: f_feed | AQ2: f_species | AR2: f_animal | AS2: feed_par_AME
A3: ='feed pars'!$B6 -> ley silage, 1st cut | B3: =INDEX('feed pars'!C$6:C$47,MATCH($A3,'feed pars'!$B$6:$B$47,0)) -> 100 | C3: =INDEX('feed pars'!D$6:D$47,MATCH($A3,'feed pars'!$B$6:$B$47,0)) -> 17.316948 | D3: =INDEX('feed pars'!E$6:E$47,MATCH($A3,'feed pars'!$B$6:$B$47,0)) -> 7.55 | E3: =INDEX('feed pars'!F$6:F$47,MATCH($A3,'feed pars'!$B$6:$B$47,0)) -> 2.424 | F3: =INDEX('feed pars'!G$6:G$47,MATCH($A3,'feed pars'!$B$6:$B$47,0)) -> 0.28 | G3: =INDEX('feed pars'!H$6:H$47,MATCH($A3,'feed pars'!$B$6:$B$47,0)) -> 2.425 | I3: ='feed pars'!$B6 -> ley silage, 1st cut | J3: cattle | L3: =INDEX('feed pars'!$O$6:$O$47,MATCH($A3,'feed pars'!$B$6:$B$47,0)) -> 13.35 | M3: =INDEX('feed pars'!$N$6:$N$47,MATCH($A3,'feed pars'!$B$6:$B$47,0)) -> 11.3 | N3: =INDEX('feed pars'!$Q$6:$Q$47,MATCH($A3,'feed pars'!$B$6:$B$47,0)) -> 20 | P3: ='feed pars'!$B6 -> ley silage, 1st cut | Q3: sheep | S3: =INDEX('feed pars'!$O$6:$O$47,MATCH($A3,'feed pars'!$B$6:$B$47,0)) -> 13.35 | T3: =INDEX('feed pars'!$N$6:$N$47,MATCH($A3,'feed pars'!$B$6:$B$47,0)) -> 11.3 | U3: =INDEX('feed pars'!$Q$6:$Q$47,MATCH($A3,'feed pars'!$B$6:$B$47,0)) -> 20 | W3: ='feed pars'!$B6 -> ley silage, 1st cut | X3: horses | Z3: =INDEX('feed pars'!$O$6:$O$47,MATCH($A3,'feed pars'!$B$6:$B$47,0)) -> 13.35 | AA3: =INDEX('feed pars'!$N$6:$N$47,MATCH($A3,'feed pars'!$B$6:$B$47,0)) -> 11.3 | AB3: =INDEX('feed pars'!$Q$6:$Q$47,MATCH($A3,'feed pars'!$B$6:$B$47,0)) -> 20 | AD3: ='feed pars'!$B6 -> ley silage, 1st cut | AE3: pigs | AJ3: ='feed pars'!$B6 -> ley silage, 1st cut | AK3: pigs | AL3: sows | AP3: ='feed pars'!$B6 -> ley silage, 1st cut | AQ3: poultry
A4: ='feed pars'!$B7 -> ley silage, regrowth | B4: =INDEX('feed pars'!C$6:C$47,MATCH($A4,'feed pars'!$B$6:$B$47,0)) -> 100 | C4: =INDEX('feed pars'!D$6:D$47,MATCH($A4,'feed pars'!$B$6:$B$47,0)) -> 17.150216 | D4: =INDEX('feed pars'!E$6:E$47,MATCH($A4,'feed pars'!$B$6:$B$47,0)) -> 7.8 | E4: =INDEX('feed pars'!F$6:F$47,MATCH($A4,'feed pars'!$B$6:$B$47,0)) -> 2.128 | F4: =INDEX('feed pars'!G$6:G$47,MATCH($A4,'feed pars'!$B$6:$B$47,0)) -> 0.27 | G4: =INDEX('feed pars'!H$6:H$47,MATCH($A4,'feed pars'!$B$6:$B$47,0)) -> 2.34 | I4: ='feed pars'!$B7 -> ley silage, regrowth | J4: cattle | L4: =INDEX('feed pars'!$O$6:$O$47,MATCH($A4,'feed pars'!$B$6:$B$47,0)) -> 11.9 | M4: =INDEX('feed pars'!$N$6:$N$47,MATCH($A4,'feed pars'!$B$6:$B$47,0)) -> 10.1 | N4: =INDEX('feed pars'!$Q$6:$Q$47,MATCH($A4,'feed pars'!$B$6:$B$47,0)) -> 20 | P4: ='feed pars'!$B7 -> ley silage, regrowth | Q4: sheep | S4: =INDEX('feed pars'!$O$6:$O$47,MATCH($A4,'feed pars'!$B$6:$B$47,0)) -> 11.9 | T4: =INDEX('feed pars'!$N$6:$N$47,MATCH($A4,'feed pars'!$B$6:$B$47,0)) -> 10.1 | U4: =INDEX('feed pars'!$Q$6:$Q$47,MATCH($A4,'feed pars'!$B$6:$B$47,0)) -> 20 | W4: ='feed pars'!$B7 -> ley silage, regrowth | X4: horses | Z4: =INDEX('feed pars'!$O$6:$O$47,MATCH($A4,'feed pars'!$B$6:$B$47,0)) -> 11.9 | AA4: =INDEX('feed pars'!$N$6:$N$47,MATCH($A4,'feed pars'!$B$6:$B$47,0)) -> 10.1 | AB4: =INDEX('feed pars'!$Q$6:$Q$47,MATCH($A4,'feed pars'!$B$6:$B$47,0)) -> 20 | AD4: ='feed pars'!$B7 -> ley silage, regrowth | AE4: pigs | AJ4: ='feed pars'!$B7 -> ley silage, regrowth | AK4: pigs | AL4: sows | AP4: ='feed pars'!$B7 -> ley silage, regrowth | AQ4: poultry
A5: ='feed pars'!$B8 -> other silage | B5: =INDEX('feed pars'!C$6:C$47,MATCH($A5,'feed pars'!$B$6:$B$47,0)) -> 100 | C5: =INDEX('feed pars'!D$6:D$47,MATCH($A5,'feed pars'!$B$6:$B$47,0)) -> 16.789764 | D5: =INDEX('feed pars'!E$6:E$47,MATCH($A5,'feed pars'!$B$6:$B$47,0)) -> 8.8 | E5: =INDEX('feed pars'!F$6:F$47,MATCH($A5,'feed pars'!$B$6:$B$47,0)) -> 1.544 | F5: =INDEX('feed pars'!G$6:G$47,MATCH($A5,'feed pars'!$B$6:$B$47,0)) -> 0.21 | G5: =INDEX('feed pars'!H$6:H$47,MATCH($A5,'feed pars'!$B$6:$B$47,0)) -> 2.35 | I5: ='feed pars'!$B8 -> other silage | J5: cattle | L5: =INDEX('feed pars'!$O$6:$O$47,MATCH($A5,'feed pars'!$B$6:$B$47,0)) -> 10.75 | M5: =INDEX('feed pars'!$N$6:$N$47,MATCH($A5,'feed pars'!$B$6:$B$47,0)) -> 8.5 | N5: =INDEX('feed pars'!$Q$6:$Q$47,MATCH($A5,'feed pars'!$B$6:$B$47,0)) -> 22.5 | P5: ='feed pars'!$B8 -> other silage | Q5: sheep | S5: =INDEX('feed pars'!$O$6:$O$47,MATCH($A5,'feed pars'!$B$6:$B$47,0)) -> 10.75 | T5: =INDEX('feed pars'!$N$6:$N$47,MATCH($A5,'feed pars'!$B$6:$B$47,0)) -> 8.5 | U5: =INDEX('feed pars'!$Q$6:$Q$47,MATCH($A5,'feed pars'!$B$6:$B$47,0)) -> 22.5 | W5: ='feed pars'!$B8 -> other silage | X5: horses | Z5: =INDEX('feed pars'!$O$6:$O$47,MATCH($A5,'feed pars'!$B$6:$B$47,0)) -> 10.75 | AA5: =INDEX('feed pars'!$N$6:$N$47,MATCH($A5,'feed pars'!$B$6:$B$47,0)) -> 8.5 | AB5: =INDEX('feed pars'!$Q$6:$Q$47,MATCH($A5,'feed pars'!$B$6:$B$47,0)) -> 22.5 | AD5: ='feed pars'!$B8 -> other silage | AE5: pigs | AJ5: ='feed pars'!$B8 -> other silage | AK5: pigs | AL5: sows | AP5: ='feed pars'!$B8 -> other silage | AQ5: poultry
