Workbook

Sheet default
A1: f_activity | B1: f_crop | C1: f_crop_group:crop | D1: f_species | E1: f_breed | F1: f_animal | G1: f_animal_prod | H1: f_energy_source | I1: f_operation | J1: f_soil_class | K1: f_forage_system | L1: f_compound | M1: parameter | N1: value | O1: unit | P1: description | Q1: source
M2: energy_source_share | N2: 0 | O2: % | P2: fallback
A4: field machinery | H4: Diesel | M4: energy_source_share | N4: =(241822577+237201100)/(241822577+237201100+5856000+8368914)*100 -> 97.116076 | O4: % | Q4: https://www.energimyndigheten.se/statistik/den-officiella-statistiken/statistikprodukter/energianvandningen-inom-jordbruket/
A5: field machinery | H5: Biodiesel | M5: energy_source_share | N5: =100-N4 -> 2.8839239 | O5: % | Q5: snitt 2018 och 2021
A6: field machinery | H6: Hydrogen | M6: energy_source_share | N6: 0 | O6: %
A7: field machinery | H7: Electricity | M7: energy_source_share | N7: 0 | O7: %
A9: stable machinery | D9: cattle | H9: Diesel | M9: energy_source_share | N9: 100 | O9: %
A10: stable heating | D10: cattle
A11: stable misc | D11: cattle | H11: Electricity | M11: energy_source_share | N11: 100 | O11: %
A12: stable milking | D12: cattle | H12: Electricity | M12: energy_source_share | N12: 100 | O12: %
A14: stable machinery | D14: poultry | E14: broiler | H14: Diesel | M14: energy_source_share | N14: 100 | O14: %
A15: stable heating | D15: poultry | E15: broiler | H15: Fuel oil | M15: energy_source_share | N15: 100 | O15: %
A16: stable misc | D16: poultry | E16: broiler | H16: Electricity | M16: energy_source_share | N16: 100 | O16: %
A18: stable machinery | D18: pigs | F18: piglets | H18: Diesel | M18: energy_source_share | N18: 100 | O18: % | Q18: Landquist et al (2020)
A19: stable heating | D19: pigs | F19: piglets | H19: Fuel oil | M19: energy_source_share | N19: 4 | O19: % | Q19: Landquist et al (2020)
A20: stable heating | D20: pigs | F20: piglets | H20: Woody biofuels | M20: energy_source_share | N20: 76 | O20: % | Q20: Landquist et al (2020)
A21: stable heating | D21: pigs | F21: piglets | H21: Electricity | M21: energy_source_share | N21: 20 | O21: % | Q21: Landquist et al (2020)
A22: stable misc | D22: pigs | F22: piglets | H22: Electricity | M22: energy_source_share | N22: 100 | O22: % | Q22: Landquist et al (2020)
A23: stable machinery | D23: pigs | F23: growing pigs | H23: Diesel | M23: energy_source_share | N23: 100 | O23: % | Q23: Landquist et al (2020)
A24: stable heating | D24: pigs | F24: growing pigs | H24: Fuel oil | M24: energy_source_share | N24: 20 | O24: % | Q24: Landquist et al (2020)
A25: stable heating | D25: pigs | F25: growing pigs | H25: Woody biofuels | M25: energy_source_share | N25: 60 | O25: % | Q25: Landquist et al (2020)
A26: stable heating | D26: pigs | F26: growing pigs | H26: Electricity | M26: energy_source_share | N26: 20 | O26: % | Q26: Landquist et al (2020)
A27: stable misc | D27: pigs | F27: growing pigs | H27: Electricity | M27: energy_source_share | N27: 100 | O27: % | Q27: Landquist et al (2020)
A29: stable machinery | D29: poultry | E29: layer | H29: Electricity | M29: energy_source_share | N29: 90 | O29: %
A30: stable machinery | D30: poultry | E30: layer | H30: Diesel | M30: energy_source_share | N30: 10 | O30: %
A31: stable misc | D31: poultry | E31: layer | H31: Electricity | M31: energy_source_share | N31: 100 | O31: %
A32: stable heating | D32: poultry | E32: layer | H32: Woody biofuels | M32: energy_source_share | N32: 90 | O32: % | Q32: Sonesson et al (2008), page 16
A33: stable heating | D33: poultry | E33: layer | H33: Fuel oil | M33: energy_source_share | N33: 10 | O33: % | Q33: Sonesson et al (2008), page 16
A35: stable machinery | D35: sheep | H35: Diesel | M35: energy_source_share | N35: 100 | O35: % | Q35: Ahlgren et al. (2022)
A36: stable misc | D36: sheep | H36: Electricity | M36: energy_source_share | N36: 100 | O36: % | Q36: Ahlgren et al. (2022)
A38: greenhouses | H38: Fuel oil | M38: energy_source_share | N38: 6.4777062 | O38: % | Q38: Energianvändning i växthus 2020. Tomat, gurka och prydnadsväxter.
A39: greenhouses | H39: Natural gas | M39: energy_source_share | N39: 8.7567853 | O39: % | P39: naturgas+övriga fossila | Q39: https://jordbruksverket.se/om-jordbruksverket/jordbruksverkets-officiella-statistik/jordbruksverkets-statistikrapporter/statistik/2022-04-25-energianvandning-i-vaxthus-2020.-tomat-gurka-och-prydnadsvaxter.
A40: greenhouses | H40: Woody biofuels | M40: energy_source_share | N40: 59.671114 | O40: % | P40: Bark, flis och spån+Pellets och briketter+Övriga biobränslen | Q40: snitt 2017 och 2020
A41: greenhouses | H41: Electricity | M41: energy_source_share | N41: 16.802919 | O41: %
A42: greenhouses | H42: District heating | M42: energy_source_share | N42: 7.4851295 | O42: %
A43: greenhouses | H43: Geothermal | M43: energy_source_share | N43: 0.80634576 | O43: %
A45: grain dryers | H45: Fuel oil | M45: energy_source_share | N45: 70 | O45: % | P45: 70% of dryers used oil as fuel and consumed 165 GWh oil year 2021 | Q45: Energimyndigheten. Statistikdatabas. Jordbrukets energianvändning
A46: grain dryers | H46: Woody biofuels | M46: energy_source_share | N46: 30 | O46: % | Q46: Energimyndigheten. Statistikdatabas. Jordbrukets energianvändning
A47: grain dryers auxiliary energy | H47: Electricity | M47: energy_source_share | N47: 100 | O47: %
K49: bales | M49: forage_system_share | N49: 80 | O49: %
...

Sheet energy stables
B3: Milk production
B4: Hörndahl & Neuman (2012)
D5: Gård A | E5: cows | F5: recr. | G5: Gård B | H5: cows | I5: recr.
B6: dairy cows | C6: heads | D6: 150 | G6: 220
B7: recruitment | C7: heads | D7: 150 | G7: 220
B8: milk prod. | C8: kg/cow | D8: 10500 | G8: 8800
B10: feeding | C10: kWh/cow/year | D10: 652 | E10: =D10*(2/3) -> 434.66667 | F10: =D10*(1/3) -> 217.33333 | G10: 370 | H10: =G10*(2/3) -> 246.66667 | I10: =G10*(1/3) -> 123.33333 | J10: <--- Assumes double feed consuption for dairy cows compared to recruitment
B11: ventilation | C11: kWh/cow/year | D11: 3 | E11: =(E$17-E$10-E$12-E$14) * (D11/SUM(D$11,D$13,D$15)) -> 2.1908736 | F11: =(F$17-F$10-F$12-F$14) * (D11/SUM(D$11,D$13,D$15)) -> 0.80912644 | G11: 74 | H11: =(H$17-H$10-H$12-H$14) * (G11/SUM(G$11,G$13,G$15)) -> 42.039127 | I11: =(I$17-I$10-I$12-I$14) * (G11/SUM(G$11,G$13,G$15)) -> 31.960873
B12: manure mgmt | C12: kWh/cow/year | D12: 40 | E12: =D12*(2/3) -> 26.666667 | F12: =D12*(1/3) -> 13.333333 | G12: 31 | H12: =G12*(2/3) -> 20.666667 | I12: =G12*(1/3) -> 10.333333 | J12: <--- Assumes double feed consuption for dairy cows compared to recruitment
B13: lighting | C13: kWh/cow/year | D13: 216 | E13: =(E$17-E$10-E$12-E$14) * (D13/SUM(D$11,D$13,D$15)) -> 157.7429 | F13: =(F$17-F$10-F$12-F$14) * (D13/SUM(D$11,D$13,D$15)) -> 58.257103 | G13: 224 | H13: =(H$17-H$10-H$12-H$14) * (G13/SUM(G$11,G$13,G$15)) -> 127.25357 | I13: =(I$17-I$10-I$12-I$14) * (G13/SUM(G$11,G$13,G$15)) -> 96.746426
B14: milking | C14: kWh/cow/year | D14: 386 | E14: =D14 -> 386 | F14: 0 | G14: 406 | H14: =G14 -> 406 | I14: 0 | J14: <--- Milking only dairy cows
B15: other | C15: kWh/cow/year | D15: 216 | E15: =(E$17-E$10-E$12-E$14) * (D15/SUM(D$11,D$13,D$15)) -> 157.7429 | F15: =(F$17-F$10-F$12-F$14) * (D15/SUM(D$11,D$13,D$15)) -> 58.257103 | G15: 145 | H15: =(H$17-H$10-H$12-H$14) * (G15/SUM(G$11,G$13,G$15)) -> 82.373965 | I15: =(I$17-I$10-I$12-I$14) * (G15/SUM(G$11,G$13,G$15)) -> 62.626035
B17: total | C17: kWh/cow/year | D17: =SUM(D10:D15) -> 1513 | E17: =D17*(1-D$20/100) -> 1165.01 | F17: =D17*(D$20/100) -> 347.99 | G17: =SUM(G10:G15) -> 1250 | H17: =G17*(1-G$20/100) -> 925 | I17: =G17*(G$20/100) -> 325
B18: of which electricity | C18: kWh/cow/year | D18: 868 | E18: =SUM(E11:E15) -> 730.34333 | F18: =SUM(F11:F15) -> 130.65667 | G18: 994 | H18: =SUM(H11:H15) -> 678.33333 | I18: =SUM(I11:I15) -> 201.66667
D19: =D18/D17 -> 0.57369465 | E19: =E18/E17 -> 0.62689877 | F19: =F18/F17 -> 0.37546098 | G19: =G18/G17 -> 0.7952 | H19: =H18/H17 -> 0.73333333 | I19: =I18/I17 -> 0.62051282
B20: share for recruitment | C20: % | D20: 23 | G20: 26
B22: Used values
D23: kWh/head/year | E23: kWh/kg milk
B24: stable machinery | C24: dairy cows | D24: 0 | E24: =(E10+H10)/(D8+G8) -> 0.035302245
B25: stable heating | C25: dairy cows | D25: 0 | E25: 0
B26: stable misc | C26: dairy cows | D26: =SUM(E11:E13,E15,H11:H13,H15)/2 -> 308.33833 | E26: 0
B27: stable milking | C27: dairy cows | D27: 0 | E27: =(E14+H14)/(D8+G8) -> 0.041036269
B29: stable machinery | C29: recr. | D29: =SUM(F10,I10)/2 -> 170.33333 | E29: 0
B30: stable heating | C30: recr. | D30: 0 | E30: 0
B31: stable misc | C31: recr. | D31: =SUM(F11:F13,F15,I11:I13,I15) -> 332.32333 | E31: 0
B32: stable milking | C32: recr. | D32: 0 | E32: 0
B34: Pigs
J35: Hörndahl & Neuman (2012)
J36: Gård | M36: Gård F | N36: Gård G | O36: Gård H | P36: Gård Y
B37: Landquist et al (2020) | J37: Beskrivning | M37: Hel intergrerad FTS-system 96 SIP* kWh/SIP*, år | N37: Enhetsbox 480 SIP* kWh/SIP*, år | O37: Slaktgris 1160 platser kWh/djurpl, omg | P37: Hel integrerad Tillväxtboxsyst. 254 SIP* kWh/SIP*, år
B38: Fördelning energislag, kWh | D38: Per smågris | E38: Per slaktgris | J38: Utfodring | M38: 90 | N38: 13 | O38: 2.3 | P38: 242
B39: Total energi | D39: 50 | E39: 0.4 | J39: Ventilation | M39: 654 | N39: 80 | O39: 9.6 | P39: Ej spec
B40: El | D40: 36.5 | E40: 0.28 | J40: Utgödsling | M40: 11 | N40: 12 | O40: 0.1 | P40: 43.2
B41: Biobränsle | D41: 9.5 | E41: 0.06 | J41: Belysning | M41: 244 | N41: 78 | O41: 1.8 | P41: 340
B42: Diesel | D42: 3.5 | E42: 0.04 | J42: Uppvärmning värmkälla | M42: 992 | N42: 93 | O42: 4.2 | P42: Ej spec värmepump
B43: E01 | D43: 0.5 | E43: 0.02 | M43: =M42/M49 -> 0.40772709 | N43: =N42/N49 -> 0.13497823 | O43: =O42/O49 -> 0.21319797 | Q43: =AVERAGE(M43:O43) -> 0.25196776
C44: Per SIP | D44: =D39*33+E39*26 -> 1660.4 | E44: kWh | J44: Vatten | M44: Ingår i Övrigt | N44: 4 | O44: Ingår ej | P44: Ingår
J45: Tvätt | M45: 79 | N45: 7 | O45: 0.7 | P45: Ej spec
B46: Used values | J46: Rekrytering, totalt | M46: - | N46: 11 | O46: - | P46: Ej spec
D47: kWh per | E47: Energy source | J47: Personal | M47: 38 | N47: 15 | O47: Ingår i Övrigt | P47: Ej spec
...

Sheet Sheet1
E3: Utfodring | F3: 90 | G3: 13 | H3: 2.3 | I3: 242
E4: Ventilation | F4: 654 | G4: 80 | H4: 9,6 | I4: Ej spec
E5: Utgödsling | F5: 11 | G5: 12 | H5: 0,1 | I5: 43,2
E6: Belysning | F6: 2441) | G6: 782) | H6: 1,83) | I6: 3404)
E7: Uppvärmning värmkälla | G7: 992 olja | I7: 93 värmepump | O7: 4,2 olja (före insättning) | S7: Ej spec värmepump
E8: Vatten | H8: Ingår i Övrigt | K8: 4 | P8: Ingår ej | T8: Ingår
E9: Tvätt | H9: 79 | K9: 7 | P9: 0,7 | T9: Ej spec
E10: Rekrytering, totalt | H10: - | K10: 11 | P10: - | T10: Ej spec
E11: Personal | H11: 38 | K11: 15 | P11: Ingår i Övrigt | T11: Ej spec
E12: Övrigt | H12: 164 | K12: 66 | P12: 1,0 | T12: Ej spec
E13: Summa | H13: 2433 | K13: 689 | P13: 19,7 | T13: 1252
E14: Därav el | H14: 1441 | K14: 689 | P14: 15,5 | T14: 1218
E15: Övrig utrustning 23 Drankpump | L15: 38 Kvarn | Q15: - Kvarn ingår i utfodringen
E16: Betäcknings avd | H16: Isolerad | K16: Isolerad | P16: - | T16: Isolerad
E17: Sin avd Slaktgris Byggår | H17: Isolerad Isolerad 1998 | K17: Oisolerad 1999 | P17: - Isolerad 1998 | T17: Isolerad Isolerad 2008

Sheet Sheet2
C3: Gård | F3: Gård F | G3: Gård G | H3: Gård H | I3: Gård Y
C4: Beskrivning | F4: Hel intergrerad FTS-system 96 SIP* kWh/SIP*, år | G4: Enhetsbox 480 SIP* kWh/SIP*, år | H4: Slaktgris 1160 platser kWh/djurpl, omg | I4: Hel integrerad Tillväxtboxsyst. 254 SIP* kWh/SIP*, år
C5: Utfodring | F5: 90 | G5: 13 | H5: 2.3 | I5: 242
C6: Ventilation | F6: 654 | G6: 80 | H6: 9.6 | I6: Ej spec
C7: Utgödsling | F7: 11 | G7: 12 | H7: 0.1 | I7: 43.2
C8: Belysning | F8: 244 | G8: 78 | H8: 1.8 | I8: 340
C9: Uppvärmning värmkälla | F9: 992 | G9: 93 | H9: 4.2 | I9: Ej spec värmepump
C10: Vatten | F10: Ingår i Övrigt | G10: 4 | H10: Ingår ej | I10: Ingår
C11: Tvätt | F11: 79 | G11: 7 | H11: 0.7 | I11: Ej spec
C12: Rekrytering, totalt | F12: - | G12: 11 | H12: - | I12: Ej spec
C13: Personal | F13: 38 | G13: 15 | H13: Ingår i Övrigt | I13: Ej spec
C14: Övrigt | F14: 164 | G14: 66 | H14: 1 | I14: Ej spec
C15: Summa | F15: 2433 | G15: 689 | H15: 19.7 | I15: 1252
C16: Därav el | F16: 1441 | G16: 689 | H16: 15.5 | I16: 1218
C17: Övrig utrustning | F17: 23 | G17: 38 | H17: - | I17: Kvarn ingår i utfodringen
C18: Betäcknings avd | F18: Isolerad | G18: Isolerad | H18: - | I18: Isolerad
C19: Sin avd | F19: Isolerad | G19: Oisolerad | H19: - | I19: Isolerad
C20: Slaktgris | F20: Isolerad | H20: Isolerad | I20: Isolerad
C21: Byggår | F21: 1998 | G21: 1999 | H21: 1998 | I21: 2008

Sheet references
A1: Ahlgren et al. (2022) Miljöpåverkan av svensk nöt- och lammköttsproduktion. RISE Rapport 2022:143
A2: Jordbruksverket (2022) Jordbruksstatistisk sammanställning 2022, JO1901, https://jordbruksverket.se/om-jordbruksverket/jordbruksverkets-officiella-statistik/jordbruksverkets-statistikrapporter/statistik/2022-07-05-jordbruksstatistisk---sammanstallning-2022
A3: Baky, A., Sundberg, M., & Brown, N. (2010). Kartläggning av jordbrukets energianvändning [Survey of energy use in Swedish agriculture]. Retrieved from JTI, Uppsala: https://www.diva-portal.org/smash/get/diva2:959931/FULLTEXT01.pdf
A4: Engström, J., & Lagnelöv, O. (2017). Battery Electric Autonomous Agricultural Machine - Simulation of all operations on a Swedish farm. http://www.diva-portal.org/smash/record.jsf?pid=diva2%3A1144170&dswid=-6740
A5: Grisso, R., Perumpral, J. V., Vaughan, D., Roberson, G. T., & Pitman, R. (2010). Predicting Tractor Diesel Fuel Consumption. In (Vol. Pub. 442-073). College of Agriculture and Life Sciences: Virginia Polytech Institute and State University.https://vtechworks.lib.vt.edu/bitstream/handle/10919/47472/442-073_pdf.pdf?sequence=1&isAllowed=y
A6: Kitani, A., Jungbluth, T., Peart, R. M., Ramdani, A., Badger, P. C., & Clark, N. R. (1999). CIGR Handbook of Agricultural Engineering (A. Kitani Ed. Vol. 5 - Energy and Biomass Engineering): American Society of Agricultural Engineers.
A7: Lindgren, M., Pettersson, O., Hansson, P.-A., & Norén, O. (2002). Jordbruks- och anläggningsmaskiners motorbelastning och avgasemissioner [Engine load pattern and engine exhaust gas emissions from off-road vehicles]. Retrieved from http://www.diva-portal.org/smash/record.jsf?pid=diva2%3A959556
A8: Maskinkalkylgruppen. (2020). Maskinkostnader 2020 [Machine costs 2020]. Retrieved from Maskinkalkylgruppen: http://maskinkostnader.se/
A9: Nilsson, B. (1976). Planering av jordbrukets maskinsystem. Problem, modeller och tillämpningar. [The planning of farm machinery systems - Problems, models and applications]. In (Vol. Report no. 38). Uppsala, Sweden: Swedish University of Agricultural Sciences
A10: Reif, K., & Dietsche, K.-H. (2014). Bosch Automotive Handbook (K. Reif Ed. 9th ed.). Robert Bosch GmbH, Germany: John Wiley & Sons Ltd.
A11: SAE. (2000). Agricultural Machinery Management Data. In. ASABE, St. Joseph, MI, USA: American Society of Agricultural Engineers
A12: Hörndahl, Torsten & Neuman, Lars. (2012). Energiförbrukning I jordbrukets driftsbyggnader - En kartläggning av 16 gårdar 2005-2006 kompletterat med mätningar på två gårdar 2010-2012. Sveriges lantbruksuniversitet Fakulteten för landskapsplanering, trädgårds- och jordbruksvetenskap. Rapport 2012:19
... A14: Sonesson et al (2008) Livscykelanalys (LCA) av svenska ägg (ver.2). SIK-rapport Nr 783 2008
