Workbook

Sheet references
A1: Statistics Netherlands (2012). Standardised calculation methods for animal manure and nutrients - Standard data 1990–2008. The Hague, Netherlands. https://www.cbs.nl/-/media/imported/documents/2012/26/2012-c173-pub.pdf
A2: Nilsson & Bernesson (2009). Straw as fuel - Part 1: Available resources and harvest times. SLU

Sheet default
A1: f_species | B1: f_prod_system | C1: f_breed | D1: f_animal | E1: f_animal_prod | F1: f_MMS | G1: f_element | H1: f_compound | I1: f_feed | J1: parameter | K1: value | L1: unit | M1: description | N1: source
A2: Manure management systems shares
A3: cattle | C3: dairy | D3: cows | F3: liquid | J3: mms_share | K3: =INDEX(MMS!$S$9:$AF$13,MATCH(F3,MMS!$R$9:$R$13,0),MATCH(A3&C3&D3,MMS!$S$8:$AF$8,0)) -> 83.800623 | L3: % | N3: Swedish IIR 2023 Table 5-5
A4: cattle | C4: dairy | D4: cows | F4: solid | J4: mms_share | K4: =INDEX(MMS!$S$9:$AF$13,MATCH(F4,MMS!$R$9:$R$13,0),MATCH(A4&C4&D4,MMS!$S$8:$AF$8,0)) -> 9.3457944 | L4: % | N4: Swedish IIR 2023 Table 5-6
A5: cattle | C5: dairy | D5: cows | F5: deep litter | J5: mms_share | K5: =INDEX(MMS!$S$9:$AF$13,MATCH(F5,MMS!$R$9:$R$13,0),MATCH(A5&C5&D5,MMS!$S$8:$AF$8,0)) -> 1.2906097 | L5: % | N5: Swedish IIR 2023 Table 5-7
A6: cattle | C6: dairy | D6: cows | F6: anaerobic digestion | J6: mms_share | K6: =INDEX(MMS!$S$9:$AF$13,MATCH(F6,MMS!$R$9:$R$13,0),MATCH(A6&C6&D6,MMS!$S$8:$AF$8,0)) -> 5.5629729 | L6: % | N6: Swedish IIR 2023 Table 5-8 and 5-9
A7: cattle | C7: dairy | D7: cows | F7: composting | J7: mms_share | K7: =INDEX(MMS!$S$9:$AF$13,MATCH(F7,MMS!$R$9:$R$13,0),MATCH(A7&C7&D7,MMS!$S$8:$AF$8,0)) -> 0 | L7: % | N7: Swedish IIR 2023 Table 5-8
A8: cattle | C8: beef | D8: cows | F8: liquid | J8: mms_share | K8: =INDEX(MMS!$S$9:$AF$13,MATCH(F8,MMS!$R$9:$R$13,0),MATCH(A8&C8&D8,MMS!$S$8:$AF$8,0)) -> 22.222222 | L8: % | N8: Swedish IIR 2023 Table 5-5
A9: cattle | C9: beef | D9: cows | F9: solid | J9: mms_share | K9: =INDEX(MMS!$S$9:$AF$13,MATCH(F9,MMS!$R$9:$R$13,0),MATCH(A9&C9&D9,MMS!$S$8:$AF$8,0)) -> 30.405405 | L9: % | N9: Swedish IIR 2023 Table 5-6
A10: cattle | C10: beef | D10: cows | F10: deep litter | J10: mms_share | K10: =INDEX(MMS!$S$9:$AF$13,MATCH(F10,MMS!$R$9:$R$13,0),MATCH(A10&C10&D10,MMS!$S$8:$AF$8,0)) -> 44.81982 | L10: % | N10: Swedish IIR 2023 Table 5-7
A11: cattle | C11: beef | D11: cows | F11: anaerobic digestion | J11: mms_share | K11: =INDEX(MMS!$S$9:$AF$13,MATCH(F11,MMS!$R$9:$R$13,0),MATCH(A11&C11&D11,MMS!$S$8:$AF$8,0)) -> 2.5525526 | L11: % | N11: Swedish IIR 2023 Table 5-8 and 5-9
A12: cattle | C12: beef | D12: cows | F12: composting | J12: mms_share | K12: =INDEX(MMS!$S$9:$AF$13,MATCH(F12,MMS!$R$9:$R$13,0),MATCH(A12&C12&D12,MMS!$S$8:$AF$8,0)) -> 0 | L12: % | N12: Swedish IIR 2023 Table 5-8
A13: cattle | D13: heifers | F13: liquid | J13: mms_share | K13: =INDEX(MMS!$S$9:$AF$13,MATCH(F13,MMS!$R$9:$R$13,0),MATCH(A13&C13&D13,MMS!$S$8:$AF$8,0)) -> 50.379049 | L13: % | N13: Swedish IIR 2023 Table 5-5
A14: cattle | D14: heifers | F14: solid | J14: mms_share | K14: =INDEX(MMS!$S$9:$AF$13,MATCH(F14,MMS!$R$9:$R$13,0),MATCH(A14&C14&D14,MMS!$S$8:$AF$8,0)) -> 19.090283 | L14: % | N14: Swedish IIR 2023 Table 5-6
A15: cattle | D15: heifers | F15: deep litter | J15: mms_share | K15: =INDEX(MMS!$S$9:$AF$13,MATCH(F15,MMS!$R$9:$R$13,0),MATCH(A15&C15&D15,MMS!$S$8:$AF$8,0)) -> 26.533425 | L15: % | N15: Swedish IIR 2023 Table 5-7
A16: cattle | D16: heifers | F16: anaerobic digestion | J16: mms_share | K16: =INDEX(MMS!$S$9:$AF$13,MATCH(F16,MMS!$R$9:$R$13,0),MATCH(A16&C16&D16,MMS!$S$8:$AF$8,0)) -> 3.9972433 | L16: % | N16: Swedish IIR 2023 Table 5-8 and 5-9
A17: cattle | D17: heifers | F17: composting | J17: mms_share | K17: =INDEX(MMS!$S$9:$AF$13,MATCH(F17,MMS!$R$9:$R$13,0),MATCH(A17&C17&D17,MMS!$S$8:$AF$8,0)) -> 0 | L17: % | N17: Swedish IIR 2023 Table 5-8
A18: cattle | D18: steers | F18: liquid | J18: mms_share | K18: =INDEX(MMS!$S$9:$AF$13,MATCH(F18,MMS!$R$9:$R$13,0),MATCH(A18&C18&D18,MMS!$S$8:$AF$8,0)) -> 50.379049 | L18: % | N18: Swedish IIR 2023 Table 5-5
A19: cattle | D19: steers | F19: solid | J19: mms_share | K19: =INDEX(MMS!$S$9:$AF$13,MATCH(F19,MMS!$R$9:$R$13,0),MATCH(A19&C19&D19,MMS!$S$8:$AF$8,0)) -> 19.090283 | L19: % | N19: Swedish IIR 2023 Table 5-6
A20: cattle | D20: steers | F20: deep litter | J20: mms_share | K20: =INDEX(MMS!$S$9:$AF$13,MATCH(F20,MMS!$R$9:$R$13,0),MATCH(A20&C20&D20,MMS!$S$8:$AF$8,0)) -> 26.533425 | L20: % | N20: Swedish IIR 2023 Table 5-7
A21: cattle | D21: steers | F21: anaerobic digestion | J21: mms_share | K21: =INDEX(MMS!$S$9:$AF$13,MATCH(F21,MMS!$R$9:$R$13,0),MATCH(A21&C21&D21,MMS!$S$8:$AF$8,0)) -> 3.9972433 | L21: % | N21: Swedish IIR 2023 Table 5-8 and 5-9
A22: cattle | D22: steers | F22: composting | J22: mms_share | K22: =INDEX(MMS!$S$9:$AF$13,MATCH(F22,MMS!$R$9:$R$13,0),MATCH(A22&C22&D22,MMS!$S$8:$AF$8,0)) -> 0 | L22: % | N22: Swedish IIR 2023 Table 5-8
A23: cattle | D23: bulls | F23: liquid | J23: mms_share | K23: =INDEX(MMS!$S$9:$AF$13,MATCH(F23,MMS!$R$9:$R$13,0),MATCH(A23&C23&D23,MMS!$S$8:$AF$8,0)) -> 44.8394 | L23: % | N23: Swedish IIR 2023 Table 5-5
A24: cattle | D24: bulls | F24: solid | J24: mms_share | K24: =INDEX(MMS!$S$9:$AF$13,MATCH(F24,MMS!$R$9:$R$13,0),MATCH(A24&C24&D24,MMS!$S$8:$AF$8,0)) -> 19.914347 | L24: % | N24: Swedish IIR 2023 Table 5-6
... A37: cattle | D37: breeding bulls | F37: composting | J37: mms_share | K37: =INDEX(MMS!$S$9:$AF$13,MATCH(F37,MMS!$R$9:$R$13,0),MATCH(A37&C37&D37,MMS!$S$8:$AF$8,0)) -> 0 | L37: % | N37: Swedish IIR 2023 Table 5-8
A38: horses | F38: liquid | J38: mms_share | K38: =INDEX(MMS!$S$9:$AF$13,MATCH(F38,MMS!$R$9:$R$13,0),MATCH(A38&C38&D38,MMS!$S$8:$AF$8,0)) -> 0 | L38: % | N38: Swedish IIR 2023 Table 5-5
A39: horses | F39: solid | J39: mms_share | K39: =INDEX(MMS!$S$9:$AF$13,MATCH(F39,MMS!$R$9:$R$13,0),MATCH(A39&C39&D39,MMS!$S$8:$AF$8,0)) -> 66 | L39: % | N39: Swedish IIR 2023 Table 5-6
A40: horses | F40: deep litter | J40: mms_share | K40: =INDEX(MMS!$S$9:$AF$13,MATCH(F40,MMS!$R$9:$R$13,0),MATCH(A40&C40&D40,MMS!$S$8:$AF$8,0)) -> 4 | L40: % | N40: Swedish IIR 2023 Table 5-7
A41: horses | F41: anaerobic digestion | J41: mms_share | K41: =INDEX(MMS!$S$9:$AF$13,MATCH(F41,MMS!$R$9:$R$13,0),MATCH(A41&C41&D41,MMS!$S$8:$AF$8,0)) -> 0 | L41: % | N41: Swedish IIR 2023 Table 5-8 and 5-9
A42: horses | F42: composting | J42: mms_share | K42: =INDEX(MMS!$S$9:$AF$13,MATCH(F42,MMS!$R$9:$R$13,0),MATCH(A42&C42&D42,MMS!$S$8:$AF$8,0)) -> 30 | L42: % | N42: Swedish IIR 2023 Table 5-8
A43: sheep | F43: liquid | J43: mms_share | K43: =INDEX(MMS!$S$9:$AF$13,MATCH(F43,MMS!$R$9:$R$13,0),MATCH(A43&C43&D43,MMS!$S$8:$AF$8,0)) -> 0 | L43: % | N43: Swedish IIR 2023 Table 5-5
A44: sheep | F44: solid | J44: mms_share | K44: =INDEX(MMS!$S$9:$AF$13,MATCH(F44,MMS!$R$9:$R$13,0),MATCH(A44&C44&D44,MMS!$S$8:$AF$8,0)) -> 100 | L44: % | N44: Swedish IIR 2023 Table 5-6
A45: sheep | F45: deep litter | J45: mms_share | K45: =INDEX(MMS!$S$9:$AF$13,MATCH(F45,MMS!$R$9:$R$13,0),MATCH(A45&C45&D45,MMS!$S$8:$AF$8,0)) -> 0 | L45: % | N45: Swedish IIR 2023 Table 5-7
A46: sheep | F46: anaerobic digestion | J46: mms_share | K46: =INDEX(MMS!$S$9:$AF$13,MATCH(F46,MMS!$R$9:$R$13,0),MATCH(A46&C46&D46,MMS!$S$8:$AF$8,0)) -> 0 | L46: % | N46: Swedish IIR 2023 Table 5-8 and 5-9
A47: sheep | F47: composting | J47: mms_share | K47: =INDEX(MMS!$S$9:$AF$13,MATCH(F47,MMS!$R$9:$R$13,0),MATCH(A47&C47&D47,MMS!$S$8:$AF$8,0)) -> 0 | L47: % | N47: Swedish IIR 2023 Table 5-8
A48: pigs | F48: liquid | J48: mms_share | K48: =INDEX(MMS!$S$9:$AF$13,MATCH(F48,MMS!$R$9:$R$13,0),MATCH(A48&C48&D48,MMS!$S$8:$AF$8,0)) -> 47.115705 | L48: % | N48: Swedish IIR 2023 Table 5-5
A49: pigs | F49: solid | J49: mms_share | K49: =INDEX(MMS!$S$9:$AF$13,MATCH(F49,MMS!$R$9:$R$13,0),MATCH(A49&C49&D49,MMS!$S$8:$AF$8,0)) -> 27.875959 | L49: % | N49: Swedish IIR 2023 Table 5-6
... A52: pigs | F52: composting | J52: mms_share | K52: =INDEX(MMS!$S$9:$AF$13,MATCH(F52,MMS!$R$9:$R$13,0),MATCH(A52&C52&D52,MMS!$S$8:$AF$8,0)) -> 0 | L52: % | N52: Swedish IIR 2023 Table 5-8
A53: pigs | D53: growing pigs | F53: liquid | J53: mms_share | K53: =INDEX(MMS!$S$9:$AF$13,MATCH(F53,MMS!$R$9:$R$13,0),MATCH(A53&C53&D53,MMS!$S$8:$AF$8,0)) -> 79.533333 | L53: % | N53: Swedish IIR 2023 Table 5-5
A54: pigs | D54: growing pigs | F54: solid | J54: mms_share | K54: =INDEX(MMS!$S$9:$AF$13,MATCH(F54,MMS!$R$9:$R$13,0),MATCH(A54&C54&D54,MMS!$S$8:$AF$8,0)) -> 2.6666667 | L54: % | N54: Swedish IIR 2023 Table 5-6
...

Sheet MMS
B2: Source: Informative Inventory Report Sweden 2023. Submitted under the Convention on Long-Range Transboundary Air Pollution
R4: Excluding grazing
B5: species | C5: cattle | D5: cattle | E5: cattle | F5: cattle | G5: cattle | H5: cattle | I5: cattle | J5: horses | K5: sheep | L5: pigs | M5: pigs | N5: pigs | O5: poultry | P5: poultry | R5: species | S5: cattle | T5: cattle | U5: cattle | V5: cattle | W5: cattle | X5: cattle | Y5: cattle | Z5: horses | AA5: sheep | AB5: pigs | AC5: pigs | AD5: pigs | AE5: poultry | AF5: poultry
B6: breed | C6: dairy | D6: beef | P6: broiler | R6: breed | S6: dairy | T6: beef | AF6: broiler
B7: animal | C7: cows | D7: cows | E7: heifers | F7: steers | G7: bulls | H7: calves | I7: breeding bulls | M7: growing pigs | N7: finishing pigs | P7: broilers | R7: animal | S7: cows | T7: cows | U7: heifers | V7: steers | W7: bulls | X7: calves | Y7: breeding bulls | AC7: growing pigs | AD7: finishing pigs | AF7: broilers
B8: grazing | C8: =C27 -> 25.033333 | D8: =D27 -> 55.633333 | E8: =E27 -> 51.7 | F8: =E8 -> 51.7 | G8: =F27 -> 22.133333 | H8: =G27 -> 34.366667 | I8: =G8 -> 22.133333 | J8: =K27 -> 50 | K8: =I27 -> 50 | L8: 0 | M8: 0 | N8: 0 | O8: 0 | P8: 0 | R8: id | S8: =S5&S6&S7 -> cattledairycows | T8: =T5&T6&T7 -> cattlebeefcows | U8: =U5&U6&U7 -> cattleheifers | V8: =V5&V6&V7 -> cattlesteers | W8: =W5&W6&W7 -> cattlebulls | X8: =X5&X6&X7 -> cattlecalves | Y8: =Y5&Y6&Y7 -> cattlebreeding bulls | Z8: =Z5&Z6&Z7 -> horses | ... AF8: =AF5&AF6&AF7 -> poultrybroilerbroilers
B9: liquid | C9: =C40 -> 62.766667 | D9: =D40 -> 9.8666667 | E9: =E40 -> 24.366667 | F9: =E9 -> 24.366667 | G9: =F40 -> 34.9 | H9: =G40 -> 16.633333 | I9: =G9 -> 34.9 | J9: =J40 -> 0 | K9: =J40 -> 0 | L9: =I40 -> 47.1 | M9: =H40 -> 79.533333 | N9: =M9 -> 79.533333 | O9: =K40 -> 7.7 | P9: =L40 -> 0 | R9: liquid | S9: =C9/SUM(C$9:C$13)*100 -> 83.800623 | T9: =D9/SUM(D$9:D$13)*100 -> 22.222222 | U9: =E9/SUM(E$9:E$13)*100 -> 50.379049 | V9: =F9/SUM(F$9:F$13)*100 -> 50.379049 | W9: =G9/SUM(G$9:G$13)*100 -> 44.8394 | X9: =H9/SUM(H$9:H$13)*100 -> 25.355691 | Y9: =I9/SUM(I$9:I$13)*100 -> 44.8394 | Z9: =J9/SUM(J$9:J$13)*100 -> 0 | ... AF9: =P9/SUM(P$9:P$13)*100 -> 0
B10: solid | C10: =C53 -> 7 | D10: =D53 -> 13.5 | E10: =E53 -> 9.2333333 | F10: =E10 -> 9.2333333 | G10: =F53 -> 15.5 | H10: =G53 -> 13.333333 | I10: =G10 -> 15.5 | J10: =M53 -> 33 | K10: =J53 -> 50 | L10: =I53 -> 27.866667 | M10: =H53 -> 2.6666667 | N10: =M10 -> 2.6666667 | O10: =N53 -> 85.966667 | P10: =O53 -> 0 | R10: solid | S10: =C10/SUM(C$9:C$13)*100 -> 9.3457944 | T10: =D10/SUM(D$9:D$13)*100 -> 30.405405 | U10: =E10/SUM(E$9:E$13)*100 -> 19.090283 | V10: =F10/SUM(F$9:F$13)*100 -> 19.090283 | W10: =G10/SUM(G$9:G$13)*100 -> 19.914347 | X10: =H10/SUM(H$9:H$13)*100 -> 20.325203 | Y10: =I10/SUM(I$9:I$13)*100 -> 19.914347 | Z10: =J10/SUM(J$9:J$13)*100 -> 66 | ... AF10: =P10/SUM(P$9:P$13)*100 -> 0
B11: deep litter | C11: =C66 -> 0.96666667 | D11: =D66 -> 19.9 | E11: =E66 -> 12.833333 | F11: =E11 -> 12.833333 | G11: =F66 -> 24.533333 | H11: =G66 -> 33.833333 | I11: =G11 -> 24.533333 | J11: =K66 -> 2 | K11: =J66 -> 0 | L11: =I66 -> 15.2 | M11: =H66 -> 1.1666667 | N11: =M11 -> 1.1666667 | O11: =L66 -> 6.3333333 | P11: =M66 -> 100 | R11: deep litter | S11: =C11/SUM(C$9:C$13)*100 -> 1.2906097 | T11: =D11/SUM(D$9:D$13)*100 -> 44.81982 | U11: =E11/SUM(E$9:E$13)*100 -> 26.533425 | V11: =F11/SUM(F$9:F$13)*100 -> 26.533425 | W11: =G11/SUM(G$9:G$13)*100 -> 31.520343 | X11: =H11/SUM(H$9:H$13)*100 -> 51.575203 | Y11: =I11/SUM(I$9:I$13)*100 -> 31.520343 | Z11: =J11/SUM(J$9:J$13)*100 -> 4 | ... AF11: =P11/SUM(P$9:P$13)*100 -> 100
B12: anaerobic digestion | C12: =C80+C94 -> 4.1666667 | D12: =D80+D94 -> 1.1333333 | E12: =E80+E94 -> 1.9333333 | F12: =E12 -> 1.9333333 | G12: =F80+F94 -> 2.9 | H12: =G80+G94 -> 1.8 | I12: =G12 -> 2.9 | J12: 0 | K12: 0 | L12: =J80+J94 -> 9.8 | M12: =I80+I94 -> 16.633333 | N12: =M12 -> 16.633333 | O12: 0 | P12: 0 | R12: anaerobic digestion | S12: =C12/SUM(C$9:C$13)*100 -> 5.5629729 | T12: =D12/SUM(D$9:D$13)*100 -> 2.5525526 | U12: =E12/SUM(E$9:E$13)*100 -> 3.9972433 | V12: =F12/SUM(F$9:F$13)*100 -> 3.9972433 | W12: =G12/SUM(G$9:G$13)*100 -> 3.7259101 | X12: =H12/SUM(H$9:H$13)*100 -> 2.7439024 | Y12: =I12/SUM(I$9:I$13)*100 -> 3.7259101 | Z12: =J12/SUM(J$9:J$13)*100 -> 0 | ... AF12: =P12/SUM(P$9:P$13)*100 -> 0
B13: composting | C13: 0 | D13: 0 | E13: 0 | F13: =E13 -> 0 | G13: 0 | H13: 0 | I13: =G13 -> 0 | J13: =L80 -> 15 | K13: 0 | L13: 0 | M13: 0 | N13: 0 | O13: 0 | P13: 0 | R13: composting | S13: =C13/SUM(C$9:C$13)*100 -> 0 | T13: =D13/SUM(D$9:D$13)*100 -> 0 | U13: =E13/SUM(E$9:E$13)*100 -> 0 | V13: =F13/SUM(F$9:F$13)*100 -> 0 | W13: =G13/SUM(G$9:G$13)*100 -> 0 | X13: =H13/SUM(H$9:H$13)*100 -> 0 | Y13: =I13/SUM(I$9:I$13)*100 -> 0 | Z13: =J13/SUM(J$9:J$13)*100 -> 30 | ... AF13: =P13/SUM(P$9:P$13)*100 -> 0
B14: total | C14: =SUM(C8:C13) -> 99.933333 | D14: =SUM(D8:D13) -> 100.03333 | E14: =SUM(E8:E13) -> 100.06667 | F14: =SUM(F8:F13) -> 100.06667 | G14: =SUM(G8:G13) -> 99.966667 | H14: =SUM(H8:H13) -> 99.966667 | I14: =SUM(I8:I13) -> 99.966667 | J14: =SUM(J8:J13) -> 100 | ... P14: =SUM(P8:P13) -> 100 | R14: total | S14: =SUM(S9:S13) -> 100 | T14: =SUM(T9:T13) -> 100 | U14: =SUM(U9:U13) -> 100 | V14: =SUM(V9:V13) -> 100 | W14: =SUM(W9:W13) -> 100 | X14: =SUM(X9:X13) -> 100 | Y14: =SUM(Y9:Y13) -> 100 | Z14: =SUM(Z9:Z13) -> 100 | ... AF14: =SUM(AF9:AF13) -> 100
B16: Table 5-4. Livestock grazing periods (percent).
B17: Year | C17: Dairy cattle | D17: Suckler cows | E17: Heifers | F17: Bulls and steers | G17: Calves | H17: Swine | I17: Sheep, Goats | J17: Reindeer | K17: Horses | L17: Poultry
B18: 1990 | C18: 24.8 | D18: 48.3 | E18: 45.8 | F18: 36.7 | G18: 35 | H18: NO | I18: 50 | J18: 100 | K18: 50 | L18: NO
B19: 1995 | C19: 24.8 | D19: 48.3 | E19: 45.8 | F19: 36.7 | G19: 35 | H19: NO | I19: 50 | J19: 100 | K19: 50 | L19: NO
B20: 2000 | C20: 24.8 | D20: 51.7 | E20: 49.2 | F20: 36.7 | G20: 36.7 | H20: NO | I20: 50 | J20: 100 | K20: 50 | L20: NO
B21: 2005 | C21: 26.1 | D21: 58.9 | E21: 53.7 | F21: 30.2 | G21: 36.6 | H21: NO | I21: 50 | J21: 100 | K21: 50 | L21: NO
B22: 2010 | C22: 25 | D22: 54.1 | E22: 51.7 | F22: 26.4 | G22: 31.4 | H22: NO | I22: 50 | J22: 100 | K22: 50 | L22: NO
B23: 2015 | C23: 24.5 | D23: 52.1 | E23: 49.7 | F23: 18.6 | G23: 31.7 | H23: NO | I23: 50 | J23: 100 | K23: 50 | L23: NO
B24: 2019 | C24: 25.3 | D24: 57.4 | E24: 52.7 | F24: 23.9 | G24: 35.7 | H24: NO | I24: 50 | J24: 100 | K24: 50 | L24: NO
B25: 2020 | C25: 25.3 | D25: 57.4 | E25: 52.7 | F25: 23.9 | G25: 35.7 | H25: NO | I25: 50 | J25: 100 | K25: 50 | L25: NO
B26: 2021 | C26: 25.3 | D26: 57.4 | E26: 52.7 | F26: 23.9 | G26: 35.7 | H26: NO | I26: 50 | J26: 100 | K26: 50 | L26: NO
B27: Avg. | C27: =AVERAGE(C23:C25) -> 25.033333 | D27: =AVERAGE(D23:D25) -> 55.633333 | E27: =AVERAGE(E23:E25) -> 51.7 | F27: =AVERAGE(F23:F25) -> 22.133333 | G27: =AVERAGE(G23:G25) -> 34.366667 | I27: =AVERAGE(I23:I25) -> 50 | J27: =AVERAGE(J23:J25) -> 100 | K27: =AVERAGE(K23:K25) -> 50
B29: Table 5-5. Liquid waste management systems (percent).
B30: Year | C30: Dairy cattle | D30: Suckler cows | E30: Heifers | F30: Bulls and steers | G30: Calves | H30: Pigs for meat production | I30: Other swine | J30: Sheep, goats, horses, reindeer and fur-bearing | K30: Laying Hens, Chickens | L30: Slaughter Chickens, Tur- keys
B31: 1990 | C31: 22.6 | D31: 15.5 | E31: 16.3 | F31: 19 | G31: 19.5 | H31: 44 | I31: 44 | J31: 0 | K31: 25 | L31: 0
B32: 1995 | C32: 30.6 | D32: 21 | E32: 22 | F32: 25.8 | G32: 26.5 | H32: 63 | I32: 63 | J32: 0 | K32: 25 | L32: 0
B33: 2000 | C33: 39 | D33: 12.5 | E33: 13.2 | F33: 16.4 | G33: 16.4 | H33: 80.5 | I33: 25.8 | J33: 0 | K33: 25 | L33: 0
B34: 2005 | C34: 50.8 | D34: 5.9 | E34: 19.6 | F34: 22.5 | G34: 18.9 | H34: 91.3 | I34: 31.8 | J34: 0 | K34: 20.8 | L34: 0
B35: 2010 | C35: 57.1 | D35: 11.2 | E35: 22.3 | F35: 28.6 | G35: 16.8 | H35: 91.3 | I35: 60.4 | J35: 0 | K35: 12 | L35: 0
B36: 2015 | C36: 60.4 | D36: 10 | E36: 24.9 | F36: 31.4 | G36: 16.1 | H36: 81.4 | I36: 49.7 | J36: 0 | K36: 9.3 | L36: 0
B37: 2019 | C37: 64.1 | D37: 9.8 | E37: 24.2 | F37: 36.7 | G37: 16.9 | H37: 78.9 | I37: 46 | J37: 0 | K37: 6.9 | L37: 0
B38: 2020 | C38: 63.8 | D38: 9.8 | E38: 24 | F38: 36.6 | G38: 16.9 | H38: 78.3 | I38: 45.6 | J38: 0 | K38: 6.9 | L38: 0
B39: 2021 | C39: 63.7 | D39: 9.7 | E39: 24 | F39: 36.5 | G39: 16.8 | H39: 77.8 | I39: 45.4 | J39: 0 | K39: 6.9 | L39: 0
B40: Avg. | C40: =AVERAGE(C36:C38) -> 62.766667 | D40: =AVERAGE(D36:D38) -> 9.8666667 | E40: =AVERAGE(E36:E38) -> 24.366667 | F40: =AVERAGE(F36:F38) -> 34.9 | G40: =AVERAGE(G36:G38) -> 16.633333 | H40: =AVERAGE(H36:H38) -> 79.533333 | I40: =AVERAGE(I36:I38) -> 47.1 | J40: =AVERAGE(J36:J38) -> 0 | ... L40: =AVERAGE(L36:L38) -> 0
B42: Table 5-6. Solid waste management systems (percent).
B43: Year | C43: Dairy cattle | D43: Suckler cows | E43: Heifers | F43: Bulls and steers | G43: Calves | H43: Pigs for meat production | I43: Other swine | J43: Sheep, goats | K43: Reindeer | L43: Fur-bearing animals | M43: Horses | N43: Laying Hens, Chickens | O43: Slaughter Chickens, Turkeys
B44: 1990 | C44: 51.9 | D44: 28.9 | E44: 30.3 | F44: 35.5 | G44: 36.4 | H44: 54 | I44: 45 | J44: 50 | K44: 0 | L44: 100 | M44: 33 | N44: 55 | O44: 0
B45: 1995 | C45: 43.8 | D45: 23.4 | E45: 24.5 | F45: 28.7 | G45: 29.4 | H45: 35 | I45: 26 | J45: 50 | K45: 0 | L45: 100 | M45: 33 | N45: 55 | O45: 0
...
