Workbook

Sheet default
A1: f_prod_system | B1: f_animal | C1: f_feed | D1: parameter | E1: value | F1: unit | G1: description | H1: source
A2: Fertility
A3: conventional | D3: litters_per_sow | E3: =AVERAGE(2.23,2.24,2.23,2.23,2.24) -> 2.234 | F3: nr | H3: WinPig 2016-2020
A4: organic | D4: litters_per_sow | E4: =2.1/2.3*E3 -> 2.0397391 | F4: nr | H4: org/conv ratio from Zira et al 2020
A5: conventional | D5: live_per_litter | E5: =AVERAGE(14,14.5,14.6,14.8,15) -> 14.58 | F5: nr | H5: WinPig 2016-2020
A6: organic | D6: live_per_litter | E6: =12.4/14.6*E5 -> 12.383014 | F6: nr | H6: org/conv ratio from Zira et al 2020
A7: conventional | D7: dead_per_litter | E7: =AVERAGE(1.2,1.2,1.3,1.3,1.3) -> 1.26 | F7: nr | H7: WinPig 2016-2020
A8: organic | D8: dead_per_litter | E8: =E7/E5*E6 -> 1.070137 | F8: nr | G8: Assume same proportion dead/live as in conventional
A9: conventional | D9: age_at_first_farrowing | E9: 354 | F9: days | H9: Zira et al 2020
A10: organic | D10: age_at_first_farrowing | E10: 367 | F10: days | H10: Zira et al 2020
A11: conventional | D11: replacement_rate | E11: 50 | F11: % | G11: per year | H11: Zira et al 2020
A12: organic | D12: replacement_rate | E12: 40 | F12: % | G12: per year | H12: Zira et al 2020
D13: gestation_period | E13: 115 | F13: days
D14: boars_per_sows+gilts | E14: 0.011 | F14: nr | G14: calculated from nr of sows and boars in national statistics | H14: JO0103F01
A16: Live weights
D17: birth_weight | E17: 1.5 | F17: kg | H17: Svensson, Ohlsson & Mattsson. (2011). Kan grisar med låg födelsevikt bli lönsamma tillväxt- och slaktgrisar?. Svenska Pig Nr 49 Maj 2011
D18: live_weight_weaning | E18: 10 | F18: kg | G18: branchstandard
D19: live_weight_delivery | E19: 30 | F19: kg | G19: branchstandard | H19: WinPig 2016-2020
B20: sows | D20: live_weight | E20: =E45/0.75 -> 240.64979 | F20: kg | G20: calculated from slughter weight assuming 75% slaughter yield
B21: boars | D21: live_weight | E21: =E46/0.75 -> 205.63847 | F21: kg | G21: calculated from slughter weight assuming 75% slaughter yield
D22: live_weight_slaughter | E22: =E47/0.75 -> 122.41259 | F22: kg | G22: calculated from slughter weight assuming 75% slaughter yield
A23: Growth stages
A24: conventional | D24: weaning_age | E24: 33 | F24: days | H24: Zira et al 2020
A25: organic | D25: weaning_age | E25: 42 | F25: days | H25: Zira et al 2020
A26: conventional | D26: post_weaning_nursing_period | E26: 42 | F26: days | H26: Zira et al 2020
A27: organic | D27: post_weaning_nursing_period | E27: 38.5 | F27: days | H27: Zira et al 2020
A28: conventional | D28: growing_period | E28: 37 | F28: days | H28: Zira et al 2020
A29: organic | D29: growing_period | E29: 38 | F29: days | H29: Zira et al 2020
A30: conventional | D30: finishing_period | E30: 67 | F30: days | H30: Zira et al 2020
A31: organic | D31: finishing_period | E31: 68 | F31: days | H31: Zira et al 2020
A33: Mortality
A34: conventional | D34: mortality_0towean | E34: =AVERAGE(17.1,16.9,17.6,17.7,17.2) -> 17.3 | F34: % | H34: WinPig 2016-2020
A35: organic | D35: mortality_0towean | E35: =21/18*E34 -> 20.183333 | F35: % | H35: org/conv ratio from Zira et al 2020
A36: conventional | D36: mortality_weantodelivery | E36: =AVERAGE(2.1,2,2,2,2) -> 2.02 | F36: % | H36: WinPig 2016-2020
A37: organic | D37: mortality_weantodelivery | E37: =4/2*E36 -> 4.04 | F37: % | H37: org/conv ratio from Zira et al 2020
B38: sows | D38: mortality | E38: 7 | F38: % | G38: per year | H38: Zira et al 2020
A39: conventional | B39: growing pigs | D39: mortality | E39: 1 | F39: % | H39: Zira et al 2020
A40: organic | B40: growing pigs | D40: mortality | E40: 1.9 | F40: % | H40: Zira et al 2020
A41: conventional | B41: finishing pigs | D41: mortality | E41: 1.8 | F41: % | H41: Zira et al 2020
A42: organic | B42: finishing pigs | D42: mortality | E42: 1.6 | F42: % | H42: Zira et al 2020
...

Sheet feed rations
C5: Fodersammansättning till sugga, smågris och slaktgris
C6: Råvara | D6: Kg råvara per djurslag | M6: Feed rations, kg dry matter | Q6: Feed rations, % of DM
B7: feed | D7: Per årssugga inkl. rekrytering | E7: % | F7: Per smågris | G7: % | H7: Per slaktgris | I7: % | J7: %DM | L7: feed | M7: sows, gilts | N7: piglets | O7: growing/ finishing pigs | Q7: 0 | R7: piglets | S7: growing pigs | T7: finishing pigs
B8: wheat | C8: Vete | D8: 517.6 | E8: =D8/D$45 -> 0.31776045 | F8: 14.9 | G8: =F8/F$45 -> 0.27090909 | H8: 81.1 | I8: =H8/H$45 -> 0.15836751 | J8: 86 | L8: wheat | M8: =D8*($J8/100) -> 445.136 | N8: =F8*($J8/100) -> 12.814 | O8: =H8*($J8/100) -> 69.746 | Q8: =M8/M$44*100 -> 39.939447 | R8: =N8/N$44*100 -> 37.344664 | S8: =O8/O$44*100 -> 31.302145 | T8: =O8/O$44*100 -> 31.302145
B9: barley | C9: Korn | D9: 435.3 | E9: =D9/D$45 -> 0.26723556 | F9: 13.5 | G9: =F9/F$45 -> 0.24545455 | H9: 62.3 | I9: =H9/H$45 -> 0.12165593 | J9: 86 | L9: barley | M9: =D9*($J9/100) -> 374.358 | N9: =F9*($J9/100) -> 11.61 | O9: =H9*($J9/100) -> 53.578 | Q9: =M9/M$44*100 -> 33.588951 | R9: =N9/N$44*100 -> 33.83577 | S9: =O9/O$44*100 -> 24.045914 | T9: =O9/O$44*100 -> 24.045914
B10: oats | C10: Havre | D10: 63.2 | E10: =D10/D$45 -> 0.03879919 | F10: 2.7 | G10: =F10/F$45 -> 0.049090909 | H10: 10.5 | I10: =H10/H$45 -> 0.020503808 | J10: 86 | L10: oats | M10: =D10*($J10/100)+D36*($J36/100) -> 54.352 | N10: =F10*($J10/100)+F36*($J36/100) -> 2.494 | O10: =H10*($J10/100)+H36*($J36/100) -> 9.03 | Q10: =M10/M$44*100 -> 4.8766867 | R10: =N10/N$44*100 -> 7.2684246 | S10: =O10/O$44*100 -> 4.0526822 | T10: =O10/O$44*100 -> 4.0526822
B11: triticale | C11: Rågvete | D11: 5.8 | E11: =D11/D$45 -> 0.0035606851 | F11: 0 | G11: =F11/F$45 -> 0 | H11: 9.8 | I11: =H11/H$45 -> 0.019136887 | J11: 86 | L11: triticale | M11: =D11*($J11/100) -> 4.988 | N11: =F11*($J11/100) -> 0 | O11: =H11*($J11/100) -> 8.428 | Q11: =M11/M$44*100 -> 0.44754403 | R11: =N11/N$44*100 -> 0 | S11: =O11/O$44*100 -> 3.7825034 | T11: =O11/O$44*100 -> 3.7825034
B12: maize | C12: Majs | D12: 2.9 | E12: =D12/D$45 -> 0.0017803426 | F12: 0.7 | G12: =F12/F$45 -> 0.012727273 | H12: 0.2 | I12: =H12/H$45 -> 0.00039054872 | J12: 86 | L12: maize | M12: =D12*($J12/100) -> 2.494 | N12: =F12*($J12/100) -> 0.602 | O12: =H12*($J12/100) -> 0.172 | Q12: =M12/M$44*100 -> 0.22377202 | R12: =N12/N$44*100 -> 1.7544473 | S12: =O12/O$44*100 -> 0.077193946 | T12: =O12/O$44*100 -> 0.077193946
B13: peas | C13: Ärtor | D13: 10.3 | E13: =D13/D$45 -> 0.0063232857 | F13: 0.1 | G13: =F13/F$45 -> 0.0018181818 | H13: 1.2 | I13: =H13/H$45 -> 0.0023432923 | J13: 85 | L13: peas | M13: =D13*($J13/100) -> 8.755 | N13: =F13*($J13/100) -> 0.085 | O13: =H13*($J13/100) -> 1.02 | Q13: =M13/M$44*100 -> 0.78553489 | R13: =N13/N$44*100 -> 0.24772097 | S13: =O13/O$44*100 -> 0.45777805 | T13: =O13/O$44*100 -> 0.45777805
B14: broad beans | C14: Åkerböna | D14: 1.3 | E14: =D14/D$45 -> 0.0007980846 | F14: 0.3 | G14: =F14/F$45 -> 0.0054545455 | H14: 20.3 | I14: =H14/H$45 -> 0.039640695 | J14: 85 | L14: broad beans | M14: =D14*($J14/100) -> 1.105 | N14: =F14*($J14/100) -> 0.255 | O14: =H14*($J14/100) -> 17.255 | Q14: =M14/M$44*100 -> 0.09914518 | R14: =N14/N$44*100 -> 0.7431629 | S14: =O14/O$44*100 -> 7.7440787 | T14: =O14/O$44*100 -> 7.7440787
B15: rapeseed | C15: Rapsfrö | D15: 4.3 | E15: =D15/D$45 -> 0.0026398183 | F15: 0 | G15: =F15/F$45 -> 0 | H15: 0 | I15: =H15/H$45 -> 0 | J15: 91 | L15: rapeseed | M15: =D15*($J15/100) -> 3.913 | N15: =F15*($J15/100) -> 0 | O15: =H15*($J15/100) -> 0 | Q15: =M15/M$44*100 -> 0.35109058 | R15: =N15/N$44*100 -> 0 | S15: =O15/O$44*100 -> 0 | T15: =O15/O$44*100 -> 0
B16: linseed | C16: Linfrö | D16: 1.6 | E16: =D16/D$45 -> 0.00098225797 | F16: 0 | G16: =F16/F$45 -> 0 | H16: 0 | I16: =H16/H$45 -> 0 | J16: 91 | L16: linseed | M16: =D16*($J16/100) -> 1.456 | N16: =F16*($J16/100) -> 0 | O16: =H16*($J16/100) -> 0 | Q16: =M16/M$44*100 -> 0.13063835 | R16: =N16/N$44*100 -> 0 | S16: =O16/O$44*100 -> 0 | T16: =O16/O$44*100 -> 0
B17: soybean meal | C17: Sojamjöl | D17: 88.6 | E17: =D17/D$45 -> 0.054392535 | F17: 2.8 | G17: =F17/F$45 -> 0.050909091 | H17: 7.2 | I17: =H17/H$45 -> 0.014059754 | J17: 88 | L17: soybean meal | M17: =D17*($J17/100) -> 77.968 | N17: =F17*($J17/100) -> 2.464 | O17: =H17*($J17/100) -> 6.336 | Q17: =M17/M$44*100 -> 6.9956121 | R17: =N17/N$44*100 -> 7.1809937 | S17: =O17/O$44*100 -> 2.8436096 | T17: =O17/O$44*100 -> 2.8436096
B18: soybean protein concentrate | C18: Sojaprotein koncentrat | D18: 0 | E18: =D18/D$45 -> 0 | F18: 0.9 | G18: =F18/F$45 -> 0.016363636 | H18: 0 | I18: =H18/H$45 -> 0 | J18: 87 | L18: soybean protein concentrate | M18: =D18*($J18/100) -> 0 | N18: =F18*($J18/100) -> 0.783 | O18: =H18*($J18/100) -> 0 | Q18: =M18/M$44*100 -> 0 | R18: =N18/N$44*100 -> 2.2819473 | S18: =O18/O$44*100 -> 0 | T18: =O18/O$44*100 -> 0
B19: rapeseed meal | C19: Rapsmjöl | D19: 40.7 | E19: =D19/D$45 -> 0.024986187 | F19: 0 | G19: =F19/F$45 -> 0 | H19: 8.7 | I19: =H19/H$45 -> 0.016988869 | J19: 90 | L19: rapeseed meal | M19: =D19*($J19/100) -> 36.63 | N19: =F19*($J19/100) -> 0 | O19: =H19*($J19/100) -> 7.83 | Q19: =M19/M$44*100 -> 3.2865954 | R19: =N19/N$44*100 -> 0 | S19: =O19/O$44*100 -> 3.5141198 | T19: =O19/O$44*100 -> 3.5141198
B20: sunflower seed meal | C20: Solrosmjöl | D20: 5.5 | E20: =D20/D$45 -> 0.0033765118 | F20: 0 | G20: =F20/F$45 -> 0 | H20: 0.4 | I20: =H20/H$45 -> 0.00078109744 | J20: 91 | L20: sunflower seed meal | M20: =D20*($J20/100) -> 5.005 | N20: =F20*($J20/100) -> 0 | O20: =H20*($J20/100) -> 0.364 | Q20: =M20/M$44*100 -> 0.44906935 | R20: =N20/N$44*100 -> 0 | S20: =O20/O$44*100 -> 0.16336393 | T20: =O20/O$44*100 -> 0.16336393
B21: palm kernel expeller | C21: Palmkärnexpeller | D21: 1.6 | E21: =D21/D$45 -> 0.00098225797 | F21: 0 | G21: =F21/F$45 -> 0 | H21: 0 | I21: =H21/H$45 -> 0 | J21: 91 | L21: palm kernel expeller | M21: =D21*($J21/100) -> 1.456 | N21: =F21*($J21/100) -> 0 | O21: =H21*($J21/100) -> 0 | Q21: =M21/M$44*100 -> 0.13063835 | R21: =N21/N$44*100 -> 0 | S21: =O21/O$44*100 -> 0 | T21: =O21/O$44*100 -> 0
B22: wheat bran | C22: Vetekli | D22: 39.9 | E22: =D22/D$45 -> 0.024495058 | F22: 0 | G22: =F22/F$45 -> 0 | H22: 3.3 | I22: =H22/H$45 -> 0.0064440539 | J22: 87 | L22: wheat bran | M22: =D22*($J22/100)+D39*($J39/100) -> 34.713 | N22: =F22*($J22/100)+F39*($J39/100) -> 0 | O22: =H22*($J22/100)+H39*($J39/100) -> 18.444 | Q22: =M22/M$44*100 -> 3.1145942 | R22: =N22/N$44*100 -> 0 | S22: =O22/O$44*100 -> 8.2777043 | T22: =O22/O$44*100 -> 8.2777043
A23: siktat vetekli | B23: wheat bran, fine | C23: Vetefodermjöl | D23: 29.7 | E23: =D23/D$45 -> 0.018233163 | F23: 0.5 | G23: =F23/F$45 -> 0.0090909091 | H23: 2.2 | I23: =H23/H$45 -> 0.0042960359 | J23: 88 | L23: wheat bran, fine | M23: =D23*($J23/100) -> 26.136 | N23: =F23*($J23/100) -> 0.44 | O23: =H23*($J23/100) -> 1.936 | Q23: =M23/M$44*100 -> 2.3450303 | R23: =N23/N$44*100 -> 1.2823203 | S23: =O23/O$44*100 -> 0.8688807 | T23: =O23/O$44*100 -> 0.8688807
B24: wheat distillers grain, dry | C24: Drank, torr | D24: 1.7 | E24: =D24/D$45 -> 0.0010436491 | F24: 0 | G24: =F24/F$45 -> 0 | H24: 0.4 | I24: =H24/H$45 -> 0.00078109744 | J24: 90 | L24: wheat distillers grain, dry | M24: =D24*($J24/100) -> 1.53 | N24: =F24*($J24/100) -> 0 | O24: =H24*($J24/100) -> 0.36 | Q24: =M24/M$44*100 -> 0.13727794 | R24: =N24/N$44*100 -> 0 | S24: =O24/O$44*100 -> 0.16156872 | T24: =O24/O$44*100 -> 0.16156872
B25: wheat distillers grain, wet | C25: Drank, blöt | D25: 60.4 | E25: =D25/D$45 -> 0.037080238 | F25: 0 | G25: =F25/F$45 -> 0 | H25: 0 | I25: =H25/H$45 -> 0 | J25: 11 | L25: wheat distillers grain, wet | M25: =D25*($J25/100)+D37*($J37/100) -> 6.644 | N25: =F25*($J25/100)+F37*($J37/100) -> 0 | O25: =H25*($J25/100)+H37*($J37/100) -> 10.4574 | Q25: =M25/M$44*100 -> 0.59612722 | R25: =N25/N$44*100 -> 0 | S25: =O25/O$44*100 -> 4.6933022 | T25: =O25/O$44*100 -> 4.6933022
B26: sugar beet molasses | C26: Betmelass | D26: 5.2 | E26: =D26/D$45 -> 0.0031923384 | F26: 0 | G26: =F26/F$45 -> 0 | H26: 0.3 | I26: =H26/H$45 -> 0.00058582308 | J26: 76 | L26: sugar beet molasses | M26: =D26*($J26/100) -> 3.952 | N26: =F26*($J26/100) -> 0 | O26: =H26*($J26/100) -> 0.228 | Q26: =M26/M$44*100 -> 0.35458982 | R26: =N26/N$44*100 -> 0 | S26: =O26/O$44*100 -> 0.10232686 | T26: =O26/O$44*100 -> 0.10232686
B27: sugar beet pulp | C27: Betfiber | D27: 8.7 | E27: =D27/D$45 -> 0.0053410277 | F27: 0 | G27: =F27/F$45 -> 0 | H27: 0 | I27: =H27/H$45 -> 0 | J27: 89 | L27: sugar beet pulp | M27: =D27*($J27/100) -> 7.743 | N27: =F27*($J27/100) -> 0 | O27: =H27*($J27/100) -> 0 | Q27: =M27/M$44*100 -> 0.69473405 | R27: =N27/N$44*100 -> 0 | S27: =O27/O$44*100 -> 0 | T27: =O27/O$44*100 -> 0
B28: whey | C28: Vassle | D28: 188.4 | E28: =D28/D$45 -> 0.11566088 | F28: 9.6 | G28: =F28/F$45 -> 0.17454545 | H28: 0 | I28: =H28/H$45 -> 0 | J28: 6.3 | L28: whey | M28: =D28*($J28/100)+D38*($J38/100) -> 11.8692 | N28: =F28*($J28/100)+F38*($J38/100) -> 0.6048 | O28: =H28*($J28/100)+H38*($J38/100) -> 9.711 | Q28: =M28/M$44*100 -> 1.0649538 | R28: =N28/N$44*100 -> 1.7626075 | S28: =O28/O$44*100 -> 4.3583163 | T28: =O28/O$44*100 -> 4.3583163
B29: whey powder | C29: Vasslepulver | D29: 0 | E29: =D29/D$45 -> 0 | F29: 0.1 | G29: =F29/F$45 -> 0.0018181818 | H29: 0 | I29: =H29/H$45 -> 0 | J29: 97 | L29: whey powder | M29: =D29*($J29/100) -> 0 | N29: =F29*($J29/100) -> 0.097 | O29: =H29*($J29/100) -> 0 | Q29: =M29/M$44*100 -> 0 | R29: =N29/N$44*100 -> 0.28269334 | S29: =O29/O$44*100 -> 0 | T29: =O29/O$44*100 -> 0
B30: potatoe protein | C30: Potatisprotein | D30: 0 | E30: =D30/D$45 -> 0 | F30: 0.5 | G30: =F30/F$45 -> 0.0090909091 | H30: 0 | I30: =H30/H$45 -> 0 | J30: 92 | L30: potatoe protein | M30: =D30*($J30/100) -> 0 | N30: =F30*($J30/100) -> 0.46 | O30: =H30*($J30/100) -> 0 | Q30: =M30/M$44*100 -> 0 | R30: =N30/N$44*100 -> 1.3406076 | S30: =O30/O$44*100 -> 0 | T30: =O30/O$44*100 -> 0
B31: fish meal | C31: Fiskmjöl | D31: 2.2 | E31: =D31/D$45 -> 0.0013506047 | F31: 1.2 | G31: =F31/F$45 -> 0.021818182 | H31: 0 | I31: =H31/H$45 -> 0 | J31: 92 | L31: fish meal | M31: =D31*($J31/100) -> 2.024 | N31: =F31*($J31/100) -> 1.104 | O31: =H31*($J31/100) -> 0 | Q31: =M31/M$44*100 -> 0.18160167 | R31: =N31/N$44*100 -> 3.2174582 | S31: =O31/O$44*100 -> 0 | T31: =O31/O$44*100 -> 0
B32: vegetable oils | C32: Olja / Fett | D32: 2.3 | E32: =D32/D$45 -> 0.0014119958 | F32: 0.5 | G32: =F32/F$45 -> 0.0090909091 | H32: 0 | I32: =H32/H$45 -> 0 | J32: 100 | L32: vegetable oils | M32: =D32*($J32/100) -> 2.3 | N32: =F32*($J32/100) -> 0.5 | O32: =H32*($J32/100) -> 0 | Q32: =M32/M$44*100 -> 0.20636553 | R32: =N32/N$44*100 -> 1.4571822 | S32: =O32/O$44*100 -> 0 | T32: =O32/O$44*100 -> 0
B33: excluded | C33: Premix | D33: 62.6 | E33: =D33/D$45 -> 0.038430843 | F33: 1.8 | G33: =F33/F$45 -> 0.032727273 | H33: 11 | I33: =H33/H$45 -> 0.02148018 | L33: barley brewers grain | M33: =D41*($J41/100) -> 0 | N33: =F41*($J41/100) -> 0 | O33: =H41*($J41/100) -> 7.92 | Q33: =M33/M$44*100 -> 0 | R33: =N33/N$44*100 -> 0 | S33: =O33/O$44*100 -> 3.5545119 | T33: =O33/O$44*100 -> 3.5545119
B34: excluded | C34: Maltgroddar | D34: 5.8 | E34: =D34/D$45 -> 0.0035606851 | F34: 0.2 | G34: =F34/F$45 -> 0.0036363636 | H34: 1.4 | I34: =H34/H$45 -> 0.002733841
B35: excluded | C35: Fodernjölk | D35: 43.3 | E35: =D35/D$45 -> 0.026582356 | F35: 4.5 | G35: =F35/F$45 -> 0.081818182 | H35: 0 | I35: =H35/H$45 -> 0
B36: oats | C36: Havremjöl | D36: 0 | E36: =D36/D$45 -> 0 | F36: 0.2 | G36: =F36/F$45 -> 0.0036363636 | H36: 0 | I36: =H36/H$45 -> 0 | J36: 86
B37: wheat distillers grain, wet | C37: Biprodukt etanolindustri | D37: 0 | E37: =D37/D$45 -> 0 | F37: 0 | G37: =F37/F$45 -> 0 | H37: 120.2 | I37: =H37/H$45 -> 0.23471978 | J37: 8.7
B38: whey | C38: Biprodukt mejeriindustri | D38: 0 | E38: =D38/D$45 -> 0 | F38: 0 | G38: =F38/F$45 -> 0 | H38: 124.5 | I38: =H38/H$45 -> 0.24311658 | J38: 7.8
B39: wheat bran | C39: Biprodukt spannmålsförädling | D39: 0 | E39: =D39/D$45 -> 0 | F39: 0 | G39: =F39/F$45 -> 0 | H39: 17.9 | I39: =H39/H$45 -> 0.034954111 | J39: 87
B40: excluded | C40: Bioprodukt potatisindustri | D40: 0 | E40: =D40/D$45 -> 0 | F40: 0 | G40: =F40/F$45 -> 0 | H40: 15.7 | I40: =H40/H$45 -> 0.030658075 | J40: 91
B41: barley brewers grain | C41: Biprodukt bryggeriindustri | D41: 0 | E41: =D41/D$45 -> 0 | F41: 0 | G41: =F41/F$45 -> 0 | H41: 8.8 | I41: =H41/H$45 -> 0.017184144 | J41: 90
B42: excluded | C42: Biprodukt bageri- o pastaindustri | D42: 0 | E42: =D42/D$45 -> 0 | F42: 0 | G42: =F42/F$45 -> 0 | H42: 4.7 | I42: =H42/H$45 -> 0.0091778949
C43: Vatten | D43: 2746.2 | F43: 79.9 | H43: 330.2
C44: Summa kg blött foder | D44: 4375.1 | F44: 134.9 | H44: 842.3 | L44: total, kg DM | M44: =SUM(M8:M43) -> 1114.5272 | N44: =SUM(N8:N43) -> 34.3128 | O44: =SUM(O8:O43) -> 222.8154 | Q44: =SUM(Q8:Q43) -> 100 | R44: =SUM(R8:R43) -> 100 | S44: =SUM(S8:S43) -> 100 | T44: =SUM(T8:T43) -> 100
...

Sheet feed rations organic
B2: Niels Andresen, Ingela Löfquist & Stefan Lundmark (2024) Ekologiska foderstater med lokala eller globala proteinråvaror – konsekvenser för odling, foderstat, ekonomi och marknaden. HIR Skåne
B3: https://www.slu.se/ew-nyheter/2024/10/mojligt-med-svensk-proteinforsorjning-till-ekologisk-djurproduktion/
B5: Globala fodermedel
B6: Foder, kg | C6: Difoder, kg 9,7 MJ NE/kg | D6: Dräktighetsfoder, kg 9,2 MJ NE/kg | E6: Smågrisfoder, kg /gris 9,6 MJ NE/kg | G6: Slaktgris, enhetsfoder 9,7 MJ NE/kg | H6: Slaktgris, fasfoder I 9,5 MJ NE/kg | I6: Slaktgris, fasfoder II 9,6 MJ NE/kg
B7: Korn | C7: 454 | D7: 431 | E7: 30 | G7: 165.9 | H7: 41.6 | I7: 61.3
B8: Vete | G8: 25.6 | H8: 39.9 | I8: 50.4
B9: Havre | C9: 97 | D9: 108 | E9: 4
B10: Rapskaka
B11: Åkerböna | D11: 20 | G11: 8.5
B12: Ärter
B13: Koncentrat | C13: 184 | D13: 140 | E13: 11 | G13: 56 | H13: 32.5 | I13: 34.3
B14: varav sojaexpeller/sojaböna | C14: 99 | D14: 75 | E14: 0.6 | G14: 48.4 | H14: 22.8 | I14: 20.6
B15: varav fiskmjöl | C15: 15 | D15: 11 | E15: 4.4
B16: varav potatisprotein | C16: 12 | D16: 8 | E16: 1.1
B17: varav spannmåls- baserade o övriga råvaror | C17: 60 | D17: 46 | E17: 4.9
B18: Mineraler + vitaminer, kg | G18: 5.1
B19: Summa foderbehov, kg | C19: 735 | D19: 698 | E19: 45 | G19: 256 | H19: 114 | I19: 146
B21: Lokala fodermedel
B22: Foder, kg | C22: Difoder, kg 9,9 MJ NE/kg | D22: Dräktighetsfoder, kg 9,3 MJ NE/kg | E22: Smågrisfoder, kg per gris 9,5 MJ NE/kg | G22: Slaktgris, enhetsfoder 9,8 MJ NE/kg | H22: Slaktgris, fasfoder I 9,8 MJ NE/kg | I22: Slaktgris, fasfoder II 9,8 MJ NE/kg | J22: DM | K22: feed | L22: 0 | M22: piglets | N22: growing pigs | O22: finishing pigs
B23: Korn | C23: 260 | D23: 417 | E23: 19 | G23: 77 | H23: 36.2 | I23: 50.4 | J23: 0.86 | K23: barley | L23: =(C23*J23+D23*J23) / (SUMPRODUCT(C$23:C$31,J$23:J$31) + SUMPRODUCT(D$23:D$31,J$23:J$31)) * 100 -> 47.281143 | M23: =(E23*J23) / (SUMPRODUCT(E$23:E$31,J$23:J$31)) * 100 -> 41.687927 | N23: =(G23*J23 + H23*J23+I23*J23) / (SUMPRODUCT(G$23:G$31,J$23:J$31) + SUMPRODUCT(H$23:H$31,J$23:J$31) + SUMPRODUCT(I$23:I$31,J$23:J$31)) * 100 -> 31.818429 | O23: =N23 -> 31.818429
B24: Vete | C24: 216 | E24: 11 | G24: 60 | H24: 24.2 | I24: 31.7 | J24: 0.86 | K24: wheat | L24: =(C24*J24+D24*J24) / (SUMPRODUCT(C$23:C$31,J$23:J$31) + SUMPRODUCT(D$23:D$31,J$23:J$31)) * 100 -> 15.085269 | M24: =(E24*J24) / (SUMPRODUCT(E$23:E$31,J$23:J$31)) * 100 -> 24.135116 | N24: =(G24*J24 + H24*J24+I24*J24) / (SUMPRODUCT(G$23:G$31,J$23:J$31) + SUMPRODUCT(H$23:H$31,J$23:J$31) + SUMPRODUCT(I$23:I$31,J$23:J$31)) * 100 -> 22.541295 | O24: =N24 -> 22.541295
B25: Havre | D25: 142 | J25: 0.86 | K25: oats | L25: =(C25*J25+D25*J25) / (SUMPRODUCT(C$23:C$31,J$23:J$31) + SUMPRODUCT(D$23:D$31,J$23:J$31)) * 100 -> 9.9171675 | M25: =(E25*J25) / (SUMPRODUCT(E$23:E$31,J$23:J$31)) * 100 -> 0 | N25: =(G25*J25 + H25*J25+I25*J25) / (SUMPRODUCT(G$23:G$31,J$23:J$31) + SUMPRODUCT(H$23:H$31,J$23:J$31) + SUMPRODUCT(I$23:I$31,J$23:J$31)) * 100 -> 0 | O25: =N25 -> 0
B26: Rapskaka | C26: 32 | D26: 28 | G26: 29 | H26: 12.2 | I26: 17.3 | J26: 0.92 | K26: rapeseed cake | L26: =(C26*J26+D26*J26) / (SUMPRODUCT(C$23:C$31,J$23:J$31) + SUMPRODUCT(D$23:D$31,J$23:J$31)) * 100 -> 4.4827026 | M26: =(E26*J26) / (SUMPRODUCT(E$23:E$31,J$23:J$31)) * 100 -> 0 | N26: =(G26*J26 + H26*J26+I26*J26) / (SUMPRODUCT(G$23:G$31,J$23:J$31) + SUMPRODUCT(H$23:H$31,J$23:J$31) + SUMPRODUCT(I$23:I$31,J$23:J$31)) * 100 -> 12.171404 | O26: =N26 -> 12.171404
B27: Åkerböna | C27: 101 | D27: 70 | E27: 5.3 | G27: 51 | H27: 21.1 | I27: 24.5 | J27: 0.85 | K27: broad beans | L27: =(C27*J27+D27*J27) / (SUMPRODUCT(C$23:C$31,J$23:J$31) + SUMPRODUCT(D$23:D$31,J$23:J$31)) * 100 -> 11.803638 | M27: =(E27*J27) / (SUMPRODUCT(E$23:E$31,J$23:J$31)) * 100 -> 11.49352 | N27: =(G27*J27 + H27*J27+I27*J27) / (SUMPRODUCT(G$23:G$31,J$23:J$31) + SUMPRODUCT(H$23:H$31,J$23:J$31) + SUMPRODUCT(I$23:I$31,J$23:J$31)) * 100 -> 18.569193 | O27: =N27 -> 18.569193
B28: Ärt | C28: 100 | D28: 35 | E28: 4.7 | G28: 33 | H28: 13.3 | I28: 17.3 | J28: 0.85 | K28: peas | L28: =(C28*J28+D28*J28) / (SUMPRODUCT(C$23:C$31,J$23:J$31) + SUMPRODUCT(D$23:D$31,J$23:J$31)) * 100 -> 9.3186617 | M28: =(E28*J28) / (SUMPRODUCT(E$23:E$31,J$23:J$31)) * 100 -> 10.192367 | N28: =(G28*J28 + H28*J28+I28*J28) / (SUMPRODUCT(G$23:G$31,J$23:J$31) + SUMPRODUCT(H$23:H$31,J$23:J$31) + SUMPRODUCT(I$23:I$31,J$23:J$31)) * 100 -> 12.22568 | O28: =N28 -> 12.22568
B29: Fiskmjöl 65% rp | E29: 1.7 | G29: 0 | H29: 2.2 | I29: 0 | J29: 0.92 | K29: potatoe protein | L29: =(C29*J29+D29*J29) / (SUMPRODUCT(C$23:C$31,J$23:J$31) + SUMPRODUCT(D$23:D$31,J$23:J$31)) * 100 -> 0 | M29: =(E29*J29) / (SUMPRODUCT(E$23:E$31,J$23:J$31)) * 100 -> 3.9902031 | N29: =(G29*J29 + H29*J29+I29*J29) / (SUMPRODUCT(G$23:G$31,J$23:J$31) + SUMPRODUCT(H$23:H$31,J$23:J$31) + SUMPRODUCT(I$23:I$31,J$23:J$31)) * 100 -> 0.457728 | O29: =N29 -> 0.457728
B30: Potatisprotein | E30: 2.1 | J30: 0.92 | K30: fish meal | L30: =(C30*J30+D30*J30) / (SUMPRODUCT(C$23:C$31,J$23:J$31) + SUMPRODUCT(D$23:D$31,J$23:J$31)) * 100 -> 0 | M30: =(E30*J30) / (SUMPRODUCT(E$23:E$31,J$23:J$31)) * 100 -> 4.9290744 | N30: =(G30*J30 + H30*J30+I30*J30) / (SUMPRODUCT(G$23:G$31,J$23:J$31) + SUMPRODUCT(H$23:H$31,J$23:J$31) + SUMPRODUCT(I$23:I$31,J$23:J$31)) * 100 -> 0 | O30: =N30 -> 0
B31: Mineraler & vitaminer | C31: 13 | D31: 13 | E31: 1.4 | G31: 5 | H31: 1.9 | I31: 2.9 | J31: 1 | K31: minerals | L31: =(C31*J31+D31*J31) / (SUMPRODUCT(C$23:C$31,J$23:J$31) + SUMPRODUCT(D$23:D$31,J$23:J$31)) * 100 -> 2.1114179 | M31: =(E31*J31) / (SUMPRODUCT(E$23:E$31,J$23:J$31)) * 100 -> 3.571793 | N31: =(G31*J31 + H31*J31+I31*J31) / (SUMPRODUCT(G$23:G$31,J$23:J$31) + SUMPRODUCT(H$23:H$31,J$23:J$31) + SUMPRODUCT(I$23:I$31,J$23:J$31)) * 100 -> 2.216272 | O31: =N31 -> 2.216272
B32: Summa foderbehov, kg | C32: 722 | D32: 690 | E32: 45 | G32: 255 | H32: 111 | I32: 144 | L32: =SUM(L23:L31) -> 100 | M32: =SUM(M23:M31) -> 100 | N32: =SUM(N23:N31) -> 100 | O32: =SUM(O23:O31) -> 100

Sheet Kontroll
E3: 2016-2020
A4: sows | B4: 101963.58 | C4: =SUM(B4:B5)/E4 -> 1.0165291 | D4: Suggor | E4: 133382.8 | H4: kullar per sugga | J4: 2.3 | K4: st
A5: gilts | B5: 33623.921 | H5: lev. Födda per kull | J5: 14.6 | K5: st
A6: boars | B6: 1491.4625 | C6: =B6/E6 -> 0.99643406 | D6: Galtar | E6: 1496.8 | H6: dödl. Föd-avv. | J6: 18 | K6: %
A7: piglets | B7: 525417.78 | C7: =SUM(B7:B9)/SUM(E7:E8) -> 1.0119657 | D7: Smågrisar | E7: 374972.8 | H7: Avvanda per sugga | J7: =J4*J5*(1-J6/100) -> 27.5356
A8: growing pigs | B8: 269503.55 | D8: Slaktgrisar | E8: 876801.8
A9: finishing pigs | B9: 471831.64 | J9: =J7*0.95 -> 26.15882
A11: Slakt
D12: Galtar | E12: 1.206
A13: sows | B13: 44.057295 | C13: =B13/E14 -> 1.0402648 | D13: Slaktgris | E13: 2514.042 | G13: =E12*1000/E6 -> 0.80571887
A14: finishing pigs | B14: 2576.0147 | C14: =B14/SUM(E13,E15:E16) -> 1.0141702 | D14: Suggor | E14: 42.352
D15: Unggalt | E15: 20.3
D16: Unggris | E16: 5.68

Sheet Slaktstat
B3: Djurkategori | C3: Kvantitet, 1 000 ton | I3: Slaktade hela kroppar, 1 000-tal | O3: Slaktvikt, kg
C4: 2016 | D4: 2017 | E4: 2018 | F4: 2019 | G4: 2020 | H4: 2016-2020 | I4: 2016 | J4: 2017 | K4: 2018 | L4: 2019 | M4: 2020 | N4: 2016-2020 | O4: 2016 | P4: 2017 | Q4: 2018 | R4: 2019 | S4: 2020 | T4: 2016-2020
B5: Ko | E5: 33.8 | F5: 34.25 | G5: 34 | H5: =AVERAGE(C5:G5) -> 34.016667 | K5: 104.68 | L5: 105.17 | M5: 103.26 | N5: =AVERAGE(I5:M5) -> 104.37 | Q5: =E5/K5*1000 -> 322.8888 | R5: =F5/L5*1000 -> 325.66321 | S5: =G5/M5*1000 -> 329.26593 | T5: =SUM(C5:G5)/SUM(I5:M5)*1000 -> 325.9238
B6: Ungko | E6: 10.45 | F6: 10.65 | G6: 10.32 | H6: =AVERAGE(C6:G6) -> 10.473333 | K6: 36.04 | L6: 36.38 | M6: 34.81 | N6: =AVERAGE(I6:M6) -> 35.743333 | Q6: =E6/K6*1000 -> 289.9556 | R6: =F6/L6*1000 -> 292.74327 | S6: =G6/M6*1000 -> 296.46653 | T6: =SUM(C6:G6)/SUM(I6:M6)*1000 -> 293.01501
B7: Kviga | C7: 16.88 | D7: 16.6 | E7: 17.8 | F7: 19.06 | G7: 20.85 | H7: =AVERAGE(C7:G7) -> 18.238 | I7: 55.34 | J7: 53.89 | K7: 58.76 | L7: 62.58 | M7: 68.17 | N7: =AVERAGE(I7:M7) -> 59.748 | O7: =C7/I7*1000 -> 305.02349 | P7: =D7/J7*1000 -> 308.03489 | Q7: =E7/K7*1000 -> 302.92716 | R7: =F7/L7*1000 -> 304.57015 | S7: =G7/M7*1000 -> 305.85301 | T7: =SUM(C7:G7)/SUM(I7:M7)*1000 -> 305.24871
B8: Stut | C8: 11.26 | D8: 11.97 | E8: 11.56 | F8: 11.11 | G8: 11.19 | H8: =AVERAGE(C8:G8) -> 11.418 | I8: 34.33 | J8: 36.24 | K8: 35.59 | L8: 34.06 | M8: 34.03 | N8: =AVERAGE(I8:M8) -> 34.85 | O8: =C8/I8*1000 -> 327.99301 | P8: =D8/J8*1000 -> 330.29801 | Q8: =E8/K8*1000 -> 324.81034 | R8: =F8/L8*1000 -> 326.18908 | S8: =G8/M8*1000 -> 328.82751 | T8: =SUM(C8:G8)/SUM(I8:M8)*1000 -> 327.63271
B9: Summa tjur | C9: 57.96 | D9: 60.89 | E9: 60.75 | F9: 62.26 | G9: 62.53 | H9: =AVERAGE(C9:G9) -> 60.878 | I9: 167.92 | J9: 174.33 | K9: 175.18 | L9: 180.01 | M9: 180.71 | N9: =AVERAGE(I9:M9) -> 175.63 | O9: =C9/I9*1000 -> 345.16436 | P9: =D9/J9*1000 -> 349.2801 | Q9: =E9/K9*1000 -> 346.78616 | R9: =F9/L9*1000 -> 345.86967 | S9: =G9/M9*1000 -> 346.02402 | T9: =SUM(C9:G9)/SUM(I9:M9)*1000 -> 346.62643
B10: Ungtjur | E10: 52 | F10: 52.89 | G10: 53.15 | H10: =AVERAGE(C10:G10) -> 52.68 | K10: 152.05 | L10: 154.99 | M10: 155.82 | N10: =AVERAGE(I10:M10) -> 154.28667 | Q10: =E10/K10*1000 -> 341.99277 | R10: =F10/L10*1000 -> 341.24782 | S10: =G10/M10*1000 -> 341.0987 | T10: =SUM(C10:G10)/SUM(I10:M10)*1000 -> 341.44234
B11: Yngre tjur | E11: 7.32 | F11: 7.81 | G11: 7.67 | H11: =AVERAGE(C11:G11) -> 7.6 | K11: 20.26 | L11: 21.89 | M11: 21.5 | N11: =AVERAGE(I11:M11) -> 21.216667 | Q11: =E11/K11*1000 -> 361.30306 | R11: =F11/L11*1000 -> 356.78392 | S11: =G11/M11*1000 -> 356.74419 | T11: =SUM(C11:G11)/SUM(I11:M11)*1000 -> 358.20896
B12: Äldre tjur | E12: 1.42 | F12: 1.56 | G12: 1.71 | H12: =AVERAGE(C12:G12) -> 1.5633333 | K12: 2.88 | L12: 3.13 | M12: 3.39 | N12: =AVERAGE(I12:M12) -> 3.1333333 | Q12: =E12/K12*1000 -> 493.05556 | R12: =F12/L12*1000 -> 498.40256 | S12: =G12/M12*1000 -> 504.42478 | T12: =SUM(C12:G12)/SUM(I12:M12)*1000 -> 498.93617
B13: Mellankalv | E13: 2.52 | F13: 2.43 | G13: 2.21 | H13: =AVERAGE(C13:G13) -> 2.3866667 | K13: 15.34 | L13: 14.82 | M13: 13.41 | N13: =AVERAGE(I13:M13) -> 14.523333 | Q13: =E13/K13*1000 -> 164.2764 | R13: =F13/L13*1000 -> 163.96761 | S13: =G13/M13*1000 -> 164.80239 | T13: =SUM(C13:G13)/SUM(I13:M13)*1000 -> 164.33326
B14: Suggor | C14: 8.83 | D14: 8.44 | E14: 8.35 | F14: 6.72 | G14: 5.88 | H14: =AVERAGE(C14:G14) -> 7.644 | I14: 49.54 | J14: 46.63 | K14: 46.11 | L14: 37.39 | M14: 32.09 | N14: =AVERAGE(I14:M14) -> 42.352 | O14: =C14/I14*1000 -> 178.23981 | P14: =D14/J14*1000 -> 180.99936 | Q14: =E14/K14*1000 -> 181.0887 | R14: =F14/L14*1000 -> 179.7272 | S14: =G14/M14*1000 -> 183.23465 | T14: =SUM(C14:G14)/SUM(I14:M14)*1000 -> 180.48734
B15: Galtar | C15: 0.19 | D15: 0.2 | E15: 0.19 | F15: 0.18 | G15: 0.17 | H15: =AVERAGE(C15:G15) -> 0.186 | I15: 1.26 | J15: 1.31 | K15: 1.18 | L15: 1.19 | M15: 1.09 | N15: =AVERAGE(I15:M15) -> 1.206 | O15: =C15/I15*1000 -> 150.79365 | P15: =D15/J15*1000 -> 152.67176 | Q15: =E15/K15*1000 -> 161.01695 | R15: =F15/L15*1000 -> 151.2605 | S15: =G15/M15*1000 -> 155.9633 | T15: =SUM(C15:G15)/SUM(I15:M15)*1000 -> 154.22886
B16: Unggalt | C16: 1.93 | D16: 2 | E16: 2.01 | F16: 1.66 | G16: 1.44 | H16: =AVERAGE(C16:G16) -> 1.808 | I16: 21.9 | J16: 22.49 | K16: 22.42 | L16: 18.61 | M16: 16.08 | N16: =AVERAGE(I16:M16) -> 20.3 | O16: =C16/I16*1000 -> 88.127854 | P16: =D16/J16*1000 -> 88.928413 | Q16: =E16/K16*1000 -> 89.652096 | R16: =F16/L16*1000 -> 89.199355 | S16: =G16/M16*1000 -> 89.552239 | T16: =SUM(C16:G16)/SUM(I16:M16)*1000 -> 89.064039
B17: Unggris | C17: 0.24 | D17: 0.2 | E17: 0.17 | F17: 0.15 | G17: 0.11 | H17: =AVERAGE(C17:G17) -> 0.174 | I17: 7.8 | J17: 6.47 | K17: 5.5 | L17: 5.1 | M17: 3.53 | N17: =AVERAGE(I17:M17) -> 5.68 | O17: =C17/I17*1000 -> 30.769231 | P17: =D17/J17*1000 -> 30.911901 | Q17: =E17/K17*1000 -> 30.909091 | R17: =F17/L17*1000 -> 29.411765 | S17: =G17/M17*1000 -> 31.161473 | T17: =SUM(C17:G17)/SUM(I17:M17)*1000 -> 30.633803
B18: Slaktgris | C18: 222 | D18: 229.07 | E18: 237.78 | F18: 230.3 | G18: 236.93 | H18: =AVERAGE(C18:G18) -> 231.216 | I18: 2450.58 | J18: 2495.76 | K18: 2563.05 | L18: 2507.41 | M18: 2553.41 | N18: =AVERAGE(I18:M18) -> 2514.042 | O18: =C18/I18*1000 -> 90.590799 | P18: =D18/J18*1000 -> 91.783665 | Q18: =E18/K18*1000 -> 92.772283 | R18: =F18/L18*1000 -> 91.847763 | S18: =G18/M18*1000 -> 92.789642 | T18: =SUM(C18:G18)/SUM(I18:M18)*1000 -> 91.969824
B19: Tackor och baggar | C19: 0.95 | D19: 1.06 | E19: 1.19 | F19: 1.08 | G19: 0.95 | H19: =AVERAGE(C19:G19) -> 1.046 | I19: 33.31 | J19: 37.69 | K19: 43.17 | L19: 38.39 | M19: 33.4 | N19: =AVERAGE(I19:M19) -> 37.192 | O19: =C19/I19*1000 -> 28.519964 | P19: =D19/J19*1000 -> 28.124171 | Q19: =E19/K19*1000 -> 27.565439 | R19: =F19/L19*1000 -> 28.132326 | S19: =G19/M19*1000 -> 28.443114 | T19: =SUM(C19:G19)/SUM(I19:M19)*1000 -> 28.124328
B20: Lamm | C20: 4.09 | D20: 4.21 | E20: 4.43 | F20: 4.02 | G20: 3.94 | H20: =AVERAGE(C20:G20) -> 4.138 | I20: 218.41 | J20: 224.29 | K20: 237.92 | L20: 213.94 | M20: 207.28 | N20: =AVERAGE(I20:M20) -> 220.368 | O20: =C20/I20*1000 -> 18.726249 | P20: =D20/J20*1000 -> 18.770342 | Q20: =E20/K20*1000 -> 18.619704 | R20: =F20/L20*1000 -> 18.790315 | S20: =G20/M20*1000 -> 19.008105 | T20: =SUM(C20:G20)/SUM(I20:M20)*1000 -> 18.777681
B21: Häst | C21: 0.76 | D21: 0.64 | E21: 0.6 | F21: 0.53 | G21: 0.44 | H21: =AVERAGE(C21:G21) -> 0.594 | I21: 2.67 | J21: 2.27 | K21: 2.11 | L21: 1.85 | M21: 1.53 | N21: =AVERAGE(I21:M21) -> 2.086 | O21: =C21/I21*1000 -> 284.64419 | P21: =D21/J21*1000 -> 281.93833 | Q21: =E21/K21*1000 -> 284.36019 | R21: =F21/L21*1000 -> 286.48649 | S21: =G21/M21*1000 -> 287.5817 | T21: =SUM(C21:G21)/SUM(I21:M21)*1000 -> 284.75551
B23: sows | C23: =T14 -> 180.48734
B24: boars | C24: =T15 -> 154.22886
B25: finishing pigs | C25: =SUM(C16:G18)/SUM(I16:M18)*1000 -> 91.809441

Sheet Sheet2
A1: SUMMARY OUTPUT
A3: Regression Statistics
A4: Multiple R | B4: 0.99999493
A5: R Square | B5: 0.99998987
A6: Adjusted R Square | B6: 0.85713127
A7: Standard Error | B7: 0.2567763
A8: Observations | B8: 9
A10: ANOVA
B11: df | C11: SS | D11: MS | E11: F | F11: Significance F
A12: Regression | B12: 2 | C12: 45538.976 | D12: 22769.488 | E12: 345337.23 | F12: 6.5557476e-16
A13: Residual | B13: 7 | C13: 0.46153846 | D13: 0.065934066
A14: Total | B14: 9 | C14: 45539.438
B16: Coefficients | C16: Standard Error | D16: t Stat | E16: P-value | F16: Lower 95% | G16: Upper 95% | H16: Lower 95.0% | I16: Upper 95.0%
A17: Intercept | B17: 0 | C17: #N/A | D17: #N/A | E17: #N/A | F17: #N/A | G17: #N/A | H17: #N/A | I17: #N/A
A18: Kull-storlek | B18: 5.4615385 | C18: 0.041844907 | D18: 130.51859 | E18: 4.0880236e-13 | F18: 5.362591 | G18: 5.5604859 | H18: 5.362591 | I18: 5.5604859
A19: Levande-vikt, kg | B19: 0.057692308 | C19: 0.0019019421 | D19: 30.333367 | E19: 1.0916663e-08 | F19: 0.053194929 | G19: 0.062189686 | H19: 0.053194929 | I19: 0.062189686
A23: RESIDUAL OUTPUT | F23: PROBABILITY OUTPUT
A25: Observation | B25: Predicted MJ NEs/dag | C25: Residuals | D25: Standard Residuals | F25: Percentile | G25: MJ NEs/dag
A26: 1 | B26: 41.423077 | C26: -0.17307692 | D26: -0.764287 | F26: 5.5555556 | G26: 41.25
A27: 2 | B27: 52.346154 | C27: 0.15384615 | D27: 0.67936622 | F27: 16.666667 | G27: 52.5
A28: 3 | B28: 63.269231 | C28: -0.26923077 | D28: -1.1888909 | F28: 27.777778 | G28: 62.25
A29: 4 | B29: 62.134615 | C29: 0.11538462 | D29: 0.50952467 | F29: 38.888889 | G29: 63
A30: 5 | B30: 73.057692 | C30: 0.44230769 | D30: 1.9531779 | F30: 50 | G30: 72
A31: 6 | B31: 83.980769 | C31: 0.019230769 | D31: 0.084920778 | F31: 61.111111 | G31: 73.5
A32: 7 | B32: 71.923077 | C32: 0.076923077 | D32: 0.33968311 | F32: 72.222222 | G32: 82.5
A33: 8 | B33: 82.846154 | C33: -0.34615385 | D33: -1.528574 | F33: 83.333333 | G33: 84
A34: 9 | B34: 93.769231 | C34: -0.019230769 | D34: -0.084920778 | F34: 94.444444 | G34: 93.75

Sheet Energi rek
B2: Göransson, L., Lindberg, J.E. (2011). Näringsrekommendationer ver. 2011.1 - Energi | O2: Simonsson, A. (2006). Fodermedel och näringsrekommendationer för gris. HUV Rapport 266. SLU
B3: Tabell1. Vägledande norm för utfodring av växande grisar. | O3: Tabell 13. Energinorm for avelsgalt
B4: Vikt | C4: MJ NEv/dag | D4: MJ OE/dag | O4: Vikt, kg | P4: MJ ME/dag | Q4: MJ NEs/dag
B5: 10 | C5: 6.2 | D5: 8.3 | F5: =0.41*B5+2.2 -> 6.3 | O5: 100 | P5: 26 | Q5: =P5*0.75 -> 19.5
B6: 15 | C6: 8.3 | D6: 11.2 | F6: =0.41*B6+2.2 -> 8.35 | O6: 150 | P6: 29 | Q6: =P6*0.75 -> 21.75
B7: 20 | C7: 10.4 | D7: 14 | F7: =0.41*B7+2.2 -> 10.4 | O7: 200 | P7: 31 | Q7: =P7*0.75 -> 23.25
B8: 25 | C8: 12.4 | D8: 16.5 | F8: =0.41*B8+2.2 -> 12.45 | O8: 250 | P8: 33 | Q8: =P8*0.75 -> 24.75
B9: 30 | C9: 14.5 | D9: 19.3 | F9: =0.41*B9+2.2 -> 14.5 | O9: 300 | P9: 35 | Q9: =P9*0.75 -> 26.25
B10: 35 | C10: 16.4 | D10: 21.9
B11: 40 | C11: 18.3 | D11: 24.4
B12: 45 | C12: 20.2 | D12: 26.9
B13: 50 | C13: 22.1 | D13: 29.5
B14: 55 | C14: 24 | D14: 32
B15: 60 | C15: 25.9 - 28.5 | D15: 34.5 – 38a
B16: a En högre slutgiva ger högre tillväxt och något sämre klassning. | O16: Simonsson, A. (2006). Fodermedel och näringsrekommendationer för gris. HUV Rapport 266. SLU
O17: Tabell 12. Energinorm for digivande sugga, MJ ME per dag
O18: Kull-storlek | P18: Levande-vikt, kg | Q18: MJ ME/dag | R18: MJ NEs/dag | S18: est.
O19: 6 | P19: 150 | Q19: 55 | R19: =Q19*0.75 -> 41.25 | S19: =O19*$Q$29+P19*$T$29 -> 41.46
O20: 8 | P20: 150 | Q20: 70 | R20: =Q20*0.75 -> 52.5 | S20: =O20*$Q$29+P20*$T$29 -> 52.38
B21: Göransson, L., Lindberg, J.E. (2011). Näringsrekommendationer ver. 2011.1 - Energi | O21: 10 | P21: 150 | Q21: 84 | R21: =Q21*0.75 -> 63 | S21: =O21*$Q$29+P21*$T$29 -> 63.3
B22: Tabell 2. Exempel på foderkurva för växande grisar (modifierad efter Vils 2008, 1FEsv = 8,8MJ NEv för smågrisar och 9,0 MJ NEv för slaktgrisar). | O22: 9 | P22: 225 | Q22: 83 | R22: =Q22*0.75 -> 62.25 | S22: =O22*$Q$29+P22*$T$29 -> 62.19
C23: Vikt, kg | D23: MJ NEv/dag | E23: MJ OE/dag | F23: Tillväxt, g/dag i intervallet | O23: 11 | P23: 225 | Q23: 98 | R23: =Q23*0.75 -> 73.5 | S23: =O23*$Q$29+P23*$T$29 -> 73.11
O24: 13 | P24: 225 | Q24: 112 | R24: =Q24*0.75 -> 84 | S24: =O24*$Q$29+P24*$T$29 -> 84.03
B25: Smågrisar | O25: 10 | P25: 300 | Q25: 96 | R25: =Q25*0.75 -> 72 | S25: =O25*$Q$29+P25*$T$29 -> 72
B26: Dag från avvänjning | O26: 12 | P26: 300 | Q26: 110 | R26: =Q26*0.75 -> 82.5 | S26: =O26*$Q$29+P26*$T$29 -> 82.92
B27: 1 | C27: 10 | D27: 2.1 | E27: 2.8 | O27: 14 | P27: 300 | Q27: 125 | R27: =Q27*0.75 -> 93.75 | S27: =O27*$Q$29+P27*$T$29 -> 93.84
B28: 7 | C28: 11 | D28: 6.6 | E28: 8.8 | F28: 143
B29: 14 | C29: 13.3 | D29: 7.7 | E29: 10.3 | F29: 329 | O29: MJ NE = | P29: LS * | Q29: 5.46 | R29: + | S29: LW * | T29: 0.058
B30: 21 | C30: 16.7 | D30: 9.2 | E30: 12.3 | F30: 486 | O30: LS = litter size, LW = live weight
B31: 28 | C31: 20.6 | D31: 10.7 | E31: 14.3 | F31: 557
B32: 35 | C32: 25 | D32: 12.4 | E32: 16.5 | F32: 629
B33: 42 | C33: 30 | D33: 14.5 | E33: 19.3 | F33: 714
B34: Slaktgrisar
B35: Dag från insättning
B36: 0 | C36: 30 | D36: 14.5 | E36: 19.3
B37: 7 | C37: 35.5 | D37: 16.6 | E37: 22.1 | F37: 786
B38: 14 | C38: 41.4 | D38: 18.8 | E38: 25.1 | F38: 843
B39: 21 | C39: 47.7 | D39: 21.2 | E39: 28.3 | F39: 900
B40: 28 | C40: 54.3 | D40: 23.7 | E40: 31.6 | F40: 943
B41: 35 | C41: 61 | D41: 25.9 | E41: 34.5 | F41: 957
...

Sheet references
A1: Landquist et al. 2020. Uppdaterad och utökad livscykelanalys av svensk grisproduktion. RISE
