Workbook

Sheet references

Sheet default
A1: f_breed | B1: f_prod_system | C1: f_sub_system | D1: f_animal | E1: f_feed | F1: parameter | G1: value | H1: unit | I1: description | J1: source
A3: Fertility etc.
C4: autumn lamb | F4: fertility | G4: 93 | H4: % | J4: Ahlgren et al 2022, Bilaga 6 Tabell X
C5: spring lamb | F5: fertility | G5: 88 | H5: % | J5: Ahlgren et al 2022, Bilaga 6 Tabell X
C6: winter lamb | F6: fertility | G6: 92 | H6: % | J6: Ahlgren et al 2022, Bilaga 6 Tabell X
C7: other sheep | F7: fertility | G7: 8 | H7: % | I7: Fertility pars for this category set to get few lambs for slaughter and around 0.12 lambs per ewe+ram according to statistics
C9: autumn lamb | F9: lambs_per_ewe | G9: =(2.02+1.84+2.02)/3 -> 1.96 | H9: nr | J9: Ahlgren et al 2022, Bilaga 6 Tabell X
C10: spring lamb | F10: lambs_per_ewe | G10: 1.8 | H10: nr | J10: Ahlgren et al 2022, Bilaga 6 Tabell X
C11: winter lamb | F11: lambs_per_ewe | G11: =(1.8+1.64+1.74)/3 -> 1.7266667 | H11: nr | J11: Ahlgren et al 2022, Bilaga 6 Tabell X
C12: other sheep | F12: lambs_per_ewe | G12: 1.7 | H12: nr | I12: assumed a bit lower than the others
C14: autumn lamb | F14: recruitment_rate | G14: 23 | H14: % | J14: Ahlgren et al 2022, Bilaga 6 Tabell X
C15: spring lamb | F15: recruitment_rate | G15: 25 | H15: % | J15: Ahlgren et al 2022, Bilaga 6 Tabell X
C16: winter lamb | F16: recruitment_rate | G16: 22 | H16: % | J16: Ahlgren et al 2022, Bilaga 6 Tabell X
C17: other sheep | F17: recruitment_rate | G17: 12 | H17: % | I17: gives ~9 years slaughter age
F19: recruitment_rate_rams | G19: =1/(4.5-1)*100 -> 28.571429 | H19: % | I19: assumes rams start being rams at 1 year | J19: Ahlgren et al 2022, Bilaga 6 Tabell Y
F21: age_at_first_lambing | G21: 12 | H21: months | I21: 1 year seems common in commercial herds
F23: rams_per_ewe | G23: 0.025 | H23: nr | J23: Ahlgren et al 2022, Bilaga 6 Tabell Y
A25: Mortality
C27: autumn lamb | D27: ewes | F27: mortality | G27: 3 | H27: % | I27: per year | J27: Ahlgren et al 2022, Bilaga 6 Tabell X
C28: spring lamb | D28: ewes | F28: mortality | G28: 2 | H28: % | J28: Ahlgren et al 2022, Bilaga 6 Tabell X
C29: winter lamb | D29: ewes | F29: mortality | G29: 3 | H29: % | J29: Ahlgren et al 2022, Bilaga 6 Tabell X
C30: other sheep | D30: ewes | F30: mortality | G30: 3 | H30: % | I30: assumed same as autumn
D32: rams | F32: mortality | G32: 3 | H32: % | I32: assumed same as ewes
C34: autumn lamb | D34: lambs | F34: mortality | G34: =(11+9+11)/3 -> 10.333333 | H34: % | I34: of born (??) | J34: Ahlgren et al 2022, Bilaga 6 Tabell Ö
C35: spring lamb | D35: lambs | F35: mortality | G35: 9 | H35: % | J35: Ahlgren et al 2022, Bilaga 6 Tabell Ö
C36: winter lamb | D36: lambs | F36: mortality | G36: =(11+11+14)/3 -> 12 | H36: % | J36: Ahlgren et al 2022, Bilaga 6 Tabell Ö
C37: other sheep | D37: lambs | F37: mortality | G37: 10 | H37: % | I37: assumed same as autumn
A39: Maximum shares per sub-system on national level
A40: Note:
C41: autumn lamb | F41: max_share_sub_system | G41: =30*1.1 -> 33 | H41: % | I41: From shares according to slaughter statistics plus some slack
C42: spring lamb | F42: max_share_sub_system | G42: =18 -> 18 | H42: %
C43: winter lamb | F43: max_share_sub_system | G43: =13*1.1 -> 14.3 | H43: %
C44: other sheep | F44: max_share_sub_system | G44: =39*1.1 -> 42.9 | H44: %
A46: Slaughter
C48: autumn lamb | D48: lambs | F48: slaughter_age | G48: =(160+181+163)/3 -> 168 | H48: days | J48: Ahlgren et al 2022, Bilaga 6 Tabell Ö
C49: spring lamb | D49: lambs | F49: slaughter_age | G49: 113 | H49: days | J49: Ahlgren et al 2022, Bilaga 6 Tabell Ö
C50: winter lamb | D50: lambs | F50: slaughter_age | G50: 308 | H50: days | J50: Ahlgren et al 2022, Bilaga 6 Tabell Ö
C51: other sheep | D51: lambs | F51: slaughter_age | G51: 168 | H51: days | I51: assumed same as autumn
C53: autumn lamb | D53: ewes | F53: slaughter_weight | G53: =(30+27+30)/3 -> 29 | H53: kg CW | J53: Ahlgren et al 2022, Bilaga 6 Tabell Ä
C54: spring lamb | D54: ewes | F54: slaughter_weight | G54: 33 | H54: kg CW | J54: Ahlgren et al 2022, Bilaga 6 Tabell Ä
...

Sheet feed rations
B2: Feed ration ewes and rams [kg DM/head] | I2: Feed ration lambs [kg DM/lamb]
B3: Ahlgren et al 2022 | I3: Ahlgren et al 2022
D4: Silage | E4: Grazing | F4: Concentrate | G4: Total | K4: Silage | L4: Grazing | M4: Concentrate | N4: Total
B5: autumn lamb | D5: =((290+234+364)/3)+((290+234+364)/3)*0.1 -> 325.6 | E5: =((386+399+289)/3)+((386+399+289)/3)*0.1 -> 393.8 | F5: =(26+26+35)/3 -> 29 | G5: =SUM(D5:F5) -> 748.4 | I5: autumn lamb | K5: =((3+1+5)/3)+((3+1+5)/3)*0.1 -> 3.3 | L5: =((119+138+101)/3)+((119+138+101)/3)*0.1 -> 131.26667 | M5: =(19+21+29)/3 -> 23 | N5: =SUM(K5:M5) -> 157.56667
B6: spring lamb | D6: =((223+223+242)/3)+((223+223+242)/3)*0.1 -> 252.26667 | E6: =((233+233+189)/3)+((233+233+189)/3)*0.1 -> 240.16667 | F6: =(62+62+61)/3 -> 61.666667 | G6: =SUM(D6:F6) -> 554.1 | I6: spring lamb | K6: =50+50*0.1 -> 55 | L6: 0 | M6: 59 | N6: =SUM(K6:M6) -> 114
B7: winter lamb | D7: =((276+239+350)/3)+((276+239+350)/3)*0.1 -> 317.16667 | E7: =((395+410+298)/3)+((395+410+298)/3)*0.1 -> 404.43333 | F7: =(4+6+4)/3 -> 4.6666667 | G7: =SUM(D7:F7) -> 726.26667 | I7: winter lamb | K7: =((5+5+6)/3+(118+121+132)/3)+((5+5+6)/3+(118+121+132)/3)*0.1 -> 141.9 | L7: =((102+101+87)/3)+((102+101+87)/3)*0.1 -> 106.33333 | M7: =(4+9+6)/3 -> 6.3333333 | N7: =SUM(K7:M7) -> 254.56667
B8: other sheep | D8: =((290+234+364)/3)+((290+234+364)/3)*0.1 -> 325.6 | E8: =((386+399+289)/3)+((386+399+289)/3)*0.1 -> 393.8 | F8: =(26+26+35)/3 -> 29 | G8: =SUM(D8:F8) -> 748.4 | I8: other sheep | K8: =((3+1+5)/3)+((3+1+5)/3)*0.1 -> 3.3 | L8: =((119+138+101)/3)+((119+138+101)/3)*0.1 -> 131.26667 | M8: =(19+21+29)/3 -> 23 | N8: =SUM(K8:M8) -> 157.56667 | P8: TOTAL DRY MATTER | AB8: PERCENT OF DRY MATTER
B10: SCB Feed industry statistics 2022 | O10: sub_system | P10: autumn lamb | Q10: autumn lamb | R10: spring lamb | S10: spring lamb | T10: winter lamb | U10: winter lamb | V10: other sheep | W10: other sheep | AA10: sub_system | AB10: autumn lamb | AC10: autumn lamb | AD10: spring lamb | AE10: spring lamb | AF10: winter lamb | AG10: winter lamb | AH10: other sheep | AI10: other sheep
B11: Category 'Övriga djurslag' | O11: animal | Q11: lambs | S11: lambs | U11: lambs | W11: lambs | AA11: animal | AC11: lambs | AE11: lambs | AG11: lambs | AI11: lambs
F12: DM | G12: SWE | H12: IMP | I12: TOT | J12: DM | K12: % of DM | M12: feed | P12: =P10&P11 -> autumn lamb | Q12: =Q10&Q11 -> autumn lamblambs | R12: =R10&R11 -> spring lamb | S12: =S10&S11 -> spring lamblambs | T12: =T10&T11 -> winter lamb | U12: =U10&U11 -> winter lamblambs | V12: =V10&V11 -> other sheep | W12: =W10&W11 -> other sheeplambs | Y12: feed | AB12: =AB10&AB11 -> autumn lamb | AC12: =AC10&AC11 -> autumn lamblambs | AD12: =AD10&AD11 -> spring lamb | AE12: =AE10&AE11 -> spring lamblambs | AF12: =AF10&AF11 -> winter lamb | AG12: =AG10&AG11 -> winter lamblambs | AH12: =AH10&AH11 -> other sheep | AI12: =AI10&AI11 -> other sheeplambs
B13: wheat | F13: 0.86 | G13: 39770.2 | H13: 0 | I13: =SUM(G13:H13) -> 39770.2 | J13: =F13*I13 -> 34202.372 | K13: =J13/SUM(J$13:J$43) -> 0.21853862 | M13: ley silage, 1st cut | P13: =D5*(1/3) -> 108.53333 | Q13: =K5*(1/3) -> 1.1 | R13: =D6*(1/3) -> 84.088889 | S13: =K6*(1/3) -> 18.333333 | T13: =D7*(1/3) -> 105.72222 | U13: =K7*(1/3) -> 47.3 | V13: =D8*(1/3) -> 108.53333 | W13: =K8*(1/3) -> 1.1 | Y13: ley silage, 1st cut | AB13: =P13/P$48*100 -> 14.502049 | AC13: =Q13/Q$48*100 -> 0.6981172 | AD13: =R13/R$48*100 -> 15.17576 | AE13: =S13/S$48*100 -> 16.081871 | AF13: =T13/T$48*100 -> 14.556943 | AG13: =U13/U$48*100 -> 18.580594 | AH13: =V13/V$48*100 -> 14.502049 | AI13: =W13/W$48*100 -> 0.6981172
B14: barley | F14: 0.86 | G14: 20541.1 | H14: 0 | I14: =SUM(G14:H14) -> 20541.1 | J14: =F14*I14 -> 17665.346 | K14: =J14/SUM(J$13:J$43) -> 0.11287405 | M14: ley silage, regrowth | P14: =D5*(2/3) -> 217.06667 | Q14: =K5*(2/3) -> 2.2 | R14: =D6*(2/3) -> 168.17778 | S14: =K6*(2/3) -> 36.666667 | T14: =D7*(2/3) -> 211.44444 | U14: =K7*(2/3) -> 94.6 | V14: =D8*(2/3) -> 217.06667 | W14: =K8*(2/3) -> 2.2 | Y14: ley silage, regrowth | AB14: =P14/P$48*100 -> 29.004098 | AC14: =Q14/Q$48*100 -> 1.3962344 | AD14: =R14/R$48*100 -> 30.351521 | AE14: =S14/S$48*100 -> 32.163743 | AF14: =T14/T$48*100 -> 29.113885 | AG14: =U14/U$48*100 -> 37.161189 | AH14: =V14/V$48*100 -> 29.004098 | AI14: =W14/W$48*100 -> 1.3962344
B15: oats | F15: 0.86 | G15: 31138.8 | H15: 0 | I15: =SUM(G15:H15) -> 31138.8 | J15: =F15*I15 -> 26779.368 | K15: =J15/SUM(J$13:J$43) -> 0.17110878 | M15: grazing | P15: =E5 -> 393.8 | Q15: =L5 -> 131.26667 | R15: =E6 -> 240.16667 | S15: =L6 -> 0 | T15: =E7 -> 404.43333 | U15: =L7 -> 106.33333 | V15: =E8 -> 393.8 | W15: =L8 -> 131.26667 | Y15: grazing | AB15: =P15/P$48*100 -> 52.61892 | AC15: =Q15/Q$48*100 -> 83.308652 | AD15: =R15/R$48*100 -> 43.34356 | AE15: =S15/S$48*100 -> 0 | AF15: =T15/T$48*100 -> 55.686616 | AG15: =U15/U$48*100 -> 41.770329 | AH15: =V15/V$48*100 -> 52.61892 | AI15: =W15/W$48*100 -> 83.308652
B16: triticale | F16: 0.86 | G16: 192.5 | H16: 0 | I16: =SUM(G16:H16) -> 192.5 | J16: =F16*I16 -> 165.55 | K16: =J16/SUM(J$13:J$43) -> 0.0010577941 | M16: wheat | P16: =F$5*K13 -> 6.3376199 | Q16: =M$5*K13 -> 5.0263882 | R16: =F$6*K13 -> 13.476548 | S16: =M$6*K13 -> 12.893778 | T16: =F$7*K13 -> 1.0198469 | U16: =M$7*K13 -> 1.3840779 | V16: =F$8*K13 -> 6.3376199 | W16: =M$8*K13 -> 5.0263882 | Y16: wheat | AB16: =P16/P$48*100 -> 0.84682254 | AC16: =Q16/Q$48*100 -> 3.1900073 | AD16: =R16/R$48*100 -> 2.4321509 | AE16: =S16/S$48*100 -> 11.310332 | AF16: =T16/T$48*100 -> 0.1404232 | AG16: =U16/U$48*100 -> 0.54369958 | AH16: =V16/V$48*100 -> 0.84682254 | AI16: =W16/W$48*100 -> 3.1900073
B17: rye | F17: 0.86 | G17: 0 | H17: 0 | I17: =SUM(G17:H17) -> 0 | J17: =F17*I17 -> 0 | K17: =J17/SUM(J$13:J$43) -> 0 | M17: barley | P17: =F$5*K14 -> 3.2733475 | Q17: =M$5*K14 -> 2.5961032 | R17: =F$6*K14 -> 6.9605664 | S17: =M$6*K14 -> 6.659569 | T17: =F$7*K14 -> 0.52674557 | U17: =M$7*K14 -> 0.71486899 | V17: =F$8*K14 -> 3.2733475 | W17: =M$8*K14 -> 2.5961032 | Y17: barley | AB17: =P17/P$48*100 -> 0.4373794 | AC17: =Q17/Q$48*100 -> 1.6476221 | AD17: =R17/R$48*100 -> 1.2561932 | AE17: =S17/S$48*100 -> 5.8417272 | AF17: =T17/T$48*100 -> 0.072527846 | AG17: =U17/U$48*100 -> 0.28081799 | AH17: =V17/V$48*100 -> 0.4373794 | AI17: =W17/W$48*100 -> 1.6476221
B18: maize | F18: 0.86 | G18: 8026.8 | H18: 84 | I18: =SUM(G18:H18) -> 8110.8 | J18: =F18*I18 -> 6975.288 | K18: =J18/SUM(J$13:J$43) -> 0.044569125 | M18: oats | P18: =F$5*K15 -> 4.9621545 | Q18: =M$5*K15 -> 3.9355019 | R18: =F$6*K15 -> 10.551708 | S18: =M$6*K15 -> 10.095418 | T18: =F$7*K15 -> 0.79850762 | U18: =M$7*K15 -> 1.0836889 | V18: =F$8*K15 -> 4.9621545 | W18: =M$8*K15 -> 3.9355019 | Y18: oats | AB18: =P18/P$48*100 -> 0.66303508 | AC18: =Q18/Q$48*100 -> 2.4976741 | AD18: =R18/R$48*100 -> 1.9042967 | AE18: =S18/S$48*100 -> 8.8556296 | AF18: =T18/T$48*100 -> 0.10994689 | AG18: =U18/U$48*100 -> 0.42569946 | AH18: =V18/V$48*100 -> 0.66303508 | AI18: =W18/W$48*100 -> 2.4976741
B19: peas | F19: 0.85 | G19: 155.5 | H19: 24 | I19: =SUM(G19:H19) -> 179.5 | J19: =F19*I19 -> 152.575 | K19: =J19/SUM(J$13:J$43) -> 0.00097488938 | M19: triticale | P19: =F$5*K16 -> 0.030676029 | Q19: =M$5*K16 -> 0.024329265 | R19: =F$6*K16 -> 0.065230637 | S19: =M$6*K16 -> 0.062409853 | T19: =F$7*K16 -> 0.0049363725 | U19: =M$7*K16 -> 0.0066993627 | V19: =F$8*K16 -> 0.030676029 | W19: =M$8*K16 -> 0.024329265 | Y19: triticale | AB19: =P19/P$48*100 -> 0.0040988815 | AC19: =Q19/Q$48*100 -> 0.015440616 | AD19: =R19/R$48*100 -> 0.011772358 | AE19: =S19/S$48*100 -> 0.054745485 | AF19: =T19/T$48*100 -> 0.00067969146 | AG19: =U19/U$48*100 -> 0.0026316732 | AH19: =V19/V$48*100 -> 0.0040988815 | AI19: =W19/W$48*100 -> 0.015440616
B20: broad beans | F20: 0.85 | G20: 1126.1 | H20: 0 | I20: =SUM(G20:H20) -> 1126.1 | J20: =F20*I20 -> 957.185 | K20: =J20/SUM(J$13:J$43) -> 0.0061160052 | M20: rye | P20: =F$5*K17 -> 0 | Q20: =M$5*K17 -> 0 | R20: =F$6*K17 -> 0 | S20: =M$6*K17 -> 0 | T20: =F$7*K17 -> 0 | U20: =M$7*K17 -> 0 | V20: =F$8*K17 -> 0 | W20: =M$8*K17 -> 0 | Y20: rye | AB20: =P20/P$48*100 -> 0 | AC20: =Q20/Q$48*100 -> 0 | AD20: =R20/R$48*100 -> 0 | AE20: =S20/S$48*100 -> 0 | AF20: =T20/T$48*100 -> 0 | AG20: =U20/U$48*100 -> 0 | AH20: =V20/V$48*100 -> 0 | AI20: =W20/W$48*100 -> 0
B21: rapeseed | F21: 0.91 | G21: 20227.2 | H21: 29 | I21: =SUM(G21:H21) -> 20256.2 | J21: =F21*I21 -> 18433.142 | K21: =J21/SUM(J$13:J$43) -> 0.11777994 | M21: maize | P21: =F$5*K18 -> 1.2925046 | Q21: =M$5*K18 -> 1.0250899 | R21: =F$6*K18 -> 2.7484294 | S21: =M$6*K18 -> 2.6295784 | T21: =F$7*K18 -> 0.20798925 | U21: =M$7*K18 -> 0.28227112 | V21: =F$8*K18 -> 1.2925046 | W21: =M$8*K18 -> 1.0250899 | Y21: maize | AB21: =P21/P$48*100 -> 0.17270238 | AC21: =Q21/Q$48*100 -> 0.65057533 | AD21: =R21/R$48*100 -> 0.49601685 | AE21: =S21/S$48*100 -> 2.3066477 | AF21: =T21/T$48*100 -> 0.028638138 | AG21: =U21/U$48*100 -> 0.11088299 | AH21: =V21/V$48*100 -> 0.17270238 | AI21: =W21/W$48*100 -> 0.65057533
B22: linseed | F22: 0.91 | G22: 6.3 | H22: 21 | I22: =SUM(G22:H22) -> 27.3 | J22: =F22*I22 -> 24.843 | K22: =J22/SUM(J$13:J$43) -> 0.00015873621 | M22: peas | P22: =F$5*K19 -> 0.028271792 | Q22: =M$5*K19 -> 0.022422456 | R22: =F$6*K19 -> 0.060118179 | S22: =M$6*K19 -> 0.057518474 | T22: =F$7*K19 -> 0.0045494838 | U22: =M$7*K19 -> 0.0061742994 | V22: =F$8*K19 -> 0.028271792 | W22: =M$8*K19 -> 0.022422456 | Y22: peas | AB22: =P22/P$48*100 -> 0.0037776312 | AC22: =Q22/Q$48*100 -> 0.014230456 | AD22: =R22/R$48*100 -> 0.010849698 | AE22: =S22/S$48*100 -> 0.050454801 | AF22: =T22/T$48*100 -> 0.00062642057 | AG22: =U22/U$48*100 -> 0.0024254155 | AH22: =V22/V$48*100 -> 0.0037776312 | AI22: =W22/W$48*100 -> 0.014230456
B23: vegetable oils | F23: 1 | G23: 0 | H23: 7774.3 | I23: =SUM(G23:H23) -> 7774.3 | J23: =F23*I23 -> 7774.3 | K23: =J23/SUM(J$13:J$43) -> 0.049674472 | M23: broad beans | P23: =F$5*K20 -> 0.17736415 | Q23: =M$5*K20 -> 0.14066812 | R23: =F$6*K20 -> 0.37715365 | S23: =M$6*K20 -> 0.36084431 | T23: =F$7*K20 -> 0.028541358 | U23: =M$7*K20 -> 0.0387347 | V23: =F$8*K20 -> 0.17736415 | W23: =M$8*K20 -> 0.14066812 | Y23: broad beans | AB23: =P23/P$48*100 -> 0.023699112 | AC23: =Q23/Q$48*100 -> 0.089275303 | AD23: =R23/R$48*100 -> 0.068065991 | AE23: =S23/S$48*100 -> 0.31653009 | AF23: =T23/T$48*100 -> 0.003929873 | AG23: =U23/U$48*100 -> 0.015215935 | AH23: =V23/V$48*100 -> 0.023699112 | AI23: =W23/W$48*100 -> 0.089275303
B24: soybeans | F24: 0.87 | G24: 0 | H24: 1 | I24: =SUM(G24:H24) -> 1 | J24: =F24*I24 -> 0.87 | K24: =J24/SUM(J$13:J$43) -> 5.5589301e-06 | M24: rapeseed | P24: =F$5*K21 -> 3.4156183 | Q24: =M$5*K21 -> 2.7089386 | R24: =F$6*K21 -> 7.2630963 | S24: =M$6*K21 -> 6.9490165 | T24: =F$7*K21 -> 0.54963972 | U24: =M$7*K21 -> 0.74593962 | V24: =F$8*K21 -> 3.4156183 | W24: =M$8*K21 -> 2.7089386 | Y24: rapeseed | AB24: =P24/P$48*100 -> 0.4563894 | AC24: =Q24/Q$48*100 -> 1.7192333 | AD24: =R24/R$48*100 -> 1.3107916 | AE24: =S24/S$48*100 -> 6.0956285 | AF24: =T24/T$48*100 -> 0.075680153 | AG24: =U24/U$48*100 -> 0.29302329 | AH24: =V24/V$48*100 -> 0.4563894 | AI24: =W24/W$48*100 -> 1.7192333
B25: soybean meal | F25: 0.875 | G25: 140.6 | H25: 22511.5 | I25: =SUM(G25:H25) -> 22652.1 | J25: =F25*I25 -> 19820.587 | K25: =J25/SUM(J$13:J$43) -> 0.12664513 | M25: linseed | P25: =F$5*K22 -> 0.00460335 | Q25: =M$5*K22 -> 0.0036509328 | R25: =F$6*K22 -> 0.0097887328 | S25: =M$6*K22 -> 0.0093654363 | T25: =F$7*K22 -> 0.00074076897 | U25: =M$7*K22 -> 0.0010053293 | V25: =F$8*K22 -> 0.00460335 | W25: =M$8*K22 -> 0.0036509328 | Y25: linseed | AB25: =P25/P$48*100 -> 0.0006150922 | AC25: =Q25/Q$48*100 -> 0.0023170718 | AD25: =R25/R$48*100 -> 0.0017666004 | AE25: =S25/S$48*100 -> 0.008215295 | AF25: =T25/T$48*100 -> 0.00010199683 | AG25: =U25/U$48*100 -> 0.00039491789 | AH25: =V25/V$48*100 -> 0.0006150922 | AI25: =W25/W$48*100 -> 0.0023170718
B26: soybean protein concentrate | F26: 0.87 | G26: 0 | H26: 0.9 | I26: =SUM(G26:H26) -> 0.9 | J26: =F26*I26 -> 0.783 | K26: =J26/SUM(J$13:J$43) -> 5.0030371e-06 | M26: vegetable oils | P26: =F$5*K23 -> 1.4405597 | Q26: =M$5*K23 -> 1.1425128 | R26: =F$6*K23 -> 3.0632591 | S26: =M$6*K23 -> 2.9307938 | T26: =F$7*K23 -> 0.2318142 | U26: =M$7*K23 -> 0.31460499 | V26: =F$8*K23 -> 1.4405597 | W26: =M$8*K23 -> 1.1425128 | Y26: vegetable oils | AB26: =P26/P$48*100 -> 0.19248526 | AC26: =Q26/Q$48*100 -> 0.72509806 | AD26: =R26/R$48*100 -> 0.55283506 | AE26: =S26/S$48*100 -> 2.5708718 | AF26: =T26/T$48*100 -> 0.031918607 | AG26: =U26/U$48*100 -> 0.12358452 | AH26: =V26/V$48*100 -> 0.19248526 | AI26: =W26/W$48*100 -> 0.72509806
B27: rapeseed meal | F27: 0.895 | G27: 9301.6 | H27: 191 | I27: =SUM(G27:H27) -> 9492.6 | J27: =F27*I27 -> 8495.877 | K27: =J27/SUM(J$13:J$43) -> 0.054285042 | M27: soybeans | P27: =F$5*K24 -> 0.00016120897 | Q27: =M$5*K24 -> 0.00012785539 | R27: =F$6*K24 -> 0.00034280069 | S27: =M$6*K24 -> 0.00032797688 | T27: =F$7*K24 -> 2.5941674e-05 | U27: =M$7*K24 -> 3.5206557e-05 | V27: =F$8*K24 -> 0.00016120897 | W27: =M$8*K24 -> 0.00012785539 | Y27: soybeans | AB27: =P27/P$48*100 -> 2.1540483e-05 | AC27: =Q27/Q$48*100 -> 8.1143681e-05 | AD27: =R27/R$48*100 -> 6.1866214e-05 | AE27: =S27/S$48*100 -> 0.00028769901 | AF27: =T27/T$48*100 -> 3.5719213e-06 | AG27: =U27/U$48*100 -> 1.3829995e-05 | AH27: =V27/V$48*100 -> 2.1540483e-05 | AI27: =W27/W$48*100 -> 8.1143681e-05
... B36: wheat distillers grain, dry | F36: 0.9 | G36: 706 | H36: 0 | I36: =SUM(G36:H36) -> 706 | J36: =F36*I36 -> 635.4 | K36: =J36/SUM(J$13:J$43) -> 0.0040599359 | M36: oat hulls | P36: =F$5*K33 -> 0.26930637 | Q36: =M$5*K33 -> 0.21358781 | R36: =F$6*K33 -> 0.57266297 | S36: =M$6*K33 -> 0.54789917 | T36: =F$7*K33 -> 0.043336658 | U36: =M$7*K33 -> 0.058814035 | V36: =F$8*K33 -> 0.26930637 | W36: =M$8*K33 -> 0.21358781 | Y36: oat hulls | AB36: =P36/P$48*100 -> 0.035984283 | AC36: =Q36/Q$48*100 -> 0.13555393 | AD36: =R36/R$48*100 -> 0.10335011 | AE36: =S36/S$48*100 -> 0.48061331 | AF36: =T36/T$48*100 -> 0.0059670448 | AG36: =U36/U$48*100 -> 0.023103589 | AH36: =V36/V$48*100 -> 0.035984283 | AI36: =W36/W$48*100 -> 0.13555393
B37: barley brewers grain | F37: 0.9 | I37: =SUM(G37:H37) -> 0 | J37: =F37*I37 -> 0 | K37: =J37/SUM(J$13:J$43) -> 0 | M37: oat bran | P37: =F$5*K34 -> 0.07482987 | Q37: =M$5*K34 -> 0.059347828 | R37: =F$6*K34 -> 0.15912099 | S37: =M$6*K34 -> 0.15224008 | T37: =F$7*K34 -> 0.012041588 | U37: =M$7*K34 -> 0.016342156 | V37: =F$8*K34 -> 0.07482987 | W37: =M$8*K34 -> 0.059347828 | Y37: oat bran | AB37: =P37/P$48*100 -> 0.0099986465 | AC37: =Q37/Q$48*100 -> 0.037665218 | AD37: =R37/R$48*100 -> 0.028717016 | AE37: =S37/S$48*100 -> 0.13354393 | AF37: =T37/T$48*100 -> 0.001658012 | AG37: =U37/U$48*100 -> 0.0064195976 | AH37: =V37/V$48*100 -> 0.0099986465 | AI37: =W37/W$48*100 -> 0.037665218
B38: maize gluten meal | F38: 0.885 | G38: 7 | H38: 0 | I38: =SUM(G38:H38) -> 7 | J38: =F38*I38 -> 6.195 | K38: =J38/SUM(J$13:J$43) -> 3.9583416e-05 | M38: rye bran | P38: =F$5*K35 -> 0 | Q38: =M$5*K35 -> 0 | R38: =F$6*K35 -> 0 | S38: =M$6*K35 -> 0 | T38: =F$7*K35 -> 0 | U38: =M$7*K35 -> 0 | V38: =F$8*K35 -> 0 | W38: =M$8*K35 -> 0 | Y38: rye bran | AB38: =P38/P$48*100 -> 0 | AC38: =Q38/Q$48*100 -> 0 | AD38: =R38/R$48*100 -> 0 | AE38: =S38/S$48*100 -> 0 | AF38: =T38/T$48*100 -> 0 | AG38: =U38/U$48*100 -> 0 | AH38: =V38/V$48*100 -> 0 | AI38: =W38/W$48*100 -> 0
B39: sugar beet molasses | F39: 0.755 | G39: 1078.05 | H39: 0 | I39: =SUM(G39:H39) -> 1078.05 | J39: =F39*I39 -> 813.92775 | K39: =J39/SUM(J$13:J$43) -> 0.0052006523 | M39: wheat distillers grain, dry | P39: =F$5*K36 -> 0.11773814 | Q39: =M$5*K36 -> 0.093378525 | R39: =F$6*K36 -> 0.25036271 | S39: =M$6*K36 -> 0.23953622 | T39: =F$7*K36 -> 0.018946367 | U39: =M$7*K36 -> 0.025712927 | V39: =F$8*K36 -> 0.11773814 | W39: =M$8*K36 -> 0.093378525 | Y39: wheat distillers grain, dry | AB39: =P39/P$48*100 -> 0.01573198 | AC39: =Q39/Q$48*100 -> 0.059262867 | AD39: =R39/R$48*100 -> 0.045183669 | AE39: =S39/S$48*100 -> 0.21011949 | AF39: =T39/T$48*100 -> 0.0026087343 | AG39: =U39/U$48*100 -> 0.010100665 | AH39: =V39/V$48*100 -> 0.01573198 | AI39: =W39/W$48*100 -> 0.059262867
B40: sugar beet pulp | F40: 0.895 | G40: 233.25 | H40: 2559.4 | I40: =SUM(G40:H40) -> 2792.65 | J40: =F40*I40 -> 2499.4217 | K40: =J40/SUM(J$13:J$43) -> 0.015970242 | M40: barley brewers grain | P40: =F$5*K37 -> 0 | Q40: =M$5*K37 -> 0 | R40: =F$6*K37 -> 0 | S40: =M$6*K37 -> 0 | T40: =F$7*K37 -> 0 | U40: =M$7*K37 -> 0 | V40: =F$8*K37 -> 0 | W40: =M$8*K37 -> 0 | Y40: barley brewers grain | AB40: =P40/P$48*100 -> 0 | AC40: =Q40/Q$48*100 -> 0 | AD40: =R40/R$48*100 -> 0 | AE40: =S40/S$48*100 -> 0 | AF40: =T40/T$48*100 -> 0 | AG40: =U40/U$48*100 -> 0 | AH40: =V40/V$48*100 -> 0 | AI40: =W40/W$48*100 -> 0
B41: whey powder | F41: 0.97 | G41: 0 | H41: 0 | I41: =SUM(G41:H41) -> 0 | J41: =F41*I41 -> 0 | K41: =J41/SUM(J$13:J$43) -> 0 | M41: maize gluten meal | P41: =F$5*K38 -> 0.0011479191 | Q41: =M$5*K38 -> 0.00091041857 | R41: =F$6*K38 -> 0.0024409773 | S41: =M$6*K38 -> 0.0023354216 | T41: =F$7*K38 -> 0.00018472261 | U41: =M$7*K38 -> 0.00025069497 | V41: =F$8*K38 -> 0.0011479191 | W41: =M$8*K38 -> 0.00091041857 | Y41: maize gluten meal | AB41: =P41/P$48*100 -> 0.00015338309 | AC41: =Q41/Q$48*100 -> 0.00057779897 | AD41: =R41/R$48*100 -> 0.00044053011 | AE41: =S41/S$48*100 -> 0.0020486154 | AF41: =T41/T$48*100 -> 2.5434543e-05 | AG41: =U41/U$48*100 -> 9.8479103e-05 | AH41: =V41/V$48*100 -> 0.00015338309 | AI41: =W41/W$48*100 -> 0.00057779897
B42: potatoe protein | F42: 0.91 | G42: 3.3 | H42: 0 | I42: =SUM(G42:H42) -> 3.3 | J42: =F42*I42 -> 3.003 | K42: =J42/SUM(J$13:J$43) -> 1.9187893e-05 | M42: sugar beet molasses | P42: =F$5*K39 -> 0.15081892 | Q42: =M$5*K39 -> 0.119615 | R42: =F$6*K39 -> 0.32070689 | S42: =M$6*K39 -> 0.30683848 | T42: =F$7*K39 -> 0.024269711 | U42: =M$7*K39 -> 0.032937464 | V42: =F$8*K39 -> 0.15081892 | W42: =M$8*K39 -> 0.119615 | Y42: sugar beet molasses | AB42: =P42/P$48*100 -> 0.02015218 | AC42: =Q42/Q$48*100 -> 0.0759139 | AD42: =R42/R$48*100 -> 0.057878883 | AE42: =S42/S$48*100 -> 0.26915657 | AF42: =T42/T$48*100 -> 0.0033417079 | AG42: =U42/U$48*100 -> 0.01293864 | AH42: =V42/V$48*100 -> 0.02015218 | AI42: =W42/W$48*100 -> 0.0759139
B43: fish meal | F43: 0.92 | G43: 0 | H43: 0 | I43: =SUM(G43:H43) -> 0 | J43: =F43*I43 -> 0 | K43: =J43/SUM(J$13:J$43) -> 0 | M43: sugar beet pulp | P43: =F$5*K40 -> 0.46313703 | Q43: =M$5*K40 -> 0.36731557 | R43: =F$6*K40 -> 0.98483161 | S43: =M$6*K40 -> 0.9422443 | T43: =F$7*K40 -> 0.074527798 | U43: =M$7*K40 -> 0.10114487 | V43: =F$8*K40 -> 0.46313703 | W43: =M$8*K40 -> 0.36731557 | Y43: sugar beet pulp | AB43: =P43/P$48*100 -> 0.061883622 | AC43: =Q43/Q$48*100 -> 0.23311756 | AD43: =R43/R$48*100 -> 0.17773536 | AE43: =S43/S$48*100 -> 0.82653009 | AF43: =T43/T$48*100 -> 0.010261768 | AG43: =U43/U$48*100 -> 0.039732173 | AH43: =V43/V$48*100 -> 0.061883622 | AI43: =W43/W$48*100 -> 0.23311756
B44: minerals | F44: 1 | G44: 3663.5 | H44: 3456.4 | I44: =SUM(G44:H44) -> 7119.9 | J44: =F44*I44 -> 7119.9 | M44: whey powder | P44: =F$5*K41 -> 0 | Q44: =M$5*K41 -> 0 | R44: =F$6*K41 -> 0 | S44: =M$6*K41 -> 0 | T44: =F$7*K41 -> 0 | U44: =M$7*K41 -> 0 | V44: =F$8*K41 -> 0 | W44: =M$8*K41 -> 0 | Y44: whey powder | AB44: =P44/P$48*100 -> 0 | AC44: =Q44/Q$48*100 -> 0 | AD44: =R44/R$48*100 -> 0 | AE44: =S44/S$48*100 -> 0 | AF44: =T44/T$48*100 -> 0 | AG44: =U44/U$48*100 -> 0 | AH44: =V44/V$48*100 -> 0 | AI44: =W44/W$48*100 -> 0
M45: potatoe protein | P45: =F$5*K42 -> 0.0005564489 | Q45: =M$5*K42 -> 0.00044132155 | R45: =F$6*K42 -> 0.0011832534 | S45: =M$6*K42 -> 0.0011320857 | T45: =F$7*K42 -> 8.9543502e-05 | U45: =M$7*K42 -> 0.00012152332 | V45: =F$8*K42 -> 0.0005564489 | W45: =M$8*K42 -> 0.00044132155 | Y45: potatoe protein | AB45: =P45/P$48*100 -> 7.4351804e-05 | AC45: =Q45/Q$48*100 -> 0.0002800856 | AD45: =R45/R$48*100 -> 0.0002135451 | AE45: =S45/S$48*100 -> 0.00099305763 | AF45: =T45/T$48*100 -> 1.2329287e-05 | AG45: =U45/U$48*100 -> 4.7737328e-05 | AH45: =V45/V$48*100 -> 7.4351804e-05 | AI45: =W45/W$48*100 -> 0.0002800856
M46: fish meal | P46: =F$5*K43 -> 0 | Q46: =M$5*K43 -> 0 | R46: =F$6*K43 -> 0 | S46: =M$6*K43 -> 0 | T46: =F$7*K43 -> 0 | U46: =M$7*K43 -> 0 | V46: =F$8*K43 -> 0 | W46: =M$8*K43 -> 0 | Y46: fish meal | AB46: =P46/P$48*100 -> 0 | AC46: =Q46/Q$48*100 -> 0 | AD46: =R46/R$48*100 -> 0 | AE46: =S46/S$48*100 -> 0 | AF46: =T46/T$48*100 -> 0 | AG46: =U46/U$48*100 -> 0 | AH46: =V46/V$48*100 -> 0 | AI46: =W46/W$48*100 -> 0
M48: total | P48: =SUM(P13:P46) -> 748.4 | Q48: =SUM(Q13:Q46) -> 157.56667 | R48: =SUM(R13:R46) -> 554.1 | S48: =SUM(S13:S46) -> 114 | T48: =SUM(T13:T46) -> 726.26667 | U48: =SUM(U13:U46) -> 254.56667 | V48: =SUM(V13:V46) -> 748.4 | W48: =SUM(W13:W46) -> 157.56667 | Y48: total | AB48: =SUM(AB13:AB46) -> 100 | AC48: =SUM(AC13:AC46) -> 100 | AD48: =SUM(AD13:AD46) -> 100 | AE48: =SUM(AE13:AE46) -> 100 | AF48: =SUM(AF13:AF46) -> 100 | AG48: =SUM(AG13:AG46) -> 100 | AH48: =SUM(AH13:AH46) -> 100 | AI48: =SUM(AI13:AI46) -> 100

Sheet antal djur
A3: ANTAL | B3: 2000 | C3: 2010 | D3: 2013 | E3: 2016 | F3: 2020 | G3: 2021 | H3: 2022
A4: Baggar och tackor | B4: 198268 | C4: 273126 | D4: 285520 | E4: 281327 | F4: 263369 | G4: 271638 | H4: 264453
A5: Lamm | B5: 233666 | C5: 291796 | D5: 291249 | E5: 296847 | F5: 237784 | G5: 251810 | H5: 245484
A6: Får- total | B6: =SUM(B4:B5) -> 431934 | C6: =SUM(C4:C5) -> 564922 | D6: =SUM(D4:D5) -> 576769 | E6: =SUM(E4:E5) -> 578174 | F6: =SUM(F4:F5) -> 501153 | G6: =SUM(G4:G5) -> 523448 | H6: =SUM(H4:H5) -> 509937
A8: slaktade djur | B8: =B3 -> 2000 | C8: =C3 -> 2010 | D8: =D3 -> 2013 | E8: =E3 -> 2016 | F8: =F3 -> 2020 | G8: =G3 -> 2021 | H8: =H3 -> 2022
A9: Baggar och tackor | B9: =28.3*1000 -> 28300 | C9: =32.72*1000 -> 32720 | D9: =34.68*1000 -> 34680 | E9: =33.21*1000 -> 33210 | F9: =33.38*1000 -> 33380 | G9: =31.1*1000 -> 31100 | H9: ='antalet lamm och fodertstater'!$S$45 -> 0
A10: Lamm | B10: =173.85*1000 -> 173850 | C10: =221.91*1000 -> 221910 | D10: =217.86*1000 -> 217860 | E10: =251.2*1000 -> 251200 | F10: =240.54*1000 -> 240540 | G10: =227.07*1000 -> 227070 | H10: ='antalet lamm och fodertstater'!$S$49 -> 0
A12: rekruterings procent tackor och baggar | B12: =B9/B4 -> 0.14273609 | C12: =C9/C4 -> 0.11979819 | D12: =D9/D4 -> 0.12146259 | E12: =E9/E4 -> 0.11804768 | F12: =F9/F4 -> 0.12674233 | G12: =G9/G4 -> 0.11449061 | H12: =H9/H4 -> 0 | K12: https://statistik.sjv.se/PXWeb/pxweb/sv/Jordbruksverkets%20statistikdatabas/Jordbruksverkets%20statistikdatabas__Animalieproduktion__Slakt/JO0604A3.px/table/tableViewLayout1/
A13: Lamm till slakt per tacka och bagge | B13: =B10/B4 -> 0.87684346 | C13: =C10/C4 -> 0.81248215 | D13: =D10/D4 -> 0.76302886 | E13: =E10/E4 -> 0.8929111 | F13: =F10/F4 -> 0.91331934 | G13: =G10/G4 -> 0.8359287 | H13: =H10/H4 -> 0
A16: antalet lamm i olika produktionssystem baserat på slaktstsistiken 2022
A19: OBS ingen dödlighet medräknad
A20: Antalet tackor i "intensiv lammköttsproduktione" | F20: ='antalet lamm och fodertstater'!AD63 -> 161336.13
A21: Anatalet vårlamm | F21: ='antalet lamm och fodertstater'!T61 -> 55250 | G21: =F21/F25 -> 0.2378144
A22: Anatlet höstlamm | F22: ='antalet lamm och fodertstater'!T62 -> 95550 | G22: =F22/F25 -> 0.41127902 | H22: similar to Rundgren et al 2023
A23: Antalet vinterlamm | F23: ='antalet lamm och fodertstater'!T60 -> 41190 | G23: =F23/F25 -> 0.17729548
A24: Antalet rekruteringtckor | F24: ='antalet lamm och fodertstater'!T68 -> 40334.034
A25: Totalt antalet lamm i lammköttproduktionen | F25: =SUM(F21:F24) -> 232324.03
A27: andel tackor och baggar som slaktas varje år | F27: =AVERAGE(B12:G12) -> 0.12387958
A29: Anatlet tackkor och baggar "över" | F29: =H4-F20 -> 103116.87 | G29: =F29/H4 -> 0.38992511
A30: Antalet lamm "över" | F30: =H5-F25 -> 13159.966 | G30: =F30/H5 -> 0.053608245
J31: =(1/0.12)+1 -> 9.3333333
A32: lamm/tacka eller bagge | F32: =F30/F29 -> 0.12762186

Sheet antalet lamm och fodertstater
A1: Slakt av större lantbruksdjur vid slakteri efter Djurslag, Tabelluppgift och Månad | C1: Vinterlamm | F1: Vårlamm | J1: Höstlamm
C2: Januari | D2: Februari | E2: Mars | F2: April | G2: Maj | H2: Juni | I2: Juli | J2: Augusti | K2: September | L2: October | M2: November | N2: December
C3: 2022M01 | D3: 2022M02 | E3: 2022M03 | F3: 2022M04 | G3: 2022M05 | H3: 2022M06 | I3: 2022M07 | J3: 2022M08 | K3: 2022M09 | L3: 2022M10 | M3: 2022M11 | N3: 2022M12
A4: Mellankalv | B4: Slaktade hela kroppar, 1 000-tal | C4: 0.93 | D4: 1.03 | E4: 1.02 | F4: 0.95 | G4: 1.02 | H4: 0.92 | I4: 0.74 | J4: 0.93 | K4: 0.99 | L4: 0.95 | M4: 1.12 | N4: 0.79
B5: Kvantitet, 1 000 ton | C5: 0.16 | D5: 0.17 | E5: 0.17 | F5: 0.16 | G5: 0.17 | H5: 0.16 | I5: 0.13 | J5: 0.16 | K5: 0.16 | L5: 0.15 | M5: 0.18 | N5: 0.13
A6: Summa kalv | B6: Slaktade hela kroppar, 1 000-tal | C6: 0.93 | D6: 1.03 | E6: 1.03 | F6: 0.95 | G6: 1.02 | H6: 0.92 | I6: 0.74 | J6: 0.93 | K6: 0.99 | L6: 0.95 | M6: 1.13 | N6: 0.81
B7: Kvantitet, 1 000 ton | C7: 0.16 | D7: 0.17 | E7: 0.17 | F7: 0.16 | G7: 0.17 | H7: 0.16 | I7: 0.13 | J7: 0.16 | K7: 0.16 | L7: 0.15 | M7: 0.18 | N7: 0.13
A8: Stut | B8: Slaktade hela kroppar, 1 000-tal | C8: 2.54 | D8: 2.64 | E8: 3.11 | F8: 2.48 | G8: 3.18 | H8: 2.15 | I8: 1.65 | J8: 2.8 | K8: 2.94 | L8: 2.75 | M8: 3.18 | N8: 2.44
B9: Kvantitet, 1 000 ton | C9: 0.85 | D9: 0.89 | E9: 1.05 | F9: 0.85 | G9: 1.06 | H9: 0.74 | I9: 0.56 | J9: 0.94 | K9: 0.95 | L9: 0.89 | M9: 1.04 | N9: 0.8
A10: Äldre tjur | B10: Slaktade hela kroppar, 1 000-tal | C10: 0.23 | D10: 0.16 | E10: 0.18 | F10: 0.14 | G10: 0.18 | H10: 0.17 | I10: 0.19 | J10: 0.34 | K10: 0.39 | L10: 0.38 | M10: 0.43 | N10: 0.29
B11: Kvantitet, 1 000 ton | C11: 0.12 | D11: 0.07 | E11: 0.08 | F11: 0.07 | G11: 0.09 | H11: 0.09 | I11: 0.09 | J11: 0.17 | K11: 0.2 | L11: 0.19 | M11: 0.22 | N11: 0.15
A12: Ungtjur | B12: Slaktade hela kroppar, 1 000-tal | C12: 10.06 | D12: 9.84 | E12: 12.11 | F12: 10.99 | G12: 13 | H12: 15.76 | I12: 14.78 | J12: 16.37 | K12: 14.89 | L12: 12.98 | M12: 11.44 | N12: 9.87
B13: Kvantitet, 1 000 ton | C13: 3.45 | D13: 3.32 | E13: 4.09 | F13: 3.76 | G13: 4.47 | H13: 5.48 | I13: 5.18 | J13: 5.73 | K13: 5.14 | L13: 4.45 | M13: 3.87 | N13: 3.31
A14: Yngre tjur | B14: Slaktade hela kroppar, 1 000-tal | C14: 1.25 | D14: 1.19 | E14: 1.43 | F14: 1.45 | G14: 1.76 | H14: 1.42 | I14: 1.33 | J14: 1.51 | K14: 1.38 | L14: 1.31 | M14: 1.49 | N14: 1.29
B15: Kvantitet, 1 000 ton | C15: 0.46 | D15: 0.43 | E15: 0.52 | F15: 0.54 | G15: 0.65 | H15: 0.52 | I15: 0.49 | J15: 0.54 | K15: 0.5 | L15: 0.47 | M15: 0.54 | N15: 0.47
A16: Summa tjur | B16: Slaktade hela kroppar, 1 000-tal | C16: 11.55 | D16: 11.18 | E16: 13.72 | F16: 12.58 | G16: 14.93 | H16: 17.35 | I16: 16.3 | J16: 18.21 | K16: 16.67 | L16: 14.66 | M16: 13.36 | N16: 11.44
B17: Kvantitet, 1 000 ton | C17: 4.03 | D17: 3.83 | E17: 4.69 | F17: 4.37 | G17: 5.21 | H17: 6.08 | I17: 5.76 | J17: 6.44 | K17: 5.84 | L17: 5.11 | M17: 4.63 | N17: 3.93
A18: Kviga | B18: Slaktade hela kroppar, 1 000-tal | C18: 5.49 | D18: 5.79 | E18: 6.21 | F18: 5.33 | G18: 6.45 | H18: 4.76 | I18: 3.84 | J18: 4.12 | K18: 4.87 | L18: 5.96 | M18: 7.13 | N18: 5.74
B19: Kvantitet, 1 000 ton | C19: 1.72 | D19: 1.82 | E19: 1.97 | F19: 1.7 | G19: 2.05 | H19: 1.52 | I19: 1.21 | J19: 1.29 | K19: 1.47 | L19: 1.78 | M19: 2.16 | N19: 1.74
A20: Ko | B20: Slaktade hela kroppar, 1 000-tal | C20: 8.55 | D20: 8.17 | E20: 7.58 | F20: 5.54 | G20: 6.04 | H20: 5.28 | I20: 4.79 | J20: 7.92 | K20: 9.8 | L20: 10.66 | M20: 12.76 | N20: 10.59
B21: Kvantitet, 1 000 ton | C21: 2.85 | D21: 2.72 | E21: 2.51 | F21: 1.86 | G21: 2.03 | H21: 1.77 | I21: 1.56 | J21: 2.56 | K21: 3.21 | L21: 3.52 | M21: 4.26 | N21: 3.54
A22: Ungko | B22: Slaktade hela kroppar, 1 000-tal | C22: 2.82 | D22: 3.01 | E22: 2.98 | F22: 2.42 | G22: 2.62 | H22: 2.12 | I22: 1.79 | J22: 2.66 | K22: 3.11 | L22: 3.22 | M22: 3.5 | N22: 3.28
B23: Kvantitet, 1 000 ton | C23: 0.85 | D23: 0.9 | E23: 0.89 | F23: 0.74 | G23: 0.8 | H23: 0.64 | I23: 0.53 | J23: 0.78 | K23: 0.91 | L23: 0.95 | M23: 1.04 | N23: 0.97
A24: Summa ko | B24: Slaktade hela kroppar, 1 000-tal | C24: 11.37 | D24: 11.18 | E24: 10.56 | F24: 7.96 | G24: 8.67 | H24: 7.39 | I24: 6.58 | J24: 10.58 | K24: 12.91 | L24: 13.88 | M24: 16.27 | N24: 13.87
B25: Kvantitet, 1 000 ton | C25: 3.7 | D25: 3.62 | E25: 3.41 | F25: 2.6 | G25: 2.83 | H25: 2.41 | I25: 2.1 | J25: 3.35 | K25: 4.12 | L25: 4.46 | M25: 5.3 | N25: 4.5
A26: Summa storboskap | B26: Slaktade hela kroppar, 1 000-tal | C26: 30.95 | D26: 30.79 | E26: 33.6 | F26: 28.34 | G26: 33.22 | H26: 31.65 | I26: 28.36 | J26: 35.71 | K26: 37.38 | L26: 37.24 | M26: 39.94 | N26: 33.49
B27: Kvantitet, 1 000 ton | C27: 10.29 | D27: 10.16 | E27: 11.11 | F27: 9.51 | G27: 11.15 | H27: 10.74 | I27: 9.63 | J27: 12.02 | K27: 12.38 | L27: 12.25 | M27: 13.13 | N27: 10.98
A28: Summa nötkreatur | B28: Slaktade hela kroppar, 1 000-tal | C28: 31.88 | D28: 31.82 | E28: 34.62 | F28: 29.29 | G28: 34.24 | H28: 32.57 | I28: 29.1 | J28: 36.64 | K28: 38.37 | L28: 38.19 | M28: 41.07 | N28: 34.3
B29: Kvantitet, 1 000 ton | C29: 10.45 | D29: 10.33 | E29: 11.28 | F29: 9.66 | G29: 11.32 | H29: 10.9 | I29: 9.76 | J29: 12.18 | K29: 12.54 | L29: 12.4 | M29: 13.31 | N29: 11.11
A30: Slaktgris | B30: Slaktade hela kroppar, 1 000-tal | C30: 206.27 | D30: 205.81 | E30: 236.62 | F30: 202.34 | G30: 222.75 | H30: 213.96 | I30: 215.87 | J30: 231.03 | K30: 216.49 | L30: 209.05 | M30: 224.53 | N30: 211.21
B31: Kvantitet, 1 000 ton | C31: 19.78 | D31: 19.69 | E31: 22.52 | F31: 19.15 | G31: 20.86 | H31: 19.96 | I31: 20.04 | J31: 21.18 | K31: 19.77 | L31: 19.23 | M31: 20.82 | N31: 19.64
A32: Suggor | B32: Slaktade hela kroppar, 1 000-tal | C32: 2.32 | D32: 2.38 | E32: 3.03 | F32: 2.51 | G32: 2.62 | H32: 2.67 | I32: 2.76 | J32: 2.76 | K32: 2.57 | L32: 2.47 | M32: 2.51 | N32: 2.26
B33: Kvantitet, 1 000 ton | C33: 0.43 | D33: 0.44 | E33: 0.55 | F33: 0.46 | G33: 0.48 | H33: 0.49 | I33: 0.5 | J33: 0.5 | K33: 0.46 | L33: 0.45 | M33: 0.46 | N33: 0.41
A34: Galtar | B34: Slaktade hela kroppar, 1 000-tal | C34: 0.08 | D34: 0.11 | E34: 0.07 | F34: 0.08 | G34: 0.09 | H34: 0.1 | I34: 0.05 | J34: 0.07 | K34: 0.1 | L34: 0.08 | M34: 0.07 | N34: 0.07
B35: Kvantitet, 1 000 ton | C35: 0.01 | D35: 0.02 | E35: 0.01 | F35: 0.01 | G35: 0.01 | H35: 0.02 | I35: 0.01 | J35: 0.01 | K35: 0.02 | L35: 0.01 | M35: 0.01 | N35: 0.01
A36: Unggris | B36: Slaktade hela kroppar, 1 000-tal | C36: 0.14 | D36: 0.2 | E36: 0.25 | F36: 0.14 | G36: 0.3 | H36: 0.22 | I36: 0.29 | J36: 0.38 | K36: 0.25 | L36: 0.19 | M36: 0.21 | N36: 0.24
B37: Kvantitet, 1 000 ton | C37: 0 | D37: 0.01 | E37: 0.01 | F37: 0.01 | G37: 0.01 | H37: 0.01 | I37: 0.01 | J37: 0.01 | K37: 0.01 | L37: 0.01 | M37: 0.01 | N37: 0.01
A38: Unggalt | B38: Slaktade hela kroppar, 1 000-tal | C38: 1.31 | D38: 1.47 | E38: 1.44 | F38: 1.23 | G38: 1.41 | H38: 1.13 | I38: 1.19 | J38: 1.12 | K38: 1.08 | L38: 0.97 | M38: 1.02 | N38: 1.16
B39: Kvantitet, 1 000 ton | C39: 0.12 | D39: 0.14 | E39: 0.13 | F39: 0.11 | G39: 0.13 | H39: 0.1 | I39: 0.11 | J39: 0.1 | K39: 0.09 | L39: 0.09 | M39: 0.09 | N39: 0.11
A40: Summa gris | B40: Slaktade hela kroppar, 1 000-tal | C40: 212.02 | D40: 212.05 | E40: 243.82 | F40: 208.4 | G40: 229.52 | H40: 220.36 | I40: 222.92 | J40: 237.52 | K40: 222.9 | L40: 214.97 | M40: 230.76 | N40: 217.17
...

Sheet total foderåtgång
C2: feeding losses and reject | E2: 0.15 | F2: från rasmus beräkning
C4: Total mängd foder innan dödlighet är medräknat | H4: dm per head
A5: Lamm i köttproduktion | C5: ='antalet lamm och fodertstater'!AE73 -> Ensilage | D5: ='antalet lamm och fodertstater'!AF73 -> Bete | E5: ='antalet lamm och fodertstater'!AG73 -> Kraftoder | G5: Antalet djur i respektive system | H5: =C5 -> Ensilage | I5: =D5 -> Bete | J5: Grovfoder | K5: =E5 -> Kraftoder | L5: totalt DM foder per tacka och lamm (jämför Einarsson 890 kg DM för tacka och lamm)
A6: Lamm vinterlamm | C6: ='antalet lamm och fodertstater'!U60+'antalet lamm och fodertstater'!U60*E2 -> 6721.5902 | D6: ='antalet lamm och fodertstater'!V60 -> 4379.87 | E6: ='antalet lamm och fodertstater'!W60 -> 260.87 | G6: ='antalet lamm och fodertstater'!T60 -> 41190 | H6: =C6/G6*1000 -> 163.185 | I6: =D6/$G$6*1000 -> 106.33333 | J6: =H6+I6 -> 269.51833 | K6: =E6/$G$6*1000 -> 6.3333333 | L6: =J6+J7+K7+K6 -> 1049.6933
A7: Tackor vinterlamm | C7: ='antalet lamm och fodertstater'!AE60+'antalet lamm och fodertstater'!AE60*E2 -> 12624.966 | D7: ='antalet lamm och fodertstater'!AF60 -> 13998.831 | E7: ='antalet lamm och fodertstater'!AG60 -> 161.52941 | G7: ='antalet lamm och fodertstater'!AD60 -> 34613.445 | H7: =C7/$G$7*1000 -> 364.74167 | I7: =D7/$G$7*1000 -> 404.43333 | J7: =H7+I7 -> 769.175 | K7: =E7/$G$7*1000 -> 4.6666667
A8: Lamm höstlamm | C8: ='antalet lamm och fodertstater'!AA62+'antalet lamm och fodertstater'!AA62*E2 -> 362.61225 | D8: ='antalet lamm och fodertstater'!AB62 -> 12542.53 | E8: ='antalet lamm och fodertstater'!AC62 -> 2197.65 | G8: ='antalet lamm och fodertstater'!T62 -> 95550 | H8: =C8/$G$8*1000 -> 3.795 | I8: =D8/$G$8*1000 -> 131.26667 | J8: =H8+I8 -> 135.06167 | K8: =E8/$G$8*1000 -> 23 | L8: =J8+K8+K9+J9 -> 955.30167
A9: Tackor höstlamm | C9: ='antalet lamm och fodertstater'!AK62+'antalet lamm och fodertstater'!AK62*E2 -> 30065.329 | D9: ='antalet lamm och fodertstater'!AL62 -> 31619.824 | E9: ='antalet lamm och fodertstater'!AM62 -> 2328.5294 | G9: ='antalet lamm och fodertstater'!AD62 -> 80294.118 | H9: =C9/$G$9*1000 -> 374.44 | I9: =D9/$G$9*1000 -> 393.8 | J9: =H9+I9 -> 768.24 | K9: =E9/$G$9*1000 -> 29
A10: Lamm vårlamm | C10: ='antalet lamm och fodertstater'!X61+'antalet lamm och fodertstater'!X61*E2 -> 3494.5625 | D10: ='antalet lamm och fodertstater'!Y61 -> 0 | E10: ='antalet lamm och fodertstater'!Z61 -> 3259.75 | G10: ='antalet lamm och fodertstater'!T61 -> 55250 | H10: =C10/$G$10*1000 -> 63.25 | I10: =D10/$G$10*1000 -> 0 | J10: =H10+I10 -> 63.25 | K10: =E10/$G$10*1000 -> 59 | L10: =J10+J11+K10+K11 -> 714.19
A11: Tackor vårlamm | C11: ='antalet lamm och fodertstater'!AH61+'antalet lamm och fodertstater'!AH61*E2 -> 13469.238 | D11: ='antalet lamm och fodertstater'!AI61 -> 11150.595 | E11: ='antalet lamm och fodertstater'!AJ61 -> 2863.0952 | G11: ='antalet lamm och fodertstater'!AD61 -> 46428.571 | H11: =C11/$G$11*1000 -> 290.10667 | I11: =D11/$G$11*1000 -> 240.16667 | J11: =H11+I11 -> 530.27333 | K11: =E11/$G$11*1000 -> 61.666667
A12: Rekrutering tackor (när de är lamm) | C12: ='antalet lamm och fodertstater'!U68+'antalet lamm och fodertstater'!U68*E2 -> 153.06766 | D12: ='antalet lamm och fodertstater'!V68 -> 5294.5141 | E12: ='antalet lamm och fodertstater'!W68 -> 927.68277 | G12: ='antalet lamm och fodertstater'!T68 -> 40334.034 | H12: =C12/$G$12*1000 -> 3.795 | I12: =D12/$G$12*1000 -> 131.26667 | J12: =H12+I12 -> 135.06167 | K12: =E12/$G$12*1000 -> 23
A14: Tackor och baggar icke i lammköttsproduktion (pappadjuren också) | C14: ='antalet lamm och fodertstater'!AE78+'antalet lamm och fodertstater'!AE78*E2 -> 38611.079 | D14: ='antalet lamm och fodertstater'!AF78 -> 40607.422 | E14: ='antalet lamm och fodertstater'!AG78 -> 2990.3891 | G14: ='antalet lamm och fodertstater'!AD78 -> 103116.87 | H14: =C14/$G$14*1000 -> 374.44 | I14: =D14/$G$14*1000 -> 393.8 | J14: =H14+I14 -> 768.24 | K14: =E14/$G$14*1000 -> 29 | L14: =J14+K14 -> 797.24
A15: Lamm ej i lammköttsproduktionen | C15: ='antalet lamm och fodertstater'!U78+'antalet lamm och fodertstater'!U78*E2 -> 49.942072 | D15: ='antalet lamm och fodertstater'!V78 -> 1727.4649 | E15: ='antalet lamm och fodertstater'!W78 -> 302.67923 | G15: ='antalet lamm och fodertstater'!T78 -> 13159.966 | H15: =C15/$G$15*1000 -> 3.795 | I15: =D15/$G$15*1000 -> 131.26667 | J15: =H15+I15 -> 135.06167 | K15: =E15/$G$15*1000 -> 23 | L15: =J15+K15 -> 158.06167
A18: TOTALT | C18: =SUM(C6:C15) -> 105552.39 | D18: =SUM(D6:D15) -> 121321.05 | E18: =SUM(E6:E15) -> 15292.175 | F18: =SUM(F6:F15) -> 0 | G18: =SUM(G6:G15) -> 509937
A19: Totalt | C19: =SUM(C18:E18) -> 242165.61
A20: Rougahge | C20: =C18+D18 -> 226873.44 | D20: =C20/C19 -> 0.93685241
A21: Concentrate | C21: =E18 -> 15292.175 | D21: =C21/C19 -> 0.063147591
A24: jämföra
A25: Einarsson | C25: 278812
A26: Rundgren | C26: =(263969+12790) -> 276759

Sheet dödlighet
A3: dödlighet tackor | C3: 0.03 | D3: Ahlgren et al 2022
A4: dödlighet lamm | C4: 0.1 | D4: Ahlgren et al 2022
A5: average sloughter age | C5: 7 moths | D5: Gunnar Rundgren
