Workbook

Sheet references
A1: Strid, Röös & Tidåker. (2014). Förluster av svenskt nötkött inom primärproduktion och slakt. SJV Rapport 2014:07
A2: Bertilsson (2016) Updating Swedish emission factors for cattle to be used for calculations of greenhouse gases. On commission of the Swedish Environmental Protection Agency 2016. https://publications.slu.se/?file=publ/show&id=76286
A3: Ahlgren, S., Behaderovic, D., Wirsenius, S., Carlsson, A., Hessle, A. Toräng, P., Seeman, A., den Braver, T. & et al. Kvarnbäck, O. (2022) Miljöpåverkan av svensk nöt- och lammköttsproduktion. RISE

Sheet default
A1: f_breed | B1: f_prod_system | C1: f_animal | D1: f_feed | E1: f_from_ps | F1: f_to_ps | G1: parameter | H1: value | I1: unit | J1: description | K1: source
A2: Milk production
A3: Dairy
A4: dairy | B4: conventional | G4: milk_prod | H4: =AVERAGE(9829,9903,9953,10112,10330) -> 10025.4 | I4: kg/cow/year | J4: Total incl. for calves | K4: Växa Husdjursstatistik Tab. 17 (2016-2020)
A5: dairy | B5: conventional | G5: milk_loss | H5: 8 | I5: % | J5: Mikaela?? 89% delivered to dairy?? | K5: Växa + Swedish Board of Agriculture
A6: dairy | B6: conventional | G6: milk_fat | H6: =AVERAGE(4.3,4.2,4.2,4.3,4.3) -> 4.26 | I6: % | K6: Växa Husdjursstatistik Tab. 17 (2016-2020)
A7: dairy | B7: conventional | G7: milk_protein | H7: =AVERAGE(3.5,3.6,3.5,3.6,3.6) -> 3.56 | I7: % | K7: Växa Husdjursstatistik Tab. 17 (2016-2020)
A8: dairy | B8: organic | G8: milk_prod | H8: =AVERAGE(9135,9246,9280,9499,9676) -> 9367.2 | I8: kg/cow/year | K8: Växa Husdjursstatistik Tab. 17 (2016-2020)
A9: dairy | B9: organic | G9: milk_loss | H9: 8 | I9: % | J9: Mikaela?? 89% delivered to dairy?? | K9: Växa + Swedish Board of Agriculture
A10: dairy | B10: organic | G10: milk_fat | H10: =AVERAGE(4.2,4.1,4.1,4.1,4.2) -> 4.14 | I10: % | K10: Växa Husdjursstatistik Tab. 17 (2016-2020)
A11: dairy | B11: organic | G11: milk_protein | H11: =AVERAGE(3.4,3.4,3.4,3.5,3.5) -> 3.44 | I11: % | K11: Växa Husdjursstatistik Tab. 17 (2016-2020)
A13: Fertility etc.
A14: Dairy
A15: dairy | B15: conventional | G15: calving_interval | H15: 13.2 | I15: months
A16: dairy | B16: organic | G16: calving_interval | H16: 12.9 | I16: months
A17: dairy | B17: conventional | G17: AFC | H17: 27 | I17: months | J17: age at first calving
A18: dairy | B18: organic | G18: AFC | H18: 27 | I18: months | J18: age at first calving
A19: dairy | B19: conventional | G19: recruitment_rate | H19: 37.1 | I19: % | J19: % of cows per year
A20: dairy | B20: organic | G20: recruitment_rate | H20: 36.1 | I20: % | J20: % of cows per year
A21: dairy | G21: ratio_male_calf | H21: 50.655978 | I21: % | J21: % of calves
A22: dairy | G22: twin_birth | H22: 3.2446264 | I22: % | J22: % of calvings
A23: dairy | B23: conventional | G23: stillborn_calf | H23: 5 | I23: % | J23: % of calvings
A24: dairy | B24: organic | G24: stillborn_calf | H24: 4.6 | I24: % | J24: % of calvings
A25: dairy | G25: weaning_age | H25: 100 | I25: days
A26: dairy | B26: conventional | G26: breeding_bulls_per_cow | H26: =1/300 -> 0.0033333333 | I26: nr | J26: Rough assumption, but small figure as artificial insemination is dominating
A27: dairy | B27: organic | G27: breeding_bulls_per_cow | H27: =1/300 -> 0.0033333333 | I27: nr
G30: live_weight | H30: 0 | J30: Fallback
A31: Dairy
A32: dairy | C32: cows | G32: live_weight | H32: =H59/(47/100) -> 651.52821 | I32: kg | J32: Calculated from slaughter weight and 47% slaughter yeild | K32: Strid, Roos & Tidaker (2014)
A33: dairy | C33: breeding bulls | G33: live_weight | H33: 910 | I33: kg | J33: Assumed same as for beef | K33: Ahlgren et al. (2022)
A34: dairy | C34: calves | G34: birth_weight | H34: 40 | I34: kg | J34: Mikaela???
A35: dairy | C35: calves | G35: live_weight_weaning | H35: =H34+(H61/0.5-H34)/(H55*30.4)*H25 -> 130.26609 | I35: kg | J35: Mikaela??? Calculated assuming linear growth
A36: dairy | C36: calves | G36: live_weight_slaughter | H36: =H61/(50/100) -> 339.02686 | I36: kg | J36: Calculated from slaughter weight and 50% slaughter yeild | K36: Strid, Roos & Tidaker (2014)
A37: dairy | C37: heifers | G37: live_weight_slaughter | H37: =H62/(50/100) -> 596.09654 | I37: kg | J37: Calculated from slaughter weight and 50% slaughter yeild | K37: Strid, Roos & Tidaker (2014)
A38: dairy | C38: steers | G38: live_weight_slaughter | H38: =H63/(50/100) -> 651.61429 | I38: kg | J38: Calculated from slaughter weight and 50% slaughter yeild | K38: Strid, Roos & Tidaker (2014)
A39: dairy | C39: bulls | G39: live_weight_slaughter | H39: =H64/(50/100) -> 657.75311 | I39: kg | J39: Calculated from slaughter weight and 50% slaughter yeild | K39: Strid, Roos & Tidaker (2014)
A40: Mortality
A41: Dairy
A42: dairy | C42: cows | G42: mortality | H42: 6.6 | I42: % | J42: % of cows per year | K42: Ahlgren et al. (2022)
A43: dairy | C43: calves | G43: mortality_male_0towean | H43: 4.2 | I43: % | J43: % of live born | K43: Ahlgren et al. (2022)
...

Sheet Antal djur
B2: Mjölk besättningar | Y2: Diko besättningar
D3: Number | F3: Slaughtered | H3: Slaughtered (1000 tonnes) | J3: Dead/culled | AA3: Number | AC3: Slaughtered | AE3: Slaughtered (1000 tonnes) | AG3: Dead/culled
D4: Conv | E4: Org | F4: Conv | G4: Org | H4: Conv | I4: Org | J4: Conv | K4: Org | M4: Parameter | P4: Konv | Q4: Eko | R4: Enhet | T4: Källa | AA4: Conv | AB4: Org | AC4: Conv | AD4: Org | AE4: Conv | AF4: Org | AG4: Conv | AH4: Org | AJ4: Parameter | AM4: Konv | AN4: Eko | AO4: Enhet | AQ4: Källa
B5: Cows | D5: =D80*(1-E58/100) -> 261212.59 | E5: =D80*(E58/100) -> 55025.412 | F5: =D5*P7/100-J5 -> 79669.839 | G5: =E5*Q7/100-K5 -> 16232.497 | H5: =F5*P30/1000000 -> 24.39636 | I5: =G5*Q30/1000000 -> 4.9706869 | J5: =D5*P14/100 -> 17240.031 | K5: =E5*Q14/100 -> 3631.6772 | M5: Kalvningsintervall | P5: 13.2 | Q5: 12.9 | R5: mån | T5: (Växa tab 29) | Y5: Cows | AA5: =D81*(1-E59/100) -> 133821.07 | AB5: =D81*(E59/100) -> 72692.928 | AC5: =AA5*AM7/100-AG5 -> 30913.743 | AD5: =AB5*AN7/100-AH5 -> 16792.65 | AE5: =AC5*AM30/1000000 -> 10.529212 | AF5: =AD5*AN30/1000000 -> 5.7195719 | AG5: =AA5*AM14/100 -> 2676.4214 | AH5: =AB5*AN14/100 -> 1453.8586 | AJ5: Kalvningsintervall | AM5: =(12.7+12.7+12.7+12.7)/4 -> 12.7 | AN5: 12.7 | AO5: mån | AQ5: (Växa Husdjursstatistik 2020, tab 31)
B6: Heifers | D6: =D23*((P6-12)/12)+D27*((P25-12)/12) -> #REF! | E6: =E23*((Q6-12)/12)+E27*((Q25-12)/12) -> #REF! | F6: =D27 -> #REF! | G6: =E27 -> #REF! | H6: =F6*P31/1000000 -> #REF! | I6: =G6*Q31/1000000 -> #REF! | M6: Inkalvningsålder | P6: 27 | Q6: 27 | R6: mån | T6: (Växa tab 29) | Y6: Heifers | AA6: =AA23*((AM6-12)/12)+AA27*((AM25-12)/12) -> #REF! | AB6: =AB23*((AN6-12)/12)+AB27*((AN25-12)/12) -> #REF! | AC6: =AA27 -> #REF! | AD6: =AB27 -> #REF! | AE6: =AC6*AM31/1000000 -> #REF! | AF6: =AD6*AN31/1000000 -> #REF! | AJ6: Inkalvningsålder | AM6: =(27.5+28.4+27.6+29.9+30)/5 -> 28.68 | AN6: =AM6 -> 28.68 | AO6: mån | AQ6: (Växa Husdjursstatistik 2020, tab 32)
B7: Steers | D7: =D28*((P27-12)/12) -> #REF! | E7: =E28*((Q27-12)/12) -> #REF! | F7: =D28 -> #REF! | G7: =E28 -> #REF! | H7: =F7*P33/1000000 -> #REF! | I7: =G7*Q33/1000000 -> #REF! | M7: Rekrytering | P7: 37.1 | Q7: 36.1 | R7: % | T7: (Växa tab 28) | Y7: Steers | AA7: =AA28*((AM27-12)/12) -> #REF! | AB7: =AB28*((AN27-12)/12) -> #REF! | AC7: =AA28 -> #REF! | AD7: =AB28 -> #REF! | AE7: =AC7*AM33/1000000 -> #REF! | AF7: =AD7*AN33/1000000 -> #REF! | AJ7: Rekrytering | AM7: =1/(AM24/12-AM6/12)*100 -> 25.100803 | AN7: =1/(AN24/12-AN6/12)*100 -> 25.100803 | AO7: % | AQ7: (ber.)
B8: Bulls | D8: =D29*((P28-12)/12) -> #REF! | E8: =E29*((Q28-12)/12) -> #REF! | F8: =D29 -> #REF! | G8: =E29 -> #REF! | H8: =F8*P34/1000000 -> #REF! | I8: =G8*Q34/1000000 -> #REF! | M8: Könskvot, tjurkalvar | P8: =(48.7*77196+51.7*144627)/221823 -> 50.655978 | Q8: =P8 -> 50.655978 | R8: % | T8: (Växa Husdjursstatistik 2020, tab 20) | Y8: Bulls | AA8: =AA29*((AM28-12)/12) -> #REF! | AB8: =AB29*((AN28-12)/12) -> #REF! | AC8: =AA29 -> #REF! | AD8: =AB29 -> #REF! | AE8: =AC8*AM34/1000000 -> #REF! | AF8: =AD8*AN34/1000000 -> #REF! | AJ8: Könskvot, tjurkalvar | AM8: 51.7 | AN8: =AM8 -> 51.7 | AO8: % | AQ8: (Växa KAP, tab 34)
B9: Calves | D9: =((D13-D17)*P16+(D14-D18)*P18+(D17-D19)*P20+(D18-D20)*P22+(D23+D27+D28+D29)*365.25+D24*P26*30.44)/365.25 -> #REF! | E9: =((E13-E17)*Q16+(E14-E18)*Q18+(E17-E19)*Q20+(E18-E20)*Q22+(E23+E27+E28+E29)*365.25+E24*Q26*30.44)/365.25 -> #REF! | F9: =D24 -> #REF! | G9: =E24 -> #REF! | H9: =F9*P32/1000000 -> #REF! | I9: =G9*Q32/1000000 -> #REF! | J9: =SUM(D21:D22) -> 23373.094 | K9: =SUM(E21:E22) -> 3061.7383 | M9: Tvilingfödslar | P9: =(79242*1.07+141785*4.46)/(79242+141785) -> 3.2446264 | Q9: =P9 -> 3.2446264 | R9: % | Y9: Calves | AA9: =((AA13-AA17)*AM16+(AA14-AA18)*AM18+(AA17-AA19)*AM20+(AA18-AA20)*AM22+(AA23+AA27+AA28+AA29)*365.25+AA24*AM26*30.44)/365.25 -> #REF! | AB9: =((AB13-AB17)*AN16+(AB14-AB18)*AN18+(AB17-AB19)*AN20+(AB18-AB20)*AN22+(AB23+AB27+AB28+AB29)*365.25+AB24*AN26*30.44)/365.25 -> #REF! | AC9: =AA24 -> #REF! | AD9: =AB24 -> #REF! | AE9: =AC9*AM32/1000000 -> #REF! | AF9: =AD9*AN32/1000000 -> #REF! | AG9: =SUM(AA21:AA22) -> 7304.4279 | AH9: =SUM(AB21:AB22) -> 3729.9363 | AJ9: Tvilingfödslar | AM9: 4.5730449 | AN9: =AM9 -> 4.5730449 | AO9: % | AQ9: (Växa Husdjursstatistik 2020, tab 34a)
M10: Dödfödda kalvar | P10: 5 | Q10: 4.6 | R10: % | T10: (Växa tab 28) | AJ10: Dödfödda kalvar | AM10: =(2.4*10433+1.6*1935)/(10433+1935) -> 2.2748383 | AN10: =AM10 -> 2.2748383 | AO10: % | AQ10: (Växa Husdjursstatistik 2020, tab 31)
B11: Intermediates | D11: Conv | E11: Org | G11: Andel | H11: =SUM(H5:H9)/SUM($H5:$I9,$AE5:$AF9) -> #REF! | I11: =SUM(I5:I9)/SUM($H5:$I9,$AE5:$AF9) -> #REF! | M11: Lev. kalvar per år | P11: =(12/P5*(1-P7/100)+(P7/100))*(1*(1-P9/100)+2*(P9/100))*(1-P10/100) -> 0.92473865 | Q11: =(12/Q5*(1-Q7/100)+(Q7/100))*(1*(1-Q9/100)+2*(Q9/100))*(1-Q10/100) -> 0.94104312 | R11: antal/ko/år | T11: (ber.) | Y11: Intermediates | AA11: Conv | AB11: Org | AD11: Andel | AE11: =SUM(AE5:AE9)/SUM($H5:$I9,$AE5:$AF9) -> #REF! | AF11: =SUM(AF5:AF9)/SUM($H5:$I9,$AE5:$AF9) -> #REF! | AJ11: Lev. kalvar per år | AM11: =(12/AM5*(1-AM7/100)+(AM7/100))*(1*(1-AM9/100)+2*(AM9/100))*(1-AM10/100) -> 0.97975293 | AN11: =(12/AN5*(1-AN7/100)+(AN7/100))*(1*(1-AN9/100)+2*(AN9/100))*(1-AN10/100) -> 0.97975293 | AO11: antal/ko/år | AQ11: (ber.)
B12: Calves born | D12: =D5*P11 -> 241553.38 | E12: =E5*Q11 -> 51781.286 | H12: =H11/SUM(H11:I11) -> #REF! | I12: =I11/SUM(H11:I11) -> #REF! | M12: Avvänjningsålder | P12: 100 | Q12: =P12 -> 100 | R12: dagar | T12: RISE | Y12: Calves born | AA12: =AA5*AM11 -> 131111.59 | AB12: =AB5*AN11 -> 71221.109 | AE12: =AE11/SUM(AE11:AF11) -> #REF! | AF12: =AF11/SUM(AE11:AF11) -> #REF! | AJ12: Avvänjningsålder | AM12: =7*30.4 -> 212.8 | AN12: =AM12 -> 212.8 | AO12: dagar
B13: Male calves born | D13: =D12*P8/100 -> 122361.23 | E13: =E12*Q8/100 -> 26230.317 | M13: Dödlighet | Y13: Male calves born | AA13: =AA12*AM8/100 -> 67784.691 | AB13: =AB12*AN8/100 -> 36821.313 | AJ13: Dödlighet
B14: Female calves born | D14: =D12-D13 -> 119192.15 | E14: =E12-E13 -> 25550.969 | M14: kor | P14: 6.6 | Q14: =P14 -> 6.6 | R14: % av djur | T14: RISE | Y14: Female calves born | AA14: =AA12-AA13 -> 63326.897 | AB14: =AB12-AB13 -> 34399.796 | AJ14: kor | AM14: 2 | AN14: =AM14 -> 2 | AO14: % av djur | AQ14: RISE
B15: Male calves 2 weaned before redist | D15: =D13*(1-P15/100) -> 117222.06 | E15: =E13*(1-Q15/100) -> 25128.644 | M15: tjurkalv (föds.-avv.) | P15: 4.2 | Q15: =P15 -> 4.2 | R15: % av levande födda | T15: RISE | AA15: =AA13*(1-AM15/100) -> 65073.303 | AB15: =AB13*(1-AN15/100) -> 35348.461 | AJ15: tjurkalv (föds.-avv.) | AM15: 4 | AN15: =AM15 -> 4 | AO15: % av levande födda | AQ15: RISE
B16: Female calves 2 weaned before redist | D16: =D14*(1-P17/100) -> 115139.62 | E16: =E14*(1-Q17/100) -> 24682.236 | M16: snittålder | P16: 10 | Q16: =P16 -> 10 | R16: dagar | T16: RISE | AA16: =AA14*(1-AM17/100) -> 61300.436 | AB16: =AB14*(1-AN17/100) -> 33299.002 | AJ16: snittålder | AM16: 3 | AN16: =AM16 -> 3 | AO16: dagar | AQ16: RISE
B17: Male calves 2 weaned | D17: =D15+E15*P39/100 -> 139586.55 | E17: =E15-E15*P39/100 -> 2764.1508 | M17: kvigkalv (föds.-avv.) | P17: 3.4 | Q17: =P17 -> 3.4 | R17: % av levande födda | T17: RISE | Y17: Male calves 2 weaned | AA17: =AA15+AB15*AM39/100 -> 70022.087 | AB17: =AB15-AB15*AM39/100 -> 30399.676 | AJ17: kvigkalv (föds.-avv.) | AM17: 3.2 | AN17: =AM17 -> 3.2 | AO17: % av levande födda | AQ17: RISE
B18: Female calves 2 weaned | D18: =D16+E16*P40/100 -> 117237.61 | E18: =E16-E16*P40/100 -> 22584.246 | M18: snittålder | P18: 10 | Q18: =P18 -> 10 | R18: dagar | T18: RISE | Y18: Female calves 2 weaned | AA18: =AA16+AB16*AM40/100 -> 64130.851 | AB18: =AB16-AB16*AM40/100 -> 30468.587 | AJ18: snittålder | AM18: 10 | AN18: =AM18 -> 10 | AO18: dagar | AQ18: RISE
B19: Male calves 2 end | D19: =D17*(1-P19/100) -> 130094.66 | E19: =E17*(1-Q19/100) -> 2576.1885 | M19: tjurar/stutar (avv.-slakt) | P19: 6.8 | Q19: =P19 -> 6.8 | R19: % av avvanda | T19: RISE | Y19: Male calves 2 end | AA19: =AA17*(1-AM19/100) -> 68481.602 | AB19: =AB17*(1-AN19/100) -> 29730.883 | AJ19: tjurar/stutar (avv.-slakt) | AM19: 2.2 | AN19: =AM19 -> 2.2 | AO19: % av avvanda | AQ19: RISE
B20: Female calves 2 end | D20: =D18*(1-P21/100) -> 112548.1 | E20: =E18*(1-Q21/100) -> 21680.876 | M20: snittålder | P20: 59 | Q20: =P20 -> 59 | R20: dagar | T20: RISE | Y20: Female calves 2 end | AA20: =AA18*(1-AM21/100) -> 63104.757 | AB20: =AB18*(1-AN21/100) -> 29981.09 | AJ20: snittålder | AM20: 234 | AN20: =AM20 -> 234 | AO20: dagar | AQ20: RISE
B21: Male calves 2 dead | D21: =D13-D15+D17-D19 -> 14631.057 | E21: =E13-E15+E17-E19 -> 1289.6356 | M21: kvigor (avv.-slakt) | P21: 4 | Q21: =P21 -> 4 | R21: % av avvanda | T21: RISE | Y21: Male calves 2 dead | AA21: =AA13-AA15+AA17-AA19 -> 4251.8735 | AB21: =AB13-AB15+AB17-AB19 -> 2141.6454 | AJ21: kvigor (avv.-slakt) | AM21: 1.6 | AN21: =AM21 -> 1.6 | AO21: % av avvanda | AQ21: RISE
B22: Female calves 2 dead | D22: =D14-D16+D18-D20 -> 8742.0374 | E22: =E14-E16+E18-E20 -> 1772.1028 | M22: snittålder | P22: 59 | Q22: =P22 -> 59 | R22: dagar | T22: RISE | Y22: Female calves 2 dead | AA22: =AA14-AA16+AA18-AA20 -> 3052.5543 | AB22: =AB14-AB16+AB18-AB20 -> 1588.2909 | AJ22: snittålder | AM22: 241 | AN22: =AM22 -> 241 | AO22: dagar | AQ22: RISE
B23: Calves 2 recruitment | D23: =D5*P7/100 -> 96909.87 | E23: =E5*Q7/100 -> 19864.174 | M23: Slaktålder | Y23: Calves 2 recruitment | AA23: =AA5*AM7/100 -> 33590.164 | AB23: =AB5*AN7/100 -> 18246.509 | AJ23: Slaktålder
B24: Calves 2 slaughter | D24: =(SUM(D19:D20)-D23)*P36/100 -> #REF! | E24: =(SUM(E19:E20)-E23)*Q36/100 -> #REF! | M24: kor | P24: 60.9 | Q24: 61.5 | R24: mån | T24: (Växa tab 28) | Y24: Calves 2 slaughter | AA24: =(SUM(AA19:AA20)-AA23)*AM36/100 -> #REF! | AB24: =(SUM(AB19:AB20)-AB23)*AN36/100 -> #REF! | AJ24: kor | AM24: ='G&D sammanställning'!K5 -> 76.487235 | AN24: =AM24 -> 76.487235 | AO24: mån
B25: Male calves 2 slaughter | D25: =D24*(D19)/(D19+D20-D23) -> #REF! | E25: =E24*(E19)/(E19+E20-E23) -> #REF! | M25: kvigor | P25: ='G&D sammanställning'!H8 -> #REF! | Q25: =P25 -> #REF! | R25: mån | Y25: Male calves 2 slaughter | AA25: =AA24*(AA19)/(AA19+AA20-AA23) -> #REF! | AB25: =AB24*(AB19)/(AB19+AB20-AB23) -> #REF! | AJ25: kvigor | AM25: ='G&D sammanställning'!K8 -> #REF! | AN25: =AM25 -> #REF! | AO25: mån
B26: Female calves 2 slaughter | D26: =D24-D25 -> #REF! | E26: =E24-E25 -> #REF! | M26: mellankalv | P26: ='G&D sammanställning'!H13 -> #REF! | Q26: =P26 -> #REF! | R26: mån | Y26: Female calves 2 slaughter | AA26: =AA24-AA25 -> #REF! | AB26: =AB24-AB25 -> #REF! | AJ26: mellankalv | AM26: ='G&D sammanställning'!K13 -> #REF! | AN26: =AM26 -> #REF! | AO26: mån
B27: Calves 2 heifers | D27: =D20-D23-D26 -> #REF! | E27: =E20-E23-E26 -> #REF! | M27: stutar | P27: ='G&D sammanställning'!H9 -> #REF! | Q27: =P27 -> #REF! | R27: mån | Y27: Calves 2 heifers | AA27: =AA20-AA23-AA26 -> #REF! | AB27: =AB20-AB23-AB26 -> #REF! | AJ27: stutar | AM27: ='G&D sammanställning'!K9 -> #REF! | AN27: =AM27 -> #REF! | AO27: mån
B28: Calves 2 steers | D28: =(D19-D25)*(P37/100) -> #REF! | E28: =(E19-E25)*(Q37/100) -> #REF! | M28: tjurar | P28: ='G&D sammanställning'!H10 -> 22.579883 | Q28: =P28 -> 22.579883 | R28: mån | Y28: Calves 2 steers | AA28: =(AA19-AA25)*(AM37/100) -> #REF! | AB28: =(AB19-AB25)*(AN37/100) -> #REF! | AD28: 6180.1797 | AE28: 10387.902 | AJ28: tjurar | AM28: ='G&D sammanställning'!K10 -> 20.108223 | AN28: =AM28 -> 20.108223 | AO28: mån
B29: Calves 2 bulls | D29: =D19-D25-D28 -> #REF! | E29: =E19-E25-E28 -> #REF! | M29: Slaktvikt | Y29: Calves 2 bulls | AA29: =AA19-AA25-AA28 -> #REF! | AB29: =AB19-AB25-AB28 -> #REF! | AD29: 60706.757 | AE29: 18612.205 | AJ29: Slaktvikt
M30: kor | P30: ='G&D sammanställning'!B5 -> 306.21826 | Q30: =P30 -> 306.21826 | R30: kg | AJ30: kor | AM30: ='G&D sammanställning'!E5 -> 340.59971 | AN30: =AM30 -> 340.59971 | AO30: kg
M31: kvigor | P31: ='G&D sammanställning'!B8 -> #REF! | Q31: =P31 -> #REF! | R31: kg | AJ31: kvigor | AM31: ='G&D sammanställning'!E8 -> #REF! | AN31: =AM31 -> #REF! | AO31: kg
M32: mellankalv | P32: ='G&D sammanställning'!B13 -> #REF! | Q32: =P32 -> #REF! | R32: kg | AJ32: mellankalv | AM32: ='G&D sammanställning'!E13 -> #REF! | AN32: =AM32 -> #REF! | AO32: kg
M33: stutar | P33: ='G&D sammanställning'!B9 -> #REF! | Q33: =P33 -> #REF! | R33: kg | AJ33: stutar | AM33: ='G&D sammanställning'!E9 -> #REF! | AN33: =AM33 -> #REF! | AO33: kg
M34: tjurar | P34: ='G&D sammanställning'!B10 -> 328.87656 | Q34: =P34 -> 328.87656 | R34: kg | AJ34: tjurar | AM34: ='G&D sammanställning'!E10 -> 358.43398 | AN34: =AM34 -> 358.43398 | AO34: kg
M35: Andel av slaktade ungdjur | S35: adj | AJ35: Andel av slaktade ungdjur | AP35: adj
M36: som kalv | P36: ='G&D sammanställning'!$T$13*S36 -> #REF! | Q36: ='G&D sammanställning'!$T$13*T36 -> #REF! | R36: % | S36: 0.95 | T36: 0.95 | AJ36: mellankalv | AM36: ='G&D sammanställning'!$W$13*AP36 -> #REF! | AN36: ='G&D sammanställning'!$W$13*AQ36 -> #REF! | AO36: % | AP36: 0.95 | AQ36: 0.95
M37: som stut (av handjur) | P37: ='G&D sammanställning'!$T$9/SUM('G&D sammanställning'!T9:T10)*100*S37 -> #REF! | Q37: ='G&D sammanställning'!$T$9/SUM('G&D sammanställning'!T9:T10)*100*T37 -> #REF! | R37: % | S37: 0.7 | T37: 3.1 | AJ37: stutar | AM37: ='G&D sammanställning'!$W$9/SUM('G&D sammanställning'!W9:W10)*100*AP37 -> #REF! | AN37: ='G&D sammanställning'!$W$9/SUM('G&D sammanställning'!W9:W10)*100*AQ37 -> #REF! | AO37: % | AP37: 0.8 | AQ37: 3.1
M38: Överföring djur eko -> konv | AJ38: Överföring djur eko -> konv
M39: tjurkalvar | P39: 89 | R39: % | T39: (uppskattat baserat på stat.) | AJ39: tjurkalvar | AM39: 14 | AO39: %
M40: kvigkalvar | P40: 8.5 | R40: % | T40: (uppskattat baserat på stat.) | AJ40: kvigkalvar | AM40: 8.5 | AO40: %
D42: Från modell | F42: Kontroll
...

Sheet Foderstater
B2: FEED RATIONS | D2: Ahlgren et al 2022 | Y2: Mikaela Lindberg | AA2: Einarsson et al 2022 SM2
B3: kg/head/year | D3: Tabell 10 | M3: Tabell 11 | S3: Tabell 12 | Y3: pers. com. 2023-04 | AA3: ('Feed rations') | AD3: Dairy cows | AE3: Calves, dairy, replacement | AF3: Heifers, dairy, replacement | AG3: Suckler cows | AH3: Calves, for slaughter | AI3: Calves, dairy, for fattening | AJ3: Calves, suckler, replacement or fattening | AK3: Heifers, suckler, replacement | AL3: Bulls, dairy breed | AM3: Bulls, beef breed | AN3: Steers, dairy/beef | AO3: Heifers, dairy breed, for slaughter | AP3: Heifers, beef breed, for slaughter | AQ3: Calves, dariy | AR3: Calves, beef
D4: Diko (per år) | G4: Köttrastjur | J4: Avelstjur | M4: Mjölkrastjur | P4: Mjölkrasstut | S4: Köttrasstut | V4: Köttraskviga | Y4: Mjölkko | Z4: Mjölkko
B5: Feed ration | C5: DM | D5: Gsk | E5: Gns | F5: Nn | G5: Gsk | H5: Gns | I5: Nn | J5: Gsk | K5: Gns | L5: Nn | M5: Gsk | N5: Gns | O5: Nn | P5: Gsk | Q5: Gns | R5: Nn | S5: Gsk | T5: Gns | U5: Nn | V5: Gsk | W5: Gns | X5: Nn | Y5: vall | Z5: majs | AR5: Calves, dairy
B6: Vallensilage, tidigt, kg ts | C6: 1 | G6: 1229 | I6: 1329 | M6: 2119 | O6: 2130 | Y6: 2973.75 | Z6: 1619.55 | AA6: Population (heads) | AD6: 330888.67 | AE6: 134305.6 | AF6: 161884.48 | AG6: 195238.33 | AH6: 18420.386 | AI6: 143245.78 | AJ6: 175831.9 | AK6: 55410.68 | AL6: 93814.363 | AM6: 85881.771 | AN6: 36635.904 | AO6: 22798.726 | AP6: 35985.746
B7: Vallensilage, medelsen, kg ts | C7: 1 | P7: 2663 | Q7: 2561 | R7: 2690 | S7: 2568 | T7: 2502 | U7: 2401 | V7: 2506 | W7: 2459 | X7: 2431 | Y7: 711.5 | Z7: 751.15 | AA7: age | AD7: per yr | AE7: 0-12 | AF7: 12-28 | AG7: per yr | AH7: 0-8 | AI7: 0-12 | AJ7: 0-12 | AK7: 12-26 | AL7: 12-18.9 | AM7: 12-17 | AN7: 12-26 | AO7: 12-26 | AP7: 12-23
B8: Vallensilage, sent, kg ts | C8: 1 | D8: 659 | E8: 1254 | F8: 770 | K8: 1235
B9: Vallensilage, klöverrikt, kg ts | C9: 1 | H9: 1165 | N9: 1868 | AA9: Feed ration | AC9: DM
B10: Majsensilage, kg ts | C10: 1 | H10: 272 | N10: 436 | Z10: 1250.5 | AA10: Grass/clover silage | AC10: 1 | AD10: 3312 | AE10: 1200 | AF10: 1574 | AG10: 786.48686 | AH10: 262.69098 | AI10: 806.85837 | AJ10: 826.64376 | AK10: 613.65525 | AL10: 1049.6483 | AM10: 579.64056 | AN10: 1672.5065 | AO10: 1390.5375 | AP10: 1039.6552 | AQ10: =(AE10*AE$6+AI10*AI$6+AH10*AH$6)/SUM(AE$6,AH$6,AI$6) -> 951.39023 | AR10: =AJ10 -> 826.64376
B11: Helsädesensilage, kg ts | C11: 1 | D11: 977 | F11: 970 | J11: 1536 | L11: 1614 | AA11: Whole crop silage | AC11: 1 | AF11: 426 | AG11: 707 | AK11: 426
B12: Halm, kg | C12: 0.85 | E12: 299 | K12: 139 | Y12: 244 | Z12: 244 | AA12: Maize silage | AC12: 1 | AD12: 543
B13: Permanent bete, kg ts | C13: 1 | D13: 1953 | E13: 2053 | F13: 1806 | J13: 1313 | K13: 1390 | L13: 1235 | P13: 1548 | Q13: 1662 | R13: 1548 | S13: 932 | T13: 995 | U13: 951 | V13: 926 | W13: 978 | X13: 924 | AA13: Straw | AC13: 0.85 | AG13: 236.67856
B14: Bete vallåterväxt, kg ts | C14: 1 | D14: 345 | E14: 362 | F14: 319 | J14: 232 | K14: 245 | L14: 218 | P14: 273 | Q14: 293 | R14: 273 | S14: 165 | T14: 176 | U14: 168 | V14: 163 | W14: 173 | X14: 163 | Y14: 783 | Z14: 783 | AA14: Pasture | AC14: 1 | AD14: 417.5 | AE14: 250 | AF14: 700 | AG14: 2089.9187 | AI14: 148.25672 | AJ14: 315.82638 | AK14: 1270.2489 | AM14: 0 | AN14: 2115.9077 | AO14: 1860.8263 | AP14: 1391.3037 | AQ14: =(AE14*AE$6+AI14*AI$6+AH14*AH$6)/SUM(AE$6,AH$6,AI$6) -> 185.19858 | AR14: =AJ14 -> 315.82638
B15: Spannmål, kg | C15: 0.86 | G15: 861 | H15: 654 | M15: 1084 | N15: 1014 | P15: 188 | Q15: 184 | Y15: =2180.75-(Y17*U58*C17/C15) -> 1824.2423 | Z15: =1516-(Y17*U58*C17/C15) -> 1159.4923 | AA15: Grain | AC15: 0.86 | AD15: 1280.5 | AE15: 250 | AF15: 50 | AG15: 40 | AH15: 544.72413 | AI15: 470.02657 | AJ15: 352.21215 | AL15: 761.89322 | AM15: 665.02407 | AN15: 54.611532 | AO15: 304.94243 | AP15: 0 | AQ15: =(AE15*AE$6+AI15*AI$6+AH15*AH$6)/SUM(AE$6,AH$6,AI$6) -> 374.83221 | AR15: =AJ15 -> 352.21215
B16: Åkerböna/ärt, kg | C16: 0.85 | G16: 68 | H16: 78 | M16: 124 | N16: 32 | P16: 4 | Q16: 3 | AA16: Conc | AC16: 0.9 | AD16: 1350.5 | AH16: 151.88274 | AI16: 76.165488 | AJ16: 76.642835 | AM16: 70.25886 | AN16: 0 | AO16: 0 | AP16: 0 | AQ16: =(AE16*AE$6+AI16*AI$6+AH16*AH$6)/SUM(AE$6,AH$6,AI$6) -> 46.315645 | AR16: =AJ16 -> 76.642835
B17: Färdigfoder, kg | C17: 0.9 | I17: 991 | M17: 80 | N17: 79 | O17: 1279 | P17: 119 | Q17: 119 | R17: 294 | Y17: =1244*(1+U58) -> 1522.3714 | Z17: =1966*(1+U58) -> 2405.9342 | AA17: Conc. for calves | AC17: 0.9 | AE17: 14 | AH17: 13.507589 | AI17: 13.575225 | AQ17: =(AE17*AE$6+AI17*AI$6+AH17*AH$6)/SUM(AE$6,AH$6,AI$6) -> 13.763769
B18: Mineraler, kg | C18: 1 | D18: 34 | E18: 34 | F18: 34 | G18: 12 | H18: 12 | I18: 14 | J18: 33 | K18: 33 | L18: 33 | M18: 22 | N18: 22 | O18: 21 | P18: 35 | Q18: 35 | R18: 35 | S18: 26 | T18: 26 | U18: 24 | V18: 26 | W18: 26 | X18: 26 | Y18: =SUM(Y7:Y17)*0.01 -> 50.851137 | Z18: =SUM(Z7:Z17)*0.01 -> 65.940765 | AA18: Minerals | AC18: 1 | AQ18: =SUM(AQ10:AQ17)*0.006 -> 9.4290026 | AR18: =SUM(AR10:AR17)*0.006 -> 9.4279507
AA19: Milk powder | AC19: 0.95 | AE19: 40 | AH19: 39.852222 | AI19: 39.877866 | AQ19: =(AE19*AE$6+AI19*AI$6+AH19*AH$6)/SUM(AE$6,AH$6,AI$6) -> 39.931692
B20: Total | D20: =SUM(D6:D18) -> 3968 | E20: =SUM(E6:E18) -> 4002 | F20: =SUM(F6:F18) -> 3899 | G20: =SUM(G6:G18) -> 2170 | H20: =SUM(H6:H18) -> 2181 | I20: =SUM(I6:I18) -> 2334 | J20: =SUM(J6:J18) -> 3114 | K20: =SUM(K6:K18) -> 3042 | ... Z20: =SUM(Z6:Z18) -> 8279.5673 | AA20: Whole milk | AC20: 0.13 | AJ20: 1874.9852 | AR20: =AJ20 -> 1874.9852
AA21: Total (excl. milk) | AD21: =SUM(AD10:AD17) -> 6903.5 | AE21: =SUM(AE10:AE17) -> 1714 | AF21: =SUM(AF10:AF17) -> 2750 | AG21: =SUM(AG10:AG17) -> 3860.0841 | AH21: =SUM(AH10:AH17) -> 972.80544 | AI21: =SUM(AI10:AI17) -> 1514.8824 | AJ21: =SUM(AJ10:AJ17) -> 1571.3251 | AK21: =SUM(AK10:AK17) -> 2309.9042 | ... AR21: =SUM(AR10:AR17) -> 1571.3251
B22: # Mjölkkor (2018) | D22: 103131 | E22: 40386 | F22: 21929 | L22: SCB Feed industry statistics 2022
B23: # Dikor (2018) | D23: 87632 | E23: 21961 | F23: 15238 | Q23: SWE | R23: IMP | S23: TOT | T23: Dairy | V23: Beef | X23: share | Z23: Einarsson et al 2022 SM2
P24: DM | T24: DM | U24: % of DM | V24: DM | W24: % of DM | X24: to dairy | Z24: ('Feed distribution') | AC24: Dairy | AD24: share | AE24: Beef | AF24: share | AG24: Total | AH24: to dairy
B25: Einarsson et al 2022 | D25: Feeds via feed industry | L25: wheat | P25: 0.86 | Q25: 84300.8 | R25: 2279 | S25: =SUM(Q25:R25) -> 86579.8 | T25: =S25*X25*P25 -> 46200.229 | U25: =T25/SUM(T$25:T$55) -> 0.077600984 | V25: =S25*(1-X25)*P25 -> 28258.399 | W25: =V25/SUM(V$25:V$55) -> 0.25895168 | X25: =$AH$26 -> 0.62048187 | Z25: Cereals (on-farm) | AC25: =SUM(AC26:AC29) -> 332330 | AD25: =AC25/(AC$25+AC$31) -> 0.86121145 | AE25: =SUM(AE26:AE29) -> 203269.85 | AF25: =AE25/(AE$25+AE$31) -> 0.98055414 | AG25: =SUM(AG26:AG29) -> 535599.85
B26: SM2 | E26: DM | G26: DM | I26: share | J26: Share | L26: barley | P26: 0.86 | Q26: 92367.8 | R26: 1785 | S26: =SUM(Q26:R26) -> 94152.8 | T26: =S26*X26*P26 -> 50241.291 | U26: =T26/SUM(T$25:T$55) -> 0.084388621 | V26: =S26*(1-X26)*P26 -> 30730.117 | W26: =V26/SUM(V$25:V$55) -> 0.28160178 | X26: =$AH$26 -> 0.62048187 | Z26: Wheat | AC26: =AG26*AH26 -> 77812.622 | AD26: =AC26/SUM(AC$26:AC$29) -> 0.23414264 | AE26: =AG26-AC26 -> 47594.139 | AF26: =AE26/SUM(AE$26:AE$29) -> 0.23414264 | AG26: 125406.76 | AH26: 0.62048187
B27: Feed name | C27: DM | D27: Dairy | E27: share | F27: Beef | G27: share | H27: Total | I27: to dairy | J27: import | L27: oats | P27: 0.86 | Q27: 31831.5 | R27: 0 | S27: =SUM(Q27:R27) -> 31831.5 | T27: =S27*X27*P27 -> 16985.747 | U27: =T27/SUM(T$25:T$55) -> 0.028530393 | V27: =S27*(1-X27)*P27 -> 10389.343 | W27: =V27/SUM(V$25:V$55) -> 0.09520489 | X27: =$AH$26 -> 0.62048187 | Z27: Triticale | AC27: =AG27*AH27 -> 61792.55 | AD27: =AC27/SUM(AC$26:AC$29) -> 0.18593732 | AE27: =AG27-AC27 -> 37795.452 | AF27: =AE27/SUM(AE$26:AE$29) -> 0.18593732 | AG27: 99588.001 | AH27: 0.62048187
B28: Grain maize | C28: 0.86 | D28: =H28*I28 -> 8000.2143 | E28: =D28*$C28/SUMPRODUCT(D$28:D$48,$C$28:$C$48) -> 0.010523812 | F28: =H28-D28 -> 631.31904 | G28: =F28*$C28/SUMPRODUCT(F$28:F$48,$C$28:$C$48) -> 0.0046480203 | H28: 8631.5333 | I28: 0.92685899 | J28: 0.27270318 | L28: triticale | P28: 0.86 | Q28: 11430.7 | R28: 0 | S28: =SUM(Q28:R28) -> 11430.7 | T28: =S28*X28*P28 -> 6099.5863 | U28: =T28/SUM(T$25:T$55) -> 0.010245272 | V28: =S28*(1-X28)*P28 -> 3730.8157 | W28: =V28/SUM(V$25:V$55) -> 0.034188101 | X28: =$AH$26 -> 0.62048187 | Z28: Barley | AC28: =AG28*AH28 -> 159717.73 | AD28: =AC28/SUM(AC$26:AC$29) -> 0.48059978 | AE28: =AG28-AC28 -> 97691.447 | AF28: =AE28/SUM(AE$26:AE$29) -> 0.48059978 | AG28: 257409.17 | AH28: 0.62048187
B29: Wheat | C29: 0.86 | D29: =H29*I29 -> 38739.786 | E29: =D29*C29/SUMPRODUCT(D$28:D$48,$C$28:$C$48) -> 0.050959914 | F29: =H29-D29 -> 23695.214 | G29: =F29*$C29/SUMPRODUCT(F$28:F$48,$C$28:$C$48) -> 0.17445353 | H29: 62435 | I29: 0.62048187 | J29: 0 | L29: rye | P29: 0.86 | Q29: 707 | R29: 0 | S29: =SUM(Q29:R29) -> 707 | T29: =S29*X29*P29 -> 377.26539 | U29: =T29/SUM(T$25:T$55) -> 0.00063368009 | V29: =S29*(1-X29)*P29 -> 230.75461 | W29: =V29/SUM(V$25:V$55) -> 0.0021145676 | X29: =$AH$26 -> 0.62048187 | Z29: Oats | AC29: =AG29*AH29 -> 33007.101 | AD29: =AC29/SUM(AC$26:AC$29) -> 0.099320257 | AE29: =AG29-AC29 -> 20188.814 | AF29: =AE29/SUM(AE$26:AE$29) -> 0.099320257 | AG29: 53195.915 | AH29: 0.62048187
B30: Triticale | C30: 0.86 | D30: =H30*I30 -> 21059.031 | E30: =D30*C30/SUMPRODUCT(D$28:D$48,$C$28:$C$48) -> 0.027701919 | F30: =H30-D30 -> 12880.769 | G30: =F30*$C30/SUMPRODUCT(F$28:F$48,$C$28:$C$48) -> 0.094833315 | H30: 33939.8 | I30: 0.62048187 | J30: 0 | L30: maize | P30: 0.86 | Q30: 16116.5 | R30: 537 | S30: =SUM(Q30:R30) -> 16653.5 | T30: =S30*X30*P30 -> 13319.469 | U30: =T30/SUM(T$25:T$55) -> 0.022372268 | V30: =S30*(1-X30)*P30 -> 1002.5407 | W30: =V30/SUM(V$25:V$55) -> 0.0091869889 | X30: =$AH$32 -> 0.93
B31: Barley | C31: 0.86 | D31: =H31*I31 -> 68413.876 | E31: =D31*C31/SUMPRODUCT(D$28:D$48,$C$28:$C$48) -> 0.089994438 | F31: =H31-D31 -> 41845.39 | G31: =F31*$C31/SUMPRODUCT(F$28:F$48,$C$28:$C$48) -> 0.3080823 | H31: 110259.27 | I31: 0.62048187 | J31: 0 | L31: peas | P31: 0.85 | Q31: 2047.3 | R31: 586 | S31: =SUM(Q31:R31) -> 2633.3 | T31: =S31*X31*P31 -> 2081.6236 | U31: =T31/SUM(T$25:T$55) -> 0.0034964338 | V31: =S31*(1-X31)*P31 -> 156.68135 | W31: =V31/SUM(V$25:V$55) -> 0.0014357819 | X31: =$AH$32 -> 0.93 | Z31: Grain legumes (on-farm) | AC31: =SUM(AC32:AC33) -> 53556.646 | AD31: =AC31/(AC$25+AC$31) -> 0.13878855 | AE31: =SUM(AE32:AE33) -> 4031.1454 | AF31: =AE31/(AE$25+AE$31) -> 0.019445856 | AG31: =SUM(AG32:AG33) -> 57587.792
B32: Oats | C32: 0.86 | D32: =H32*I32 -> 14138.341 | E32: =D32*C32/SUMPRODUCT(D$28:D$48,$C$28:$C$48) -> 0.018598158 | F32: =H32-D32 -> 8647.7253 | G32: =F32*$C32/SUMPRODUCT(F$28:F$48,$C$28:$C$48) -> 0.063667972 | H32: 22786.067 | I32: 0.62048187 | J32: 0 | L32: broad beans | P32: 0.85 | Q32: 9008.8 | R32: 40 | S32: =SUM(Q32:R32) -> 9048.8 | T32: =S32*X32*P32 -> 7153.0764 | U32: =T32/SUM(T$25:T$55) -> 0.012014784 | V32: =S32*(1-X32)*P32 -> 538.4036 | W32: =V32/SUM(V$25:V$55) -> 0.0049337726 | X32: =$AH$32 -> 0.93 | Z32: Peas | AC32: =AG32*AH32 -> 27475.937 | AD32: =AC32/SUM(AC$32:AC$33) -> 0.51302572 | AE32: =AG32-AC32 -> 2068.0813 | AF32: =AE32/SUM(AE$32:AE$33) -> 0.51302572 | AG32: 29544.018 | AH32: 0.93
B33: Peas | C33: 0.85 | D33: =H33*I33 -> 4095.4809 | E33: =D33*C33/SUMPRODUCT(D$28:D$48,$C$28:$C$48) -> 0.005324721 | F33: =H33-D33 -> 323.18573 | G33: =F33*$C33/SUMPRODUCT(F$28:F$48,$C$28:$C$48) -> 0.0023517534 | H33: 4418.6667 | I33: 0.92685899 | J33: 0 | L33: rapeseed | P33: 0.91 | Q33: 40016.7 | R33: 93785 | S33: =SUM(Q33:R33) -> 133801.7 | T33: =S33*X33*P33 -> 113236.38 | U33: =T33/SUM(T$25:T$55) -> 0.19019937 | V33: =S33*(1-X33)*P33 -> 8523.1683 | W33: =V33/SUM(V$25:V$55) -> 0.078103814 | X33: =$AH$32 -> 0.93 | Z33: Faba beans | AC33: =AG33*AH33 -> 26080.709 | AD33: =AC33/SUM(AC$32:AC$33) -> 0.48697428 | AE33: =AG33-AC33 -> 1963.0641 | AF33: =AE33/SUM(AE$32:AE$33) -> 0.48697428 | AG33: 28043.773 | AH33: 0.93
B34: Faba beans | C34: 0.85 | D34: =H34*I34 -> 11613.018 | E34: =D34*C34/SUMPRODUCT(D$28:D$48,$C$28:$C$48) -> 0.015098613 | F34: =H34-D34 -> 916.41538 | G34: =F34*$C34/SUMPRODUCT(F$28:F$48,$C$28:$C$48) -> 0.0066685586 | H34: 12529.433 | I34: 0.92685899 | J34: 0 | L34: linseed | P34: 0.91 | Q34: 98.7 | R34: 0 | S34: =SUM(Q34:R34) -> 98.7 | T34: =S34*X34*P34 -> 83.52981 | U34: =T34/SUM(T$25:T$55) -> 0.00014030224 | V34: =S34*(1-X34)*P34 -> 6.28719 | W34: =V34/SUM(V$25:V$55) -> 5.7613965e-05 | X34: =$AH$32 -> 0.93
B35: Rapeseed, whole | C35: 0.93 | D35: =H35*I35 -> 125972.19 | E35: =D35*C35/SUMPRODUCT(D$28:D$48,$C$28:$C$48) -> 0.17919696 | F35: =H35-D35 -> 9940.8137 | G35: =F35*$C35/SUMPRODUCT(F$28:F$48,$C$28:$C$48) -> 0.079145379 | H35: 135913 | I35: 0.92685899 | J35: 0.19883912 | L35: vegetable oils | P35: 1 | Q35: 2126.8 | R35: 192 | S35: =SUM(Q35:R35) -> 2318.8 | T35: =S35*X35*P35 -> 2156.484 | U35: =T35/SUM(T$25:T$55) -> 0.0036221742 | V35: =S35*(1-X35)*P35 -> 162.316 | W35: =V35/SUM(V$25:V$55) -> 0.0014874162 | X35: =$AH$32 -> 0.93
B36: Distiller’s dried grain | C36: 0.9 | D36: =H36*I36 -> 36603.206 | E36: =D36*C36/SUMPRODUCT(D$28:D$48,$C$28:$C$48) -> 0.050388875 | F36: =H36-D36 -> 2888.4603 | G36: =F36*$C36/SUMPRODUCT(F$28:F$48,$C$28:$C$48) -> 0.022255102 | H36: 39491.667 | I36: 0.92685899 | J36: 0 | L36: soybeans | P36: 0.87 | Q36: 0 | R36: 2604.6 | S36: =SUM(Q36:R36) -> 2604.6 | T36: =S36*X36*P36 -> 2107.3819 | U36: =T36/SUM(T$25:T$55) -> 0.003539699 | V36: =S36*(1-X36)*P36 -> 158.62014 | W36: =V36/SUM(V$25:V$55) -> 0.0014535484 | X36: =$AH$32 -> 0.93
B37: Bran, middlings, etc. | C37: 0.87 | D37: =H37*I37 -> 90204.111 | E37: =D37*C37/SUMPRODUCT(D$28:D$48,$C$28:$C$48) -> 0.12003796 | F37: =H37-D37 -> 7118.2559 | G37: =F37*$C37/SUMPRODUCT(F$28:F$48,$C$28:$C$48) -> 0.053016802 | H37: 97322.367 | I37: 0.92685899 | J37: 0 | L37: soybean meal | P37: 0.875 | Q37: 6226.3 | R37: 17429.8 | S37: =SUM(Q37:R37) -> 23656.1 | T37: =S37*X37*P37 -> 19250.151 | U37: =T37/SUM(T$25:T$55) -> 0.032333837 | V37: =S37*(1-X37)*P37 -> 1448.9361 | W37: =V37/SUM(V$25:V$55) -> 0.013277626 | X37: =$AH$32 -> 0.93
B38: Palm kernel expeller | C38: 0.91 | D38: =H38*I38 -> 29382.975 | E38: =D38*C38/SUMPRODUCT(D$28:D$48,$C$28:$C$48) -> 0.040898763 | F38: =H38-D38 -> 2318.6918 | G38: =F38*$C38/SUMPRODUCT(F$28:F$48,$C$28:$C$48) -> 0.018063633 | H38: 31701.667 | I38: 0.92685899 | J38: 1 | L38: soybean protein concentrate | P38: 0.87 | Q38: 0 | R38: 0 | S38: =SUM(Q38:R38) -> 0 | T38: =S38*X38*P38 -> 0 | U38: =T38/SUM(T$25:T$55) -> 0 | V38: =S38*(1-X38)*P38 -> 0 | W38: =V38/SUM(V$25:V$55) -> 0 | X38: =$AH$32 -> 0.93
B39: Soybeans, whole | C39: 0.87 | D39: =H39*I39 -> 15543.487 | E39: =D39*C39/SUMPRODUCT(D$28:D$48,$C$28:$C$48) -> 0.020684295 | F39: =H39-D39 -> 1226.5796 | G39: =F39*$C39/SUMPRODUCT(F$28:F$48,$C$28:$C$48) -> 0.0091355702 | H39: 16770.067 | I39: 0.92685899 | J39: 1 | L39: rapeseed meal | P39: 0.895 | Q39: 143785.1 | R39: 34843 | S39: =SUM(Q39:R39) -> 178628.1 | T39: =S39*X39*P39 -> 148681.1 | U39: =T39/SUM(T$25:T$55) -> 0.24973468 | V39: =S39*(1-X39)*P39 -> 11191.05 | W39: =V39/SUM(V$25:V$55) -> 0.1025515 | X39: =$AH$32 -> 0.93
B40: Soybean meal via feed industry | C40: 0.87 | D40: =H40*I40 -> 39489.569 | E40: =D40*C40/SUMPRODUCT(D$28:D$48,$C$28:$C$48) -> 0.052550235 | F40: =H40-D40 -> 3116.2311 | G40: =F40*$C40/SUMPRODUCT(F$28:F$48,$C$28:$C$48) -> 0.023209703 | H40: 42605.8 | I40: 0.92685899 | J40: 1 | L40: sunflower seed meal | P40: 0.91 | Q40: 1937.9 | R40: 489 | S40: =SUM(Q40:R40) -> 2426.9 | T40: =S40*X40*P40 -> 2053.8855 | U40: =T40/SUM(T$25:T$55) -> 0.0034498429 | V40: =S40*(1-X40)*P40 -> 154.59353 | W40: =V40/SUM(V$25:V$55) -> 0.0014166498 | X40: =$AH$32 -> 0.93
B41: Rapeseed meal | C41: 0.9 | D41: =H41*I41 -> 103581.4 | E41: =D41*C41/SUMPRODUCT(D$28:D$48,$C$28:$C$48) -> 0.14259271 | F41: =H41-D41 -> 8173.8952 | G41: =F41*$C41/SUMPRODUCT(F$28:F$48,$C$28:$C$48) -> 0.062978491 | H41: 111755.3 | I41: 0.92685899 | J41: 0.60570717 | L41: palm kernel expeller | P41: 0.91 | Q41: 1397.8 | R41: 14372 | S41: =SUM(Q41:R41) -> 15769.8 | T41: =S41*X41*P41 -> 13345.982 | U41: =T41/SUM(T$25:T$55) -> 0.0224168 | V41: =S41*(1-X41)*P41 -> 1004.5363 | W41: =V41/SUM(V$25:V$55) -> 0.0092052756 | X41: =$AH$32 -> 0.93
...

Sheet G&D slakt
A1: Djur | B1: Ras | C1: År | D1: Antal djur | E1: Slaktvikt (kg) | F1: Fettgrupp | G1: Formklass | H1: Ålder (månader) | I1: Slaktvikt*Antal | J1: Ålder*Antal | L1: År | M1: - multiple -
A2: ko | B2: 01 SRB | C2: 2016 | D2: 30638 | E2: 302.7 | F2: 7.7 | G2: 4 | H2: 68.6 | I2: =D2*E2 -> 9274122.6 | J2: =D2*H2 -> 2101766.8
A3: ko | B3: 01 SRB | C3: 2017 | D3: 26251 | E3: 308.5 | F3: 7.8 | G3: 4.1 | H3: 68.9 | I3: =D3*E3 -> 8098433.5 | J3: =D3*H3 -> 1808693.9 | L3: Row Labels | M3: Sum of Antal djur | N3: Sum of Slaktvikt*Antal | O3: Sum of Ålder*Antal
A4: ko | B4: 01 SRB | C4: 2018 | D4: 26489 | E4: 306.2 | F4: 7.5 | G4: 4 | H4: 69.3 | I4: =D4*E4 -> 8110931.8 | J4: =D4*H4 -> 1835687.7 | L4: Mjölkras
A5: ko | B5: 01 SRB | C5: 2019 | D5: 25859 | E5: 310.4 | F5: 7.6 | G5: 4.1 | H5: 70.1 | I5: =D5*E5 -> 8026633.6 | J5: =D5*H5 -> 1812715.9 | L5: ko, tot | M5: 458500 | N5: 1.4040107e+08 | O5: 28527102
A6: ko | B6: 01 SRB | C6: 2020 | D6: 23718 | E6: 311.7 | F6: 7.4 | G6: 4 | H6: 71.6 | I6: =D6*E6 -> 7392900.6 | J6: =D6*H6 -> 1698208.8 | L6: ko | M6: 334565 | N6: 1.0495434e+08 | O6: 23342514
A7: ko | B7: 01 SRB | C7: 2021 | D7: 21589 | E7: 313.4 | F7: 7.3 | G7: 4 | H7: 72.9 | I7: =D7*E7 -> 6765992.6 | J7: =D7*H7 -> 1573838.1 | L7: ungko | M7: 123935 | N7: 35446730 | O7: 5184588.5
A8: ko | B8: 02 SLB | C8: 2016 | D8: 41922 | E8: 310.8 | F8: 7 | G8: 3.4 | H8: 69.2 | I8: =D8*E8 -> 13029358 | J8: =D8*H8 -> 2901002.4 | L8: kviga | M8: 74870 | N8: 22314874 | O8: 2415442.8
A9: ko | B9: 02 SLB | C9: 2017 | D9: 38032 | E9: 316.9 | F9: 7.2 | G9: 3.5 | H9: 68.9 | I9: =D9*E9 -> 12052341 | J9: =D9*H9 -> 2620404.8 | L9: kviga | M9: 74870 | N9: 22314874 | O9: 2415442.8
A10: ko | B10: 02 SLB | C10: 2018 | D10: 40654 | E10: 317 | F10: 7 | G10: 3.4 | H10: 69.4 | I10: =D10*E10 -> 12887318 | J10: =D10*H10 -> 2821387.6 | L10: stut | M10: 108867 | N10: 35469646 | O10: 3232646.8
A11: ko | B11: 02 SLB | C11: 2019 | D11: 40784 | E11: 321.4 | F11: 7.1 | G11: 3.5 | H11: 70.2 | I11: =D11*E11 -> 13107978 | J11: =D11*H11 -> 2863036.8 | L11: stut | M11: 108867 | N11: 35469646 | O11: 3232646.8
A12: ko | B12: 02 SLB | C12: 2020 | D12: 40218 | E12: 322.6 | F12: 7 | G12: 3.4 | H12: 71.6 | I12: =D12*E12 -> 12974327 | J12: =D12*H12 -> 2879608.8 | L12: tjur, tot | M12: 406109 | N12: 1.3355973e+08 | O12: 9169893.8
A13: ko | B13: 02 SLB | C13: 2021 | D13: 38776 | E13: 324.9 | F13: 6.9 | G13: 3.4 | H13: 73.2 | I13: =D13*E13 -> 12598322 | J13: =D13*H13 -> 2838403.2 | L13: ungtjur | M13: 351490 | N13: 1.1433162e+08 | O13: 7579081.5
A14: ko | B14: 08 Hereford | C14: 2016 | D14: 2843 | E14: 368.4 | F14: 11.3 | G14: 6.2 | H14: 92.6 | I14: =D14*E14 -> 1047361.2 | J14: =D14*H14 -> 263261.8 | L14: yngre tjur | M14: 54619 | N14: 19228107 | O14: 1590812.3
A15: ko | B15: 08 Hereford | C15: 2017 | D15: 3147 | E15: 365 | F15: 11.1 | G15: 6.1 | H15: 94 | I15: =D15*E15 -> 1148655 | J15: =D15*H15 -> 295818 | L15: mellankalv | M15: 52087 | N15: 8829445.9 | O15: 567598.6
A16: ko | B16: 08 Hereford | C16: 2018 | D16: 4193 | E16: 352.3 | F16: 10.2 | G16: 5.9 | H16: 91.3 | I16: =D16*E16 -> 1477193.9 | J16: =D16*H16 -> 382820.9 | L16: mellankalv | M16: 52087 | N16: 8829445.9 | O16: 567598.6
A17: ko | B17: 08 Hereford | C17: 2019 | D17: 4427 | E17: 348.6 | F17: 9.9 | G17: 5.8 | H17: 91.1 | I17: =D17*E17 -> 1543252.2 | J17: =D17*H17 -> 403299.7 | L17: Köttras
A18: ko | B18: 08 Hereford | C18: 2020 | D18: 4642 | E18: 355.5 | F18: 10.1 | G18: 5.9 | H18: 89.2 | I18: =D18*E18 -> 1650231 | J18: =D18*H18 -> 414066.4 | L18: ko, tot | M18: 73015 | N18: 25944410 | O18: 5910236.4
A19: ko | B19: 08 Hereford | C19: 2021 | D19: 4235 | E19: 364.2 | F19: 10.1 | G19: 6.2 | H19: 89.6 | I19: =D19*E19 -> 1542387 | J19: =D19*H19 -> 379456 | L19: ko | M19: 57301 | N19: 20949588 | O19: 5314264.8
A20: ko | B20: 09 Charolais | C20: 2016 | D20: 2485 | E20: 408.3 | F20: 9.3 | G20: 7.4 | H20: 98.5 | I20: =D20*E20 -> 1014625.5 | J20: =D20*H20 -> 244772.5 | L20: ungko | M20: 15714 | N20: 4994822.6 | O20: 595971.6
A21: ko | B21: 09 Charolais | C21: 2017 | D21: 2981 | E21: 405.9 | F21: 9.1 | G21: 7.4 | H21: 99.1 | I21: =D21*E21 -> 1209987.9 | J21: =D21*H21 -> 295417.1 | L21: kviga | M21: 69883 | N21: 21504076 | O21: 1879535.8
A22: ko | B22: 09 Charolais | C22: 2018 | D22: 3573 | E22: 393 | F22: 8.3 | G22: 7.1 | H22: 94.2 | I22: =D22*E22 -> 1404189 | J22: =D22*H22 -> 336576.6 | L22: kviga | M22: 69883 | N22: 21504076 | O22: 1879535.8
A23: ko | B23: 09 Charolais | C23: 2019 | D23: 3426 | E23: 387.3 | F23: 8.1 | G23: 6.9 | H23: 94.6 | I23: =D23*E23 -> 1326889.8 | J23: =D23*H23 -> 324099.6 | L23: stut | M23: 15451 | N23: 5150008.2 | O23: 437018.7
A24: ko | B24: 09 Charolais | C24: 2020 | D24: 3258 | E24: 396.6 | F24: 8.2 | G24: 7.1 | H24: 96.2 | I24: =D24*E24 -> 1292122.8 | J24: =D24*H24 -> 313419.6 | L24: stut | M24: 15451 | N24: 5150008.2 | O24: 437018.7
A25: ko | B25: 09 Charolais | C25: 2021 | D25: 2898 | E25: 409.9 | F25: 8.3 | G25: 7.5 | H25: 96.2 | I25: =D25*E25 -> 1187890.2 | J25: =D25*H25 -> 278787.6 | L25: tjur, tot | M25: 146789 | N25: 52855908 | O25: 2981903.4
A26: ko | B26: 11 Aberdeen Angus | C26: 2016 | D26: 820 | E26: 363.4 | F26: 11.1 | G26: 6.4 | H26: 88.1 | I26: =D26*E26 -> 297988 | J26: =D26*H26 -> 72242 | L26: ungtjur | M26: 130247 | N26: 46602706 | O26: 2474850.4
A27: ko | B27: 11 Aberdeen Angus | C27: 2017 | D27: 800 | E27: 359.4 | F27: 10.8 | G27: 6.3 | H27: 89 | I27: =D27*E27 -> 287520 | J27: =D27*H27 -> 71200 | L27: yngre tjur | M27: 16542 | N27: 6253201.7 | O27: 507053
A28: ko | B28: 11 Aberdeen Angus | C28: 2018 | D28: 1144 | E28: 353.4 | F28: 10.2 | G28: 6.3 | H28: 85 | I28: =D28*E28 -> 404289.6 | J28: =D28*H28 -> 97240 | L28: mellankalv | M28: 5086 | N28: 788569.7 | O28: 54710.6
A29: ko | B29: 11 Aberdeen Angus | C29: 2019 | D29: 1352 | E29: 348.2 | F29: 10.1 | G29: 6.1 | H29: 87.3 | I29: =D29*E29 -> 470766.4 | J29: =D29*H29 -> 118029.6 | L29: mellankalv | M29: 5086 | N29: 788569.7 | O29: 54710.6
A30: ko | B30: 11 Aberdeen Angus | C30: 2020 | D30: 1390 | E30: 351.6 | F30: 9.9 | G30: 6.1 | H30: 84.5 | I30: =D30*E30 -> 488724 | J30: =D30*H30 -> 117455 | L30: Korsning/övriga raser
A31: ko | B31: 11 Aberdeen Angus | C31: 2021 | D31: 1184 | E31: 357.6 | F31: 9.9 | G31: 6.3 | H31: 82.1 | I31: =D31*E31 -> 423398.4 | J31: =D31*H31 -> 97206.4 | L31: ko, tot | M31: 129627 | N31: 43075396 | O31: 9589289.8
A32: ko | B32: 12 Limousin | C32: 2016 | D32: 376 | E32: 387.2 | F32: 9.3 | G32: 8.3 | H32: 96.2 | I32: =D32*E32 -> 145587.2 | J32: =D32*H32 -> 36171.2 | L32: ko | M32: 95834 | N32: 32796065 | O32: 8301026.9
A33: ko | B33: 12 Limousin | C33: 2017 | D33: 438 | E33: 381.2 | F33: 9 | G33: 8.3 | H33: 93 | I33: =D33*E33 -> 166965.6 | J33: =D33*H33 -> 40734 | L33: ungko | M33: 33793 | N33: 10279331 | O33: 1288262.9
A34: ko | B34: 12 Limousin | C34: 2018 | D34: 621 | E34: 372.9 | F34: 8.3 | G34: 8.1 | H34: 89.5 | I34: =D34*E34 -> 231570.9 | J34: =D34*H34 -> 55579.5 | L34: kviga | M34: 135714 | N34: 42059544 | O34: 3666350.4
A35: ko | B35: 12 Limousin | C35: 2019 | D35: 507 | E35: 365.3 | F35: 7.9 | G35: 7.7 | H35: 92.1 | I35: =D35*E35 -> 185207.1 | J35: =D35*H35 -> 46694.7 | L35: kviga | M35: 135714 | N35: 42059544 | O35: 3666350.4
A36: ko | B36: 12 Limousin | C36: 2020 | D36: 692 | E36: 372 | F36: 7.7 | G36: 7.8 | H36: 100.2 | I36: =D36*E36 -> 257424 | J36: =D36*H36 -> 69338.4 | L36: stut | M36: 39806 | N36: 13394002 | O36: 1134912.8
A37: ko | B37: 12 Limousin | C37: 2021 | D37: 549 | E37: 381.3 | F37: 8.3 | G37: 8 | H37: 89 | I37: =D37*E37 -> 209333.7 | J37: =D37*H37 -> 48861 | L37: stut | M37: 39806 | N37: 13394002 | O37: 1134912.8
A38: ko | B38: 14 Simmental | C38: 2016 | D38: 1709 | E38: 374.6 | F38: 8.8 | G38: 6.6 | H38: 91.2 | I38: =D38*E38 -> 640191.4 | J38: =D38*H38 -> 155860.8 | L38: tjur, tot | M38: 274571 | N38: 98173836 | O38: 5490897.6
A39: ko | B39: 14 Simmental | C39: 2017 | D39: 1951 | E39: 379.3 | F39: 8.7 | G39: 6.7 | H39: 92.5 | I39: =D39*E39 -> 740014.3 | J39: =D39*H39 -> 180467.5 | L39: ungtjur | M39: 245666 | N39: 87640451 | O39: 4640779.1
A40: ko | B40: 14 Simmental | C40: 2018 | D40: 2598 | E40: 358.3 | F40: 7.6 | G40: 6.2 | H40: 89.8 | I40: =D40*E40 -> 930863.4 | J40: =D40*H40 -> 233300.4 | L40: yngre tjur | M40: 28905 | N40: 10533385 | O40: 850118.5
...

Sheet G&D sammanställning
A2: Medel 2016-2020
B3: Slaktvikt (kg) | H3: Ålder (mån) | N3: Antal | T3: Andel av slaktade ungdjur (%)
B4: Mjölkras | C4: Köttras | D4: Korsning/övriga raser | E4: Kött+korsn./övr. | F4: Totalt | H4: Mjölkras | I4: Köttras | J4: Korsning/övriga raser | K4: Kött+korsn./övr. | L4: Totalt | N4: Mjölkras | O4: Köttras | P4: Korsning/övriga raser | Q4: Kött+korsn./övr. | R4: Totalt | T4: Mjölkras | U4: Köttras | V4: Korsning/övriga raser | W4: Kött+korsn./övr. | X4: Totalt
A5: Ko, tot | B5: =GETPIVOTDATA("Sum of Slaktvikt*Antal",'G&D slakt'!$L$3,"Djur2",$A5,"Ras2",B$4)/GETPIVOTDATA("Sum of Antal djur",'G&D slakt'!$L$3,"Djur2",$A5,"Ras2",B$4) -> 306.21826 | C5: =GETPIVOTDATA("Sum of Slaktvikt*Antal",'G&D slakt'!$L$3,"Djur2",$A5,"Ras2",C$4)/GETPIVOTDATA("Sum of Antal djur",'G&D slakt'!$L$3,"Djur2",$A5,"Ras2",C$4) -> 355.32987 | D5: =GETPIVOTDATA("Sum of Slaktvikt*Antal",'G&D slakt'!$L$3,"Djur2",$A5,"Ras2",D$4)/GETPIVOTDATA("Sum of Antal djur",'G&D slakt'!$L$3,"Djur2",$A5,"Ras2",D$4) -> 332.30265 | E5: =(C5*$O5+D5*$P5)/SUM($O5,$P5) -> 340.59971 | F5: =(B5*$N5+C5*$O5+D5*$P5)/SUM($N5:$P5) -> 316.75628 | H5: =GETPIVOTDATA("Sum of Ålder*Antal",'G&D slakt'!$L$3,"Djur2",$A5,"Ras2",H$4)/GETPIVOTDATA("Sum of Antal djur",'G&D slakt'!$L$3,"Djur2",$A5,"Ras2",H$4) -> 62.218325 | I5: =GETPIVOTDATA("Sum of Ålder*Antal",'G&D slakt'!$L$3,"Djur2",$A5,"Ras2",I$4)/GETPIVOTDATA("Sum of Antal djur",'G&D slakt'!$L$3,"Djur2",$A5,"Ras2",I$4) -> 80.94551 | J5: =GETPIVOTDATA("Sum of Ålder*Antal",'G&D slakt'!$L$3,"Djur2",$A5,"Ras2",J$4)/GETPIVOTDATA("Sum of Antal djur",'G&D slakt'!$L$3,"Djur2",$A5,"Ras2",J$4) -> 73.976022 | K5: =(I5*$O5+J5*$P5)/SUM($O5,$P5) -> 76.487235 | L5: =(H5*$N5+I5*$O5+J5*$P5)/SUM($N5:$P5) -> 66.591788 | N5: =GETPIVOTDATA("Sum of Antal djur",'G&D slakt'!$L$3,"Djur2",$A5,"Ras2",N$4)/5 -> 91700 | O5: =GETPIVOTDATA("Sum of Antal djur",'G&D slakt'!$L$3,"Djur2",$A5,"Ras2",O$4)/5 -> 14603 | P5: =GETPIVOTDATA("Sum of Antal djur",'G&D slakt'!$L$3,"Djur2",$A5,"Ras2",P$4)/5 -> 25925.4 | Q5: =SUM(O5,P5) -> 40528.4 | R5: =SUM(N5,O5,P5) -> 132228.4
A6: ko | B6: =GETPIVOTDATA("Sum of Slaktvikt*Antal",'G&D slakt'!$L$3,"Djur",$A6,"Ras2",B$4)/GETPIVOTDATA("Sum of Antal djur",'G&D slakt'!$L$3,"Djur",$A6,"Ras2",B$4) -> #REF! | C6: =GETPIVOTDATA("Sum of Slaktvikt*Antal",'G&D slakt'!$L$3,"Djur",$A6,"Ras2",C$4)/GETPIVOTDATA("Sum of Antal djur",'G&D slakt'!$L$3,"Djur",$A6,"Ras2",C$4) -> #REF! | D6: =GETPIVOTDATA("Sum of Slaktvikt*Antal",'G&D slakt'!$L$3,"Djur",$A6,"Ras2",D$4)/GETPIVOTDATA("Sum of Antal djur",'G&D slakt'!$L$3,"Djur",$A6,"Ras2",D$4) -> #REF! | E6: =(C6*$O6+D6*$P6)/SUM($O6,$P6) -> #REF! | F6: =(B6*$N6+C6*$O6+D6*$P6)/SUM($N6:$P6) -> #REF! | H6: =GETPIVOTDATA("Sum of Ålder*Antal",'G&D slakt'!$L$3,"Djur",$A6,"Ras2",H$4)/GETPIVOTDATA("Sum of Antal djur",'G&D slakt'!$L$3,"Djur",$A6,"Ras2",H$4) -> #REF! | I6: =GETPIVOTDATA("Sum of Ålder*Antal",'G&D slakt'!$L$3,"Djur",$A6,"Ras2",I$4)/GETPIVOTDATA("Sum of Antal djur",'G&D slakt'!$L$3,"Djur",$A6,"Ras2",I$4) -> #REF! | J6: =GETPIVOTDATA("Sum of Ålder*Antal",'G&D slakt'!$L$3,"Djur",$A6,"Ras2",J$4)/GETPIVOTDATA("Sum of Antal djur",'G&D slakt'!$L$3,"Djur",$A6,"Ras2",J$4) -> #REF! | K6: =(I6*$O6+J6*$P6)/SUM($O6,$P6) -> #REF! | L6: =(H6*$N6+I6*$O6+J6*$P6)/SUM($N6:$P6) -> #REF! | N6: =GETPIVOTDATA("Sum of Antal djur",'G&D slakt'!$L$3,"Djur",$A6,"Ras2",N$4)/5 -> #REF! | O6: =GETPIVOTDATA("Sum of Antal djur",'G&D slakt'!$L$3,"Djur",$A6,"Ras2",O$4)/5 -> #REF! | P6: =GETPIVOTDATA("Sum of Antal djur",'G&D slakt'!$L$3,"Djur",$A6,"Ras2",P$4)/5 -> #REF! | Q6: =SUM(O6,P6) -> #REF! | R6: =SUM(N6,O6,P6) -> #REF!
A7: ungko | B7: =GETPIVOTDATA("Sum of Slaktvikt*Antal",'G&D slakt'!$L$3,"Djur",$A7,"Ras2",B$4)/GETPIVOTDATA("Sum of Antal djur",'G&D slakt'!$L$3,"Djur",$A7,"Ras2",B$4) -> #REF! | C7: =GETPIVOTDATA("Sum of Slaktvikt*Antal",'G&D slakt'!$L$3,"Djur",$A7,"Ras2",C$4)/GETPIVOTDATA("Sum of Antal djur",'G&D slakt'!$L$3,"Djur",$A7,"Ras2",C$4) -> #REF! | D7: =GETPIVOTDATA("Sum of Slaktvikt*Antal",'G&D slakt'!$L$3,"Djur",$A7,"Ras2",D$4)/GETPIVOTDATA("Sum of Antal djur",'G&D slakt'!$L$3,"Djur",$A7,"Ras2",D$4) -> #REF! | E7: =(C7*$O7+D7*$P7)/SUM($O7,$P7) -> #REF! | F7: =(B7*$N7+C7*$O7+D7*$P7)/SUM($N7:$P7) -> #REF! | H7: =GETPIVOTDATA("Sum of Ålder*Antal",'G&D slakt'!$L$3,"Djur",$A7,"Ras2",H$4)/GETPIVOTDATA("Sum of Antal djur",'G&D slakt'!$L$3,"Djur",$A7,"Ras2",H$4) -> #REF! | I7: =GETPIVOTDATA("Sum of Ålder*Antal",'G&D slakt'!$L$3,"Djur",$A7,"Ras2",I$4)/GETPIVOTDATA("Sum of Antal djur",'G&D slakt'!$L$3,"Djur",$A7,"Ras2",I$4) -> #REF! | J7: =GETPIVOTDATA("Sum of Ålder*Antal",'G&D slakt'!$L$3,"Djur",$A7,"Ras2",J$4)/GETPIVOTDATA("Sum of Antal djur",'G&D slakt'!$L$3,"Djur",$A7,"Ras2",J$4) -> #REF! | K7: =(I7*$O7+J7*$P7)/SUM($O7,$P7) -> #REF! | L7: =(H7*$N7+I7*$O7+J7*$P7)/SUM($N7:$P7) -> #REF! | N7: =GETPIVOTDATA("Sum of Antal djur",'G&D slakt'!$L$3,"Djur",$A7,"Ras2",N$4)/5 -> #REF! | O7: =GETPIVOTDATA("Sum of Antal djur",'G&D slakt'!$L$3,"Djur",$A7,"Ras2",O$4)/5 -> #REF! | P7: =GETPIVOTDATA("Sum of Antal djur",'G&D slakt'!$L$3,"Djur",$A7,"Ras2",P$4)/5 -> #REF! | Q7: =SUM(O7,P7) -> #REF! | R7: =SUM(N7,O7,P7) -> #REF!
A8: kviga | B8: =GETPIVOTDATA("Sum of Slaktvikt*Antal",'G&D slakt'!$L$3,"Djur",$A8,"Ras2",B$4)/GETPIVOTDATA("Sum of Antal djur",'G&D slakt'!$L$3,"Djur",$A8,"Ras2",B$4) -> #REF! | C8: =GETPIVOTDATA("Sum of Slaktvikt*Antal",'G&D slakt'!$L$3,"Djur",$A8,"Ras2",C$4)/GETPIVOTDATA("Sum of Antal djur",'G&D slakt'!$L$3,"Djur",$A8,"Ras2",C$4) -> #REF! | D8: =GETPIVOTDATA("Sum of Slaktvikt*Antal",'G&D slakt'!$L$3,"Djur",$A8,"Ras2",D$4)/GETPIVOTDATA("Sum of Antal djur",'G&D slakt'!$L$3,"Djur",$A8,"Ras2",D$4) -> #REF! | E8: =(C8*$O8+D8*$P8)/SUM($O8,$P8) -> #REF! | F8: =(B8*$N8+C8*$O8+D8*$P8)/SUM($N8:$P8) -> #REF! | H8: =GETPIVOTDATA("Sum of Ålder*Antal",'G&D slakt'!$L$3,"Djur",$A8,"Ras2",H$4)/GETPIVOTDATA("Sum of Antal djur",'G&D slakt'!$L$3,"Djur",$A8,"Ras2",H$4) -> #REF! | I8: =GETPIVOTDATA("Sum of Ålder*Antal",'G&D slakt'!$L$3,"Djur",$A8,"Ras2",I$4)/GETPIVOTDATA("Sum of Antal djur",'G&D slakt'!$L$3,"Djur",$A8,"Ras2",I$4) -> #REF! | J8: =GETPIVOTDATA("Sum of Ålder*Antal",'G&D slakt'!$L$3,"Djur",$A8,"Ras2",J$4)/GETPIVOTDATA("Sum of Antal djur",'G&D slakt'!$L$3,"Djur",$A8,"Ras2",J$4) -> #REF! | K8: =(I8*$O8+J8*$P8)/SUM($O8,$P8) -> #REF! | L8: =(H8*$N8+I8*$O8+J8*$P8)/SUM($N8:$P8) -> #REF! | N8: =GETPIVOTDATA("Sum of Antal djur",'G&D slakt'!$L$3,"Djur",$A8,"Ras2",N$4)/5 -> #REF! | O8: =GETPIVOTDATA("Sum of Antal djur",'G&D slakt'!$L$3,"Djur",$A8,"Ras2",O$4)/5 -> #REF! | P8: =GETPIVOTDATA("Sum of Antal djur",'G&D slakt'!$L$3,"Djur",$A8,"Ras2",P$4)/5 -> #REF! | Q8: =SUM(O8,P8) -> #REF! | R8: =SUM(N8,O8,P8) -> #REF! | T8: =N8/SUM(N$8:N$10,N$13)*100 -> #REF! | U8: =O8/SUM(O$8:O$10,O$13)*100 -> #REF! | V8: =P8/SUM(P$8:P$10,P$13)*100 -> #REF! | W8: =Q8/SUM(Q$8:Q$10,Q$13)*100 -> #REF! | X8: =R8/SUM(R$8:R$10,R$13)*100 -> #REF!
A9: stut | B9: =GETPIVOTDATA("Sum of Slaktvikt*Antal",'G&D slakt'!$L$3,"Djur",$A9,"Ras2",B$4)/GETPIVOTDATA("Sum of Antal djur",'G&D slakt'!$L$3,"Djur",$A9,"Ras2",B$4) -> #REF! | C9: =GETPIVOTDATA("Sum of Slaktvikt*Antal",'G&D slakt'!$L$3,"Djur",$A9,"Ras2",C$4)/GETPIVOTDATA("Sum of Antal djur",'G&D slakt'!$L$3,"Djur",$A9,"Ras2",C$4) -> #REF! | D9: =GETPIVOTDATA("Sum of Slaktvikt*Antal",'G&D slakt'!$L$3,"Djur",$A9,"Ras2",D$4)/GETPIVOTDATA("Sum of Antal djur",'G&D slakt'!$L$3,"Djur",$A9,"Ras2",D$4) -> #REF! | E9: =(C9*$O9+D9*$P9)/SUM($O9,$P9) -> #REF! | F9: =(B9*$N9+C9*$O9+D9*$P9)/SUM($N9:$P9) -> #REF! | H9: =GETPIVOTDATA("Sum of Ålder*Antal",'G&D slakt'!$L$3,"Djur",$A9,"Ras2",H$4)/GETPIVOTDATA("Sum of Antal djur",'G&D slakt'!$L$3,"Djur",$A9,"Ras2",H$4) -> #REF! | I9: =GETPIVOTDATA("Sum of Ålder*Antal",'G&D slakt'!$L$3,"Djur",$A9,"Ras2",I$4)/GETPIVOTDATA("Sum of Antal djur",'G&D slakt'!$L$3,"Djur",$A9,"Ras2",I$4) -> #REF! | J9: =GETPIVOTDATA("Sum of Ålder*Antal",'G&D slakt'!$L$3,"Djur",$A9,"Ras2",J$4)/GETPIVOTDATA("Sum of Antal djur",'G&D slakt'!$L$3,"Djur",$A9,"Ras2",J$4) -> #REF! | K9: =(I9*$O9+J9*$P9)/SUM($O9,$P9) -> #REF! | L9: =(H9*$N9+I9*$O9+J9*$P9)/SUM($N9:$P9) -> #REF! | N9: =GETPIVOTDATA("Sum of Antal djur",'G&D slakt'!$L$3,"Djur",$A9,"Ras2",N$4)/5 -> #REF! | O9: =GETPIVOTDATA("Sum of Antal djur",'G&D slakt'!$L$3,"Djur",$A9,"Ras2",O$4)/5 -> #REF! | P9: =GETPIVOTDATA("Sum of Antal djur",'G&D slakt'!$L$3,"Djur",$A9,"Ras2",P$4)/5 -> #REF! | Q9: =SUM(O9,P9) -> #REF! | R9: =SUM(N9,O9,P9) -> #REF! | T9: =N9/SUM(N$8:N$10,N$13)*100 -> #REF! | U9: =O9/SUM(O$8:O$10,O$13)*100 -> #REF! | V9: =P9/SUM(P$8:P$10,P$13)*100 -> #REF! | W9: =Q9/SUM(Q$8:Q$10,Q$13)*100 -> #REF! | X9: =R9/SUM(R$8:R$10,R$13)*100 -> #REF!
A10: tjur, tot | B10: =GETPIVOTDATA("Sum of Slaktvikt*Antal",'G&D slakt'!$L$3,"Djur2",$A10,"Ras2",B$4)/GETPIVOTDATA("Sum of Antal djur",'G&D slakt'!$L$3,"Djur2",$A10,"Ras2",B$4) -> 328.87656 | C10: =GETPIVOTDATA("Sum of Slaktvikt*Antal",'G&D slakt'!$L$3,"Djur2",$A10,"Ras2",C$4)/GETPIVOTDATA("Sum of Antal djur",'G&D slakt'!$L$3,"Djur2",$A10,"Ras2",C$4) -> 360.08085 | D10: =GETPIVOTDATA("Sum of Slaktvikt*Antal",'G&D slakt'!$L$3,"Djur2",$A10,"Ras2",D$4)/GETPIVOTDATA("Sum of Antal djur",'G&D slakt'!$L$3,"Djur2",$A10,"Ras2",D$4) -> 357.55355 | E10: =(C10*$O10+D10*$P10)/SUM($O10,$P10) -> 358.43398 | F10: =(B10*$N10+C10*$O10+D10*$P10)/SUM($N10:$P10) -> 343.92766 | H10: =GETPIVOTDATA("Sum of Ålder*Antal",'G&D slakt'!$L$3,"Djur2",$A10,"Ras2",H$4)/GETPIVOTDATA("Sum of Antal djur",'G&D slakt'!$L$3,"Djur2",$A10,"Ras2",H$4) -> 22.579883 | I10: =GETPIVOTDATA("Sum of Ålder*Antal",'G&D slakt'!$L$3,"Djur2",$A10,"Ras2",I$4)/GETPIVOTDATA("Sum of Antal djur",'G&D slakt'!$L$3,"Djur2",$A10,"Ras2",I$4) -> 20.314216 | J10: =GETPIVOTDATA("Sum of Ålder*Antal",'G&D slakt'!$L$3,"Djur2",$A10,"Ras2",J$4)/GETPIVOTDATA("Sum of Antal djur",'G&D slakt'!$L$3,"Djur2",$A10,"Ras2",J$4) -> 19.998097 | K10: =(I10*$O10+J10*$P10)/SUM($O10,$P10) -> 20.108223 | L10: =(H10*$N10+I10*$O10+J10*$P10)/SUM($N10:$P10) -> 21.321276 | N10: =GETPIVOTDATA("Sum of Antal djur",'G&D slakt'!$L$3,"Djur2",$A10,"Ras2",N$4)/5 -> 81221.8 | O10: =GETPIVOTDATA("Sum of Antal djur",'G&D slakt'!$L$3,"Djur2",$A10,"Ras2",O$4)/5 -> 29357.8 | P10: =GETPIVOTDATA("Sum of Antal djur",'G&D slakt'!$L$3,"Djur2",$A10,"Ras2",P$4)/5 -> 54914.2 | Q10: =SUM(O10,P10) -> 84272 | R10: =SUM(N10,O10,P10) -> 165493.8 | T10: =N10/SUM(N$8:N$10,N$13)*100 -> #REF! | U10: =O10/SUM(O$8:O$10,O$13)*100 -> #REF! | V10: =P10/SUM(P$8:P$10,P$13)*100 -> #REF! | W10: =Q10/SUM(Q$8:Q$10,Q$13)*100 -> #REF! | X10: =R10/SUM(R$8:R$10,R$13)*100 -> #REF!
A11: ungtjur | B11: =GETPIVOTDATA("Sum of Slaktvikt*Antal",'G&D slakt'!$L$3,"Djur",$A11,"Ras2",B$4)/GETPIVOTDATA("Sum of Antal djur",'G&D slakt'!$L$3,"Djur",$A11,"Ras2",B$4) -> #REF! | C11: =GETPIVOTDATA("Sum of Slaktvikt*Antal",'G&D slakt'!$L$3,"Djur",$A11,"Ras2",C$4)/GETPIVOTDATA("Sum of Antal djur",'G&D slakt'!$L$3,"Djur",$A11,"Ras2",C$4) -> #REF! | D11: =GETPIVOTDATA("Sum of Slaktvikt*Antal",'G&D slakt'!$L$3,"Djur",$A11,"Ras2",D$4)/GETPIVOTDATA("Sum of Antal djur",'G&D slakt'!$L$3,"Djur",$A11,"Ras2",D$4) -> #REF! | E11: =(C11*$O11+D11*$P11)/SUM($O11,$P11) -> #REF! | F11: =(B11*$N11+C11*$O11+D11*$P11)/SUM($N11:$P11) -> #REF! | H11: =GETPIVOTDATA("Sum of Ålder*Antal",'G&D slakt'!$L$3,"Djur",$A11,"Ras2",H$4)/GETPIVOTDATA("Sum of Antal djur",'G&D slakt'!$L$3,"Djur",$A11,"Ras2",H$4) -> #REF! | I11: =GETPIVOTDATA("Sum of Ålder*Antal",'G&D slakt'!$L$3,"Djur",$A11,"Ras2",I$4)/GETPIVOTDATA("Sum of Antal djur",'G&D slakt'!$L$3,"Djur",$A11,"Ras2",I$4) -> #REF! | J11: =GETPIVOTDATA("Sum of Ålder*Antal",'G&D slakt'!$L$3,"Djur",$A11,"Ras2",J$4)/GETPIVOTDATA("Sum of Antal djur",'G&D slakt'!$L$3,"Djur",$A11,"Ras2",J$4) -> #REF! | K11: =(I11*$O11+J11*$P11)/SUM($O11,$P11) -> #REF! | L11: =(H11*$N11+I11*$O11+J11*$P11)/SUM($N11:$P11) -> #REF! | N11: =GETPIVOTDATA("Sum of Antal djur",'G&D slakt'!$L$3,"Djur",$A11,"Ras2",N$4)/5 -> #REF! | O11: =GETPIVOTDATA("Sum of Antal djur",'G&D slakt'!$L$3,"Djur",$A11,"Ras2",O$4)/5 -> #REF! | P11: =GETPIVOTDATA("Sum of Antal djur",'G&D slakt'!$L$3,"Djur",$A11,"Ras2",P$4)/5 -> #REF! | Q11: =SUM(O11,P11) -> #REF! | R11: =SUM(N11,O11,P11) -> #REF! | T11: =N11/SUM(N$8:N$10,N$13)*100 -> #REF! | U11: =O11/SUM(O$8:O$10,O$13)*100 -> #REF! | V11: =P11/SUM(P$8:P$10,P$13)*100 -> #REF! | W11: =Q11/SUM(Q$8:Q$10,Q$13)*100 -> #REF! | X11: =R11/SUM(R$8:R$10,R$13)*100 -> #REF!
A12: yngre tjur | B12: =GETPIVOTDATA("Sum of Slaktvikt*Antal",'G&D slakt'!$L$3,"Djur",$A12,"Ras2",B$4)/GETPIVOTDATA("Sum of Antal djur",'G&D slakt'!$L$3,"Djur",$A12,"Ras2",B$4) -> #REF! | C12: =GETPIVOTDATA("Sum of Slaktvikt*Antal",'G&D slakt'!$L$3,"Djur",$A12,"Ras2",C$4)/GETPIVOTDATA("Sum of Antal djur",'G&D slakt'!$L$3,"Djur",$A12,"Ras2",C$4) -> #REF! | D12: =GETPIVOTDATA("Sum of Slaktvikt*Antal",'G&D slakt'!$L$3,"Djur",$A12,"Ras2",D$4)/GETPIVOTDATA("Sum of Antal djur",'G&D slakt'!$L$3,"Djur",$A12,"Ras2",D$4) -> #REF! | E12: =(C12*$O12+D12*$P12)/SUM($O12,$P12) -> #REF! | F12: =(B12*$N12+C12*$O12+D12*$P12)/SUM($N12:$P12) -> #REF! | H12: =GETPIVOTDATA("Sum of Ålder*Antal",'G&D slakt'!$L$3,"Djur",$A12,"Ras2",H$4)/GETPIVOTDATA("Sum of Antal djur",'G&D slakt'!$L$3,"Djur",$A12,"Ras2",H$4) -> #REF! | I12: =GETPIVOTDATA("Sum of Ålder*Antal",'G&D slakt'!$L$3,"Djur",$A12,"Ras2",I$4)/GETPIVOTDATA("Sum of Antal djur",'G&D slakt'!$L$3,"Djur",$A12,"Ras2",I$4) -> #REF! | J12: =GETPIVOTDATA("Sum of Ålder*Antal",'G&D slakt'!$L$3,"Djur",$A12,"Ras2",J$4)/GETPIVOTDATA("Sum of Antal djur",'G&D slakt'!$L$3,"Djur",$A12,"Ras2",J$4) -> #REF! | K12: =(I12*$O12+J12*$P12)/SUM($O12,$P12) -> #REF! | L12: =(H12*$N12+I12*$O12+J12*$P12)/SUM($N12:$P12) -> #REF! | N12: =GETPIVOTDATA("Sum of Antal djur",'G&D slakt'!$L$3,"Djur",$A12,"Ras2",N$4)/5 -> #REF! | O12: =GETPIVOTDATA("Sum of Antal djur",'G&D slakt'!$L$3,"Djur",$A12,"Ras2",O$4)/5 -> #REF! | P12: =GETPIVOTDATA("Sum of Antal djur",'G&D slakt'!$L$3,"Djur",$A12,"Ras2",P$4)/5 -> #REF! | Q12: =SUM(O12,P12) -> #REF! | R12: =SUM(N12,O12,P12) -> #REF! | T12: =N12/SUM(N$8:N$10,N$13)*100 -> #REF! | U12: =O12/SUM(O$8:O$10,O$13)*100 -> #REF! | V12: =P12/SUM(P$8:P$10,P$13)*100 -> #REF! | W12: =Q12/SUM(Q$8:Q$10,Q$13)*100 -> #REF! | X12: =R12/SUM(R$8:R$10,R$13)*100 -> #REF!
A13: mellankalv | B13: =GETPIVOTDATA("Sum of Slaktvikt*Antal",'G&D slakt'!$L$3,"Djur",$A13,"Ras2",B$4)/GETPIVOTDATA("Sum of Antal djur",'G&D slakt'!$L$3,"Djur",$A13,"Ras2",B$4) -> #REF! | C13: =GETPIVOTDATA("Sum of Slaktvikt*Antal",'G&D slakt'!$L$3,"Djur",$A13,"Ras2",C$4)/GETPIVOTDATA("Sum of Antal djur",'G&D slakt'!$L$3,"Djur",$A13,"Ras2",C$4) -> #REF! | D13: =GETPIVOTDATA("Sum of Slaktvikt*Antal",'G&D slakt'!$L$3,"Djur",$A13,"Ras2",D$4)/GETPIVOTDATA("Sum of Antal djur",'G&D slakt'!$L$3,"Djur",$A13,"Ras2",D$4) -> #REF! | E13: =(C13*$O13+D13*$P13)/SUM($O13,$P13) -> #REF! | F13: =(B13*$N13+C13*$O13+D13*$P13)/SUM($N13:$P13) -> #REF! | H13: =GETPIVOTDATA("Sum of Ålder*Antal",'G&D slakt'!$L$3,"Djur",$A13,"Ras2",H$4)/GETPIVOTDATA("Sum of Antal djur",'G&D slakt'!$L$3,"Djur",$A13,"Ras2",H$4) -> #REF! | I13: =GETPIVOTDATA("Sum of Ålder*Antal",'G&D slakt'!$L$3,"Djur",$A13,"Ras2",I$4)/GETPIVOTDATA("Sum of Antal djur",'G&D slakt'!$L$3,"Djur",$A13,"Ras2",I$4) -> #REF! | J13: =GETPIVOTDATA("Sum of Ålder*Antal",'G&D slakt'!$L$3,"Djur",$A13,"Ras2",J$4)/GETPIVOTDATA("Sum of Antal djur",'G&D slakt'!$L$3,"Djur",$A13,"Ras2",J$4) -> #REF! | K13: =(I13*$O13+J13*$P13)/SUM($O13,$P13) -> #REF! | L13: =(H13*$N13+I13*$O13+J13*$P13)/SUM($N13:$P13) -> #REF! | N13: =GETPIVOTDATA("Sum of Antal djur",'G&D slakt'!$L$3,"Djur",$A13,"Ras2",N$4)/5 -> #REF! | O13: =GETPIVOTDATA("Sum of Antal djur",'G&D slakt'!$L$3,"Djur",$A13,"Ras2",O$4)/5 -> #REF! | P13: =GETPIVOTDATA("Sum of Antal djur",'G&D slakt'!$L$3,"Djur",$A13,"Ras2",P$4)/5 -> #REF! | Q13: =SUM(O13,P13) -> #REF! | R13: =SUM(N13,O13,P13) -> #REF! | T13: =N13/SUM(N$8:N$10,N$13)*100 -> #REF! | U13: =O13/SUM(O$8:O$10,O$13)*100 -> #REF! | V13: =P13/SUM(P$8:P$10,P$13)*100 -> #REF! | W13: =Q13/SUM(Q$8:Q$10,Q$13)*100 -> #REF! | X13: =R13/SUM(R$8:R$10,R$13)*100 -> #REF!
H15: =H10/H11 -> #REF! | I15: =I10/I11 -> #REF! | J15: =J10/J11 -> #REF! | K15: =K10/K11 -> #REF! | L15: =L10/L11 -> #REF!

Sheet Växa slakt
A1: Medelvärde för 2015-2019
C4: Antal djur | D4: Födelsevikt (kg) | E4: Slaktvikt (kg) | F4: Klass | G4: Fett | H4: Ålder (mån) | I4: Slakttillväxt | N4: Antal djur | P4: Slaktvikt (kg) | R4: Ålder (mån)
